[2024-05-02 17:22:05,583] {taskinstance.py:1032} INFO - Dependencies all met for <TaskInstance: ingest_data_bigquery_yt.local_to_gcs_task scheduled__2019-11-02T06:00:00+00:00 [queued]>
[2024-05-02 17:22:05,595] {taskinstance.py:1032} INFO - Dependencies all met for <TaskInstance: ingest_data_bigquery_yt.local_to_gcs_task scheduled__2019-11-02T06:00:00+00:00 [queued]>
[2024-05-02 17:22:05,595] {taskinstance.py:1238} INFO - 
--------------------------------------------------------------------------------
[2024-05-02 17:22:05,595] {taskinstance.py:1239} INFO - Starting attempt 3 of 4
[2024-05-02 17:22:05,595] {taskinstance.py:1240} INFO - 
--------------------------------------------------------------------------------
[2024-05-02 17:22:05,607] {taskinstance.py:1259} INFO - Executing <Task(PythonOperator): local_to_gcs_task> on 2019-11-02 06:00:00+00:00
[2024-05-02 17:22:05,614] {standard_task_runner.py:52} INFO - Started process 2663 to run task
[2024-05-02 17:22:05,619] {standard_task_runner.py:76} INFO - Running: ['***', 'tasks', 'run', 'ingest_data_bigquery_yt', 'local_to_gcs_task', 'scheduled__2019-11-02T06:00:00+00:00', '--job-id', '3796', '--raw', '--subdir', 'DAGS_FOLDER/data_ingestion_gcs_yt_dag.py', '--cfg-path', '/tmp/tmp1ozk21kj', '--error-file', '/tmp/tmpvxkitv7a']
[2024-05-02 17:22:05,624] {standard_task_runner.py:77} INFO - Job 3796: Subtask local_to_gcs_task
[2024-05-02 17:22:05,695] {logging_mixin.py:109} INFO - Running <TaskInstance: ingest_data_bigquery_yt.local_to_gcs_task scheduled__2019-11-02T06:00:00+00:00 [running]> on host 1ed1a38cd1e3
[2024-05-02 17:22:05,740] {warnings.py:99} WARNING - /home/***/.local/lib/python3.6/site-packages/***/utils/context.py:152: AirflowContextDeprecationWarning: Accessing 'execution_date' from the template is deprecated and will be removed in a future version. Please use 'data_interval_start' or 'logical_date' instead.
  warnings.warn(_create_deprecation_warning(key, self._deprecation_replacements[key]))

[2024-05-02 17:22:05,773] {taskinstance.py:1426} INFO - Exporting the following env vars:
AIRFLOW_CTX_DAG_OWNER=***
AIRFLOW_CTX_DAG_ID=ingest_data_bigquery_yt
AIRFLOW_CTX_TASK_ID=local_to_gcs_task
AIRFLOW_CTX_EXECUTION_DATE=2019-11-02T06:00:00+00:00
AIRFLOW_CTX_DAG_RUN_ID=scheduled__2019-11-02T06:00:00+00:00
[2024-05-02 17:22:21,346] {warnings.py:99} WARNING - /home/***/.local/lib/python3.6/site-packages/***/operators/python.py:174: DtypeWarning: Columns (6) have mixed types.Specify dtype option on import or set low_memory=False.
  return_value = self.execute_callable()

[2024-05-02 17:22:33,898] {python.py:175} INFO - Done. Returned value was: None
[2024-05-02 17:22:33,919] {taskinstance.py:1277} INFO - Marking task as SUCCESS. dag_id=ingest_data_bigquery_yt, task_id=local_to_gcs_task, execution_date=20191102T060000, start_date=20240502T172205, end_date=20240502T172233
[2024-05-02 17:22:33,993] {local_task_job.py:154} INFO - Task exited with return code 0
[2024-05-02 17:22:34,034] {local_task_job.py:264} INFO - 1 downstream tasks scheduled from follow-on schedule check
[2024-05-03 17:42:48,706] {taskinstance.py:1032} INFO - Dependencies all met for <TaskInstance: ingest_data_bigquery_yt.local_to_gcs_task scheduled__2019-11-02T06:00:00+00:00 [queued]>
[2024-05-03 17:42:48,722] {taskinstance.py:1032} INFO - Dependencies all met for <TaskInstance: ingest_data_bigquery_yt.local_to_gcs_task scheduled__2019-11-02T06:00:00+00:00 [queued]>
[2024-05-03 17:42:48,722] {taskinstance.py:1238} INFO - 
--------------------------------------------------------------------------------
[2024-05-03 17:42:48,722] {taskinstance.py:1239} INFO - Starting attempt 3 of 3
[2024-05-03 17:42:48,722] {taskinstance.py:1240} INFO - 
--------------------------------------------------------------------------------
[2024-05-03 17:42:48,736] {taskinstance.py:1259} INFO - Executing <Task(PythonOperator): local_to_gcs_task> on 2019-11-02 06:00:00+00:00
[2024-05-03 17:42:48,743] {standard_task_runner.py:52} INFO - Started process 1320 to run task
[2024-05-03 17:42:48,750] {standard_task_runner.py:76} INFO - Running: ['***', 'tasks', 'run', 'ingest_data_bigquery_yt', 'local_to_gcs_task', 'scheduled__2019-11-02T06:00:00+00:00', '--job-id', '4324', '--raw', '--subdir', 'DAGS_FOLDER/data_ingstion_gcs_yt_dag.py', '--cfg-path', '/tmp/tmpgv0ej6bn', '--error-file', '/tmp/tmpf1mup46h']
[2024-05-03 17:42:48,756] {standard_task_runner.py:77} INFO - Job 4324: Subtask local_to_gcs_task
[2024-05-03 17:42:48,844] {logging_mixin.py:109} INFO - Running <TaskInstance: ingest_data_bigquery_yt.local_to_gcs_task scheduled__2019-11-02T06:00:00+00:00 [running]> on host f0ab9bf9b587
[2024-05-03 17:42:48,900] {warnings.py:99} WARNING - /home/***/.local/lib/python3.6/site-packages/***/utils/context.py:152: AirflowContextDeprecationWarning: Accessing 'execution_date' from the template is deprecated and will be removed in a future version. Please use 'data_interval_start' or 'logical_date' instead.
  warnings.warn(_create_deprecation_warning(key, self._deprecation_replacements[key]))

[2024-05-03 17:42:48,941] {taskinstance.py:1426} INFO - Exporting the following env vars:
AIRFLOW_CTX_DAG_OWNER=***
AIRFLOW_CTX_DAG_ID=ingest_data_bigquery_yt
AIRFLOW_CTX_TASK_ID=local_to_gcs_task
AIRFLOW_CTX_EXECUTION_DATE=2019-11-02T06:00:00+00:00
AIRFLOW_CTX_DAG_RUN_ID=scheduled__2019-11-02T06:00:00+00:00
[2024-05-03 17:43:06,815] {warnings.py:99} WARNING - /home/***/.local/lib/python3.6/site-packages/***/operators/python.py:174: DtypeWarning: Columns (6) have mixed types.Specify dtype option on import or set low_memory=False.
  return_value = self.execute_callable()

[2024-05-03 17:43:20,816] {python.py:175} INFO - Done. Returned value was: None
[2024-05-03 17:43:20,836] {taskinstance.py:1277} INFO - Marking task as SUCCESS. dag_id=ingest_data_bigquery_yt, task_id=local_to_gcs_task, execution_date=20191102T060000, start_date=20240503T174248, end_date=20240503T174320
[2024-05-03 17:43:21,025] {local_task_job.py:154} INFO - Task exited with return code 0
[2024-05-03 17:43:21,093] {local_task_job.py:264} INFO - 1 downstream tasks scheduled from follow-on schedule check
[2024-05-05 13:54:01,246] {taskinstance.py:1032} INFO - Dependencies all met for <TaskInstance: ingest_data_bigquery_yt.local_to_gcs_task scheduled__2019-11-02T06:00:00+00:00 [queued]>
[2024-05-05 13:54:01,331] {taskinstance.py:1032} INFO - Dependencies all met for <TaskInstance: ingest_data_bigquery_yt.local_to_gcs_task scheduled__2019-11-02T06:00:00+00:00 [queued]>
[2024-05-05 13:54:01,331] {taskinstance.py:1238} INFO - 
--------------------------------------------------------------------------------
[2024-05-05 13:54:01,332] {taskinstance.py:1239} INFO - Starting attempt 3 of 3
[2024-05-05 13:54:01,332] {taskinstance.py:1240} INFO - 
--------------------------------------------------------------------------------
[2024-05-05 13:54:01,387] {taskinstance.py:1259} INFO - Executing <Task(PythonOperator): local_to_gcs_task> on 2019-11-02 06:00:00+00:00
[2024-05-05 13:54:01,419] {standard_task_runner.py:52} INFO - Started process 126 to run task
[2024-05-05 13:54:01,460] {standard_task_runner.py:76} INFO - Running: ['***', 'tasks', 'run', 'ingest_data_bigquery_yt', 'local_to_gcs_task', 'scheduled__2019-11-02T06:00:00+00:00', '--job-id', '4421', '--raw', '--subdir', 'DAGS_FOLDER/data_ingstion_gcs_yt_dag.py', '--cfg-path', '/tmp/tmp3achuzwx', '--error-file', '/tmp/tmp65ihnykb']
[2024-05-05 13:54:01,474] {standard_task_runner.py:77} INFO - Job 4421: Subtask local_to_gcs_task
[2024-05-05 13:54:01,751] {logging_mixin.py:109} INFO - Running <TaskInstance: ingest_data_bigquery_yt.local_to_gcs_task scheduled__2019-11-02T06:00:00+00:00 [running]> on host 43faca6eb596
[2024-05-05 13:54:01,854] {warnings.py:99} WARNING - /home/***/.local/lib/python3.6/site-packages/***/utils/context.py:152: AirflowContextDeprecationWarning: Accessing 'execution_date' from the template is deprecated and will be removed in a future version. Please use 'data_interval_start' or 'logical_date' instead.
  warnings.warn(_create_deprecation_warning(key, self._deprecation_replacements[key]))

[2024-05-05 13:54:01,965] {taskinstance.py:1426} INFO - Exporting the following env vars:
AIRFLOW_CTX_DAG_OWNER=***
AIRFLOW_CTX_DAG_ID=ingest_data_bigquery_yt
AIRFLOW_CTX_TASK_ID=local_to_gcs_task
AIRFLOW_CTX_EXECUTION_DATE=2019-11-02T06:00:00+00:00
AIRFLOW_CTX_DAG_RUN_ID=scheduled__2019-11-02T06:00:00+00:00
[2024-05-05 13:54:02,022] {taskinstance.py:1700} ERROR - Task failed with exception
Traceback (most recent call last):
  File "/home/airflow/.local/lib/python3.6/site-packages/airflow/models/taskinstance.py", line 1329, in _run_raw_task
    self._execute_task_with_callbacks(context)
  File "/home/airflow/.local/lib/python3.6/site-packages/airflow/models/taskinstance.py", line 1455, in _execute_task_with_callbacks
    result = self._execute_task(context, self.task)
  File "/home/airflow/.local/lib/python3.6/site-packages/airflow/models/taskinstance.py", line 1511, in _execute_task
    result = execute_callable(context=context)
  File "/home/airflow/.local/lib/python3.6/site-packages/airflow/operators/python.py", line 174, in execute
    return_value = self.execute_callable()
  File "/home/airflow/.local/lib/python3.6/site-packages/airflow/operators/python.py", line 185, in execute_callable
    return self.python_callable(*self.op_args, **self.op_kwargs)
  File "/opt/airflow/dags/data_ingstion_gcs_yt_dag.py", line 84, in upload_to_gcs
    __clean_file(raw_file_name, clean_file_name)
  File "/opt/airflow/dags/data_ingstion_gcs_yt_dag.py", line 65, in __clean_file
    "payment_type": "int64",
  File "/home/airflow/.local/lib/python3.6/site-packages/pandas/io/parsers.py", line 688, in read_csv
    return _read(filepath_or_buffer, kwds)
  File "/home/airflow/.local/lib/python3.6/site-packages/pandas/io/parsers.py", line 454, in _read
    parser = TextFileReader(fp_or_buf, **kwds)
  File "/home/airflow/.local/lib/python3.6/site-packages/pandas/io/parsers.py", line 948, in __init__
    self._make_engine(self.engine)
  File "/home/airflow/.local/lib/python3.6/site-packages/pandas/io/parsers.py", line 1180, in _make_engine
    self._engine = CParserWrapper(self.f, **self.options)
  File "/home/airflow/.local/lib/python3.6/site-packages/pandas/io/parsers.py", line 2010, in __init__
    self._reader = parsers.TextReader(src, **kwds)
  File "pandas/_libs/parsers.pyx", line 382, in pandas._libs.parsers.TextReader.__cinit__
  File "pandas/_libs/parsers.pyx", line 674, in pandas._libs.parsers.TextReader._setup_parser_source
FileNotFoundError: [Errno 2] No such file or directory: '/opt/airflow/raw_data/yellowtaxi_tripdata_2019-11.csv'
[2024-05-05 13:54:02,049] {taskinstance.py:1277} INFO - Marking task as FAILED. dag_id=ingest_data_bigquery_yt, task_id=local_to_gcs_task, execution_date=20191102T060000, start_date=20240505T135401, end_date=20240505T135402
[2024-05-05 13:54:02,090] {standard_task_runner.py:92} ERROR - Failed to execute job 4421 for task local_to_gcs_task
Traceback (most recent call last):
  File "/home/airflow/.local/lib/python3.6/site-packages/airflow/task/task_runner/standard_task_runner.py", line 85, in _start_by_fork
    args.func(args, dag=self.dag)
  File "/home/airflow/.local/lib/python3.6/site-packages/airflow/cli/cli_parser.py", line 48, in command
    return func(*args, **kwargs)
  File "/home/airflow/.local/lib/python3.6/site-packages/airflow/utils/cli.py", line 92, in wrapper
    return f(*args, **kwargs)
  File "/home/airflow/.local/lib/python3.6/site-packages/airflow/cli/commands/task_command.py", line 298, in task_run
    _run_task_by_selected_method(args, dag, ti)
  File "/home/airflow/.local/lib/python3.6/site-packages/airflow/cli/commands/task_command.py", line 107, in _run_task_by_selected_method
    _run_raw_task(args, ti)
  File "/home/airflow/.local/lib/python3.6/site-packages/airflow/cli/commands/task_command.py", line 184, in _run_raw_task
    error_file=args.error_file,
  File "/home/airflow/.local/lib/python3.6/site-packages/airflow/utils/session.py", line 70, in wrapper
    return func(*args, session=session, **kwargs)
  File "/home/airflow/.local/lib/python3.6/site-packages/airflow/models/taskinstance.py", line 1329, in _run_raw_task
    self._execute_task_with_callbacks(context)
  File "/home/airflow/.local/lib/python3.6/site-packages/airflow/models/taskinstance.py", line 1455, in _execute_task_with_callbacks
    result = self._execute_task(context, self.task)
  File "/home/airflow/.local/lib/python3.6/site-packages/airflow/models/taskinstance.py", line 1511, in _execute_task
    result = execute_callable(context=context)
  File "/home/airflow/.local/lib/python3.6/site-packages/airflow/operators/python.py", line 174, in execute
    return_value = self.execute_callable()
  File "/home/airflow/.local/lib/python3.6/site-packages/airflow/operators/python.py", line 185, in execute_callable
    return self.python_callable(*self.op_args, **self.op_kwargs)
  File "/opt/airflow/dags/data_ingstion_gcs_yt_dag.py", line 84, in upload_to_gcs
    __clean_file(raw_file_name, clean_file_name)
  File "/opt/airflow/dags/data_ingstion_gcs_yt_dag.py", line 65, in __clean_file
    "payment_type": "int64",
  File "/home/airflow/.local/lib/python3.6/site-packages/pandas/io/parsers.py", line 688, in read_csv
    return _read(filepath_or_buffer, kwds)
  File "/home/airflow/.local/lib/python3.6/site-packages/pandas/io/parsers.py", line 454, in _read
    parser = TextFileReader(fp_or_buf, **kwds)
  File "/home/airflow/.local/lib/python3.6/site-packages/pandas/io/parsers.py", line 948, in __init__
    self._make_engine(self.engine)
  File "/home/airflow/.local/lib/python3.6/site-packages/pandas/io/parsers.py", line 1180, in _make_engine
    self._engine = CParserWrapper(self.f, **self.options)
  File "/home/airflow/.local/lib/python3.6/site-packages/pandas/io/parsers.py", line 2010, in __init__
    self._reader = parsers.TextReader(src, **kwds)
  File "pandas/_libs/parsers.pyx", line 382, in pandas._libs.parsers.TextReader.__cinit__
  File "pandas/_libs/parsers.pyx", line 674, in pandas._libs.parsers.TextReader._setup_parser_source
FileNotFoundError: [Errno 2] No such file or directory: '/opt/airflow/raw_data/yellowtaxi_tripdata_2019-11.csv'
[2024-05-05 13:54:02,141] {local_task_job.py:154} INFO - Task exited with return code 1
[2024-05-05 13:54:02,351] {local_task_job.py:264} INFO - 0 downstream tasks scheduled from follow-on schedule check
[2024-05-06 09:24:45,180] {taskinstance.py:1032} INFO - Dependencies all met for <TaskInstance: ingest_data_bigquery_yt.local_to_gcs_task scheduled__2019-11-02T06:00:00+00:00 [queued]>
[2024-05-06 09:24:45,421] {taskinstance.py:1032} INFO - Dependencies all met for <TaskInstance: ingest_data_bigquery_yt.local_to_gcs_task scheduled__2019-11-02T06:00:00+00:00 [queued]>
[2024-05-06 09:24:45,421] {taskinstance.py:1238} INFO - 
--------------------------------------------------------------------------------
[2024-05-06 09:24:45,421] {taskinstance.py:1239} INFO - Starting attempt 3 of 3
[2024-05-06 09:24:45,421] {taskinstance.py:1240} INFO - 
--------------------------------------------------------------------------------
[2024-05-06 09:24:45,616] {taskinstance.py:1259} INFO - Executing <Task(PythonOperator): local_to_gcs_task> on 2019-11-02 06:00:00+00:00
[2024-05-06 09:24:45,657] {standard_task_runner.py:52} INFO - Started process 215 to run task
[2024-05-06 09:24:45,746] {standard_task_runner.py:76} INFO - Running: ['***', 'tasks', 'run', 'ingest_data_bigquery_yt', 'local_to_gcs_task', 'scheduled__2019-11-02T06:00:00+00:00', '--job-id', '4575', '--raw', '--subdir', 'DAGS_FOLDER/data_ingstion_gcs_yt_dag.py', '--cfg-path', '/tmp/tmp2pft11k0', '--error-file', '/tmp/tmpdgx1qc4_']
[2024-05-06 09:24:45,824] {standard_task_runner.py:77} INFO - Job 4575: Subtask local_to_gcs_task
[2024-05-06 09:24:46,521] {logging_mixin.py:109} INFO - Running <TaskInstance: ingest_data_bigquery_yt.local_to_gcs_task scheduled__2019-11-02T06:00:00+00:00 [running]> on host 4d4efceb404e
[2024-05-06 09:24:46,748] {warnings.py:99} WARNING - /home/***/.local/lib/python3.6/site-packages/***/utils/context.py:152: AirflowContextDeprecationWarning: Accessing 'execution_date' from the template is deprecated and will be removed in a future version. Please use 'data_interval_start' or 'logical_date' instead.
  warnings.warn(_create_deprecation_warning(key, self._deprecation_replacements[key]))

[2024-05-06 09:24:46,915] {taskinstance.py:1426} INFO - Exporting the following env vars:
AIRFLOW_CTX_DAG_OWNER=***
AIRFLOW_CTX_DAG_ID=ingest_data_bigquery_yt
AIRFLOW_CTX_TASK_ID=local_to_gcs_task
AIRFLOW_CTX_EXECUTION_DATE=2019-11-02T06:00:00+00:00
AIRFLOW_CTX_DAG_RUN_ID=scheduled__2019-11-02T06:00:00+00:00
[2024-05-06 09:24:47,123] {taskinstance.py:1700} ERROR - Task failed with exception
Traceback (most recent call last):
  File "/home/airflow/.local/lib/python3.6/site-packages/airflow/models/taskinstance.py", line 1329, in _run_raw_task
    self._execute_task_with_callbacks(context)
  File "/home/airflow/.local/lib/python3.6/site-packages/airflow/models/taskinstance.py", line 1455, in _execute_task_with_callbacks
    result = self._execute_task(context, self.task)
  File "/home/airflow/.local/lib/python3.6/site-packages/airflow/models/taskinstance.py", line 1511, in _execute_task
    result = execute_callable(context=context)
  File "/home/airflow/.local/lib/python3.6/site-packages/airflow/operators/python.py", line 174, in execute
    return_value = self.execute_callable()
  File "/home/airflow/.local/lib/python3.6/site-packages/airflow/operators/python.py", line 185, in execute_callable
    return self.python_callable(*self.op_args, **self.op_kwargs)
  File "/opt/airflow/dags/data_ingstion_gcs_yt_dag.py", line 84, in upload_to_gcs
    __clean_file(raw_file_name, clean_file_name)
  File "/opt/airflow/dags/data_ingstion_gcs_yt_dag.py", line 59, in __clean_file
    parse_dates=["tpep_pickup_datetime", "tpep_dropoff_datetime"],
  File "/home/airflow/.local/lib/python3.6/site-packages/pandas/io/parsers.py", line 688, in read_csv
    return _read(filepath_or_buffer, kwds)
  File "/home/airflow/.local/lib/python3.6/site-packages/pandas/io/parsers.py", line 454, in _read
    parser = TextFileReader(fp_or_buf, **kwds)
  File "/home/airflow/.local/lib/python3.6/site-packages/pandas/io/parsers.py", line 948, in __init__
    self._make_engine(self.engine)
  File "/home/airflow/.local/lib/python3.6/site-packages/pandas/io/parsers.py", line 1180, in _make_engine
    self._engine = CParserWrapper(self.f, **self.options)
  File "/home/airflow/.local/lib/python3.6/site-packages/pandas/io/parsers.py", line 2010, in __init__
    self._reader = parsers.TextReader(src, **kwds)
  File "pandas/_libs/parsers.pyx", line 382, in pandas._libs.parsers.TextReader.__cinit__
  File "pandas/_libs/parsers.pyx", line 674, in pandas._libs.parsers.TextReader._setup_parser_source
FileNotFoundError: [Errno 2] No such file or directory: '/opt/airflow/raw_data/yellowtaxi_tripdata_2019-11.csv'
[2024-05-06 09:24:47,249] {taskinstance.py:1277} INFO - Marking task as FAILED. dag_id=ingest_data_bigquery_yt, task_id=local_to_gcs_task, execution_date=20191102T060000, start_date=20240506T092445, end_date=20240506T092447
[2024-05-06 09:24:47,397] {standard_task_runner.py:92} ERROR - Failed to execute job 4575 for task local_to_gcs_task
Traceback (most recent call last):
  File "/home/airflow/.local/lib/python3.6/site-packages/airflow/task/task_runner/standard_task_runner.py", line 85, in _start_by_fork
    args.func(args, dag=self.dag)
  File "/home/airflow/.local/lib/python3.6/site-packages/airflow/cli/cli_parser.py", line 48, in command
    return func(*args, **kwargs)
  File "/home/airflow/.local/lib/python3.6/site-packages/airflow/utils/cli.py", line 92, in wrapper
    return f(*args, **kwargs)
  File "/home/airflow/.local/lib/python3.6/site-packages/airflow/cli/commands/task_command.py", line 298, in task_run
    _run_task_by_selected_method(args, dag, ti)
  File "/home/airflow/.local/lib/python3.6/site-packages/airflow/cli/commands/task_command.py", line 107, in _run_task_by_selected_method
    _run_raw_task(args, ti)
  File "/home/airflow/.local/lib/python3.6/site-packages/airflow/cli/commands/task_command.py", line 184, in _run_raw_task
    error_file=args.error_file,
  File "/home/airflow/.local/lib/python3.6/site-packages/airflow/utils/session.py", line 70, in wrapper
    return func(*args, session=session, **kwargs)
  File "/home/airflow/.local/lib/python3.6/site-packages/airflow/models/taskinstance.py", line 1329, in _run_raw_task
    self._execute_task_with_callbacks(context)
  File "/home/airflow/.local/lib/python3.6/site-packages/airflow/models/taskinstance.py", line 1455, in _execute_task_with_callbacks
    result = self._execute_task(context, self.task)
  File "/home/airflow/.local/lib/python3.6/site-packages/airflow/models/taskinstance.py", line 1511, in _execute_task
    result = execute_callable(context=context)
  File "/home/airflow/.local/lib/python3.6/site-packages/airflow/operators/python.py", line 174, in execute
    return_value = self.execute_callable()
  File "/home/airflow/.local/lib/python3.6/site-packages/airflow/operators/python.py", line 185, in execute_callable
    return self.python_callable(*self.op_args, **self.op_kwargs)
  File "/opt/airflow/dags/data_ingstion_gcs_yt_dag.py", line 84, in upload_to_gcs
    __clean_file(raw_file_name, clean_file_name)
  File "/opt/airflow/dags/data_ingstion_gcs_yt_dag.py", line 59, in __clean_file
    parse_dates=["tpep_pickup_datetime", "tpep_dropoff_datetime"],
  File "/home/airflow/.local/lib/python3.6/site-packages/pandas/io/parsers.py", line 688, in read_csv
    return _read(filepath_or_buffer, kwds)
  File "/home/airflow/.local/lib/python3.6/site-packages/pandas/io/parsers.py", line 454, in _read
    parser = TextFileReader(fp_or_buf, **kwds)
  File "/home/airflow/.local/lib/python3.6/site-packages/pandas/io/parsers.py", line 948, in __init__
    self._make_engine(self.engine)
  File "/home/airflow/.local/lib/python3.6/site-packages/pandas/io/parsers.py", line 1180, in _make_engine
    self._engine = CParserWrapper(self.f, **self.options)
  File "/home/airflow/.local/lib/python3.6/site-packages/pandas/io/parsers.py", line 2010, in __init__
    self._reader = parsers.TextReader(src, **kwds)
  File "pandas/_libs/parsers.pyx", line 382, in pandas._libs.parsers.TextReader.__cinit__
  File "pandas/_libs/parsers.pyx", line 674, in pandas._libs.parsers.TextReader._setup_parser_source
FileNotFoundError: [Errno 2] No such file or directory: '/opt/airflow/raw_data/yellowtaxi_tripdata_2019-11.csv'
[2024-05-06 09:24:47,502] {local_task_job.py:154} INFO - Task exited with return code 1
[2024-05-06 09:24:47,657] {local_task_job.py:264} INFO - 0 downstream tasks scheduled from follow-on schedule check
