[2024-03-26 17:34:09,106] {taskinstance.py:1032} INFO - Dependencies all met for <TaskInstance: ingest_data.ingest_to_postgres_task scheduled__2022-09-02T06:00:00+00:00 [queued]>
[2024-03-26 17:34:09,304] {taskinstance.py:1032} INFO - Dependencies all met for <TaskInstance: ingest_data.ingest_to_postgres_task scheduled__2022-09-02T06:00:00+00:00 [queued]>
[2024-03-26 17:34:09,304] {taskinstance.py:1238} INFO - 
--------------------------------------------------------------------------------
[2024-03-26 17:34:09,304] {taskinstance.py:1239} INFO - Starting attempt 1 of 1
[2024-03-26 17:34:09,304] {taskinstance.py:1240} INFO - 
--------------------------------------------------------------------------------
[2024-03-26 17:34:09,479] {taskinstance.py:1259} INFO - Executing <Task(PythonOperator): ingest_to_postgres_task> on 2022-09-02 06:00:00+00:00
[2024-03-26 17:34:09,557] {standard_task_runner.py:52} INFO - Started process 2947 to run task
[2024-03-26 17:34:09,658] {standard_task_runner.py:76} INFO - Running: ['***', 'tasks', 'run', 'ingest_data', 'ingest_to_postgres_task', 'scheduled__2022-09-02T06:00:00+00:00', '--job-id', '434', '--raw', '--subdir', 'DAGS_FOLDER/data_ingestion_dag.py', '--cfg-path', '/tmp/tmprdb4qyvx', '--error-file', '/tmp/tmpspk7reaa']
[2024-03-26 17:34:09,662] {standard_task_runner.py:77} INFO - Job 434: Subtask ingest_to_postgres_task
[2024-03-26 17:34:10,103] {logging_mixin.py:109} INFO - Running <TaskInstance: ingest_data.ingest_to_postgres_task scheduled__2022-09-02T06:00:00+00:00 [running]> on host d71984e59113
[2024-03-26 17:34:10,437] {warnings.py:99} WARNING - /home/***/.local/lib/python3.6/site-packages/***/utils/context.py:152: AirflowContextDeprecationWarning: Accessing 'execution_date' from the template is deprecated and will be removed in a future version. Please use 'data_interval_start' or 'logical_date' instead.
  warnings.warn(_create_deprecation_warning(key, self._deprecation_replacements[key]))

[2024-03-26 17:34:10,583] {taskinstance.py:1426} INFO - Exporting the following env vars:
AIRFLOW_CTX_DAG_OWNER=***
AIRFLOW_CTX_DAG_ID=ingest_data
AIRFLOW_CTX_TASK_ID=ingest_to_postgres_task
AIRFLOW_CTX_EXECUTION_DATE=2022-09-02T06:00:00+00:00
AIRFLOW_CTX_DAG_RUN_ID=scheduled__2022-09-02T06:00:00+00:00
[2024-03-26 17:34:10,584] {logging_mixin.py:109} INFO - yellow_taxi_2022_09 /opt/***/yellowtaxi_tripdata_2022-09.parquet 2022-09-02T06:00:00+00:00
[2024-03-26 17:34:10,584] {logging_mixin.py:109} INFO - Starting data ingestion process...
[2024-03-26 17:34:10,674] {taskinstance.py:1700} ERROR - Task failed with exception
Traceback (most recent call last):
  File "/home/airflow/.local/lib/python3.6/site-packages/airflow/models/taskinstance.py", line 1329, in _run_raw_task
    self._execute_task_with_callbacks(context)
  File "/home/airflow/.local/lib/python3.6/site-packages/airflow/models/taskinstance.py", line 1455, in _execute_task_with_callbacks
    result = self._execute_task(context, self.task)
  File "/home/airflow/.local/lib/python3.6/site-packages/airflow/models/taskinstance.py", line 1511, in _execute_task
    result = execute_callable(context=context)
  File "/home/airflow/.local/lib/python3.6/site-packages/airflow/operators/python.py", line 174, in execute
    return_value = self.execute_callable()
  File "/home/airflow/.local/lib/python3.6/site-packages/airflow/operators/python.py", line 185, in execute_callable
    return self.python_callable(*self.op_args, **self.op_kwargs)
  File "/opt/airflow/dags/ingest_scipt.py", line 22, in ingest_callable
    df = pd.read_csv(parquet_file)
  File "/home/airflow/.local/lib/python3.6/site-packages/pandas/io/parsers.py", line 688, in read_csv
    return _read(filepath_or_buffer, kwds)
  File "/home/airflow/.local/lib/python3.6/site-packages/pandas/io/parsers.py", line 460, in _read
    data = parser.read(nrows)
  File "/home/airflow/.local/lib/python3.6/site-packages/pandas/io/parsers.py", line 1198, in read
    ret = self._engine.read(nrows)
  File "/home/airflow/.local/lib/python3.6/site-packages/pandas/io/parsers.py", line 2157, in read
    data = self._reader.read(nrows)
  File "pandas/_libs/parsers.pyx", line 847, in pandas._libs.parsers.TextReader.read
  File "pandas/_libs/parsers.pyx", line 862, in pandas._libs.parsers.TextReader._read_low_memory
  File "pandas/_libs/parsers.pyx", line 918, in pandas._libs.parsers.TextReader._read_rows
  File "pandas/_libs/parsers.pyx", line 905, in pandas._libs.parsers.TextReader._tokenize_rows
  File "pandas/_libs/parsers.pyx", line 2042, in pandas._libs.parsers.raise_parser_error
pandas.errors.ParserError: Error tokenizing data. C error: Expected 1 fields in line 3, saw 2

[2024-03-26 17:34:10,789] {taskinstance.py:1277} INFO - Marking task as FAILED. dag_id=ingest_data, task_id=ingest_to_postgres_task, execution_date=20220902T060000, start_date=20240326T173409, end_date=20240326T173410
[2024-03-26 17:34:10,858] {standard_task_runner.py:92} ERROR - Failed to execute job 434 for task ingest_to_postgres_task
Traceback (most recent call last):
  File "/home/airflow/.local/lib/python3.6/site-packages/airflow/task/task_runner/standard_task_runner.py", line 85, in _start_by_fork
    args.func(args, dag=self.dag)
  File "/home/airflow/.local/lib/python3.6/site-packages/airflow/cli/cli_parser.py", line 48, in command
    return func(*args, **kwargs)
  File "/home/airflow/.local/lib/python3.6/site-packages/airflow/utils/cli.py", line 92, in wrapper
    return f(*args, **kwargs)
  File "/home/airflow/.local/lib/python3.6/site-packages/airflow/cli/commands/task_command.py", line 298, in task_run
    _run_task_by_selected_method(args, dag, ti)
  File "/home/airflow/.local/lib/python3.6/site-packages/airflow/cli/commands/task_command.py", line 107, in _run_task_by_selected_method
    _run_raw_task(args, ti)
  File "/home/airflow/.local/lib/python3.6/site-packages/airflow/cli/commands/task_command.py", line 184, in _run_raw_task
    error_file=args.error_file,
  File "/home/airflow/.local/lib/python3.6/site-packages/airflow/utils/session.py", line 70, in wrapper
    return func(*args, session=session, **kwargs)
  File "/home/airflow/.local/lib/python3.6/site-packages/airflow/models/taskinstance.py", line 1329, in _run_raw_task
    self._execute_task_with_callbacks(context)
  File "/home/airflow/.local/lib/python3.6/site-packages/airflow/models/taskinstance.py", line 1455, in _execute_task_with_callbacks
    result = self._execute_task(context, self.task)
  File "/home/airflow/.local/lib/python3.6/site-packages/airflow/models/taskinstance.py", line 1511, in _execute_task
    result = execute_callable(context=context)
  File "/home/airflow/.local/lib/python3.6/site-packages/airflow/operators/python.py", line 174, in execute
    return_value = self.execute_callable()
  File "/home/airflow/.local/lib/python3.6/site-packages/airflow/operators/python.py", line 185, in execute_callable
    return self.python_callable(*self.op_args, **self.op_kwargs)
  File "/opt/airflow/dags/ingest_scipt.py", line 22, in ingest_callable
    df = pd.read_csv(parquet_file)
  File "/home/airflow/.local/lib/python3.6/site-packages/pandas/io/parsers.py", line 688, in read_csv
    return _read(filepath_or_buffer, kwds)
  File "/home/airflow/.local/lib/python3.6/site-packages/pandas/io/parsers.py", line 460, in _read
    data = parser.read(nrows)
  File "/home/airflow/.local/lib/python3.6/site-packages/pandas/io/parsers.py", line 1198, in read
    ret = self._engine.read(nrows)
  File "/home/airflow/.local/lib/python3.6/site-packages/pandas/io/parsers.py", line 2157, in read
    data = self._reader.read(nrows)
  File "pandas/_libs/parsers.pyx", line 847, in pandas._libs.parsers.TextReader.read
  File "pandas/_libs/parsers.pyx", line 862, in pandas._libs.parsers.TextReader._read_low_memory
  File "pandas/_libs/parsers.pyx", line 918, in pandas._libs.parsers.TextReader._read_rows
  File "pandas/_libs/parsers.pyx", line 905, in pandas._libs.parsers.TextReader._tokenize_rows
  File "pandas/_libs/parsers.pyx", line 2042, in pandas._libs.parsers.raise_parser_error
pandas.errors.ParserError: Error tokenizing data. C error: Expected 1 fields in line 3, saw 2

[2024-03-26 17:34:10,923] {local_task_job.py:154} INFO - Task exited with return code 1
[2024-03-26 17:34:11,067] {local_task_job.py:264} INFO - 0 downstream tasks scheduled from follow-on schedule check
[2024-03-26 17:48:59,950] {taskinstance.py:1032} INFO - Dependencies all met for <TaskInstance: ingest_data.ingest_to_postgres_task scheduled__2022-09-02T06:00:00+00:00 [queued]>
[2024-03-26 17:48:59,975] {taskinstance.py:1032} INFO - Dependencies all met for <TaskInstance: ingest_data.ingest_to_postgres_task scheduled__2022-09-02T06:00:00+00:00 [queued]>
[2024-03-26 17:48:59,975] {taskinstance.py:1238} INFO - 
--------------------------------------------------------------------------------
[2024-03-26 17:48:59,976] {taskinstance.py:1239} INFO - Starting attempt 1 of 1
[2024-03-26 17:48:59,976] {taskinstance.py:1240} INFO - 
--------------------------------------------------------------------------------
[2024-03-26 17:48:59,999] {taskinstance.py:1259} INFO - Executing <Task(PythonOperator): ingest_to_postgres_task> on 2022-09-02 06:00:00+00:00
[2024-03-26 17:49:00,012] {standard_task_runner.py:52} INFO - Started process 348 to run task
[2024-03-26 17:49:00,025] {standard_task_runner.py:76} INFO - Running: ['***', 'tasks', 'run', 'ingest_data', 'ingest_to_postgres_task', 'scheduled__2022-09-02T06:00:00+00:00', '--job-id', '514', '--raw', '--subdir', 'DAGS_FOLDER/data_ingestion_dag.py', '--cfg-path', '/tmp/tmpa79x1c88', '--error-file', '/tmp/tmpf4jba3om']
[2024-03-26 17:49:00,026] {standard_task_runner.py:77} INFO - Job 514: Subtask ingest_to_postgres_task
[2024-03-26 17:49:00,202] {logging_mixin.py:109} INFO - Running <TaskInstance: ingest_data.ingest_to_postgres_task scheduled__2022-09-02T06:00:00+00:00 [running]> on host 05f84def3a12
[2024-03-26 17:49:00,309] {warnings.py:99} WARNING - /home/***/.local/lib/python3.6/site-packages/***/utils/context.py:152: AirflowContextDeprecationWarning: Accessing 'execution_date' from the template is deprecated and will be removed in a future version. Please use 'data_interval_start' or 'logical_date' instead.
  warnings.warn(_create_deprecation_warning(key, self._deprecation_replacements[key]))

[2024-03-26 17:49:00,366] {taskinstance.py:1426} INFO - Exporting the following env vars:
AIRFLOW_CTX_DAG_OWNER=***
AIRFLOW_CTX_DAG_ID=ingest_data
AIRFLOW_CTX_TASK_ID=ingest_to_postgres_task
AIRFLOW_CTX_EXECUTION_DATE=2022-09-02T06:00:00+00:00
AIRFLOW_CTX_DAG_RUN_ID=scheduled__2022-09-02T06:00:00+00:00
[2024-03-26 17:49:00,367] {logging_mixin.py:109} INFO - yellow_taxi_2022_09 /opt/***/yellowtaxi_tripdata_2022-09.parquet 2022-09-02T06:00:00+00:00
[2024-03-26 17:49:00,368] {logging_mixin.py:109} INFO - Starting data ingestion process...
[2024-03-26 17:49:00,393] {taskinstance.py:1700} ERROR - Task failed with exception
Traceback (most recent call last):
  File "/home/airflow/.local/lib/python3.6/site-packages/airflow/models/taskinstance.py", line 1329, in _run_raw_task
    self._execute_task_with_callbacks(context)
  File "/home/airflow/.local/lib/python3.6/site-packages/airflow/models/taskinstance.py", line 1455, in _execute_task_with_callbacks
    result = self._execute_task(context, self.task)
  File "/home/airflow/.local/lib/python3.6/site-packages/airflow/models/taskinstance.py", line 1511, in _execute_task
    result = execute_callable(context=context)
  File "/home/airflow/.local/lib/python3.6/site-packages/airflow/operators/python.py", line 174, in execute
    return_value = self.execute_callable()
  File "/home/airflow/.local/lib/python3.6/site-packages/airflow/operators/python.py", line 185, in execute_callable
    return self.python_callable(*self.op_args, **self.op_kwargs)
  File "/opt/airflow/dags/ingest_scipt.py", line 22, in ingest_callable
    df = pd.read_csv(parquet_file)
  File "/home/airflow/.local/lib/python3.6/site-packages/pandas/io/parsers.py", line 688, in read_csv
    return _read(filepath_or_buffer, kwds)
  File "/home/airflow/.local/lib/python3.6/site-packages/pandas/io/parsers.py", line 460, in _read
    data = parser.read(nrows)
  File "/home/airflow/.local/lib/python3.6/site-packages/pandas/io/parsers.py", line 1198, in read
    ret = self._engine.read(nrows)
  File "/home/airflow/.local/lib/python3.6/site-packages/pandas/io/parsers.py", line 2157, in read
    data = self._reader.read(nrows)
  File "pandas/_libs/parsers.pyx", line 847, in pandas._libs.parsers.TextReader.read
  File "pandas/_libs/parsers.pyx", line 862, in pandas._libs.parsers.TextReader._read_low_memory
  File "pandas/_libs/parsers.pyx", line 918, in pandas._libs.parsers.TextReader._read_rows
  File "pandas/_libs/parsers.pyx", line 905, in pandas._libs.parsers.TextReader._tokenize_rows
  File "pandas/_libs/parsers.pyx", line 2042, in pandas._libs.parsers.raise_parser_error
pandas.errors.ParserError: Error tokenizing data. C error: Expected 1 fields in line 3, saw 2

[2024-03-26 17:49:00,415] {taskinstance.py:1277} INFO - Marking task as FAILED. dag_id=ingest_data, task_id=ingest_to_postgres_task, execution_date=20220902T060000, start_date=20240326T174859, end_date=20240326T174900
[2024-03-26 17:49:00,436] {standard_task_runner.py:92} ERROR - Failed to execute job 514 for task ingest_to_postgres_task
Traceback (most recent call last):
  File "/home/airflow/.local/lib/python3.6/site-packages/airflow/task/task_runner/standard_task_runner.py", line 85, in _start_by_fork
    args.func(args, dag=self.dag)
  File "/home/airflow/.local/lib/python3.6/site-packages/airflow/cli/cli_parser.py", line 48, in command
    return func(*args, **kwargs)
  File "/home/airflow/.local/lib/python3.6/site-packages/airflow/utils/cli.py", line 92, in wrapper
    return f(*args, **kwargs)
  File "/home/airflow/.local/lib/python3.6/site-packages/airflow/cli/commands/task_command.py", line 298, in task_run
    _run_task_by_selected_method(args, dag, ti)
  File "/home/airflow/.local/lib/python3.6/site-packages/airflow/cli/commands/task_command.py", line 107, in _run_task_by_selected_method
    _run_raw_task(args, ti)
  File "/home/airflow/.local/lib/python3.6/site-packages/airflow/cli/commands/task_command.py", line 184, in _run_raw_task
    error_file=args.error_file,
  File "/home/airflow/.local/lib/python3.6/site-packages/airflow/utils/session.py", line 70, in wrapper
    return func(*args, session=session, **kwargs)
  File "/home/airflow/.local/lib/python3.6/site-packages/airflow/models/taskinstance.py", line 1329, in _run_raw_task
    self._execute_task_with_callbacks(context)
  File "/home/airflow/.local/lib/python3.6/site-packages/airflow/models/taskinstance.py", line 1455, in _execute_task_with_callbacks
    result = self._execute_task(context, self.task)
  File "/home/airflow/.local/lib/python3.6/site-packages/airflow/models/taskinstance.py", line 1511, in _execute_task
    result = execute_callable(context=context)
  File "/home/airflow/.local/lib/python3.6/site-packages/airflow/operators/python.py", line 174, in execute
    return_value = self.execute_callable()
  File "/home/airflow/.local/lib/python3.6/site-packages/airflow/operators/python.py", line 185, in execute_callable
    return self.python_callable(*self.op_args, **self.op_kwargs)
  File "/opt/airflow/dags/ingest_scipt.py", line 22, in ingest_callable
    df = pd.read_csv(parquet_file)
  File "/home/airflow/.local/lib/python3.6/site-packages/pandas/io/parsers.py", line 688, in read_csv
    return _read(filepath_or_buffer, kwds)
  File "/home/airflow/.local/lib/python3.6/site-packages/pandas/io/parsers.py", line 460, in _read
    data = parser.read(nrows)
  File "/home/airflow/.local/lib/python3.6/site-packages/pandas/io/parsers.py", line 1198, in read
    ret = self._engine.read(nrows)
  File "/home/airflow/.local/lib/python3.6/site-packages/pandas/io/parsers.py", line 2157, in read
    data = self._reader.read(nrows)
  File "pandas/_libs/parsers.pyx", line 847, in pandas._libs.parsers.TextReader.read
  File "pandas/_libs/parsers.pyx", line 862, in pandas._libs.parsers.TextReader._read_low_memory
  File "pandas/_libs/parsers.pyx", line 918, in pandas._libs.parsers.TextReader._read_rows
  File "pandas/_libs/parsers.pyx", line 905, in pandas._libs.parsers.TextReader._tokenize_rows
  File "pandas/_libs/parsers.pyx", line 2042, in pandas._libs.parsers.raise_parser_error
pandas.errors.ParserError: Error tokenizing data. C error: Expected 1 fields in line 3, saw 2

[2024-03-26 17:49:00,482] {local_task_job.py:154} INFO - Task exited with return code 1
[2024-03-26 17:49:00,599] {local_task_job.py:264} INFO - 0 downstream tasks scheduled from follow-on schedule check
[2024-03-26 17:52:32,673] {taskinstance.py:1032} INFO - Dependencies all met for <TaskInstance: ingest_data.ingest_to_postgres_task scheduled__2022-09-02T06:00:00+00:00 [queued]>
[2024-03-26 17:52:32,719] {taskinstance.py:1032} INFO - Dependencies all met for <TaskInstance: ingest_data.ingest_to_postgres_task scheduled__2022-09-02T06:00:00+00:00 [queued]>
[2024-03-26 17:52:32,720] {taskinstance.py:1238} INFO - 
--------------------------------------------------------------------------------
[2024-03-26 17:52:32,720] {taskinstance.py:1239} INFO - Starting attempt 1 of 1
[2024-03-26 17:52:32,720] {taskinstance.py:1240} INFO - 
--------------------------------------------------------------------------------
[2024-03-26 17:52:32,773] {taskinstance.py:1259} INFO - Executing <Task(PythonOperator): ingest_to_postgres_task> on 2022-09-02 06:00:00+00:00
[2024-03-26 17:52:32,813] {standard_task_runner.py:52} INFO - Started process 772 to run task
[2024-03-26 17:52:32,855] {standard_task_runner.py:76} INFO - Running: ['***', 'tasks', 'run', 'ingest_data', 'ingest_to_postgres_task', 'scheduled__2022-09-02T06:00:00+00:00', '--job-id', '591', '--raw', '--subdir', 'DAGS_FOLDER/data_ingestion_dag.py', '--cfg-path', '/tmp/tmpsj6flp0y', '--error-file', '/tmp/tmpcu3d5zl1']
[2024-03-26 17:52:32,856] {standard_task_runner.py:77} INFO - Job 591: Subtask ingest_to_postgres_task
[2024-03-26 17:52:33,091] {logging_mixin.py:109} INFO - Running <TaskInstance: ingest_data.ingest_to_postgres_task scheduled__2022-09-02T06:00:00+00:00 [running]> on host 05f84def3a12
[2024-03-26 17:52:33,302] {warnings.py:99} WARNING - /home/***/.local/lib/python3.6/site-packages/***/utils/context.py:152: AirflowContextDeprecationWarning: Accessing 'execution_date' from the template is deprecated and will be removed in a future version. Please use 'data_interval_start' or 'logical_date' instead.
  warnings.warn(_create_deprecation_warning(key, self._deprecation_replacements[key]))

[2024-03-26 17:52:33,369] {taskinstance.py:1426} INFO - Exporting the following env vars:
AIRFLOW_CTX_DAG_OWNER=***
AIRFLOW_CTX_DAG_ID=ingest_data
AIRFLOW_CTX_TASK_ID=ingest_to_postgres_task
AIRFLOW_CTX_EXECUTION_DATE=2022-09-02T06:00:00+00:00
AIRFLOW_CTX_DAG_RUN_ID=scheduled__2022-09-02T06:00:00+00:00
[2024-03-26 17:52:33,370] {logging_mixin.py:109} INFO - yellow_taxi_2022_09 /opt/***/yellowtaxi_tripdata_2022-09.parquet 2022-09-02T06:00:00+00:00
[2024-03-26 17:52:33,374] {logging_mixin.py:109} INFO - Starting data ingestion process...
[2024-03-26 17:52:33,410] {taskinstance.py:1700} ERROR - Task failed with exception
Traceback (most recent call last):
  File "/home/airflow/.local/lib/python3.6/site-packages/airflow/models/taskinstance.py", line 1329, in _run_raw_task
    self._execute_task_with_callbacks(context)
  File "/home/airflow/.local/lib/python3.6/site-packages/airflow/models/taskinstance.py", line 1455, in _execute_task_with_callbacks
    result = self._execute_task(context, self.task)
  File "/home/airflow/.local/lib/python3.6/site-packages/airflow/models/taskinstance.py", line 1511, in _execute_task
    result = execute_callable(context=context)
  File "/home/airflow/.local/lib/python3.6/site-packages/airflow/operators/python.py", line 174, in execute
    return_value = self.execute_callable()
  File "/home/airflow/.local/lib/python3.6/site-packages/airflow/operators/python.py", line 185, in execute_callable
    return self.python_callable(*self.op_args, **self.op_kwargs)
  File "/opt/airflow/dags/ingest_scipt.py", line 22, in ingest_callable
    df = pd.read_csv(parquet_file)
  File "/home/airflow/.local/lib/python3.6/site-packages/pandas/io/parsers.py", line 688, in read_csv
    return _read(filepath_or_buffer, kwds)
  File "/home/airflow/.local/lib/python3.6/site-packages/pandas/io/parsers.py", line 460, in _read
    data = parser.read(nrows)
  File "/home/airflow/.local/lib/python3.6/site-packages/pandas/io/parsers.py", line 1198, in read
    ret = self._engine.read(nrows)
  File "/home/airflow/.local/lib/python3.6/site-packages/pandas/io/parsers.py", line 2157, in read
    data = self._reader.read(nrows)
  File "pandas/_libs/parsers.pyx", line 847, in pandas._libs.parsers.TextReader.read
  File "pandas/_libs/parsers.pyx", line 862, in pandas._libs.parsers.TextReader._read_low_memory
  File "pandas/_libs/parsers.pyx", line 918, in pandas._libs.parsers.TextReader._read_rows
  File "pandas/_libs/parsers.pyx", line 905, in pandas._libs.parsers.TextReader._tokenize_rows
  File "pandas/_libs/parsers.pyx", line 2042, in pandas._libs.parsers.raise_parser_error
pandas.errors.ParserError: Error tokenizing data. C error: Expected 1 fields in line 3, saw 2

[2024-03-26 17:52:33,447] {taskinstance.py:1277} INFO - Marking task as FAILED. dag_id=ingest_data, task_id=ingest_to_postgres_task, execution_date=20220902T060000, start_date=20240326T175232, end_date=20240326T175233
[2024-03-26 17:52:33,503] {standard_task_runner.py:92} ERROR - Failed to execute job 591 for task ingest_to_postgres_task
Traceback (most recent call last):
  File "/home/airflow/.local/lib/python3.6/site-packages/airflow/task/task_runner/standard_task_runner.py", line 85, in _start_by_fork
    args.func(args, dag=self.dag)
  File "/home/airflow/.local/lib/python3.6/site-packages/airflow/cli/cli_parser.py", line 48, in command
    return func(*args, **kwargs)
  File "/home/airflow/.local/lib/python3.6/site-packages/airflow/utils/cli.py", line 92, in wrapper
    return f(*args, **kwargs)
  File "/home/airflow/.local/lib/python3.6/site-packages/airflow/cli/commands/task_command.py", line 298, in task_run
    _run_task_by_selected_method(args, dag, ti)
  File "/home/airflow/.local/lib/python3.6/site-packages/airflow/cli/commands/task_command.py", line 107, in _run_task_by_selected_method
    _run_raw_task(args, ti)
  File "/home/airflow/.local/lib/python3.6/site-packages/airflow/cli/commands/task_command.py", line 184, in _run_raw_task
    error_file=args.error_file,
  File "/home/airflow/.local/lib/python3.6/site-packages/airflow/utils/session.py", line 70, in wrapper
    return func(*args, session=session, **kwargs)
  File "/home/airflow/.local/lib/python3.6/site-packages/airflow/models/taskinstance.py", line 1329, in _run_raw_task
    self._execute_task_with_callbacks(context)
  File "/home/airflow/.local/lib/python3.6/site-packages/airflow/models/taskinstance.py", line 1455, in _execute_task_with_callbacks
    result = self._execute_task(context, self.task)
  File "/home/airflow/.local/lib/python3.6/site-packages/airflow/models/taskinstance.py", line 1511, in _execute_task
    result = execute_callable(context=context)
  File "/home/airflow/.local/lib/python3.6/site-packages/airflow/operators/python.py", line 174, in execute
    return_value = self.execute_callable()
  File "/home/airflow/.local/lib/python3.6/site-packages/airflow/operators/python.py", line 185, in execute_callable
    return self.python_callable(*self.op_args, **self.op_kwargs)
  File "/opt/airflow/dags/ingest_scipt.py", line 22, in ingest_callable
    df = pd.read_csv(parquet_file)
  File "/home/airflow/.local/lib/python3.6/site-packages/pandas/io/parsers.py", line 688, in read_csv
    return _read(filepath_or_buffer, kwds)
  File "/home/airflow/.local/lib/python3.6/site-packages/pandas/io/parsers.py", line 460, in _read
    data = parser.read(nrows)
  File "/home/airflow/.local/lib/python3.6/site-packages/pandas/io/parsers.py", line 1198, in read
    ret = self._engine.read(nrows)
  File "/home/airflow/.local/lib/python3.6/site-packages/pandas/io/parsers.py", line 2157, in read
    data = self._reader.read(nrows)
  File "pandas/_libs/parsers.pyx", line 847, in pandas._libs.parsers.TextReader.read
  File "pandas/_libs/parsers.pyx", line 862, in pandas._libs.parsers.TextReader._read_low_memory
  File "pandas/_libs/parsers.pyx", line 918, in pandas._libs.parsers.TextReader._read_rows
  File "pandas/_libs/parsers.pyx", line 905, in pandas._libs.parsers.TextReader._tokenize_rows
  File "pandas/_libs/parsers.pyx", line 2042, in pandas._libs.parsers.raise_parser_error
pandas.errors.ParserError: Error tokenizing data. C error: Expected 1 fields in line 3, saw 2

[2024-03-26 17:52:33,546] {local_task_job.py:154} INFO - Task exited with return code 1
[2024-03-26 17:52:33,854] {local_task_job.py:264} INFO - 0 downstream tasks scheduled from follow-on schedule check
[2024-03-26 18:22:03,009] {taskinstance.py:1032} INFO - Dependencies all met for <TaskInstance: ingest_data.ingest_to_postgres_task scheduled__2022-09-02T06:00:00+00:00 [queued]>
[2024-03-26 18:22:03,054] {taskinstance.py:1032} INFO - Dependencies all met for <TaskInstance: ingest_data.ingest_to_postgres_task scheduled__2022-09-02T06:00:00+00:00 [queued]>
[2024-03-26 18:22:03,055] {taskinstance.py:1238} INFO - 
--------------------------------------------------------------------------------
[2024-03-26 18:22:03,055] {taskinstance.py:1239} INFO - Starting attempt 1 of 1
[2024-03-26 18:22:03,055] {taskinstance.py:1240} INFO - 
--------------------------------------------------------------------------------
[2024-03-26 18:22:03,093] {taskinstance.py:1259} INFO - Executing <Task(PythonOperator): ingest_to_postgres_task> on 2022-09-02 06:00:00+00:00
[2024-03-26 18:22:03,122] {standard_task_runner.py:52} INFO - Started process 175 to run task
[2024-03-26 18:22:03,179] {standard_task_runner.py:76} INFO - Running: ['***', 'tasks', 'run', 'ingest_data', 'ingest_to_postgres_task', 'scheduled__2022-09-02T06:00:00+00:00', '--job-id', '700', '--raw', '--subdir', 'DAGS_FOLDER/data_ingestion_dag.py', '--cfg-path', '/tmp/tmpdclzskwo', '--error-file', '/tmp/tmpot5ypogl']
[2024-03-26 18:22:03,190] {standard_task_runner.py:77} INFO - Job 700: Subtask ingest_to_postgres_task
[2024-03-26 18:22:03,693] {logging_mixin.py:109} INFO - Running <TaskInstance: ingest_data.ingest_to_postgres_task scheduled__2022-09-02T06:00:00+00:00 [running]> on host 05f84def3a12
[2024-03-26 18:22:03,982] {warnings.py:99} WARNING - /home/***/.local/lib/python3.6/site-packages/***/utils/context.py:152: AirflowContextDeprecationWarning: Accessing 'execution_date' from the template is deprecated and will be removed in a future version. Please use 'data_interval_start' or 'logical_date' instead.
  warnings.warn(_create_deprecation_warning(key, self._deprecation_replacements[key]))

[2024-03-26 18:22:04,091] {taskinstance.py:1426} INFO - Exporting the following env vars:
AIRFLOW_CTX_DAG_OWNER=***
AIRFLOW_CTX_DAG_ID=ingest_data
AIRFLOW_CTX_TASK_ID=ingest_to_postgres_task
AIRFLOW_CTX_EXECUTION_DATE=2022-09-02T06:00:00+00:00
AIRFLOW_CTX_DAG_RUN_ID=scheduled__2022-09-02T06:00:00+00:00
[2024-03-26 18:22:04,092] {logging_mixin.py:109} INFO - yellow_taxi_2022_09 /opt/***/yellowtaxi_tripdata_2022-09.parquet 2022-09-02T06:00:00+00:00
[2024-03-26 18:22:04,093] {logging_mixin.py:109} INFO - Starting data ingestion process...
[2024-03-26 18:22:15,342] {taskinstance.py:1700} ERROR - Task failed with exception
Traceback (most recent call last):
  File "/home/airflow/.local/lib/python3.6/site-packages/sqlalchemy/engine/base.py", line 2336, in _wrap_pool_connect
    return fn()
  File "/home/airflow/.local/lib/python3.6/site-packages/sqlalchemy/pool/base.py", line 304, in unique_connection
    return _ConnectionFairy._checkout(self)
  File "/home/airflow/.local/lib/python3.6/site-packages/sqlalchemy/pool/base.py", line 778, in _checkout
    fairy = _ConnectionRecord.checkout(pool)
  File "/home/airflow/.local/lib/python3.6/site-packages/sqlalchemy/pool/base.py", line 495, in checkout
    rec = pool._do_get()
  File "/home/airflow/.local/lib/python3.6/site-packages/sqlalchemy/pool/impl.py", line 140, in _do_get
    self._dec_overflow()
  File "/home/airflow/.local/lib/python3.6/site-packages/sqlalchemy/util/langhelpers.py", line 70, in __exit__
    with_traceback=exc_tb,
  File "/home/airflow/.local/lib/python3.6/site-packages/sqlalchemy/util/compat.py", line 182, in raise_
    raise exception
  File "/home/airflow/.local/lib/python3.6/site-packages/sqlalchemy/pool/impl.py", line 137, in _do_get
    return self._create_connection()
  File "/home/airflow/.local/lib/python3.6/site-packages/sqlalchemy/pool/base.py", line 309, in _create_connection
    return _ConnectionRecord(self)
  File "/home/airflow/.local/lib/python3.6/site-packages/sqlalchemy/pool/base.py", line 440, in __init__
    self.__connect(first_connect_check=True)
  File "/home/airflow/.local/lib/python3.6/site-packages/sqlalchemy/pool/base.py", line 661, in __connect
    pool.logger.debug("Error on connect(): %s", e)
  File "/home/airflow/.local/lib/python3.6/site-packages/sqlalchemy/util/langhelpers.py", line 70, in __exit__
    with_traceback=exc_tb,
  File "/home/airflow/.local/lib/python3.6/site-packages/sqlalchemy/util/compat.py", line 182, in raise_
    raise exception
  File "/home/airflow/.local/lib/python3.6/site-packages/sqlalchemy/pool/base.py", line 656, in __connect
    connection = pool._invoke_creator(self)
  File "/home/airflow/.local/lib/python3.6/site-packages/sqlalchemy/engine/strategies.py", line 114, in connect
    return dialect.connect(*cargs, **cparams)
  File "/home/airflow/.local/lib/python3.6/site-packages/sqlalchemy/engine/default.py", line 508, in connect
    return self.dbapi.connect(*cargs, **cparams)
  File "/home/airflow/.local/lib/python3.6/site-packages/psycopg2/__init__.py", line 122, in connect
    conn = _connect(dsn, connection_factory=connection_factory, **kwasync)
psycopg2.OperationalError: could not translate host name "pgdatabase" to address: Name or service not known


The above exception was the direct cause of the following exception:

Traceback (most recent call last):
  File "/home/airflow/.local/lib/python3.6/site-packages/airflow/models/taskinstance.py", line 1329, in _run_raw_task
    self._execute_task_with_callbacks(context)
  File "/home/airflow/.local/lib/python3.6/site-packages/airflow/models/taskinstance.py", line 1455, in _execute_task_with_callbacks
    result = self._execute_task(context, self.task)
  File "/home/airflow/.local/lib/python3.6/site-packages/airflow/models/taskinstance.py", line 1511, in _execute_task
    result = execute_callable(context=context)
  File "/home/airflow/.local/lib/python3.6/site-packages/airflow/operators/python.py", line 174, in execute
    return_value = self.execute_callable()
  File "/home/airflow/.local/lib/python3.6/site-packages/airflow/operators/python.py", line 185, in execute_callable
    return self.python_callable(*self.op_args, **self.op_kwargs)
  File "/opt/airflow/dags/ingest_script.py", line 32, in ingest_callable
    connection = engine.connect()
  File "/home/airflow/.local/lib/python3.6/site-packages/sqlalchemy/engine/base.py", line 2263, in connect
    return self._connection_cls(self, **kwargs)
  File "/home/airflow/.local/lib/python3.6/site-packages/sqlalchemy/engine/base.py", line 104, in __init__
    else engine.raw_connection()
  File "/home/airflow/.local/lib/python3.6/site-packages/sqlalchemy/engine/base.py", line 2370, in raw_connection
    self.pool.unique_connection, _connection
  File "/home/airflow/.local/lib/python3.6/site-packages/sqlalchemy/engine/base.py", line 2340, in _wrap_pool_connect
    e, dialect, self
  File "/home/airflow/.local/lib/python3.6/site-packages/sqlalchemy/engine/base.py", line 1584, in _handle_dbapi_exception_noconnection
    sqlalchemy_exception, with_traceback=exc_info[2], from_=e
  File "/home/airflow/.local/lib/python3.6/site-packages/sqlalchemy/util/compat.py", line 182, in raise_
    raise exception
  File "/home/airflow/.local/lib/python3.6/site-packages/sqlalchemy/engine/base.py", line 2336, in _wrap_pool_connect
    return fn()
  File "/home/airflow/.local/lib/python3.6/site-packages/sqlalchemy/pool/base.py", line 304, in unique_connection
    return _ConnectionFairy._checkout(self)
  File "/home/airflow/.local/lib/python3.6/site-packages/sqlalchemy/pool/base.py", line 778, in _checkout
    fairy = _ConnectionRecord.checkout(pool)
  File "/home/airflow/.local/lib/python3.6/site-packages/sqlalchemy/pool/base.py", line 495, in checkout
    rec = pool._do_get()
  File "/home/airflow/.local/lib/python3.6/site-packages/sqlalchemy/pool/impl.py", line 140, in _do_get
    self._dec_overflow()
  File "/home/airflow/.local/lib/python3.6/site-packages/sqlalchemy/util/langhelpers.py", line 70, in __exit__
    with_traceback=exc_tb,
  File "/home/airflow/.local/lib/python3.6/site-packages/sqlalchemy/util/compat.py", line 182, in raise_
    raise exception
  File "/home/airflow/.local/lib/python3.6/site-packages/sqlalchemy/pool/impl.py", line 137, in _do_get
    return self._create_connection()
  File "/home/airflow/.local/lib/python3.6/site-packages/sqlalchemy/pool/base.py", line 309, in _create_connection
    return _ConnectionRecord(self)
  File "/home/airflow/.local/lib/python3.6/site-packages/sqlalchemy/pool/base.py", line 440, in __init__
    self.__connect(first_connect_check=True)
  File "/home/airflow/.local/lib/python3.6/site-packages/sqlalchemy/pool/base.py", line 661, in __connect
    pool.logger.debug("Error on connect(): %s", e)
  File "/home/airflow/.local/lib/python3.6/site-packages/sqlalchemy/util/langhelpers.py", line 70, in __exit__
    with_traceback=exc_tb,
  File "/home/airflow/.local/lib/python3.6/site-packages/sqlalchemy/util/compat.py", line 182, in raise_
    raise exception
  File "/home/airflow/.local/lib/python3.6/site-packages/sqlalchemy/pool/base.py", line 656, in __connect
    connection = pool._invoke_creator(self)
  File "/home/airflow/.local/lib/python3.6/site-packages/sqlalchemy/engine/strategies.py", line 114, in connect
    return dialect.connect(*cargs, **cparams)
  File "/home/airflow/.local/lib/python3.6/site-packages/sqlalchemy/engine/default.py", line 508, in connect
    return self.dbapi.connect(*cargs, **cparams)
  File "/home/airflow/.local/lib/python3.6/site-packages/psycopg2/__init__.py", line 122, in connect
    conn = _connect(dsn, connection_factory=connection_factory, **kwasync)
sqlalchemy.exc.OperationalError: (psycopg2.OperationalError) could not translate host name "pgdatabase" to address: Name or service not known

(Background on this error at: http://sqlalche.me/e/13/e3q8)
[2024-03-26 18:22:15,453] {taskinstance.py:1277} INFO - Marking task as FAILED. dag_id=ingest_data, task_id=ingest_to_postgres_task, execution_date=20220902T060000, start_date=20240326T182203, end_date=20240326T182215
[2024-03-26 18:22:15,553] {standard_task_runner.py:92} ERROR - Failed to execute job 700 for task ingest_to_postgres_task
Traceback (most recent call last):
  File "/home/airflow/.local/lib/python3.6/site-packages/sqlalchemy/engine/base.py", line 2336, in _wrap_pool_connect
    return fn()
  File "/home/airflow/.local/lib/python3.6/site-packages/sqlalchemy/pool/base.py", line 304, in unique_connection
    return _ConnectionFairy._checkout(self)
  File "/home/airflow/.local/lib/python3.6/site-packages/sqlalchemy/pool/base.py", line 778, in _checkout
    fairy = _ConnectionRecord.checkout(pool)
  File "/home/airflow/.local/lib/python3.6/site-packages/sqlalchemy/pool/base.py", line 495, in checkout
    rec = pool._do_get()
  File "/home/airflow/.local/lib/python3.6/site-packages/sqlalchemy/pool/impl.py", line 140, in _do_get
    self._dec_overflow()
  File "/home/airflow/.local/lib/python3.6/site-packages/sqlalchemy/util/langhelpers.py", line 70, in __exit__
    with_traceback=exc_tb,
  File "/home/airflow/.local/lib/python3.6/site-packages/sqlalchemy/util/compat.py", line 182, in raise_
    raise exception
  File "/home/airflow/.local/lib/python3.6/site-packages/sqlalchemy/pool/impl.py", line 137, in _do_get
    return self._create_connection()
  File "/home/airflow/.local/lib/python3.6/site-packages/sqlalchemy/pool/base.py", line 309, in _create_connection
    return _ConnectionRecord(self)
  File "/home/airflow/.local/lib/python3.6/site-packages/sqlalchemy/pool/base.py", line 440, in __init__
    self.__connect(first_connect_check=True)
  File "/home/airflow/.local/lib/python3.6/site-packages/sqlalchemy/pool/base.py", line 661, in __connect
    pool.logger.debug("Error on connect(): %s", e)
  File "/home/airflow/.local/lib/python3.6/site-packages/sqlalchemy/util/langhelpers.py", line 70, in __exit__
    with_traceback=exc_tb,
  File "/home/airflow/.local/lib/python3.6/site-packages/sqlalchemy/util/compat.py", line 182, in raise_
    raise exception
  File "/home/airflow/.local/lib/python3.6/site-packages/sqlalchemy/pool/base.py", line 656, in __connect
    connection = pool._invoke_creator(self)
  File "/home/airflow/.local/lib/python3.6/site-packages/sqlalchemy/engine/strategies.py", line 114, in connect
    return dialect.connect(*cargs, **cparams)
  File "/home/airflow/.local/lib/python3.6/site-packages/sqlalchemy/engine/default.py", line 508, in connect
    return self.dbapi.connect(*cargs, **cparams)
  File "/home/airflow/.local/lib/python3.6/site-packages/psycopg2/__init__.py", line 122, in connect
    conn = _connect(dsn, connection_factory=connection_factory, **kwasync)
psycopg2.OperationalError: could not translate host name "pgdatabase" to address: Name or service not known


The above exception was the direct cause of the following exception:

Traceback (most recent call last):
  File "/home/airflow/.local/lib/python3.6/site-packages/airflow/task/task_runner/standard_task_runner.py", line 85, in _start_by_fork
    args.func(args, dag=self.dag)
  File "/home/airflow/.local/lib/python3.6/site-packages/airflow/cli/cli_parser.py", line 48, in command
    return func(*args, **kwargs)
  File "/home/airflow/.local/lib/python3.6/site-packages/airflow/utils/cli.py", line 92, in wrapper
    return f(*args, **kwargs)
  File "/home/airflow/.local/lib/python3.6/site-packages/airflow/cli/commands/task_command.py", line 298, in task_run
    _run_task_by_selected_method(args, dag, ti)
  File "/home/airflow/.local/lib/python3.6/site-packages/airflow/cli/commands/task_command.py", line 107, in _run_task_by_selected_method
    _run_raw_task(args, ti)
  File "/home/airflow/.local/lib/python3.6/site-packages/airflow/cli/commands/task_command.py", line 184, in _run_raw_task
    error_file=args.error_file,
  File "/home/airflow/.local/lib/python3.6/site-packages/airflow/utils/session.py", line 70, in wrapper
    return func(*args, session=session, **kwargs)
  File "/home/airflow/.local/lib/python3.6/site-packages/airflow/models/taskinstance.py", line 1329, in _run_raw_task
    self._execute_task_with_callbacks(context)
  File "/home/airflow/.local/lib/python3.6/site-packages/airflow/models/taskinstance.py", line 1455, in _execute_task_with_callbacks
    result = self._execute_task(context, self.task)
  File "/home/airflow/.local/lib/python3.6/site-packages/airflow/models/taskinstance.py", line 1511, in _execute_task
    result = execute_callable(context=context)
  File "/home/airflow/.local/lib/python3.6/site-packages/airflow/operators/python.py", line 174, in execute
    return_value = self.execute_callable()
  File "/home/airflow/.local/lib/python3.6/site-packages/airflow/operators/python.py", line 185, in execute_callable
    return self.python_callable(*self.op_args, **self.op_kwargs)
  File "/opt/airflow/dags/ingest_script.py", line 32, in ingest_callable
    connection = engine.connect()
  File "/home/airflow/.local/lib/python3.6/site-packages/sqlalchemy/engine/base.py", line 2263, in connect
    return self._connection_cls(self, **kwargs)
  File "/home/airflow/.local/lib/python3.6/site-packages/sqlalchemy/engine/base.py", line 104, in __init__
    else engine.raw_connection()
  File "/home/airflow/.local/lib/python3.6/site-packages/sqlalchemy/engine/base.py", line 2370, in raw_connection
    self.pool.unique_connection, _connection
  File "/home/airflow/.local/lib/python3.6/site-packages/sqlalchemy/engine/base.py", line 2340, in _wrap_pool_connect
    e, dialect, self
  File "/home/airflow/.local/lib/python3.6/site-packages/sqlalchemy/engine/base.py", line 1584, in _handle_dbapi_exception_noconnection
    sqlalchemy_exception, with_traceback=exc_info[2], from_=e
  File "/home/airflow/.local/lib/python3.6/site-packages/sqlalchemy/util/compat.py", line 182, in raise_
    raise exception
  File "/home/airflow/.local/lib/python3.6/site-packages/sqlalchemy/engine/base.py", line 2336, in _wrap_pool_connect
    return fn()
  File "/home/airflow/.local/lib/python3.6/site-packages/sqlalchemy/pool/base.py", line 304, in unique_connection
    return _ConnectionFairy._checkout(self)
  File "/home/airflow/.local/lib/python3.6/site-packages/sqlalchemy/pool/base.py", line 778, in _checkout
    fairy = _ConnectionRecord.checkout(pool)
  File "/home/airflow/.local/lib/python3.6/site-packages/sqlalchemy/pool/base.py", line 495, in checkout
    rec = pool._do_get()
  File "/home/airflow/.local/lib/python3.6/site-packages/sqlalchemy/pool/impl.py", line 140, in _do_get
    self._dec_overflow()
  File "/home/airflow/.local/lib/python3.6/site-packages/sqlalchemy/util/langhelpers.py", line 70, in __exit__
    with_traceback=exc_tb,
  File "/home/airflow/.local/lib/python3.6/site-packages/sqlalchemy/util/compat.py", line 182, in raise_
    raise exception
  File "/home/airflow/.local/lib/python3.6/site-packages/sqlalchemy/pool/impl.py", line 137, in _do_get
    return self._create_connection()
  File "/home/airflow/.local/lib/python3.6/site-packages/sqlalchemy/pool/base.py", line 309, in _create_connection
    return _ConnectionRecord(self)
  File "/home/airflow/.local/lib/python3.6/site-packages/sqlalchemy/pool/base.py", line 440, in __init__
    self.__connect(first_connect_check=True)
  File "/home/airflow/.local/lib/python3.6/site-packages/sqlalchemy/pool/base.py", line 661, in __connect
    pool.logger.debug("Error on connect(): %s", e)
  File "/home/airflow/.local/lib/python3.6/site-packages/sqlalchemy/util/langhelpers.py", line 70, in __exit__
    with_traceback=exc_tb,
  File "/home/airflow/.local/lib/python3.6/site-packages/sqlalchemy/util/compat.py", line 182, in raise_
    raise exception
  File "/home/airflow/.local/lib/python3.6/site-packages/sqlalchemy/pool/base.py", line 656, in __connect
    connection = pool._invoke_creator(self)
  File "/home/airflow/.local/lib/python3.6/site-packages/sqlalchemy/engine/strategies.py", line 114, in connect
    return dialect.connect(*cargs, **cparams)
  File "/home/airflow/.local/lib/python3.6/site-packages/sqlalchemy/engine/default.py", line 508, in connect
    return self.dbapi.connect(*cargs, **cparams)
  File "/home/airflow/.local/lib/python3.6/site-packages/psycopg2/__init__.py", line 122, in connect
    conn = _connect(dsn, connection_factory=connection_factory, **kwasync)
sqlalchemy.exc.OperationalError: (psycopg2.OperationalError) could not translate host name "pgdatabase" to address: Name or service not known

(Background on this error at: http://sqlalche.me/e/13/e3q8)
[2024-03-26 18:22:15,721] {local_task_job.py:154} INFO - Task exited with return code 1
[2024-03-26 18:22:15,974] {local_task_job.py:264} INFO - 0 downstream tasks scheduled from follow-on schedule check
[2024-03-27 03:48:18,903] {taskinstance.py:1032} INFO - Dependencies all met for <TaskInstance: ingest_data.ingest_to_postgres_task scheduled__2022-09-02T06:00:00+00:00 [queued]>
[2024-03-27 03:48:19,032] {taskinstance.py:1032} INFO - Dependencies all met for <TaskInstance: ingest_data.ingest_to_postgres_task scheduled__2022-09-02T06:00:00+00:00 [queued]>
[2024-03-27 03:48:19,033] {taskinstance.py:1238} INFO - 
--------------------------------------------------------------------------------
[2024-03-27 03:48:19,033] {taskinstance.py:1239} INFO - Starting attempt 1 of 1
[2024-03-27 03:48:19,033] {taskinstance.py:1240} INFO - 
--------------------------------------------------------------------------------
[2024-03-27 03:48:19,123] {taskinstance.py:1259} INFO - Executing <Task(PythonOperator): ingest_to_postgres_task> on 2022-09-02 06:00:00+00:00
[2024-03-27 03:48:19,152] {standard_task_runner.py:52} INFO - Started process 248 to run task
[2024-03-27 03:48:19,185] {standard_task_runner.py:76} INFO - Running: ['***', 'tasks', 'run', 'ingest_data', 'ingest_to_postgres_task', 'scheduled__2022-09-02T06:00:00+00:00', '--job-id', '782', '--raw', '--subdir', 'DAGS_FOLDER/data_ingestion_dag.py', '--cfg-path', '/tmp/tmppcjw517g', '--error-file', '/tmp/tmp1uqcvbax']
[2024-03-27 03:48:19,185] {standard_task_runner.py:77} INFO - Job 782: Subtask ingest_to_postgres_task
[2024-03-27 03:48:19,418] {logging_mixin.py:109} INFO - Running <TaskInstance: ingest_data.ingest_to_postgres_task scheduled__2022-09-02T06:00:00+00:00 [running]> on host 05f84def3a12
[2024-03-27 03:48:19,537] {warnings.py:99} WARNING - /home/***/.local/lib/python3.6/site-packages/***/utils/context.py:152: AirflowContextDeprecationWarning: Accessing 'execution_date' from the template is deprecated and will be removed in a future version. Please use 'data_interval_start' or 'logical_date' instead.
  warnings.warn(_create_deprecation_warning(key, self._deprecation_replacements[key]))

[2024-03-27 03:48:19,651] {taskinstance.py:1426} INFO - Exporting the following env vars:
AIRFLOW_CTX_DAG_OWNER=***
AIRFLOW_CTX_DAG_ID=ingest_data
AIRFLOW_CTX_TASK_ID=ingest_to_postgres_task
AIRFLOW_CTX_EXECUTION_DATE=2022-09-02T06:00:00+00:00
AIRFLOW_CTX_DAG_RUN_ID=scheduled__2022-09-02T06:00:00+00:00
[2024-03-27 03:48:19,651] {logging_mixin.py:109} INFO - yellow_taxi_2022_09 /opt/***/yellowtaxi_tripdata_2022-09.parquet 2022-09-02T06:00:00+00:00
[2024-03-27 03:48:19,652] {logging_mixin.py:109} INFO - Starting data ingestion process...
[2024-03-27 03:48:27,603] {taskinstance.py:1700} ERROR - Task failed with exception
Traceback (most recent call last):
  File "/home/airflow/.local/lib/python3.6/site-packages/sqlalchemy/engine/base.py", line 2336, in _wrap_pool_connect
    return fn()
  File "/home/airflow/.local/lib/python3.6/site-packages/sqlalchemy/pool/base.py", line 304, in unique_connection
    return _ConnectionFairy._checkout(self)
  File "/home/airflow/.local/lib/python3.6/site-packages/sqlalchemy/pool/base.py", line 778, in _checkout
    fairy = _ConnectionRecord.checkout(pool)
  File "/home/airflow/.local/lib/python3.6/site-packages/sqlalchemy/pool/base.py", line 495, in checkout
    rec = pool._do_get()
  File "/home/airflow/.local/lib/python3.6/site-packages/sqlalchemy/pool/impl.py", line 140, in _do_get
    self._dec_overflow()
  File "/home/airflow/.local/lib/python3.6/site-packages/sqlalchemy/util/langhelpers.py", line 70, in __exit__
    with_traceback=exc_tb,
  File "/home/airflow/.local/lib/python3.6/site-packages/sqlalchemy/util/compat.py", line 182, in raise_
    raise exception
  File "/home/airflow/.local/lib/python3.6/site-packages/sqlalchemy/pool/impl.py", line 137, in _do_get
    return self._create_connection()
  File "/home/airflow/.local/lib/python3.6/site-packages/sqlalchemy/pool/base.py", line 309, in _create_connection
    return _ConnectionRecord(self)
  File "/home/airflow/.local/lib/python3.6/site-packages/sqlalchemy/pool/base.py", line 440, in __init__
    self.__connect(first_connect_check=True)
  File "/home/airflow/.local/lib/python3.6/site-packages/sqlalchemy/pool/base.py", line 661, in __connect
    pool.logger.debug("Error on connect(): %s", e)
  File "/home/airflow/.local/lib/python3.6/site-packages/sqlalchemy/util/langhelpers.py", line 70, in __exit__
    with_traceback=exc_tb,
  File "/home/airflow/.local/lib/python3.6/site-packages/sqlalchemy/util/compat.py", line 182, in raise_
    raise exception
  File "/home/airflow/.local/lib/python3.6/site-packages/sqlalchemy/pool/base.py", line 656, in __connect
    connection = pool._invoke_creator(self)
  File "/home/airflow/.local/lib/python3.6/site-packages/sqlalchemy/engine/strategies.py", line 114, in connect
    return dialect.connect(*cargs, **cparams)
  File "/home/airflow/.local/lib/python3.6/site-packages/sqlalchemy/engine/default.py", line 508, in connect
    return self.dbapi.connect(*cargs, **cparams)
  File "/home/airflow/.local/lib/python3.6/site-packages/psycopg2/__init__.py", line 122, in connect
    conn = _connect(dsn, connection_factory=connection_factory, **kwasync)
psycopg2.OperationalError: could not translate host name "pgdatabase" to address: Name or service not known


The above exception was the direct cause of the following exception:

Traceback (most recent call last):
  File "/home/airflow/.local/lib/python3.6/site-packages/airflow/models/taskinstance.py", line 1329, in _run_raw_task
    self._execute_task_with_callbacks(context)
  File "/home/airflow/.local/lib/python3.6/site-packages/airflow/models/taskinstance.py", line 1455, in _execute_task_with_callbacks
    result = self._execute_task(context, self.task)
  File "/home/airflow/.local/lib/python3.6/site-packages/airflow/models/taskinstance.py", line 1511, in _execute_task
    result = execute_callable(context=context)
  File "/home/airflow/.local/lib/python3.6/site-packages/airflow/operators/python.py", line 174, in execute
    return_value = self.execute_callable()
  File "/home/airflow/.local/lib/python3.6/site-packages/airflow/operators/python.py", line 185, in execute_callable
    return self.python_callable(*self.op_args, **self.op_kwargs)
  File "/opt/airflow/dags/ingest_script.py", line 32, in ingest_callable
    connection = engine.connect()
  File "/home/airflow/.local/lib/python3.6/site-packages/sqlalchemy/engine/base.py", line 2263, in connect
    return self._connection_cls(self, **kwargs)
  File "/home/airflow/.local/lib/python3.6/site-packages/sqlalchemy/engine/base.py", line 104, in __init__
    else engine.raw_connection()
  File "/home/airflow/.local/lib/python3.6/site-packages/sqlalchemy/engine/base.py", line 2370, in raw_connection
    self.pool.unique_connection, _connection
  File "/home/airflow/.local/lib/python3.6/site-packages/sqlalchemy/engine/base.py", line 2340, in _wrap_pool_connect
    e, dialect, self
  File "/home/airflow/.local/lib/python3.6/site-packages/sqlalchemy/engine/base.py", line 1584, in _handle_dbapi_exception_noconnection
    sqlalchemy_exception, with_traceback=exc_info[2], from_=e
  File "/home/airflow/.local/lib/python3.6/site-packages/sqlalchemy/util/compat.py", line 182, in raise_
    raise exception
  File "/home/airflow/.local/lib/python3.6/site-packages/sqlalchemy/engine/base.py", line 2336, in _wrap_pool_connect
    return fn()
  File "/home/airflow/.local/lib/python3.6/site-packages/sqlalchemy/pool/base.py", line 304, in unique_connection
    return _ConnectionFairy._checkout(self)
  File "/home/airflow/.local/lib/python3.6/site-packages/sqlalchemy/pool/base.py", line 778, in _checkout
    fairy = _ConnectionRecord.checkout(pool)
  File "/home/airflow/.local/lib/python3.6/site-packages/sqlalchemy/pool/base.py", line 495, in checkout
    rec = pool._do_get()
  File "/home/airflow/.local/lib/python3.6/site-packages/sqlalchemy/pool/impl.py", line 140, in _do_get
    self._dec_overflow()
  File "/home/airflow/.local/lib/python3.6/site-packages/sqlalchemy/util/langhelpers.py", line 70, in __exit__
    with_traceback=exc_tb,
  File "/home/airflow/.local/lib/python3.6/site-packages/sqlalchemy/util/compat.py", line 182, in raise_
    raise exception
  File "/home/airflow/.local/lib/python3.6/site-packages/sqlalchemy/pool/impl.py", line 137, in _do_get
    return self._create_connection()
  File "/home/airflow/.local/lib/python3.6/site-packages/sqlalchemy/pool/base.py", line 309, in _create_connection
    return _ConnectionRecord(self)
  File "/home/airflow/.local/lib/python3.6/site-packages/sqlalchemy/pool/base.py", line 440, in __init__
    self.__connect(first_connect_check=True)
  File "/home/airflow/.local/lib/python3.6/site-packages/sqlalchemy/pool/base.py", line 661, in __connect
    pool.logger.debug("Error on connect(): %s", e)
  File "/home/airflow/.local/lib/python3.6/site-packages/sqlalchemy/util/langhelpers.py", line 70, in __exit__
    with_traceback=exc_tb,
  File "/home/airflow/.local/lib/python3.6/site-packages/sqlalchemy/util/compat.py", line 182, in raise_
    raise exception
  File "/home/airflow/.local/lib/python3.6/site-packages/sqlalchemy/pool/base.py", line 656, in __connect
    connection = pool._invoke_creator(self)
  File "/home/airflow/.local/lib/python3.6/site-packages/sqlalchemy/engine/strategies.py", line 114, in connect
    return dialect.connect(*cargs, **cparams)
  File "/home/airflow/.local/lib/python3.6/site-packages/sqlalchemy/engine/default.py", line 508, in connect
    return self.dbapi.connect(*cargs, **cparams)
  File "/home/airflow/.local/lib/python3.6/site-packages/psycopg2/__init__.py", line 122, in connect
    conn = _connect(dsn, connection_factory=connection_factory, **kwasync)
sqlalchemy.exc.OperationalError: (psycopg2.OperationalError) could not translate host name "pgdatabase" to address: Name or service not known

(Background on this error at: http://sqlalche.me/e/13/e3q8)
[2024-03-27 03:48:27,667] {taskinstance.py:1277} INFO - Marking task as FAILED. dag_id=ingest_data, task_id=ingest_to_postgres_task, execution_date=20220902T060000, start_date=20240327T034818, end_date=20240327T034827
[2024-03-27 03:48:27,713] {standard_task_runner.py:92} ERROR - Failed to execute job 782 for task ingest_to_postgres_task
Traceback (most recent call last):
  File "/home/airflow/.local/lib/python3.6/site-packages/sqlalchemy/engine/base.py", line 2336, in _wrap_pool_connect
    return fn()
  File "/home/airflow/.local/lib/python3.6/site-packages/sqlalchemy/pool/base.py", line 304, in unique_connection
    return _ConnectionFairy._checkout(self)
  File "/home/airflow/.local/lib/python3.6/site-packages/sqlalchemy/pool/base.py", line 778, in _checkout
    fairy = _ConnectionRecord.checkout(pool)
  File "/home/airflow/.local/lib/python3.6/site-packages/sqlalchemy/pool/base.py", line 495, in checkout
    rec = pool._do_get()
  File "/home/airflow/.local/lib/python3.6/site-packages/sqlalchemy/pool/impl.py", line 140, in _do_get
    self._dec_overflow()
  File "/home/airflow/.local/lib/python3.6/site-packages/sqlalchemy/util/langhelpers.py", line 70, in __exit__
    with_traceback=exc_tb,
  File "/home/airflow/.local/lib/python3.6/site-packages/sqlalchemy/util/compat.py", line 182, in raise_
    raise exception
  File "/home/airflow/.local/lib/python3.6/site-packages/sqlalchemy/pool/impl.py", line 137, in _do_get
    return self._create_connection()
  File "/home/airflow/.local/lib/python3.6/site-packages/sqlalchemy/pool/base.py", line 309, in _create_connection
    return _ConnectionRecord(self)
  File "/home/airflow/.local/lib/python3.6/site-packages/sqlalchemy/pool/base.py", line 440, in __init__
    self.__connect(first_connect_check=True)
  File "/home/airflow/.local/lib/python3.6/site-packages/sqlalchemy/pool/base.py", line 661, in __connect
    pool.logger.debug("Error on connect(): %s", e)
  File "/home/airflow/.local/lib/python3.6/site-packages/sqlalchemy/util/langhelpers.py", line 70, in __exit__
    with_traceback=exc_tb,
  File "/home/airflow/.local/lib/python3.6/site-packages/sqlalchemy/util/compat.py", line 182, in raise_
    raise exception
  File "/home/airflow/.local/lib/python3.6/site-packages/sqlalchemy/pool/base.py", line 656, in __connect
    connection = pool._invoke_creator(self)
  File "/home/airflow/.local/lib/python3.6/site-packages/sqlalchemy/engine/strategies.py", line 114, in connect
    return dialect.connect(*cargs, **cparams)
  File "/home/airflow/.local/lib/python3.6/site-packages/sqlalchemy/engine/default.py", line 508, in connect
    return self.dbapi.connect(*cargs, **cparams)
  File "/home/airflow/.local/lib/python3.6/site-packages/psycopg2/__init__.py", line 122, in connect
    conn = _connect(dsn, connection_factory=connection_factory, **kwasync)
psycopg2.OperationalError: could not translate host name "pgdatabase" to address: Name or service not known


The above exception was the direct cause of the following exception:

Traceback (most recent call last):
  File "/home/airflow/.local/lib/python3.6/site-packages/airflow/task/task_runner/standard_task_runner.py", line 85, in _start_by_fork
    args.func(args, dag=self.dag)
  File "/home/airflow/.local/lib/python3.6/site-packages/airflow/cli/cli_parser.py", line 48, in command
    return func(*args, **kwargs)
  File "/home/airflow/.local/lib/python3.6/site-packages/airflow/utils/cli.py", line 92, in wrapper
    return f(*args, **kwargs)
  File "/home/airflow/.local/lib/python3.6/site-packages/airflow/cli/commands/task_command.py", line 298, in task_run
    _run_task_by_selected_method(args, dag, ti)
  File "/home/airflow/.local/lib/python3.6/site-packages/airflow/cli/commands/task_command.py", line 107, in _run_task_by_selected_method
    _run_raw_task(args, ti)
  File "/home/airflow/.local/lib/python3.6/site-packages/airflow/cli/commands/task_command.py", line 184, in _run_raw_task
    error_file=args.error_file,
  File "/home/airflow/.local/lib/python3.6/site-packages/airflow/utils/session.py", line 70, in wrapper
    return func(*args, session=session, **kwargs)
  File "/home/airflow/.local/lib/python3.6/site-packages/airflow/models/taskinstance.py", line 1329, in _run_raw_task
    self._execute_task_with_callbacks(context)
  File "/home/airflow/.local/lib/python3.6/site-packages/airflow/models/taskinstance.py", line 1455, in _execute_task_with_callbacks
    result = self._execute_task(context, self.task)
  File "/home/airflow/.local/lib/python3.6/site-packages/airflow/models/taskinstance.py", line 1511, in _execute_task
    result = execute_callable(context=context)
  File "/home/airflow/.local/lib/python3.6/site-packages/airflow/operators/python.py", line 174, in execute
    return_value = self.execute_callable()
  File "/home/airflow/.local/lib/python3.6/site-packages/airflow/operators/python.py", line 185, in execute_callable
    return self.python_callable(*self.op_args, **self.op_kwargs)
  File "/opt/airflow/dags/ingest_script.py", line 32, in ingest_callable
    connection = engine.connect()
  File "/home/airflow/.local/lib/python3.6/site-packages/sqlalchemy/engine/base.py", line 2263, in connect
    return self._connection_cls(self, **kwargs)
  File "/home/airflow/.local/lib/python3.6/site-packages/sqlalchemy/engine/base.py", line 104, in __init__
    else engine.raw_connection()
  File "/home/airflow/.local/lib/python3.6/site-packages/sqlalchemy/engine/base.py", line 2370, in raw_connection
    self.pool.unique_connection, _connection
  File "/home/airflow/.local/lib/python3.6/site-packages/sqlalchemy/engine/base.py", line 2340, in _wrap_pool_connect
    e, dialect, self
  File "/home/airflow/.local/lib/python3.6/site-packages/sqlalchemy/engine/base.py", line 1584, in _handle_dbapi_exception_noconnection
    sqlalchemy_exception, with_traceback=exc_info[2], from_=e
  File "/home/airflow/.local/lib/python3.6/site-packages/sqlalchemy/util/compat.py", line 182, in raise_
    raise exception
  File "/home/airflow/.local/lib/python3.6/site-packages/sqlalchemy/engine/base.py", line 2336, in _wrap_pool_connect
    return fn()
  File "/home/airflow/.local/lib/python3.6/site-packages/sqlalchemy/pool/base.py", line 304, in unique_connection
    return _ConnectionFairy._checkout(self)
  File "/home/airflow/.local/lib/python3.6/site-packages/sqlalchemy/pool/base.py", line 778, in _checkout
    fairy = _ConnectionRecord.checkout(pool)
  File "/home/airflow/.local/lib/python3.6/site-packages/sqlalchemy/pool/base.py", line 495, in checkout
    rec = pool._do_get()
  File "/home/airflow/.local/lib/python3.6/site-packages/sqlalchemy/pool/impl.py", line 140, in _do_get
    self._dec_overflow()
  File "/home/airflow/.local/lib/python3.6/site-packages/sqlalchemy/util/langhelpers.py", line 70, in __exit__
    with_traceback=exc_tb,
  File "/home/airflow/.local/lib/python3.6/site-packages/sqlalchemy/util/compat.py", line 182, in raise_
    raise exception
  File "/home/airflow/.local/lib/python3.6/site-packages/sqlalchemy/pool/impl.py", line 137, in _do_get
    return self._create_connection()
  File "/home/airflow/.local/lib/python3.6/site-packages/sqlalchemy/pool/base.py", line 309, in _create_connection
    return _ConnectionRecord(self)
  File "/home/airflow/.local/lib/python3.6/site-packages/sqlalchemy/pool/base.py", line 440, in __init__
    self.__connect(first_connect_check=True)
  File "/home/airflow/.local/lib/python3.6/site-packages/sqlalchemy/pool/base.py", line 661, in __connect
    pool.logger.debug("Error on connect(): %s", e)
  File "/home/airflow/.local/lib/python3.6/site-packages/sqlalchemy/util/langhelpers.py", line 70, in __exit__
    with_traceback=exc_tb,
  File "/home/airflow/.local/lib/python3.6/site-packages/sqlalchemy/util/compat.py", line 182, in raise_
    raise exception
  File "/home/airflow/.local/lib/python3.6/site-packages/sqlalchemy/pool/base.py", line 656, in __connect
    connection = pool._invoke_creator(self)
  File "/home/airflow/.local/lib/python3.6/site-packages/sqlalchemy/engine/strategies.py", line 114, in connect
    return dialect.connect(*cargs, **cparams)
  File "/home/airflow/.local/lib/python3.6/site-packages/sqlalchemy/engine/default.py", line 508, in connect
    return self.dbapi.connect(*cargs, **cparams)
  File "/home/airflow/.local/lib/python3.6/site-packages/psycopg2/__init__.py", line 122, in connect
    conn = _connect(dsn, connection_factory=connection_factory, **kwasync)
sqlalchemy.exc.OperationalError: (psycopg2.OperationalError) could not translate host name "pgdatabase" to address: Name or service not known

(Background on this error at: http://sqlalche.me/e/13/e3q8)
[2024-03-27 03:48:27,853] {local_task_job.py:154} INFO - Task exited with return code 1
[2024-03-27 03:48:27,940] {local_task_job.py:264} INFO - 0 downstream tasks scheduled from follow-on schedule check
[2024-03-28 03:50:34,916] {taskinstance.py:1032} INFO - Dependencies all met for <TaskInstance: ingest_data.ingest_to_postgres_task scheduled__2022-09-02T06:00:00+00:00 [queued]>
[2024-03-28 03:50:35,213] {taskinstance.py:1032} INFO - Dependencies all met for <TaskInstance: ingest_data.ingest_to_postgres_task scheduled__2022-09-02T06:00:00+00:00 [queued]>
[2024-03-28 03:50:35,217] {taskinstance.py:1238} INFO - 
--------------------------------------------------------------------------------
[2024-03-28 03:50:35,218] {taskinstance.py:1239} INFO - Starting attempt 1 of 1
[2024-03-28 03:50:35,219] {taskinstance.py:1240} INFO - 
--------------------------------------------------------------------------------
[2024-03-28 03:50:35,352] {taskinstance.py:1259} INFO - Executing <Task(PythonOperator): ingest_to_postgres_task> on 2022-09-02 06:00:00+00:00
[2024-03-28 03:50:35,362] {standard_task_runner.py:52} INFO - Started process 248 to run task
[2024-03-28 03:50:35,618] {standard_task_runner.py:76} INFO - Running: ['***', 'tasks', 'run', 'ingest_data', 'ingest_to_postgres_task', 'scheduled__2022-09-02T06:00:00+00:00', '--job-id', '862', '--raw', '--subdir', 'DAGS_FOLDER/data_ingestion_dag.py', '--cfg-path', '/tmp/tmp2m_l7r7y', '--error-file', '/tmp/tmpjmzybv0y']
[2024-03-28 03:50:35,619] {standard_task_runner.py:77} INFO - Job 862: Subtask ingest_to_postgres_task
[2024-03-28 03:50:37,092] {logging_mixin.py:109} INFO - Running <TaskInstance: ingest_data.ingest_to_postgres_task scheduled__2022-09-02T06:00:00+00:00 [running]> on host 05f84def3a12
[2024-03-28 03:50:38,108] {warnings.py:99} WARNING - /home/***/.local/lib/python3.6/site-packages/***/utils/context.py:152: AirflowContextDeprecationWarning: Accessing 'execution_date' from the template is deprecated and will be removed in a future version. Please use 'data_interval_start' or 'logical_date' instead.
  warnings.warn(_create_deprecation_warning(key, self._deprecation_replacements[key]))

[2024-03-28 03:50:38,493] {taskinstance.py:1426} INFO - Exporting the following env vars:
AIRFLOW_CTX_DAG_OWNER=***
AIRFLOW_CTX_DAG_ID=ingest_data
AIRFLOW_CTX_TASK_ID=ingest_to_postgres_task
AIRFLOW_CTX_EXECUTION_DATE=2022-09-02T06:00:00+00:00
AIRFLOW_CTX_DAG_RUN_ID=scheduled__2022-09-02T06:00:00+00:00
[2024-03-28 03:50:38,495] {logging_mixin.py:109} INFO - yellow_taxi_2022_09 /opt/***/yellowtaxi_tripdata_2022-09.parquet 2022-09-02T06:00:00+00:00
[2024-03-28 03:50:38,495] {logging_mixin.py:109} INFO - Starting data ingestion process...
[2024-03-28 03:50:55,950] {taskinstance.py:1700} ERROR - Task failed with exception
Traceback (most recent call last):
  File "/home/airflow/.local/lib/python3.6/site-packages/sqlalchemy/engine/base.py", line 2336, in _wrap_pool_connect
    return fn()
  File "/home/airflow/.local/lib/python3.6/site-packages/sqlalchemy/pool/base.py", line 304, in unique_connection
    return _ConnectionFairy._checkout(self)
  File "/home/airflow/.local/lib/python3.6/site-packages/sqlalchemy/pool/base.py", line 778, in _checkout
    fairy = _ConnectionRecord.checkout(pool)
  File "/home/airflow/.local/lib/python3.6/site-packages/sqlalchemy/pool/base.py", line 495, in checkout
    rec = pool._do_get()
  File "/home/airflow/.local/lib/python3.6/site-packages/sqlalchemy/pool/impl.py", line 140, in _do_get
    self._dec_overflow()
  File "/home/airflow/.local/lib/python3.6/site-packages/sqlalchemy/util/langhelpers.py", line 70, in __exit__
    with_traceback=exc_tb,
  File "/home/airflow/.local/lib/python3.6/site-packages/sqlalchemy/util/compat.py", line 182, in raise_
    raise exception
  File "/home/airflow/.local/lib/python3.6/site-packages/sqlalchemy/pool/impl.py", line 137, in _do_get
    return self._create_connection()
  File "/home/airflow/.local/lib/python3.6/site-packages/sqlalchemy/pool/base.py", line 309, in _create_connection
    return _ConnectionRecord(self)
  File "/home/airflow/.local/lib/python3.6/site-packages/sqlalchemy/pool/base.py", line 440, in __init__
    self.__connect(first_connect_check=True)
  File "/home/airflow/.local/lib/python3.6/site-packages/sqlalchemy/pool/base.py", line 661, in __connect
    pool.logger.debug("Error on connect(): %s", e)
  File "/home/airflow/.local/lib/python3.6/site-packages/sqlalchemy/util/langhelpers.py", line 70, in __exit__
    with_traceback=exc_tb,
  File "/home/airflow/.local/lib/python3.6/site-packages/sqlalchemy/util/compat.py", line 182, in raise_
    raise exception
  File "/home/airflow/.local/lib/python3.6/site-packages/sqlalchemy/pool/base.py", line 656, in __connect
    connection = pool._invoke_creator(self)
  File "/home/airflow/.local/lib/python3.6/site-packages/sqlalchemy/engine/strategies.py", line 114, in connect
    return dialect.connect(*cargs, **cparams)
  File "/home/airflow/.local/lib/python3.6/site-packages/sqlalchemy/engine/default.py", line 508, in connect
    return self.dbapi.connect(*cargs, **cparams)
  File "/home/airflow/.local/lib/python3.6/site-packages/psycopg2/__init__.py", line 122, in connect
    conn = _connect(dsn, connection_factory=connection_factory, **kwasync)
psycopg2.OperationalError: could not translate host name "pgdatabase" to address: Name or service not known


The above exception was the direct cause of the following exception:

Traceback (most recent call last):
  File "/home/airflow/.local/lib/python3.6/site-packages/airflow/models/taskinstance.py", line 1329, in _run_raw_task
    self._execute_task_with_callbacks(context)
  File "/home/airflow/.local/lib/python3.6/site-packages/airflow/models/taskinstance.py", line 1455, in _execute_task_with_callbacks
    result = self._execute_task(context, self.task)
  File "/home/airflow/.local/lib/python3.6/site-packages/airflow/models/taskinstance.py", line 1511, in _execute_task
    result = execute_callable(context=context)
  File "/home/airflow/.local/lib/python3.6/site-packages/airflow/operators/python.py", line 174, in execute
    return_value = self.execute_callable()
  File "/home/airflow/.local/lib/python3.6/site-packages/airflow/operators/python.py", line 185, in execute_callable
    return self.python_callable(*self.op_args, **self.op_kwargs)
  File "/opt/airflow/dags/ingest_script.py", line 32, in ingest_callable
    connection = engine.connect()
  File "/home/airflow/.local/lib/python3.6/site-packages/sqlalchemy/engine/base.py", line 2263, in connect
    return self._connection_cls(self, **kwargs)
  File "/home/airflow/.local/lib/python3.6/site-packages/sqlalchemy/engine/base.py", line 104, in __init__
    else engine.raw_connection()
  File "/home/airflow/.local/lib/python3.6/site-packages/sqlalchemy/engine/base.py", line 2370, in raw_connection
    self.pool.unique_connection, _connection
  File "/home/airflow/.local/lib/python3.6/site-packages/sqlalchemy/engine/base.py", line 2340, in _wrap_pool_connect
    e, dialect, self
  File "/home/airflow/.local/lib/python3.6/site-packages/sqlalchemy/engine/base.py", line 1584, in _handle_dbapi_exception_noconnection
    sqlalchemy_exception, with_traceback=exc_info[2], from_=e
  File "/home/airflow/.local/lib/python3.6/site-packages/sqlalchemy/util/compat.py", line 182, in raise_
    raise exception
  File "/home/airflow/.local/lib/python3.6/site-packages/sqlalchemy/engine/base.py", line 2336, in _wrap_pool_connect
    return fn()
  File "/home/airflow/.local/lib/python3.6/site-packages/sqlalchemy/pool/base.py", line 304, in unique_connection
    return _ConnectionFairy._checkout(self)
  File "/home/airflow/.local/lib/python3.6/site-packages/sqlalchemy/pool/base.py", line 778, in _checkout
    fairy = _ConnectionRecord.checkout(pool)
  File "/home/airflow/.local/lib/python3.6/site-packages/sqlalchemy/pool/base.py", line 495, in checkout
    rec = pool._do_get()
  File "/home/airflow/.local/lib/python3.6/site-packages/sqlalchemy/pool/impl.py", line 140, in _do_get
    self._dec_overflow()
  File "/home/airflow/.local/lib/python3.6/site-packages/sqlalchemy/util/langhelpers.py", line 70, in __exit__
    with_traceback=exc_tb,
  File "/home/airflow/.local/lib/python3.6/site-packages/sqlalchemy/util/compat.py", line 182, in raise_
    raise exception
  File "/home/airflow/.local/lib/python3.6/site-packages/sqlalchemy/pool/impl.py", line 137, in _do_get
    return self._create_connection()
  File "/home/airflow/.local/lib/python3.6/site-packages/sqlalchemy/pool/base.py", line 309, in _create_connection
    return _ConnectionRecord(self)
  File "/home/airflow/.local/lib/python3.6/site-packages/sqlalchemy/pool/base.py", line 440, in __init__
    self.__connect(first_connect_check=True)
  File "/home/airflow/.local/lib/python3.6/site-packages/sqlalchemy/pool/base.py", line 661, in __connect
    pool.logger.debug("Error on connect(): %s", e)
  File "/home/airflow/.local/lib/python3.6/site-packages/sqlalchemy/util/langhelpers.py", line 70, in __exit__
    with_traceback=exc_tb,
  File "/home/airflow/.local/lib/python3.6/site-packages/sqlalchemy/util/compat.py", line 182, in raise_
    raise exception
  File "/home/airflow/.local/lib/python3.6/site-packages/sqlalchemy/pool/base.py", line 656, in __connect
    connection = pool._invoke_creator(self)
  File "/home/airflow/.local/lib/python3.6/site-packages/sqlalchemy/engine/strategies.py", line 114, in connect
    return dialect.connect(*cargs, **cparams)
  File "/home/airflow/.local/lib/python3.6/site-packages/sqlalchemy/engine/default.py", line 508, in connect
    return self.dbapi.connect(*cargs, **cparams)
  File "/home/airflow/.local/lib/python3.6/site-packages/psycopg2/__init__.py", line 122, in connect
    conn = _connect(dsn, connection_factory=connection_factory, **kwasync)
sqlalchemy.exc.OperationalError: (psycopg2.OperationalError) could not translate host name "pgdatabase" to address: Name or service not known

(Background on this error at: http://sqlalche.me/e/13/e3q8)
[2024-03-28 03:50:56,132] {taskinstance.py:1277} INFO - Marking task as FAILED. dag_id=ingest_data, task_id=ingest_to_postgres_task, execution_date=20220902T060000, start_date=20240328T035035, end_date=20240328T035056
[2024-03-28 03:50:56,381] {standard_task_runner.py:92} ERROR - Failed to execute job 862 for task ingest_to_postgres_task
Traceback (most recent call last):
  File "/home/airflow/.local/lib/python3.6/site-packages/sqlalchemy/engine/base.py", line 2336, in _wrap_pool_connect
    return fn()
  File "/home/airflow/.local/lib/python3.6/site-packages/sqlalchemy/pool/base.py", line 304, in unique_connection
    return _ConnectionFairy._checkout(self)
  File "/home/airflow/.local/lib/python3.6/site-packages/sqlalchemy/pool/base.py", line 778, in _checkout
    fairy = _ConnectionRecord.checkout(pool)
  File "/home/airflow/.local/lib/python3.6/site-packages/sqlalchemy/pool/base.py", line 495, in checkout
    rec = pool._do_get()
  File "/home/airflow/.local/lib/python3.6/site-packages/sqlalchemy/pool/impl.py", line 140, in _do_get
    self._dec_overflow()
  File "/home/airflow/.local/lib/python3.6/site-packages/sqlalchemy/util/langhelpers.py", line 70, in __exit__
    with_traceback=exc_tb,
  File "/home/airflow/.local/lib/python3.6/site-packages/sqlalchemy/util/compat.py", line 182, in raise_
    raise exception
  File "/home/airflow/.local/lib/python3.6/site-packages/sqlalchemy/pool/impl.py", line 137, in _do_get
    return self._create_connection()
  File "/home/airflow/.local/lib/python3.6/site-packages/sqlalchemy/pool/base.py", line 309, in _create_connection
    return _ConnectionRecord(self)
  File "/home/airflow/.local/lib/python3.6/site-packages/sqlalchemy/pool/base.py", line 440, in __init__
    self.__connect(first_connect_check=True)
  File "/home/airflow/.local/lib/python3.6/site-packages/sqlalchemy/pool/base.py", line 661, in __connect
    pool.logger.debug("Error on connect(): %s", e)
  File "/home/airflow/.local/lib/python3.6/site-packages/sqlalchemy/util/langhelpers.py", line 70, in __exit__
    with_traceback=exc_tb,
  File "/home/airflow/.local/lib/python3.6/site-packages/sqlalchemy/util/compat.py", line 182, in raise_
    raise exception
  File "/home/airflow/.local/lib/python3.6/site-packages/sqlalchemy/pool/base.py", line 656, in __connect
    connection = pool._invoke_creator(self)
  File "/home/airflow/.local/lib/python3.6/site-packages/sqlalchemy/engine/strategies.py", line 114, in connect
    return dialect.connect(*cargs, **cparams)
  File "/home/airflow/.local/lib/python3.6/site-packages/sqlalchemy/engine/default.py", line 508, in connect
    return self.dbapi.connect(*cargs, **cparams)
  File "/home/airflow/.local/lib/python3.6/site-packages/psycopg2/__init__.py", line 122, in connect
    conn = _connect(dsn, connection_factory=connection_factory, **kwasync)
psycopg2.OperationalError: could not translate host name "pgdatabase" to address: Name or service not known


The above exception was the direct cause of the following exception:

Traceback (most recent call last):
  File "/home/airflow/.local/lib/python3.6/site-packages/airflow/task/task_runner/standard_task_runner.py", line 85, in _start_by_fork
    args.func(args, dag=self.dag)
  File "/home/airflow/.local/lib/python3.6/site-packages/airflow/cli/cli_parser.py", line 48, in command
    return func(*args, **kwargs)
  File "/home/airflow/.local/lib/python3.6/site-packages/airflow/utils/cli.py", line 92, in wrapper
    return f(*args, **kwargs)
  File "/home/airflow/.local/lib/python3.6/site-packages/airflow/cli/commands/task_command.py", line 298, in task_run
    _run_task_by_selected_method(args, dag, ti)
  File "/home/airflow/.local/lib/python3.6/site-packages/airflow/cli/commands/task_command.py", line 107, in _run_task_by_selected_method
    _run_raw_task(args, ti)
  File "/home/airflow/.local/lib/python3.6/site-packages/airflow/cli/commands/task_command.py", line 184, in _run_raw_task
    error_file=args.error_file,
  File "/home/airflow/.local/lib/python3.6/site-packages/airflow/utils/session.py", line 70, in wrapper
    return func(*args, session=session, **kwargs)
  File "/home/airflow/.local/lib/python3.6/site-packages/airflow/models/taskinstance.py", line 1329, in _run_raw_task
    self._execute_task_with_callbacks(context)
  File "/home/airflow/.local/lib/python3.6/site-packages/airflow/models/taskinstance.py", line 1455, in _execute_task_with_callbacks
    result = self._execute_task(context, self.task)
  File "/home/airflow/.local/lib/python3.6/site-packages/airflow/models/taskinstance.py", line 1511, in _execute_task
    result = execute_callable(context=context)
  File "/home/airflow/.local/lib/python3.6/site-packages/airflow/operators/python.py", line 174, in execute
    return_value = self.execute_callable()
  File "/home/airflow/.local/lib/python3.6/site-packages/airflow/operators/python.py", line 185, in execute_callable
    return self.python_callable(*self.op_args, **self.op_kwargs)
  File "/opt/airflow/dags/ingest_script.py", line 32, in ingest_callable
    connection = engine.connect()
  File "/home/airflow/.local/lib/python3.6/site-packages/sqlalchemy/engine/base.py", line 2263, in connect
    return self._connection_cls(self, **kwargs)
  File "/home/airflow/.local/lib/python3.6/site-packages/sqlalchemy/engine/base.py", line 104, in __init__
    else engine.raw_connection()
  File "/home/airflow/.local/lib/python3.6/site-packages/sqlalchemy/engine/base.py", line 2370, in raw_connection
    self.pool.unique_connection, _connection
  File "/home/airflow/.local/lib/python3.6/site-packages/sqlalchemy/engine/base.py", line 2340, in _wrap_pool_connect
    e, dialect, self
  File "/home/airflow/.local/lib/python3.6/site-packages/sqlalchemy/engine/base.py", line 1584, in _handle_dbapi_exception_noconnection
    sqlalchemy_exception, with_traceback=exc_info[2], from_=e
  File "/home/airflow/.local/lib/python3.6/site-packages/sqlalchemy/util/compat.py", line 182, in raise_
    raise exception
  File "/home/airflow/.local/lib/python3.6/site-packages/sqlalchemy/engine/base.py", line 2336, in _wrap_pool_connect
    return fn()
  File "/home/airflow/.local/lib/python3.6/site-packages/sqlalchemy/pool/base.py", line 304, in unique_connection
    return _ConnectionFairy._checkout(self)
  File "/home/airflow/.local/lib/python3.6/site-packages/sqlalchemy/pool/base.py", line 778, in _checkout
    fairy = _ConnectionRecord.checkout(pool)
  File "/home/airflow/.local/lib/python3.6/site-packages/sqlalchemy/pool/base.py", line 495, in checkout
    rec = pool._do_get()
  File "/home/airflow/.local/lib/python3.6/site-packages/sqlalchemy/pool/impl.py", line 140, in _do_get
    self._dec_overflow()
  File "/home/airflow/.local/lib/python3.6/site-packages/sqlalchemy/util/langhelpers.py", line 70, in __exit__
    with_traceback=exc_tb,
  File "/home/airflow/.local/lib/python3.6/site-packages/sqlalchemy/util/compat.py", line 182, in raise_
    raise exception
  File "/home/airflow/.local/lib/python3.6/site-packages/sqlalchemy/pool/impl.py", line 137, in _do_get
    return self._create_connection()
  File "/home/airflow/.local/lib/python3.6/site-packages/sqlalchemy/pool/base.py", line 309, in _create_connection
    return _ConnectionRecord(self)
  File "/home/airflow/.local/lib/python3.6/site-packages/sqlalchemy/pool/base.py", line 440, in __init__
    self.__connect(first_connect_check=True)
  File "/home/airflow/.local/lib/python3.6/site-packages/sqlalchemy/pool/base.py", line 661, in __connect
    pool.logger.debug("Error on connect(): %s", e)
  File "/home/airflow/.local/lib/python3.6/site-packages/sqlalchemy/util/langhelpers.py", line 70, in __exit__
    with_traceback=exc_tb,
  File "/home/airflow/.local/lib/python3.6/site-packages/sqlalchemy/util/compat.py", line 182, in raise_
    raise exception
  File "/home/airflow/.local/lib/python3.6/site-packages/sqlalchemy/pool/base.py", line 656, in __connect
    connection = pool._invoke_creator(self)
  File "/home/airflow/.local/lib/python3.6/site-packages/sqlalchemy/engine/strategies.py", line 114, in connect
    return dialect.connect(*cargs, **cparams)
  File "/home/airflow/.local/lib/python3.6/site-packages/sqlalchemy/engine/default.py", line 508, in connect
    return self.dbapi.connect(*cargs, **cparams)
  File "/home/airflow/.local/lib/python3.6/site-packages/psycopg2/__init__.py", line 122, in connect
    conn = _connect(dsn, connection_factory=connection_factory, **kwasync)
sqlalchemy.exc.OperationalError: (psycopg2.OperationalError) could not translate host name "pgdatabase" to address: Name or service not known

(Background on this error at: http://sqlalche.me/e/13/e3q8)
[2024-03-28 03:50:56,672] {local_task_job.py:212} WARNING - State of this instance has been externally set to failed. Terminating instance.
[2024-03-28 03:50:56,687] {process_utils.py:124} INFO - Sending Signals.SIGTERM to group 248. PIDs of all processes in the group: [248]
[2024-03-28 03:50:56,702] {process_utils.py:75} INFO - Sending the signal Signals.SIGTERM to group 248
[2024-03-28 03:50:56,809] {process_utils.py:70} INFO - Process psutil.Process(pid=248, status='terminated', exitcode=1, started='03:50:34') (248) terminated with exit code 1
[2024-03-28 09:17:39,401] {taskinstance.py:1032} INFO - Dependencies all met for <TaskInstance: ingest_data.ingest_to_postgres_task scheduled__2022-09-02T06:00:00+00:00 [queued]>
[2024-03-28 09:17:39,459] {taskinstance.py:1032} INFO - Dependencies all met for <TaskInstance: ingest_data.ingest_to_postgres_task scheduled__2022-09-02T06:00:00+00:00 [queued]>
[2024-03-28 09:17:39,459] {taskinstance.py:1238} INFO - 
--------------------------------------------------------------------------------
[2024-03-28 09:17:39,459] {taskinstance.py:1239} INFO - Starting attempt 1 of 1
[2024-03-28 09:17:39,459] {taskinstance.py:1240} INFO - 
--------------------------------------------------------------------------------
[2024-03-28 09:17:39,913] {taskinstance.py:1259} INFO - Executing <Task(PythonOperator): ingest_to_postgres_task> on 2022-09-02 06:00:00+00:00
[2024-03-28 09:17:39,972] {standard_task_runner.py:52} INFO - Started process 218 to run task
[2024-03-28 09:17:40,018] {standard_task_runner.py:76} INFO - Running: ['***', 'tasks', 'run', 'ingest_data', 'ingest_to_postgres_task', 'scheduled__2022-09-02T06:00:00+00:00', '--job-id', '1004', '--raw', '--subdir', 'DAGS_FOLDER/data_ingestion_dag.py', '--cfg-path', '/tmp/tmprhmjbb9q', '--error-file', '/tmp/tmpby1uvnez']
[2024-03-28 09:17:40,019] {standard_task_runner.py:77} INFO - Job 1004: Subtask ingest_to_postgres_task
[2024-03-28 09:17:40,651] {logging_mixin.py:109} INFO - Running <TaskInstance: ingest_data.ingest_to_postgres_task scheduled__2022-09-02T06:00:00+00:00 [running]> on host 05f84def3a12
[2024-03-28 09:17:40,794] {warnings.py:99} WARNING - /home/***/.local/lib/python3.6/site-packages/***/utils/context.py:152: AirflowContextDeprecationWarning: Accessing 'execution_date' from the template is deprecated and will be removed in a future version. Please use 'data_interval_start' or 'logical_date' instead.
  warnings.warn(_create_deprecation_warning(key, self._deprecation_replacements[key]))

[2024-03-28 09:17:40,867] {taskinstance.py:1426} INFO - Exporting the following env vars:
AIRFLOW_CTX_DAG_OWNER=***
AIRFLOW_CTX_DAG_ID=ingest_data
AIRFLOW_CTX_TASK_ID=ingest_to_postgres_task
AIRFLOW_CTX_EXECUTION_DATE=2022-09-02T06:00:00+00:00
AIRFLOW_CTX_DAG_RUN_ID=scheduled__2022-09-02T06:00:00+00:00
[2024-03-28 09:17:40,868] {logging_mixin.py:109} INFO - yellow_taxi_2022_09 /opt/***/yellowtaxi_tripdata_2022-09.parquet 2022-09-02T06:00:00+00:00
[2024-03-28 09:17:40,869] {logging_mixin.py:109} INFO - Starting data ingestion process...
[2024-03-28 09:17:56,194] {taskinstance.py:1700} ERROR - Task failed with exception
Traceback (most recent call last):
  File "/home/airflow/.local/lib/python3.6/site-packages/sqlalchemy/engine/base.py", line 2336, in _wrap_pool_connect
    return fn()
  File "/home/airflow/.local/lib/python3.6/site-packages/sqlalchemy/pool/base.py", line 304, in unique_connection
    return _ConnectionFairy._checkout(self)
  File "/home/airflow/.local/lib/python3.6/site-packages/sqlalchemy/pool/base.py", line 778, in _checkout
    fairy = _ConnectionRecord.checkout(pool)
  File "/home/airflow/.local/lib/python3.6/site-packages/sqlalchemy/pool/base.py", line 495, in checkout
    rec = pool._do_get()
  File "/home/airflow/.local/lib/python3.6/site-packages/sqlalchemy/pool/impl.py", line 140, in _do_get
    self._dec_overflow()
  File "/home/airflow/.local/lib/python3.6/site-packages/sqlalchemy/util/langhelpers.py", line 70, in __exit__
    with_traceback=exc_tb,
  File "/home/airflow/.local/lib/python3.6/site-packages/sqlalchemy/util/compat.py", line 182, in raise_
    raise exception
  File "/home/airflow/.local/lib/python3.6/site-packages/sqlalchemy/pool/impl.py", line 137, in _do_get
    return self._create_connection()
  File "/home/airflow/.local/lib/python3.6/site-packages/sqlalchemy/pool/base.py", line 309, in _create_connection
    return _ConnectionRecord(self)
  File "/home/airflow/.local/lib/python3.6/site-packages/sqlalchemy/pool/base.py", line 440, in __init__
    self.__connect(first_connect_check=True)
  File "/home/airflow/.local/lib/python3.6/site-packages/sqlalchemy/pool/base.py", line 661, in __connect
    pool.logger.debug("Error on connect(): %s", e)
  File "/home/airflow/.local/lib/python3.6/site-packages/sqlalchemy/util/langhelpers.py", line 70, in __exit__
    with_traceback=exc_tb,
  File "/home/airflow/.local/lib/python3.6/site-packages/sqlalchemy/util/compat.py", line 182, in raise_
    raise exception
  File "/home/airflow/.local/lib/python3.6/site-packages/sqlalchemy/pool/base.py", line 656, in __connect
    connection = pool._invoke_creator(self)
  File "/home/airflow/.local/lib/python3.6/site-packages/sqlalchemy/engine/strategies.py", line 114, in connect
    return dialect.connect(*cargs, **cparams)
  File "/home/airflow/.local/lib/python3.6/site-packages/sqlalchemy/engine/default.py", line 508, in connect
    return self.dbapi.connect(*cargs, **cparams)
  File "/home/airflow/.local/lib/python3.6/site-packages/psycopg2/__init__.py", line 122, in connect
    conn = _connect(dsn, connection_factory=connection_factory, **kwasync)
psycopg2.OperationalError: could not translate host name "pgdatabase" to address: Name or service not known


The above exception was the direct cause of the following exception:

Traceback (most recent call last):
  File "/home/airflow/.local/lib/python3.6/site-packages/airflow/models/taskinstance.py", line 1329, in _run_raw_task
    self._execute_task_with_callbacks(context)
  File "/home/airflow/.local/lib/python3.6/site-packages/airflow/models/taskinstance.py", line 1455, in _execute_task_with_callbacks
    result = self._execute_task(context, self.task)
  File "/home/airflow/.local/lib/python3.6/site-packages/airflow/models/taskinstance.py", line 1511, in _execute_task
    result = execute_callable(context=context)
  File "/home/airflow/.local/lib/python3.6/site-packages/airflow/operators/python.py", line 174, in execute
    return_value = self.execute_callable()
  File "/home/airflow/.local/lib/python3.6/site-packages/airflow/operators/python.py", line 185, in execute_callable
    return self.python_callable(*self.op_args, **self.op_kwargs)
  File "/opt/airflow/dags/ingest_script.py", line 32, in ingest_callable
    connection = engine.connect()
  File "/home/airflow/.local/lib/python3.6/site-packages/sqlalchemy/engine/base.py", line 2263, in connect
    return self._connection_cls(self, **kwargs)
  File "/home/airflow/.local/lib/python3.6/site-packages/sqlalchemy/engine/base.py", line 104, in __init__
    else engine.raw_connection()
  File "/home/airflow/.local/lib/python3.6/site-packages/sqlalchemy/engine/base.py", line 2370, in raw_connection
    self.pool.unique_connection, _connection
  File "/home/airflow/.local/lib/python3.6/site-packages/sqlalchemy/engine/base.py", line 2340, in _wrap_pool_connect
    e, dialect, self
  File "/home/airflow/.local/lib/python3.6/site-packages/sqlalchemy/engine/base.py", line 1584, in _handle_dbapi_exception_noconnection
    sqlalchemy_exception, with_traceback=exc_info[2], from_=e
  File "/home/airflow/.local/lib/python3.6/site-packages/sqlalchemy/util/compat.py", line 182, in raise_
    raise exception
  File "/home/airflow/.local/lib/python3.6/site-packages/sqlalchemy/engine/base.py", line 2336, in _wrap_pool_connect
    return fn()
  File "/home/airflow/.local/lib/python3.6/site-packages/sqlalchemy/pool/base.py", line 304, in unique_connection
    return _ConnectionFairy._checkout(self)
  File "/home/airflow/.local/lib/python3.6/site-packages/sqlalchemy/pool/base.py", line 778, in _checkout
    fairy = _ConnectionRecord.checkout(pool)
  File "/home/airflow/.local/lib/python3.6/site-packages/sqlalchemy/pool/base.py", line 495, in checkout
    rec = pool._do_get()
  File "/home/airflow/.local/lib/python3.6/site-packages/sqlalchemy/pool/impl.py", line 140, in _do_get
    self._dec_overflow()
  File "/home/airflow/.local/lib/python3.6/site-packages/sqlalchemy/util/langhelpers.py", line 70, in __exit__
    with_traceback=exc_tb,
  File "/home/airflow/.local/lib/python3.6/site-packages/sqlalchemy/util/compat.py", line 182, in raise_
    raise exception
  File "/home/airflow/.local/lib/python3.6/site-packages/sqlalchemy/pool/impl.py", line 137, in _do_get
    return self._create_connection()
  File "/home/airflow/.local/lib/python3.6/site-packages/sqlalchemy/pool/base.py", line 309, in _create_connection
    return _ConnectionRecord(self)
  File "/home/airflow/.local/lib/python3.6/site-packages/sqlalchemy/pool/base.py", line 440, in __init__
    self.__connect(first_connect_check=True)
  File "/home/airflow/.local/lib/python3.6/site-packages/sqlalchemy/pool/base.py", line 661, in __connect
    pool.logger.debug("Error on connect(): %s", e)
  File "/home/airflow/.local/lib/python3.6/site-packages/sqlalchemy/util/langhelpers.py", line 70, in __exit__
    with_traceback=exc_tb,
  File "/home/airflow/.local/lib/python3.6/site-packages/sqlalchemy/util/compat.py", line 182, in raise_
    raise exception
  File "/home/airflow/.local/lib/python3.6/site-packages/sqlalchemy/pool/base.py", line 656, in __connect
    connection = pool._invoke_creator(self)
  File "/home/airflow/.local/lib/python3.6/site-packages/sqlalchemy/engine/strategies.py", line 114, in connect
    return dialect.connect(*cargs, **cparams)
  File "/home/airflow/.local/lib/python3.6/site-packages/sqlalchemy/engine/default.py", line 508, in connect
    return self.dbapi.connect(*cargs, **cparams)
  File "/home/airflow/.local/lib/python3.6/site-packages/psycopg2/__init__.py", line 122, in connect
    conn = _connect(dsn, connection_factory=connection_factory, **kwasync)
sqlalchemy.exc.OperationalError: (psycopg2.OperationalError) could not translate host name "pgdatabase" to address: Name or service not known

(Background on this error at: http://sqlalche.me/e/13/e3q8)
[2024-03-28 09:17:56,236] {taskinstance.py:1277} INFO - Marking task as FAILED. dag_id=ingest_data, task_id=ingest_to_postgres_task, execution_date=20220902T060000, start_date=20240328T091739, end_date=20240328T091756
[2024-03-28 09:17:56,286] {standard_task_runner.py:92} ERROR - Failed to execute job 1004 for task ingest_to_postgres_task
Traceback (most recent call last):
  File "/home/airflow/.local/lib/python3.6/site-packages/sqlalchemy/engine/base.py", line 2336, in _wrap_pool_connect
    return fn()
  File "/home/airflow/.local/lib/python3.6/site-packages/sqlalchemy/pool/base.py", line 304, in unique_connection
    return _ConnectionFairy._checkout(self)
  File "/home/airflow/.local/lib/python3.6/site-packages/sqlalchemy/pool/base.py", line 778, in _checkout
    fairy = _ConnectionRecord.checkout(pool)
  File "/home/airflow/.local/lib/python3.6/site-packages/sqlalchemy/pool/base.py", line 495, in checkout
    rec = pool._do_get()
  File "/home/airflow/.local/lib/python3.6/site-packages/sqlalchemy/pool/impl.py", line 140, in _do_get
    self._dec_overflow()
  File "/home/airflow/.local/lib/python3.6/site-packages/sqlalchemy/util/langhelpers.py", line 70, in __exit__
    with_traceback=exc_tb,
  File "/home/airflow/.local/lib/python3.6/site-packages/sqlalchemy/util/compat.py", line 182, in raise_
    raise exception
  File "/home/airflow/.local/lib/python3.6/site-packages/sqlalchemy/pool/impl.py", line 137, in _do_get
    return self._create_connection()
  File "/home/airflow/.local/lib/python3.6/site-packages/sqlalchemy/pool/base.py", line 309, in _create_connection
    return _ConnectionRecord(self)
  File "/home/airflow/.local/lib/python3.6/site-packages/sqlalchemy/pool/base.py", line 440, in __init__
    self.__connect(first_connect_check=True)
  File "/home/airflow/.local/lib/python3.6/site-packages/sqlalchemy/pool/base.py", line 661, in __connect
    pool.logger.debug("Error on connect(): %s", e)
  File "/home/airflow/.local/lib/python3.6/site-packages/sqlalchemy/util/langhelpers.py", line 70, in __exit__
    with_traceback=exc_tb,
  File "/home/airflow/.local/lib/python3.6/site-packages/sqlalchemy/util/compat.py", line 182, in raise_
    raise exception
  File "/home/airflow/.local/lib/python3.6/site-packages/sqlalchemy/pool/base.py", line 656, in __connect
    connection = pool._invoke_creator(self)
  File "/home/airflow/.local/lib/python3.6/site-packages/sqlalchemy/engine/strategies.py", line 114, in connect
    return dialect.connect(*cargs, **cparams)
  File "/home/airflow/.local/lib/python3.6/site-packages/sqlalchemy/engine/default.py", line 508, in connect
    return self.dbapi.connect(*cargs, **cparams)
  File "/home/airflow/.local/lib/python3.6/site-packages/psycopg2/__init__.py", line 122, in connect
    conn = _connect(dsn, connection_factory=connection_factory, **kwasync)
psycopg2.OperationalError: could not translate host name "pgdatabase" to address: Name or service not known


The above exception was the direct cause of the following exception:

Traceback (most recent call last):
  File "/home/airflow/.local/lib/python3.6/site-packages/airflow/task/task_runner/standard_task_runner.py", line 85, in _start_by_fork
    args.func(args, dag=self.dag)
  File "/home/airflow/.local/lib/python3.6/site-packages/airflow/cli/cli_parser.py", line 48, in command
    return func(*args, **kwargs)
  File "/home/airflow/.local/lib/python3.6/site-packages/airflow/utils/cli.py", line 92, in wrapper
    return f(*args, **kwargs)
  File "/home/airflow/.local/lib/python3.6/site-packages/airflow/cli/commands/task_command.py", line 298, in task_run
    _run_task_by_selected_method(args, dag, ti)
  File "/home/airflow/.local/lib/python3.6/site-packages/airflow/cli/commands/task_command.py", line 107, in _run_task_by_selected_method
    _run_raw_task(args, ti)
  File "/home/airflow/.local/lib/python3.6/site-packages/airflow/cli/commands/task_command.py", line 184, in _run_raw_task
    error_file=args.error_file,
  File "/home/airflow/.local/lib/python3.6/site-packages/airflow/utils/session.py", line 70, in wrapper
    return func(*args, session=session, **kwargs)
  File "/home/airflow/.local/lib/python3.6/site-packages/airflow/models/taskinstance.py", line 1329, in _run_raw_task
    self._execute_task_with_callbacks(context)
  File "/home/airflow/.local/lib/python3.6/site-packages/airflow/models/taskinstance.py", line 1455, in _execute_task_with_callbacks
    result = self._execute_task(context, self.task)
  File "/home/airflow/.local/lib/python3.6/site-packages/airflow/models/taskinstance.py", line 1511, in _execute_task
    result = execute_callable(context=context)
  File "/home/airflow/.local/lib/python3.6/site-packages/airflow/operators/python.py", line 174, in execute
    return_value = self.execute_callable()
  File "/home/airflow/.local/lib/python3.6/site-packages/airflow/operators/python.py", line 185, in execute_callable
    return self.python_callable(*self.op_args, **self.op_kwargs)
  File "/opt/airflow/dags/ingest_script.py", line 32, in ingest_callable
    connection = engine.connect()
  File "/home/airflow/.local/lib/python3.6/site-packages/sqlalchemy/engine/base.py", line 2263, in connect
    return self._connection_cls(self, **kwargs)
  File "/home/airflow/.local/lib/python3.6/site-packages/sqlalchemy/engine/base.py", line 104, in __init__
    else engine.raw_connection()
  File "/home/airflow/.local/lib/python3.6/site-packages/sqlalchemy/engine/base.py", line 2370, in raw_connection
    self.pool.unique_connection, _connection
  File "/home/airflow/.local/lib/python3.6/site-packages/sqlalchemy/engine/base.py", line 2340, in _wrap_pool_connect
    e, dialect, self
  File "/home/airflow/.local/lib/python3.6/site-packages/sqlalchemy/engine/base.py", line 1584, in _handle_dbapi_exception_noconnection
    sqlalchemy_exception, with_traceback=exc_info[2], from_=e
  File "/home/airflow/.local/lib/python3.6/site-packages/sqlalchemy/util/compat.py", line 182, in raise_
    raise exception
  File "/home/airflow/.local/lib/python3.6/site-packages/sqlalchemy/engine/base.py", line 2336, in _wrap_pool_connect
    return fn()
  File "/home/airflow/.local/lib/python3.6/site-packages/sqlalchemy/pool/base.py", line 304, in unique_connection
    return _ConnectionFairy._checkout(self)
  File "/home/airflow/.local/lib/python3.6/site-packages/sqlalchemy/pool/base.py", line 778, in _checkout
    fairy = _ConnectionRecord.checkout(pool)
  File "/home/airflow/.local/lib/python3.6/site-packages/sqlalchemy/pool/base.py", line 495, in checkout
    rec = pool._do_get()
  File "/home/airflow/.local/lib/python3.6/site-packages/sqlalchemy/pool/impl.py", line 140, in _do_get
    self._dec_overflow()
  File "/home/airflow/.local/lib/python3.6/site-packages/sqlalchemy/util/langhelpers.py", line 70, in __exit__
    with_traceback=exc_tb,
  File "/home/airflow/.local/lib/python3.6/site-packages/sqlalchemy/util/compat.py", line 182, in raise_
    raise exception
  File "/home/airflow/.local/lib/python3.6/site-packages/sqlalchemy/pool/impl.py", line 137, in _do_get
    return self._create_connection()
  File "/home/airflow/.local/lib/python3.6/site-packages/sqlalchemy/pool/base.py", line 309, in _create_connection
    return _ConnectionRecord(self)
  File "/home/airflow/.local/lib/python3.6/site-packages/sqlalchemy/pool/base.py", line 440, in __init__
    self.__connect(first_connect_check=True)
  File "/home/airflow/.local/lib/python3.6/site-packages/sqlalchemy/pool/base.py", line 661, in __connect
    pool.logger.debug("Error on connect(): %s", e)
  File "/home/airflow/.local/lib/python3.6/site-packages/sqlalchemy/util/langhelpers.py", line 70, in __exit__
    with_traceback=exc_tb,
  File "/home/airflow/.local/lib/python3.6/site-packages/sqlalchemy/util/compat.py", line 182, in raise_
    raise exception
  File "/home/airflow/.local/lib/python3.6/site-packages/sqlalchemy/pool/base.py", line 656, in __connect
    connection = pool._invoke_creator(self)
  File "/home/airflow/.local/lib/python3.6/site-packages/sqlalchemy/engine/strategies.py", line 114, in connect
    return dialect.connect(*cargs, **cparams)
  File "/home/airflow/.local/lib/python3.6/site-packages/sqlalchemy/engine/default.py", line 508, in connect
    return self.dbapi.connect(*cargs, **cparams)
  File "/home/airflow/.local/lib/python3.6/site-packages/psycopg2/__init__.py", line 122, in connect
    conn = _connect(dsn, connection_factory=connection_factory, **kwasync)
sqlalchemy.exc.OperationalError: (psycopg2.OperationalError) could not translate host name "pgdatabase" to address: Name or service not known

(Background on this error at: http://sqlalche.me/e/13/e3q8)
[2024-03-28 09:17:56,341] {local_task_job.py:154} INFO - Task exited with return code 1
[2024-03-28 09:17:56,447] {local_task_job.py:264} INFO - 0 downstream tasks scheduled from follow-on schedule check
[2024-03-28 09:47:49,124] {taskinstance.py:1032} INFO - Dependencies all met for <TaskInstance: ingest_data.ingest_to_postgres_task scheduled__2022-09-02T06:00:00+00:00 [queued]>
[2024-03-28 09:47:49,153] {taskinstance.py:1032} INFO - Dependencies all met for <TaskInstance: ingest_data.ingest_to_postgres_task scheduled__2022-09-02T06:00:00+00:00 [queued]>
[2024-03-28 09:47:49,154] {taskinstance.py:1238} INFO - 
--------------------------------------------------------------------------------
[2024-03-28 09:47:49,155] {taskinstance.py:1239} INFO - Starting attempt 1 of 1
[2024-03-28 09:47:49,156] {taskinstance.py:1240} INFO - 
--------------------------------------------------------------------------------
[2024-03-28 09:47:49,186] {taskinstance.py:1259} INFO - Executing <Task(PythonOperator): ingest_to_postgres_task> on 2022-09-02 06:00:00+00:00
[2024-03-28 09:47:49,203] {standard_task_runner.py:52} INFO - Started process 1918 to run task
[2024-03-28 09:47:49,220] {standard_task_runner.py:76} INFO - Running: ['***', 'tasks', 'run', 'ingest_data', 'ingest_to_postgres_task', 'scheduled__2022-09-02T06:00:00+00:00', '--job-id', '1071', '--raw', '--subdir', 'DAGS_FOLDER/data_ingestion_dag.py', '--cfg-path', '/tmp/tmp8ay14w_p', '--error-file', '/tmp/tmpfi3x0h13']
[2024-03-28 09:47:49,222] {standard_task_runner.py:77} INFO - Job 1071: Subtask ingest_to_postgres_task
[2024-03-28 09:47:49,334] {logging_mixin.py:109} INFO - Running <TaskInstance: ingest_data.ingest_to_postgres_task scheduled__2022-09-02T06:00:00+00:00 [running]> on host 05f84def3a12
[2024-03-28 09:47:49,400] {warnings.py:99} WARNING - /home/***/.local/lib/python3.6/site-packages/***/utils/context.py:152: AirflowContextDeprecationWarning: Accessing 'execution_date' from the template is deprecated and will be removed in a future version. Please use 'data_interval_start' or 'logical_date' instead.
  warnings.warn(_create_deprecation_warning(key, self._deprecation_replacements[key]))

[2024-03-28 09:47:49,427] {taskinstance.py:1426} INFO - Exporting the following env vars:
AIRFLOW_CTX_DAG_OWNER=***
AIRFLOW_CTX_DAG_ID=ingest_data
AIRFLOW_CTX_TASK_ID=ingest_to_postgres_task
AIRFLOW_CTX_EXECUTION_DATE=2022-09-02T06:00:00+00:00
AIRFLOW_CTX_DAG_RUN_ID=scheduled__2022-09-02T06:00:00+00:00
[2024-03-28 09:47:49,428] {logging_mixin.py:109} INFO - yellow_taxi_2022_09 /opt/***/yellowtaxi_tripdata_2022-09.parquet 2022-09-02T06:00:00+00:00
[2024-03-28 09:47:49,429] {logging_mixin.py:109} INFO - Starting data ingestion process...
[2024-03-28 09:47:52,105] {logging_mixin.py:109} INFO - Writing data to table yellow_taxi_2022_09 in the database...
[2024-03-28 14:48:46,693] {taskinstance.py:1032} INFO - Dependencies all met for <TaskInstance: ingest_data.ingest_to_postgres_task scheduled__2022-09-02T06:00:00+00:00 [queued]>
[2024-03-28 14:48:46,960] {taskinstance.py:1032} INFO - Dependencies all met for <TaskInstance: ingest_data.ingest_to_postgres_task scheduled__2022-09-02T06:00:00+00:00 [queued]>
[2024-03-28 14:48:46,960] {taskinstance.py:1238} INFO - 
--------------------------------------------------------------------------------
[2024-03-28 14:48:46,961] {taskinstance.py:1239} INFO - Starting attempt 1 of 1
[2024-03-28 14:48:46,961] {taskinstance.py:1240} INFO - 
--------------------------------------------------------------------------------
[2024-03-28 14:48:47,237] {taskinstance.py:1259} INFO - Executing <Task(PythonOperator): ingest_to_postgres_task> on 2022-09-02 06:00:00+00:00
[2024-03-28 14:48:47,286] {standard_task_runner.py:52} INFO - Started process 183 to run task
[2024-03-28 14:48:47,342] {standard_task_runner.py:76} INFO - Running: ['***', 'tasks', 'run', 'ingest_data', 'ingest_to_postgres_task', 'scheduled__2022-09-02T06:00:00+00:00', '--job-id', '1156', '--raw', '--subdir', 'DAGS_FOLDER/data_ingestion_dag.py', '--cfg-path', '/tmp/tmpv7gkou__', '--error-file', '/tmp/tmps6rmpku1']
[2024-03-28 14:48:47,362] {standard_task_runner.py:77} INFO - Job 1156: Subtask ingest_to_postgres_task
[2024-03-28 14:48:47,942] {logging_mixin.py:109} INFO - Running <TaskInstance: ingest_data.ingest_to_postgres_task scheduled__2022-09-02T06:00:00+00:00 [running]> on host 05f84def3a12
[2024-03-28 14:48:48,531] {warnings.py:99} WARNING - /home/***/.local/lib/python3.6/site-packages/***/utils/context.py:152: AirflowContextDeprecationWarning: Accessing 'execution_date' from the template is deprecated and will be removed in a future version. Please use 'data_interval_start' or 'logical_date' instead.
  warnings.warn(_create_deprecation_warning(key, self._deprecation_replacements[key]))

[2024-03-28 14:48:48,681] {taskinstance.py:1426} INFO - Exporting the following env vars:
AIRFLOW_CTX_DAG_OWNER=***
AIRFLOW_CTX_DAG_ID=ingest_data
AIRFLOW_CTX_TASK_ID=ingest_to_postgres_task
AIRFLOW_CTX_EXECUTION_DATE=2022-09-02T06:00:00+00:00
AIRFLOW_CTX_DAG_RUN_ID=scheduled__2022-09-02T06:00:00+00:00
[2024-03-28 14:48:48,683] {logging_mixin.py:109} INFO - yellow_taxi_2022_09 /opt/***/yellowtaxi_tripdata_2022-09.parquet 2022-09-02T06:00:00+00:00
[2024-03-28 14:48:48,693] {logging_mixin.py:109} INFO - Starting data ingestion process...
[2024-03-28 14:48:58,602] {taskinstance.py:1700} ERROR - Task failed with exception
Traceback (most recent call last):
  File "/home/airflow/.local/lib/python3.6/site-packages/sqlalchemy/engine/base.py", line 2336, in _wrap_pool_connect
    return fn()
  File "/home/airflow/.local/lib/python3.6/site-packages/sqlalchemy/pool/base.py", line 304, in unique_connection
    return _ConnectionFairy._checkout(self)
  File "/home/airflow/.local/lib/python3.6/site-packages/sqlalchemy/pool/base.py", line 778, in _checkout
    fairy = _ConnectionRecord.checkout(pool)
  File "/home/airflow/.local/lib/python3.6/site-packages/sqlalchemy/pool/base.py", line 495, in checkout
    rec = pool._do_get()
  File "/home/airflow/.local/lib/python3.6/site-packages/sqlalchemy/pool/impl.py", line 140, in _do_get
    self._dec_overflow()
  File "/home/airflow/.local/lib/python3.6/site-packages/sqlalchemy/util/langhelpers.py", line 70, in __exit__
    with_traceback=exc_tb,
  File "/home/airflow/.local/lib/python3.6/site-packages/sqlalchemy/util/compat.py", line 182, in raise_
    raise exception
  File "/home/airflow/.local/lib/python3.6/site-packages/sqlalchemy/pool/impl.py", line 137, in _do_get
    return self._create_connection()
  File "/home/airflow/.local/lib/python3.6/site-packages/sqlalchemy/pool/base.py", line 309, in _create_connection
    return _ConnectionRecord(self)
  File "/home/airflow/.local/lib/python3.6/site-packages/sqlalchemy/pool/base.py", line 440, in __init__
    self.__connect(first_connect_check=True)
  File "/home/airflow/.local/lib/python3.6/site-packages/sqlalchemy/pool/base.py", line 661, in __connect
    pool.logger.debug("Error on connect(): %s", e)
  File "/home/airflow/.local/lib/python3.6/site-packages/sqlalchemy/util/langhelpers.py", line 70, in __exit__
    with_traceback=exc_tb,
  File "/home/airflow/.local/lib/python3.6/site-packages/sqlalchemy/util/compat.py", line 182, in raise_
    raise exception
  File "/home/airflow/.local/lib/python3.6/site-packages/sqlalchemy/pool/base.py", line 656, in __connect
    connection = pool._invoke_creator(self)
  File "/home/airflow/.local/lib/python3.6/site-packages/sqlalchemy/engine/strategies.py", line 114, in connect
    return dialect.connect(*cargs, **cparams)
  File "/home/airflow/.local/lib/python3.6/site-packages/sqlalchemy/engine/default.py", line 508, in connect
    return self.dbapi.connect(*cargs, **cparams)
  File "/home/airflow/.local/lib/python3.6/site-packages/psycopg2/__init__.py", line 122, in connect
    conn = _connect(dsn, connection_factory=connection_factory, **kwasync)
psycopg2.OperationalError: could not translate host name "pgdatabase" to address: Name or service not known


The above exception was the direct cause of the following exception:

Traceback (most recent call last):
  File "/home/airflow/.local/lib/python3.6/site-packages/airflow/models/taskinstance.py", line 1329, in _run_raw_task
    self._execute_task_with_callbacks(context)
  File "/home/airflow/.local/lib/python3.6/site-packages/airflow/models/taskinstance.py", line 1455, in _execute_task_with_callbacks
    result = self._execute_task(context, self.task)
  File "/home/airflow/.local/lib/python3.6/site-packages/airflow/models/taskinstance.py", line 1511, in _execute_task
    result = execute_callable(context=context)
  File "/home/airflow/.local/lib/python3.6/site-packages/airflow/operators/python.py", line 174, in execute
    return_value = self.execute_callable()
  File "/home/airflow/.local/lib/python3.6/site-packages/airflow/operators/python.py", line 185, in execute_callable
    return self.python_callable(*self.op_args, **self.op_kwargs)
  File "/opt/airflow/dags/ingest_script.py", line 32, in ingest_callable
    connection = engine.connect()
  File "/home/airflow/.local/lib/python3.6/site-packages/sqlalchemy/engine/base.py", line 2263, in connect
    return self._connection_cls(self, **kwargs)
  File "/home/airflow/.local/lib/python3.6/site-packages/sqlalchemy/engine/base.py", line 104, in __init__
    else engine.raw_connection()
  File "/home/airflow/.local/lib/python3.6/site-packages/sqlalchemy/engine/base.py", line 2370, in raw_connection
    self.pool.unique_connection, _connection
  File "/home/airflow/.local/lib/python3.6/site-packages/sqlalchemy/engine/base.py", line 2340, in _wrap_pool_connect
    e, dialect, self
  File "/home/airflow/.local/lib/python3.6/site-packages/sqlalchemy/engine/base.py", line 1584, in _handle_dbapi_exception_noconnection
    sqlalchemy_exception, with_traceback=exc_info[2], from_=e
  File "/home/airflow/.local/lib/python3.6/site-packages/sqlalchemy/util/compat.py", line 182, in raise_
    raise exception
  File "/home/airflow/.local/lib/python3.6/site-packages/sqlalchemy/engine/base.py", line 2336, in _wrap_pool_connect
    return fn()
  File "/home/airflow/.local/lib/python3.6/site-packages/sqlalchemy/pool/base.py", line 304, in unique_connection
    return _ConnectionFairy._checkout(self)
  File "/home/airflow/.local/lib/python3.6/site-packages/sqlalchemy/pool/base.py", line 778, in _checkout
    fairy = _ConnectionRecord.checkout(pool)
  File "/home/airflow/.local/lib/python3.6/site-packages/sqlalchemy/pool/base.py", line 495, in checkout
    rec = pool._do_get()
  File "/home/airflow/.local/lib/python3.6/site-packages/sqlalchemy/pool/impl.py", line 140, in _do_get
    self._dec_overflow()
  File "/home/airflow/.local/lib/python3.6/site-packages/sqlalchemy/util/langhelpers.py", line 70, in __exit__
    with_traceback=exc_tb,
  File "/home/airflow/.local/lib/python3.6/site-packages/sqlalchemy/util/compat.py", line 182, in raise_
    raise exception
  File "/home/airflow/.local/lib/python3.6/site-packages/sqlalchemy/pool/impl.py", line 137, in _do_get
    return self._create_connection()
  File "/home/airflow/.local/lib/python3.6/site-packages/sqlalchemy/pool/base.py", line 309, in _create_connection
    return _ConnectionRecord(self)
  File "/home/airflow/.local/lib/python3.6/site-packages/sqlalchemy/pool/base.py", line 440, in __init__
    self.__connect(first_connect_check=True)
  File "/home/airflow/.local/lib/python3.6/site-packages/sqlalchemy/pool/base.py", line 661, in __connect
    pool.logger.debug("Error on connect(): %s", e)
  File "/home/airflow/.local/lib/python3.6/site-packages/sqlalchemy/util/langhelpers.py", line 70, in __exit__
    with_traceback=exc_tb,
  File "/home/airflow/.local/lib/python3.6/site-packages/sqlalchemy/util/compat.py", line 182, in raise_
    raise exception
  File "/home/airflow/.local/lib/python3.6/site-packages/sqlalchemy/pool/base.py", line 656, in __connect
    connection = pool._invoke_creator(self)
  File "/home/airflow/.local/lib/python3.6/site-packages/sqlalchemy/engine/strategies.py", line 114, in connect
    return dialect.connect(*cargs, **cparams)
  File "/home/airflow/.local/lib/python3.6/site-packages/sqlalchemy/engine/default.py", line 508, in connect
    return self.dbapi.connect(*cargs, **cparams)
  File "/home/airflow/.local/lib/python3.6/site-packages/psycopg2/__init__.py", line 122, in connect
    conn = _connect(dsn, connection_factory=connection_factory, **kwasync)
sqlalchemy.exc.OperationalError: (psycopg2.OperationalError) could not translate host name "pgdatabase" to address: Name or service not known

(Background on this error at: http://sqlalche.me/e/13/e3q8)
[2024-03-28 14:48:58,762] {taskinstance.py:1277} INFO - Marking task as FAILED. dag_id=ingest_data, task_id=ingest_to_postgres_task, execution_date=20220902T060000, start_date=20240328T144846, end_date=20240328T144858
[2024-03-28 14:48:59,311] {standard_task_runner.py:92} ERROR - Failed to execute job 1156 for task ingest_to_postgres_task
Traceback (most recent call last):
  File "/home/airflow/.local/lib/python3.6/site-packages/sqlalchemy/engine/base.py", line 2336, in _wrap_pool_connect
    return fn()
  File "/home/airflow/.local/lib/python3.6/site-packages/sqlalchemy/pool/base.py", line 304, in unique_connection
    return _ConnectionFairy._checkout(self)
  File "/home/airflow/.local/lib/python3.6/site-packages/sqlalchemy/pool/base.py", line 778, in _checkout
    fairy = _ConnectionRecord.checkout(pool)
  File "/home/airflow/.local/lib/python3.6/site-packages/sqlalchemy/pool/base.py", line 495, in checkout
    rec = pool._do_get()
  File "/home/airflow/.local/lib/python3.6/site-packages/sqlalchemy/pool/impl.py", line 140, in _do_get
    self._dec_overflow()
  File "/home/airflow/.local/lib/python3.6/site-packages/sqlalchemy/util/langhelpers.py", line 70, in __exit__
    with_traceback=exc_tb,
  File "/home/airflow/.local/lib/python3.6/site-packages/sqlalchemy/util/compat.py", line 182, in raise_
    raise exception
  File "/home/airflow/.local/lib/python3.6/site-packages/sqlalchemy/pool/impl.py", line 137, in _do_get
    return self._create_connection()
  File "/home/airflow/.local/lib/python3.6/site-packages/sqlalchemy/pool/base.py", line 309, in _create_connection
    return _ConnectionRecord(self)
  File "/home/airflow/.local/lib/python3.6/site-packages/sqlalchemy/pool/base.py", line 440, in __init__
    self.__connect(first_connect_check=True)
  File "/home/airflow/.local/lib/python3.6/site-packages/sqlalchemy/pool/base.py", line 661, in __connect
    pool.logger.debug("Error on connect(): %s", e)
  File "/home/airflow/.local/lib/python3.6/site-packages/sqlalchemy/util/langhelpers.py", line 70, in __exit__
    with_traceback=exc_tb,
  File "/home/airflow/.local/lib/python3.6/site-packages/sqlalchemy/util/compat.py", line 182, in raise_
    raise exception
  File "/home/airflow/.local/lib/python3.6/site-packages/sqlalchemy/pool/base.py", line 656, in __connect
    connection = pool._invoke_creator(self)
  File "/home/airflow/.local/lib/python3.6/site-packages/sqlalchemy/engine/strategies.py", line 114, in connect
    return dialect.connect(*cargs, **cparams)
  File "/home/airflow/.local/lib/python3.6/site-packages/sqlalchemy/engine/default.py", line 508, in connect
    return self.dbapi.connect(*cargs, **cparams)
  File "/home/airflow/.local/lib/python3.6/site-packages/psycopg2/__init__.py", line 122, in connect
    conn = _connect(dsn, connection_factory=connection_factory, **kwasync)
psycopg2.OperationalError: could not translate host name "pgdatabase" to address: Name or service not known


The above exception was the direct cause of the following exception:

Traceback (most recent call last):
  File "/home/airflow/.local/lib/python3.6/site-packages/airflow/task/task_runner/standard_task_runner.py", line 85, in _start_by_fork
    args.func(args, dag=self.dag)
  File "/home/airflow/.local/lib/python3.6/site-packages/airflow/cli/cli_parser.py", line 48, in command
    return func(*args, **kwargs)
  File "/home/airflow/.local/lib/python3.6/site-packages/airflow/utils/cli.py", line 92, in wrapper
    return f(*args, **kwargs)
  File "/home/airflow/.local/lib/python3.6/site-packages/airflow/cli/commands/task_command.py", line 298, in task_run
    _run_task_by_selected_method(args, dag, ti)
  File "/home/airflow/.local/lib/python3.6/site-packages/airflow/cli/commands/task_command.py", line 107, in _run_task_by_selected_method
    _run_raw_task(args, ti)
  File "/home/airflow/.local/lib/python3.6/site-packages/airflow/cli/commands/task_command.py", line 184, in _run_raw_task
    error_file=args.error_file,
  File "/home/airflow/.local/lib/python3.6/site-packages/airflow/utils/session.py", line 70, in wrapper
    return func(*args, session=session, **kwargs)
  File "/home/airflow/.local/lib/python3.6/site-packages/airflow/models/taskinstance.py", line 1329, in _run_raw_task
    self._execute_task_with_callbacks(context)
  File "/home/airflow/.local/lib/python3.6/site-packages/airflow/models/taskinstance.py", line 1455, in _execute_task_with_callbacks
    result = self._execute_task(context, self.task)
  File "/home/airflow/.local/lib/python3.6/site-packages/airflow/models/taskinstance.py", line 1511, in _execute_task
    result = execute_callable(context=context)
  File "/home/airflow/.local/lib/python3.6/site-packages/airflow/operators/python.py", line 174, in execute
    return_value = self.execute_callable()
  File "/home/airflow/.local/lib/python3.6/site-packages/airflow/operators/python.py", line 185, in execute_callable
    return self.python_callable(*self.op_args, **self.op_kwargs)
  File "/opt/airflow/dags/ingest_script.py", line 32, in ingest_callable
    connection = engine.connect()
  File "/home/airflow/.local/lib/python3.6/site-packages/sqlalchemy/engine/base.py", line 2263, in connect
    return self._connection_cls(self, **kwargs)
  File "/home/airflow/.local/lib/python3.6/site-packages/sqlalchemy/engine/base.py", line 104, in __init__
    else engine.raw_connection()
  File "/home/airflow/.local/lib/python3.6/site-packages/sqlalchemy/engine/base.py", line 2370, in raw_connection
    self.pool.unique_connection, _connection
  File "/home/airflow/.local/lib/python3.6/site-packages/sqlalchemy/engine/base.py", line 2340, in _wrap_pool_connect
    e, dialect, self
  File "/home/airflow/.local/lib/python3.6/site-packages/sqlalchemy/engine/base.py", line 1584, in _handle_dbapi_exception_noconnection
    sqlalchemy_exception, with_traceback=exc_info[2], from_=e
  File "/home/airflow/.local/lib/python3.6/site-packages/sqlalchemy/util/compat.py", line 182, in raise_
    raise exception
  File "/home/airflow/.local/lib/python3.6/site-packages/sqlalchemy/engine/base.py", line 2336, in _wrap_pool_connect
    return fn()
  File "/home/airflow/.local/lib/python3.6/site-packages/sqlalchemy/pool/base.py", line 304, in unique_connection
    return _ConnectionFairy._checkout(self)
  File "/home/airflow/.local/lib/python3.6/site-packages/sqlalchemy/pool/base.py", line 778, in _checkout
    fairy = _ConnectionRecord.checkout(pool)
  File "/home/airflow/.local/lib/python3.6/site-packages/sqlalchemy/pool/base.py", line 495, in checkout
    rec = pool._do_get()
  File "/home/airflow/.local/lib/python3.6/site-packages/sqlalchemy/pool/impl.py", line 140, in _do_get
    self._dec_overflow()
  File "/home/airflow/.local/lib/python3.6/site-packages/sqlalchemy/util/langhelpers.py", line 70, in __exit__
    with_traceback=exc_tb,
  File "/home/airflow/.local/lib/python3.6/site-packages/sqlalchemy/util/compat.py", line 182, in raise_
    raise exception
  File "/home/airflow/.local/lib/python3.6/site-packages/sqlalchemy/pool/impl.py", line 137, in _do_get
    return self._create_connection()
  File "/home/airflow/.local/lib/python3.6/site-packages/sqlalchemy/pool/base.py", line 309, in _create_connection
    return _ConnectionRecord(self)
  File "/home/airflow/.local/lib/python3.6/site-packages/sqlalchemy/pool/base.py", line 440, in __init__
    self.__connect(first_connect_check=True)
  File "/home/airflow/.local/lib/python3.6/site-packages/sqlalchemy/pool/base.py", line 661, in __connect
    pool.logger.debug("Error on connect(): %s", e)
  File "/home/airflow/.local/lib/python3.6/site-packages/sqlalchemy/util/langhelpers.py", line 70, in __exit__
    with_traceback=exc_tb,
  File "/home/airflow/.local/lib/python3.6/site-packages/sqlalchemy/util/compat.py", line 182, in raise_
    raise exception
  File "/home/airflow/.local/lib/python3.6/site-packages/sqlalchemy/pool/base.py", line 656, in __connect
    connection = pool._invoke_creator(self)
  File "/home/airflow/.local/lib/python3.6/site-packages/sqlalchemy/engine/strategies.py", line 114, in connect
    return dialect.connect(*cargs, **cparams)
  File "/home/airflow/.local/lib/python3.6/site-packages/sqlalchemy/engine/default.py", line 508, in connect
    return self.dbapi.connect(*cargs, **cparams)
  File "/home/airflow/.local/lib/python3.6/site-packages/psycopg2/__init__.py", line 122, in connect
    conn = _connect(dsn, connection_factory=connection_factory, **kwasync)
sqlalchemy.exc.OperationalError: (psycopg2.OperationalError) could not translate host name "pgdatabase" to address: Name or service not known

(Background on this error at: http://sqlalche.me/e/13/e3q8)
[2024-03-28 14:48:59,490] {local_task_job.py:154} INFO - Task exited with return code 1
[2024-03-28 14:49:00,026] {local_task_job.py:264} INFO - 0 downstream tasks scheduled from follow-on schedule check
