[2024-05-19 04:21:04,140] {taskinstance.py:1032} INFO - Dependencies all met for <TaskInstance: ingest_data_bigquery_fhvhv.local_to_gcs_task scheduled__2021-07-02T06:00:00+00:00 [queued]>
[2024-05-19 04:21:04,427] {taskinstance.py:1032} INFO - Dependencies all met for <TaskInstance: ingest_data_bigquery_fhvhv.local_to_gcs_task scheduled__2021-07-02T06:00:00+00:00 [queued]>
[2024-05-19 04:21:04,436] {taskinstance.py:1238} INFO - 
--------------------------------------------------------------------------------
[2024-05-19 04:21:04,437] {taskinstance.py:1239} INFO - Starting attempt 1 of 3
[2024-05-19 04:21:04,438] {taskinstance.py:1240} INFO - 
--------------------------------------------------------------------------------
[2024-05-19 04:21:04,722] {taskinstance.py:1259} INFO - Executing <Task(PythonOperator): local_to_gcs_task> on 2021-07-02 06:00:00+00:00
[2024-05-19 04:21:04,907] {standard_task_runner.py:76} INFO - Running: ['***', 'tasks', 'run', 'ingest_data_bigquery_fhvhv', 'local_to_gcs_task', 'scheduled__2021-07-02T06:00:00+00:00', '--job-id', '5517', '--raw', '--subdir', 'DAGS_FOLDER/data_ingestion_gcs_fhvhv_dag.py', '--cfg-path', '/tmp/tmpbgiyiovl', '--error-file', '/tmp/tmpogaxjarg']
[2024-05-19 04:21:05,002] {standard_task_runner.py:77} INFO - Job 5517: Subtask local_to_gcs_task
[2024-05-19 04:21:04,809] {standard_task_runner.py:52} INFO - Started process 562 to run task
[2024-05-19 04:21:06,339] {logging_mixin.py:109} INFO - Running <TaskInstance: ingest_data_bigquery_fhvhv.local_to_gcs_task scheduled__2021-07-02T06:00:00+00:00 [running]> on host b57d73dcebce
[2024-05-19 04:21:12,292] {warnings.py:99} WARNING - /home/***/.local/lib/python3.6/site-packages/***/utils/context.py:152: AirflowContextDeprecationWarning: Accessing 'execution_date' from the template is deprecated and will be removed in a future version. Please use 'data_interval_start' or 'logical_date' instead.
  warnings.warn(_create_deprecation_warning(key, self._deprecation_replacements[key]))

[2024-05-19 04:21:12,631] {taskinstance.py:1426} INFO - Exporting the following env vars:
AIRFLOW_CTX_DAG_OWNER=***
AIRFLOW_CTX_DAG_ID=ingest_data_bigquery_fhvhv
AIRFLOW_CTX_TASK_ID=local_to_gcs_task
AIRFLOW_CTX_EXECUTION_DATE=2021-07-02T06:00:00+00:00
AIRFLOW_CTX_DAG_RUN_ID=scheduled__2021-07-02T06:00:00+00:00
[2024-05-19 04:22:41,399] {base_job.py:230} ERROR - LocalTaskJob heartbeat got an exception
Traceback (most recent call last):
  File "/home/airflow/.local/lib/python3.6/site-packages/sqlalchemy/engine/base.py", line 2336, in _wrap_pool_connect
    return fn()
  File "/home/airflow/.local/lib/python3.6/site-packages/sqlalchemy/pool/base.py", line 364, in connect
    return _ConnectionFairy._checkout(self)
  File "/home/airflow/.local/lib/python3.6/site-packages/sqlalchemy/pool/base.py", line 778, in _checkout
    fairy = _ConnectionRecord.checkout(pool)
  File "/home/airflow/.local/lib/python3.6/site-packages/sqlalchemy/pool/base.py", line 495, in checkout
    rec = pool._do_get()
  File "/home/airflow/.local/lib/python3.6/site-packages/sqlalchemy/pool/impl.py", line 241, in _do_get
    return self._create_connection()
  File "/home/airflow/.local/lib/python3.6/site-packages/sqlalchemy/pool/base.py", line 309, in _create_connection
    return _ConnectionRecord(self)
  File "/home/airflow/.local/lib/python3.6/site-packages/sqlalchemy/pool/base.py", line 440, in __init__
    self.__connect(first_connect_check=True)
  File "/home/airflow/.local/lib/python3.6/site-packages/sqlalchemy/pool/base.py", line 661, in __connect
    pool.logger.debug("Error on connect(): %s", e)
  File "/home/airflow/.local/lib/python3.6/site-packages/sqlalchemy/util/langhelpers.py", line 70, in __exit__
    with_traceback=exc_tb,
  File "/home/airflow/.local/lib/python3.6/site-packages/sqlalchemy/util/compat.py", line 182, in raise_
    raise exception
  File "/home/airflow/.local/lib/python3.6/site-packages/sqlalchemy/pool/base.py", line 656, in __connect
    connection = pool._invoke_creator(self)
  File "/home/airflow/.local/lib/python3.6/site-packages/sqlalchemy/engine/strategies.py", line 114, in connect
    return dialect.connect(*cargs, **cparams)
  File "/home/airflow/.local/lib/python3.6/site-packages/sqlalchemy/engine/default.py", line 508, in connect
    return self.dbapi.connect(*cargs, **cparams)
  File "/home/airflow/.local/lib/python3.6/site-packages/psycopg2/__init__.py", line 122, in connect
    conn = _connect(dsn, connection_factory=connection_factory, **kwasync)
psycopg2.OperationalError: connection to server at "postgres" (172.18.0.3), port 5432 failed: server closed the connection unexpectedly
	This probably means the server terminated abnormally
	before or while processing the request.


The above exception was the direct cause of the following exception:

Traceback (most recent call last):
  File "/home/airflow/.local/lib/python3.6/site-packages/airflow/jobs/base_job.py", line 202, in heartbeat
    session.merge(self)
  File "/home/airflow/.local/lib/python3.6/site-packages/sqlalchemy/orm/session.py", line 2171, in merge
    _resolve_conflict_map=_resolve_conflict_map,
  File "/home/airflow/.local/lib/python3.6/site-packages/sqlalchemy/orm/session.py", line 2244, in _merge
    merged = self.query(mapper.class_).get(key[1])
  File "/home/airflow/.local/lib/python3.6/site-packages/sqlalchemy/orm/query.py", line 1018, in get
    return self._get_impl(ident, loading.load_on_pk_identity)
  File "/home/airflow/.local/lib/python3.6/site-packages/sqlalchemy/orm/query.py", line 1135, in _get_impl
    return db_load_fn(self, primary_key_identity)
  File "/home/airflow/.local/lib/python3.6/site-packages/sqlalchemy/orm/loading.py", line 286, in load_on_pk_identity
    return q.one()
  File "/home/airflow/.local/lib/python3.6/site-packages/sqlalchemy/orm/query.py", line 3490, in one
    ret = self.one_or_none()
  File "/home/airflow/.local/lib/python3.6/site-packages/sqlalchemy/orm/query.py", line 3459, in one_or_none
    ret = list(self)
  File "/home/airflow/.local/lib/python3.6/site-packages/sqlalchemy/orm/query.py", line 3535, in __iter__
    return self._execute_and_instances(context)
  File "/home/airflow/.local/lib/python3.6/site-packages/sqlalchemy/orm/query.py", line 3557, in _execute_and_instances
    querycontext, self._connection_from_session, close_with_result=True
  File "/home/airflow/.local/lib/python3.6/site-packages/sqlalchemy/orm/query.py", line 3572, in _get_bind_args
    mapper=self._bind_mapper(), clause=querycontext.statement, **kw
  File "/home/airflow/.local/lib/python3.6/site-packages/sqlalchemy/orm/query.py", line 3550, in _connection_from_session
    conn = self.session.connection(**kw)
  File "/home/airflow/.local/lib/python3.6/site-packages/sqlalchemy/orm/session.py", line 1145, in connection
    execution_options=execution_options,
  File "/home/airflow/.local/lib/python3.6/site-packages/sqlalchemy/orm/session.py", line 1151, in _connection_for_bind
    engine, execution_options
  File "/home/airflow/.local/lib/python3.6/site-packages/sqlalchemy/orm/session.py", line 433, in _connection_for_bind
    conn = bind._contextual_connect()
  File "/home/airflow/.local/lib/python3.6/site-packages/sqlalchemy/engine/base.py", line 2302, in _contextual_connect
    self._wrap_pool_connect(self.pool.connect, None),
  File "/home/airflow/.local/lib/python3.6/site-packages/sqlalchemy/engine/base.py", line 2340, in _wrap_pool_connect
    e, dialect, self
  File "/home/airflow/.local/lib/python3.6/site-packages/sqlalchemy/engine/base.py", line 1584, in _handle_dbapi_exception_noconnection
    sqlalchemy_exception, with_traceback=exc_info[2], from_=e
  File "/home/airflow/.local/lib/python3.6/site-packages/sqlalchemy/util/compat.py", line 182, in raise_
    raise exception
  File "/home/airflow/.local/lib/python3.6/site-packages/sqlalchemy/engine/base.py", line 2336, in _wrap_pool_connect
    return fn()
  File "/home/airflow/.local/lib/python3.6/site-packages/sqlalchemy/pool/base.py", line 364, in connect
    return _ConnectionFairy._checkout(self)
  File "/home/airflow/.local/lib/python3.6/site-packages/sqlalchemy/pool/base.py", line 778, in _checkout
    fairy = _ConnectionRecord.checkout(pool)
  File "/home/airflow/.local/lib/python3.6/site-packages/sqlalchemy/pool/base.py", line 495, in checkout
    rec = pool._do_get()
  File "/home/airflow/.local/lib/python3.6/site-packages/sqlalchemy/pool/impl.py", line 241, in _do_get
    return self._create_connection()
  File "/home/airflow/.local/lib/python3.6/site-packages/sqlalchemy/pool/base.py", line 309, in _create_connection
    return _ConnectionRecord(self)
  File "/home/airflow/.local/lib/python3.6/site-packages/sqlalchemy/pool/base.py", line 440, in __init__
    self.__connect(first_connect_check=True)
  File "/home/airflow/.local/lib/python3.6/site-packages/sqlalchemy/pool/base.py", line 661, in __connect
    pool.logger.debug("Error on connect(): %s", e)
  File "/home/airflow/.local/lib/python3.6/site-packages/sqlalchemy/util/langhelpers.py", line 70, in __exit__
    with_traceback=exc_tb,
  File "/home/airflow/.local/lib/python3.6/site-packages/sqlalchemy/util/compat.py", line 182, in raise_
    raise exception
  File "/home/airflow/.local/lib/python3.6/site-packages/sqlalchemy/pool/base.py", line 656, in __connect
    connection = pool._invoke_creator(self)
  File "/home/airflow/.local/lib/python3.6/site-packages/sqlalchemy/engine/strategies.py", line 114, in connect
    return dialect.connect(*cargs, **cparams)
  File "/home/airflow/.local/lib/python3.6/site-packages/sqlalchemy/engine/default.py", line 508, in connect
    return self.dbapi.connect(*cargs, **cparams)
  File "/home/airflow/.local/lib/python3.6/site-packages/psycopg2/__init__.py", line 122, in connect
    conn = _connect(dsn, connection_factory=connection_factory, **kwasync)
sqlalchemy.exc.OperationalError: (psycopg2.OperationalError) connection to server at "postgres" (172.18.0.3), port 5432 failed: server closed the connection unexpectedly
	This probably means the server terminated abnormally
	before or while processing the request.

(Background on this error at: http://sqlalche.me/e/13/e3q8)
[2024-05-19 04:24:52,208] {python.py:175} INFO - Done. Returned value was: None
[2024-05-19 04:24:52,237] {taskinstance.py:1277} INFO - Marking task as SUCCESS. dag_id=ingest_data_bigquery_fhvhv, task_id=local_to_gcs_task, execution_date=20210702T060000, start_date=20240519T042104, end_date=20240519T042452
[2024-05-19 04:24:52,689] {local_task_job.py:154} INFO - Task exited with return code 0
[2024-05-19 04:24:52,736] {local_task_job.py:264} INFO - 1 downstream tasks scheduled from follow-on schedule check
[2024-12-29 15:10:35,644] {taskinstance.py:1032} INFO - Dependencies all met for <TaskInstance: ingest_data_bigquery_fhvhv.local_to_gcs_task scheduled__2021-07-02T06:00:00+00:00 [queued]>
[2024-12-29 15:10:35,662] {taskinstance.py:1032} INFO - Dependencies all met for <TaskInstance: ingest_data_bigquery_fhvhv.local_to_gcs_task scheduled__2021-07-02T06:00:00+00:00 [queued]>
[2024-12-29 15:10:35,662] {taskinstance.py:1238} INFO - 
--------------------------------------------------------------------------------
[2024-12-29 15:10:35,662] {taskinstance.py:1239} INFO - Starting attempt 1 of 3
[2024-12-29 15:10:35,662] {taskinstance.py:1240} INFO - 
--------------------------------------------------------------------------------
[2024-12-29 15:10:35,693] {taskinstance.py:1259} INFO - Executing <Task(PythonOperator): local_to_gcs_task> on 2021-07-02 06:00:00+00:00
[2024-12-29 15:10:35,702] {standard_task_runner.py:52} INFO - Started process 123 to run task
[2024-12-29 15:10:35,721] {standard_task_runner.py:76} INFO - Running: ['***', 'tasks', 'run', 'ingest_data_bigquery_fhvhv', 'local_to_gcs_task', 'scheduled__2021-07-02T06:00:00+00:00', '--job-id', '5957', '--raw', '--subdir', 'DAGS_FOLDER/data_ingestion_gcs_fhvhv_dag.py', '--cfg-path', '/tmp/tmpw4744q3a', '--error-file', '/tmp/tmpktqo5jpm']
[2024-12-29 15:10:35,746] {standard_task_runner.py:77} INFO - Job 5957: Subtask local_to_gcs_task
[2024-12-29 15:10:35,885] {logging_mixin.py:109} INFO - Running <TaskInstance: ingest_data_bigquery_fhvhv.local_to_gcs_task scheduled__2021-07-02T06:00:00+00:00 [running]> on host a180708a7c2c
[2024-12-29 15:10:35,978] {warnings.py:99} WARNING - /home/***/.local/lib/python3.6/site-packages/***/utils/context.py:152: AirflowContextDeprecationWarning: Accessing 'execution_date' from the template is deprecated and will be removed in a future version. Please use 'data_interval_start' or 'logical_date' instead.
  warnings.warn(_create_deprecation_warning(key, self._deprecation_replacements[key]))

[2024-12-29 15:10:36,037] {taskinstance.py:1426} INFO - Exporting the following env vars:
AIRFLOW_CTX_DAG_OWNER=***
AIRFLOW_CTX_DAG_ID=ingest_data_bigquery_fhvhv
AIRFLOW_CTX_TASK_ID=local_to_gcs_task
AIRFLOW_CTX_EXECUTION_DATE=2021-07-02T06:00:00+00:00
AIRFLOW_CTX_DAG_RUN_ID=scheduled__2021-07-02T06:00:00+00:00
[2024-12-29 15:11:23,369] {python.py:175} INFO - Done. Returned value was: None
[2024-12-29 15:11:23,597] {taskinstance.py:1277} INFO - Marking task as SUCCESS. dag_id=ingest_data_bigquery_fhvhv, task_id=local_to_gcs_task, execution_date=20210702T060000, start_date=20241229T151035, end_date=20241229T151123
[2024-12-29 15:11:23,772] {local_task_job.py:154} INFO - Task exited with return code 0
[2024-12-29 15:11:23,810] {local_task_job.py:264} INFO - 1 downstream tasks scheduled from follow-on schedule check
[2025-01-01 05:22:56,283] {taskinstance.py:1032} INFO - Dependencies all met for <TaskInstance: ingest_data_bigquery_fhvhv.local_to_gcs_task scheduled__2021-07-02T06:00:00+00:00 [queued]>
[2025-01-01 05:22:56,298] {taskinstance.py:1032} INFO - Dependencies all met for <TaskInstance: ingest_data_bigquery_fhvhv.local_to_gcs_task scheduled__2021-07-02T06:00:00+00:00 [queued]>
[2025-01-01 05:22:56,298] {taskinstance.py:1238} INFO - 
--------------------------------------------------------------------------------
[2025-01-01 05:22:56,298] {taskinstance.py:1239} INFO - Starting attempt 1 of 3
[2025-01-01 05:22:56,298] {taskinstance.py:1240} INFO - 
--------------------------------------------------------------------------------
[2025-01-01 05:22:56,310] {taskinstance.py:1259} INFO - Executing <Task(PythonOperator): local_to_gcs_task> on 2021-07-02 06:00:00+00:00
[2025-01-01 05:22:56,319] {standard_task_runner.py:52} INFO - Started process 5214 to run task
[2025-01-01 05:22:56,326] {standard_task_runner.py:76} INFO - Running: ['***', 'tasks', 'run', 'ingest_data_bigquery_fhvhv', 'local_to_gcs_task', 'scheduled__2021-07-02T06:00:00+00:00', '--job-id', '6254', '--raw', '--subdir', 'DAGS_FOLDER/data_ingestion_gcs_fhvhv_dag.py', '--cfg-path', '/tmp/tmpylx0dz7a', '--error-file', '/tmp/tmpfs37qfeb']
[2025-01-01 05:22:56,332] {standard_task_runner.py:77} INFO - Job 6254: Subtask local_to_gcs_task
[2025-01-01 05:22:56,418] {logging_mixin.py:109} INFO - Running <TaskInstance: ingest_data_bigquery_fhvhv.local_to_gcs_task scheduled__2021-07-02T06:00:00+00:00 [running]> on host 4228b0d90dbc
[2025-01-01 05:22:56,476] {warnings.py:99} WARNING - /home/***/.local/lib/python3.6/site-packages/***/utils/context.py:152: AirflowContextDeprecationWarning: Accessing 'execution_date' from the template is deprecated and will be removed in a future version. Please use 'data_interval_start' or 'logical_date' instead.
  warnings.warn(_create_deprecation_warning(key, self._deprecation_replacements[key]))

[2025-01-01 05:22:56,506] {taskinstance.py:1426} INFO - Exporting the following env vars:
AIRFLOW_CTX_DAG_OWNER=***
AIRFLOW_CTX_DAG_ID=ingest_data_bigquery_fhvhv
AIRFLOW_CTX_TASK_ID=local_to_gcs_task
AIRFLOW_CTX_EXECUTION_DATE=2021-07-02T06:00:00+00:00
AIRFLOW_CTX_DAG_RUN_ID=scheduled__2021-07-02T06:00:00+00:00
[2025-01-01 05:23:30,075] {python.py:175} INFO - Done. Returned value was: None
[2025-01-01 05:23:30,097] {taskinstance.py:1277} INFO - Marking task as SUCCESS. dag_id=ingest_data_bigquery_fhvhv, task_id=local_to_gcs_task, execution_date=20210702T060000, start_date=20250101T052256, end_date=20250101T052330
[2025-01-01 05:23:30,203] {local_task_job.py:154} INFO - Task exited with return code 0
[2025-01-01 05:23:30,241] {local_task_job.py:264} INFO - 1 downstream tasks scheduled from follow-on schedule check
[2025-01-01 12:03:30,154] {taskinstance.py:1032} INFO - Dependencies all met for <TaskInstance: ingest_data_bigquery_fhvhv.local_to_gcs_task scheduled__2021-07-02T06:00:00+00:00 [queued]>
[2025-01-01 12:03:30,174] {taskinstance.py:1032} INFO - Dependencies all met for <TaskInstance: ingest_data_bigquery_fhvhv.local_to_gcs_task scheduled__2021-07-02T06:00:00+00:00 [queued]>
[2025-01-01 12:03:30,174] {taskinstance.py:1238} INFO - 
--------------------------------------------------------------------------------
[2025-01-01 12:03:30,175] {taskinstance.py:1239} INFO - Starting attempt 1 of 3
[2025-01-01 12:03:30,175] {taskinstance.py:1240} INFO - 
--------------------------------------------------------------------------------
[2025-01-01 12:03:30,191] {taskinstance.py:1259} INFO - Executing <Task(PythonOperator): local_to_gcs_task> on 2021-07-02 06:00:00+00:00
[2025-01-01 12:03:30,202] {standard_task_runner.py:52} INFO - Started process 8356 to run task
[2025-01-01 12:03:30,208] {standard_task_runner.py:76} INFO - Running: ['***', 'tasks', 'run', 'ingest_data_bigquery_fhvhv', 'local_to_gcs_task', 'scheduled__2021-07-02T06:00:00+00:00', '--job-id', '6370', '--raw', '--subdir', 'DAGS_FOLDER/data_ingestion_gcs_fhvhv_dag.py', '--cfg-path', '/tmp/tmpnr1j6x7b', '--error-file', '/tmp/tmpls0bajvn']
[2025-01-01 12:03:30,214] {standard_task_runner.py:77} INFO - Job 6370: Subtask local_to_gcs_task
[2025-01-01 12:03:30,303] {logging_mixin.py:109} INFO - Running <TaskInstance: ingest_data_bigquery_fhvhv.local_to_gcs_task scheduled__2021-07-02T06:00:00+00:00 [running]> on host b9549a156c09
[2025-01-01 12:03:30,352] {warnings.py:99} WARNING - /home/***/.local/lib/python3.6/site-packages/***/utils/context.py:152: AirflowContextDeprecationWarning: Accessing 'execution_date' from the template is deprecated and will be removed in a future version. Please use 'data_interval_start' or 'logical_date' instead.
  warnings.warn(_create_deprecation_warning(key, self._deprecation_replacements[key]))

[2025-01-01 12:03:30,382] {taskinstance.py:1426} INFO - Exporting the following env vars:
AIRFLOW_CTX_DAG_OWNER=***
AIRFLOW_CTX_DAG_ID=ingest_data_bigquery_fhvhv
AIRFLOW_CTX_TASK_ID=local_to_gcs_task
AIRFLOW_CTX_EXECUTION_DATE=2021-07-02T06:00:00+00:00
AIRFLOW_CTX_DAG_RUN_ID=scheduled__2021-07-02T06:00:00+00:00
[2025-01-01 12:04:03,429] {python.py:175} INFO - Done. Returned value was: None
[2025-01-01 12:04:03,447] {taskinstance.py:1277} INFO - Marking task as SUCCESS. dag_id=ingest_data_bigquery_fhvhv, task_id=local_to_gcs_task, execution_date=20210702T060000, start_date=20250101T120330, end_date=20250101T120403
[2025-01-01 12:04:03,611] {local_task_job.py:154} INFO - Task exited with return code 0
[2025-01-01 12:04:03,672] {local_task_job.py:264} INFO - 0 downstream tasks scheduled from follow-on schedule check
