[2024-05-02 04:03:01,181] {taskinstance.py:1032} INFO - Dependencies all met for <TaskInstance: ingest_data_bigquery_yt.download_dataset_task scheduled__2019-02-02T06:00:00+00:00 [queued]>
[2024-05-02 04:03:01,192] {taskinstance.py:1032} INFO - Dependencies all met for <TaskInstance: ingest_data_bigquery_yt.download_dataset_task scheduled__2019-02-02T06:00:00+00:00 [queued]>
[2024-05-02 04:03:01,193] {taskinstance.py:1238} INFO - 
--------------------------------------------------------------------------------
[2024-05-02 04:03:01,193] {taskinstance.py:1239} INFO - Starting attempt 2 of 2
[2024-05-02 04:03:01,194] {taskinstance.py:1240} INFO - 
--------------------------------------------------------------------------------
[2024-05-02 04:03:01,291] {taskinstance.py:1259} INFO - Executing <Task(BashOperator): download_dataset_task> on 2019-02-02 06:00:00+00:00
[2024-05-02 04:03:01,302] {standard_task_runner.py:52} INFO - Started process 5055 to run task
[2024-05-02 04:03:01,311] {standard_task_runner.py:76} INFO - Running: ['***', 'tasks', 'run', 'ingest_data_bigquery_yt', 'download_dataset_task', 'scheduled__2019-02-02T06:00:00+00:00', '--job-id', '3722', '--raw', '--subdir', 'DAGS_FOLDER/data_ingestion_gcs_yt_dag.py', '--cfg-path', '/tmp/tmpl99d5g8z', '--error-file', '/tmp/tmptv88m5cu']
[2024-05-02 04:03:01,317] {standard_task_runner.py:77} INFO - Job 3722: Subtask download_dataset_task
[2024-05-02 04:03:01,624] {logging_mixin.py:109} INFO - Running <TaskInstance: ingest_data_bigquery_yt.download_dataset_task scheduled__2019-02-02T06:00:00+00:00 [running]> on host bef445d594dc
[2024-05-02 04:03:01,726] {warnings.py:99} WARNING - /home/***/.local/lib/python3.6/site-packages/***/utils/context.py:152: AirflowContextDeprecationWarning: Accessing 'execution_date' from the template is deprecated and will be removed in a future version. Please use 'data_interval_start' or 'logical_date' instead.
  warnings.warn(_create_deprecation_warning(key, self._deprecation_replacements[key]))

[2024-05-02 04:03:01,781] {taskinstance.py:1426} INFO - Exporting the following env vars:
AIRFLOW_CTX_DAG_OWNER=***
AIRFLOW_CTX_DAG_ID=ingest_data_bigquery_yt
AIRFLOW_CTX_TASK_ID=download_dataset_task
AIRFLOW_CTX_EXECUTION_DATE=2019-02-02T06:00:00+00:00
AIRFLOW_CTX_DAG_RUN_ID=scheduled__2019-02-02T06:00:00+00:00
[2024-05-02 04:03:01,783] {subprocess.py:62} INFO - Tmp dir root location: 
 /tmp
[2024-05-02 04:03:01,784] {subprocess.py:74} INFO - Running command: ['bash', '-c', 'curl -sSL https://github.com/DataTalksClub/nyc-tlc-data/releases/download/yellow/yellow_tripdata_2019-02.csv.gz > /opt/***/raw_data/yellowtaxi_tripdata_2019-02.csv.gz | gzip -d > /opt/***/raw_data/yellowtaxi_tripdata_2019-02.csv && rm /opt/***/raw_data/yellowtaxi_tripdata_2019-02.csv.gz']
[2024-05-02 04:03:01,805] {subprocess.py:85} INFO - Output:
[2024-05-02 04:03:01,844] {subprocess.py:89} INFO - 
[2024-05-02 04:03:01,844] {subprocess.py:89} INFO - gzip: stdin: unexpected end of file
[2024-05-02 04:03:03,960] {subprocess.py:93} INFO - Command exited with return code 1
[2024-05-02 04:03:03,981] {taskinstance.py:1700} ERROR - Task failed with exception
Traceback (most recent call last):
  File "/home/airflow/.local/lib/python3.6/site-packages/airflow/models/taskinstance.py", line 1329, in _run_raw_task
    self._execute_task_with_callbacks(context)
  File "/home/airflow/.local/lib/python3.6/site-packages/airflow/models/taskinstance.py", line 1455, in _execute_task_with_callbacks
    result = self._execute_task(context, self.task)
  File "/home/airflow/.local/lib/python3.6/site-packages/airflow/models/taskinstance.py", line 1511, in _execute_task
    result = execute_callable(context=context)
  File "/home/airflow/.local/lib/python3.6/site-packages/airflow/operators/bash.py", line 188, in execute
    f'Bash command failed. The command returned a non-zero exit code {result.exit_code}.'
airflow.exceptions.AirflowException: Bash command failed. The command returned a non-zero exit code 1.
[2024-05-02 04:03:03,992] {taskinstance.py:1277} INFO - Marking task as FAILED. dag_id=ingest_data_bigquery_yt, task_id=download_dataset_task, execution_date=20190202T060000, start_date=20240502T040301, end_date=20240502T040303
[2024-05-02 04:03:04,015] {standard_task_runner.py:92} ERROR - Failed to execute job 3722 for task download_dataset_task
Traceback (most recent call last):
  File "/home/airflow/.local/lib/python3.6/site-packages/airflow/task/task_runner/standard_task_runner.py", line 85, in _start_by_fork
    args.func(args, dag=self.dag)
  File "/home/airflow/.local/lib/python3.6/site-packages/airflow/cli/cli_parser.py", line 48, in command
    return func(*args, **kwargs)
  File "/home/airflow/.local/lib/python3.6/site-packages/airflow/utils/cli.py", line 92, in wrapper
    return f(*args, **kwargs)
  File "/home/airflow/.local/lib/python3.6/site-packages/airflow/cli/commands/task_command.py", line 298, in task_run
    _run_task_by_selected_method(args, dag, ti)
  File "/home/airflow/.local/lib/python3.6/site-packages/airflow/cli/commands/task_command.py", line 107, in _run_task_by_selected_method
    _run_raw_task(args, ti)
  File "/home/airflow/.local/lib/python3.6/site-packages/airflow/cli/commands/task_command.py", line 184, in _run_raw_task
    error_file=args.error_file,
  File "/home/airflow/.local/lib/python3.6/site-packages/airflow/utils/session.py", line 70, in wrapper
    return func(*args, session=session, **kwargs)
  File "/home/airflow/.local/lib/python3.6/site-packages/airflow/models/taskinstance.py", line 1329, in _run_raw_task
    self._execute_task_with_callbacks(context)
  File "/home/airflow/.local/lib/python3.6/site-packages/airflow/models/taskinstance.py", line 1455, in _execute_task_with_callbacks
    result = self._execute_task(context, self.task)
  File "/home/airflow/.local/lib/python3.6/site-packages/airflow/models/taskinstance.py", line 1511, in _execute_task
    result = execute_callable(context=context)
  File "/home/airflow/.local/lib/python3.6/site-packages/airflow/operators/bash.py", line 188, in execute
    f'Bash command failed. The command returned a non-zero exit code {result.exit_code}.'
airflow.exceptions.AirflowException: Bash command failed. The command returned a non-zero exit code 1.
[2024-05-02 04:03:04,039] {local_task_job.py:154} INFO - Task exited with return code 1
[2024-05-02 04:03:04,114] {local_task_job.py:264} INFO - 0 downstream tasks scheduled from follow-on schedule check
[2024-05-03 08:04:06,395] {taskinstance.py:1032} INFO - Dependencies all met for <TaskInstance: ingest_data_bigquery_yt.download_dataset_task scheduled__2019-02-02T06:00:00+00:00 [queued]>
[2024-05-03 08:04:06,537] {taskinstance.py:1032} INFO - Dependencies all met for <TaskInstance: ingest_data_bigquery_yt.download_dataset_task scheduled__2019-02-02T06:00:00+00:00 [queued]>
[2024-05-03 08:04:06,543] {taskinstance.py:1238} INFO - 
--------------------------------------------------------------------------------
[2024-05-03 08:04:06,543] {taskinstance.py:1239} INFO - Starting attempt 2 of 2
[2024-05-03 08:04:06,544] {taskinstance.py:1240} INFO - 
--------------------------------------------------------------------------------
[2024-05-03 08:04:06,693] {taskinstance.py:1259} INFO - Executing <Task(BashOperator): download_dataset_task> on 2019-02-02 06:00:00+00:00
[2024-05-03 08:04:06,776] {standard_task_runner.py:52} INFO - Started process 137 to run task
[2024-05-03 08:04:06,887] {standard_task_runner.py:76} INFO - Running: ['***', 'tasks', 'run', 'ingest_data_bigquery_yt', 'download_dataset_task', 'scheduled__2019-02-02T06:00:00+00:00', '--job-id', '3860', '--raw', '--subdir', 'DAGS_FOLDER/data_ingestion_gcs_yt_dag.py', '--cfg-path', '/tmp/tmpz6ud2h1q', '--error-file', '/tmp/tmp8skcbn6x']
[2024-05-03 08:04:06,923] {standard_task_runner.py:77} INFO - Job 3860: Subtask download_dataset_task
[2024-05-03 08:04:07,380] {logging_mixin.py:109} INFO - Running <TaskInstance: ingest_data_bigquery_yt.download_dataset_task scheduled__2019-02-02T06:00:00+00:00 [running]> on host 5bfe1025092b
[2024-05-03 08:04:07,658] {warnings.py:99} WARNING - /home/***/.local/lib/python3.6/site-packages/***/utils/context.py:152: AirflowContextDeprecationWarning: Accessing 'execution_date' from the template is deprecated and will be removed in a future version. Please use 'data_interval_start' or 'logical_date' instead.
  warnings.warn(_create_deprecation_warning(key, self._deprecation_replacements[key]))

[2024-05-03 08:04:07,942] {taskinstance.py:1426} INFO - Exporting the following env vars:
AIRFLOW_CTX_DAG_OWNER=***
AIRFLOW_CTX_DAG_ID=ingest_data_bigquery_yt
AIRFLOW_CTX_TASK_ID=download_dataset_task
AIRFLOW_CTX_EXECUTION_DATE=2019-02-02T06:00:00+00:00
AIRFLOW_CTX_DAG_RUN_ID=scheduled__2019-02-02T06:00:00+00:00
[2024-05-03 08:04:07,943] {subprocess.py:62} INFO - Tmp dir root location: 
 /tmp
[2024-05-03 08:04:07,944] {subprocess.py:74} INFO - Running command: ['bash', '-c', 'curl -sSL https://github.com/DataTalksClub/nyc-tlc-data/releases/download/yellow/yellow_tripdata_2019-02.csv.gz > /opt/***/raw_data/yellowtaxi_tripdata_2019-02.csv.gz && gunzip /opt/***/raw_data/yellowtaxi_tripdata_2019-02.csv.gz']
[2024-05-03 08:04:08,050] {subprocess.py:85} INFO - Output:
[2024-05-03 08:04:27,754] {subprocess.py:89} INFO - 
[2024-05-03 08:04:27,754] {subprocess.py:89} INFO - gzip: /opt/***/raw_data/yellowtaxi_tripdata_2019-02.csv: No space left on device
[2024-05-03 08:04:28,001] {subprocess.py:93} INFO - Command exited with return code 1
[2024-05-03 08:04:28,038] {taskinstance.py:1700} ERROR - Task failed with exception
Traceback (most recent call last):
  File "/home/airflow/.local/lib/python3.6/site-packages/airflow/models/taskinstance.py", line 1329, in _run_raw_task
    self._execute_task_with_callbacks(context)
  File "/home/airflow/.local/lib/python3.6/site-packages/airflow/models/taskinstance.py", line 1455, in _execute_task_with_callbacks
    result = self._execute_task(context, self.task)
  File "/home/airflow/.local/lib/python3.6/site-packages/airflow/models/taskinstance.py", line 1511, in _execute_task
    result = execute_callable(context=context)
  File "/home/airflow/.local/lib/python3.6/site-packages/airflow/operators/bash.py", line 188, in execute
    f'Bash command failed. The command returned a non-zero exit code {result.exit_code}.'
airflow.exceptions.AirflowException: Bash command failed. The command returned a non-zero exit code 1.
[2024-05-03 08:04:28,151] {taskinstance.py:1277} INFO - Marking task as FAILED. dag_id=ingest_data_bigquery_yt, task_id=download_dataset_task, execution_date=20190202T060000, start_date=20240503T080406, end_date=20240503T080428
[2024-05-03 08:04:28,561] {standard_task_runner.py:92} ERROR - Failed to execute job 3860 for task download_dataset_task
Traceback (most recent call last):
  File "/home/airflow/.local/lib/python3.6/site-packages/airflow/task/task_runner/standard_task_runner.py", line 85, in _start_by_fork
    args.func(args, dag=self.dag)
  File "/home/airflow/.local/lib/python3.6/site-packages/airflow/cli/cli_parser.py", line 48, in command
    return func(*args, **kwargs)
  File "/home/airflow/.local/lib/python3.6/site-packages/airflow/utils/cli.py", line 92, in wrapper
    return f(*args, **kwargs)
  File "/home/airflow/.local/lib/python3.6/site-packages/airflow/cli/commands/task_command.py", line 298, in task_run
    _run_task_by_selected_method(args, dag, ti)
  File "/home/airflow/.local/lib/python3.6/site-packages/airflow/cli/commands/task_command.py", line 107, in _run_task_by_selected_method
    _run_raw_task(args, ti)
  File "/home/airflow/.local/lib/python3.6/site-packages/airflow/cli/commands/task_command.py", line 184, in _run_raw_task
    error_file=args.error_file,
  File "/home/airflow/.local/lib/python3.6/site-packages/airflow/utils/session.py", line 70, in wrapper
    return func(*args, session=session, **kwargs)
  File "/home/airflow/.local/lib/python3.6/site-packages/airflow/models/taskinstance.py", line 1329, in _run_raw_task
    self._execute_task_with_callbacks(context)
  File "/home/airflow/.local/lib/python3.6/site-packages/airflow/models/taskinstance.py", line 1455, in _execute_task_with_callbacks
    result = self._execute_task(context, self.task)
  File "/home/airflow/.local/lib/python3.6/site-packages/airflow/models/taskinstance.py", line 1511, in _execute_task
    result = execute_callable(context=context)
  File "/home/airflow/.local/lib/python3.6/site-packages/airflow/operators/bash.py", line 188, in execute
    f'Bash command failed. The command returned a non-zero exit code {result.exit_code}.'
airflow.exceptions.AirflowException: Bash command failed. The command returned a non-zero exit code 1.
[2024-05-03 08:04:28,711] {local_task_job.py:154} INFO - Task exited with return code 1
[2024-05-03 08:04:29,216] {local_task_job.py:264} INFO - 0 downstream tasks scheduled from follow-on schedule check
[2024-05-03 15:23:40,648] {taskinstance.py:1032} INFO - Dependencies all met for <TaskInstance: ingest_data_bigquery_yt.download_dataset_task scheduled__2019-02-02T06:00:00+00:00 [queued]>
[2024-05-03 15:23:40,774] {taskinstance.py:1032} INFO - Dependencies all met for <TaskInstance: ingest_data_bigquery_yt.download_dataset_task scheduled__2019-02-02T06:00:00+00:00 [queued]>
[2024-05-03 15:23:40,779] {taskinstance.py:1238} INFO - 
--------------------------------------------------------------------------------
[2024-05-03 15:23:40,780] {taskinstance.py:1239} INFO - Starting attempt 2 of 3
[2024-05-03 15:23:40,780] {taskinstance.py:1240} INFO - 
--------------------------------------------------------------------------------
[2024-05-03 15:23:40,921] {taskinstance.py:1259} INFO - Executing <Task(BashOperator): download_dataset_task> on 2019-02-02 06:00:00+00:00
[2024-05-03 15:23:41,090] {standard_task_runner.py:76} INFO - Running: ['***', 'tasks', 'run', 'ingest_data_bigquery_yt', 'download_dataset_task', 'scheduled__2019-02-02T06:00:00+00:00', '--job-id', '4065', '--raw', '--subdir', 'DAGS_FOLDER/data_ingstion_gcs_yt_dag.py', '--cfg-path', '/tmp/tmpuqkx1pvc', '--error-file', '/tmp/tmpbc1t8jy3']
[2024-05-03 15:23:41,164] {standard_task_runner.py:77} INFO - Job 4065: Subtask download_dataset_task
[2024-05-03 15:23:40,972] {standard_task_runner.py:52} INFO - Started process 114 to run task
[2024-05-03 15:23:41,731] {logging_mixin.py:109} INFO - Running <TaskInstance: ingest_data_bigquery_yt.download_dataset_task scheduled__2019-02-02T06:00:00+00:00 [running]> on host 269238f68a58
[2024-05-03 15:23:42,167] {warnings.py:99} WARNING - /home/***/.local/lib/python3.6/site-packages/***/utils/context.py:152: AirflowContextDeprecationWarning: Accessing 'execution_date' from the template is deprecated and will be removed in a future version. Please use 'data_interval_start' or 'logical_date' instead.
  warnings.warn(_create_deprecation_warning(key, self._deprecation_replacements[key]))

[2024-05-03 15:23:42,258] {taskinstance.py:1426} INFO - Exporting the following env vars:
AIRFLOW_CTX_DAG_OWNER=***
AIRFLOW_CTX_DAG_ID=ingest_data_bigquery_yt
AIRFLOW_CTX_TASK_ID=download_dataset_task
AIRFLOW_CTX_EXECUTION_DATE=2019-02-02T06:00:00+00:00
AIRFLOW_CTX_DAG_RUN_ID=scheduled__2019-02-02T06:00:00+00:00
[2024-05-03 15:23:42,262] {subprocess.py:62} INFO - Tmp dir root location: 
 /tmp
[2024-05-03 15:23:42,267] {subprocess.py:74} INFO - Running command: ['bash', '-c', 'curl -sSL https://github.com/DataTalksClub/nyc-tlc-data/releases/download/yellow/yellow_tripdata_2019-02.csv.gz > /opt/***/raw_data/yellowtaxi_tripdata_2019-02.csv.gz && gunzip /opt/***/raw_data/yellowtaxi_tripdata_2019-02.csv.gz']
[2024-05-03 15:23:42,322] {subprocess.py:85} INFO - Output:
[2024-05-03 15:24:05,642] {subprocess.py:89} INFO - 
[2024-05-03 15:24:05,642] {subprocess.py:89} INFO - gzip: /opt/***/raw_data/yellowtaxi_tripdata_2019-02.csv: No space left on device
[2024-05-03 15:24:05,791] {subprocess.py:93} INFO - Command exited with return code 1
[2024-05-03 15:24:05,871] {taskinstance.py:1700} ERROR - Task failed with exception
Traceback (most recent call last):
  File "/home/airflow/.local/lib/python3.6/site-packages/airflow/models/taskinstance.py", line 1329, in _run_raw_task
    self._execute_task_with_callbacks(context)
  File "/home/airflow/.local/lib/python3.6/site-packages/airflow/models/taskinstance.py", line 1455, in _execute_task_with_callbacks
    result = self._execute_task(context, self.task)
  File "/home/airflow/.local/lib/python3.6/site-packages/airflow/models/taskinstance.py", line 1511, in _execute_task
    result = execute_callable(context=context)
  File "/home/airflow/.local/lib/python3.6/site-packages/airflow/operators/bash.py", line 188, in execute
    f'Bash command failed. The command returned a non-zero exit code {result.exit_code}.'
airflow.exceptions.AirflowException: Bash command failed. The command returned a non-zero exit code 1.
[2024-05-03 15:24:05,951] {taskinstance.py:1277} INFO - Marking task as UP_FOR_RETRY. dag_id=ingest_data_bigquery_yt, task_id=download_dataset_task, execution_date=20190202T060000, start_date=20240503T152340, end_date=20240503T152405
[2024-05-03 15:24:06,249] {standard_task_runner.py:92} ERROR - Failed to execute job 4065 for task download_dataset_task
Traceback (most recent call last):
  File "/home/airflow/.local/lib/python3.6/site-packages/airflow/task/task_runner/standard_task_runner.py", line 85, in _start_by_fork
    args.func(args, dag=self.dag)
  File "/home/airflow/.local/lib/python3.6/site-packages/airflow/cli/cli_parser.py", line 48, in command
    return func(*args, **kwargs)
  File "/home/airflow/.local/lib/python3.6/site-packages/airflow/utils/cli.py", line 92, in wrapper
    return f(*args, **kwargs)
  File "/home/airflow/.local/lib/python3.6/site-packages/airflow/cli/commands/task_command.py", line 298, in task_run
    _run_task_by_selected_method(args, dag, ti)
  File "/home/airflow/.local/lib/python3.6/site-packages/airflow/cli/commands/task_command.py", line 107, in _run_task_by_selected_method
    _run_raw_task(args, ti)
  File "/home/airflow/.local/lib/python3.6/site-packages/airflow/cli/commands/task_command.py", line 184, in _run_raw_task
    error_file=args.error_file,
  File "/home/airflow/.local/lib/python3.6/site-packages/airflow/utils/session.py", line 70, in wrapper
    return func(*args, session=session, **kwargs)
  File "/home/airflow/.local/lib/python3.6/site-packages/airflow/models/taskinstance.py", line 1329, in _run_raw_task
    self._execute_task_with_callbacks(context)
  File "/home/airflow/.local/lib/python3.6/site-packages/airflow/models/taskinstance.py", line 1455, in _execute_task_with_callbacks
    result = self._execute_task(context, self.task)
  File "/home/airflow/.local/lib/python3.6/site-packages/airflow/models/taskinstance.py", line 1511, in _execute_task
    result = execute_callable(context=context)
  File "/home/airflow/.local/lib/python3.6/site-packages/airflow/operators/bash.py", line 188, in execute
    f'Bash command failed. The command returned a non-zero exit code {result.exit_code}.'
airflow.exceptions.AirflowException: Bash command failed. The command returned a non-zero exit code 1.
[2024-05-03 15:24:06,357] {local_task_job.py:154} INFO - Task exited with return code 1
[2024-05-03 15:24:06,720] {local_task_job.py:264} INFO - 0 downstream tasks scheduled from follow-on schedule check
[2024-05-06 09:30:05,691] {taskinstance.py:1032} INFO - Dependencies all met for <TaskInstance: ingest_data_bigquery_yt.download_dataset_task scheduled__2019-02-02T06:00:00+00:00 [queued]>
[2024-05-06 09:30:05,703] {taskinstance.py:1032} INFO - Dependencies all met for <TaskInstance: ingest_data_bigquery_yt.download_dataset_task scheduled__2019-02-02T06:00:00+00:00 [queued]>
[2024-05-06 09:30:05,703] {taskinstance.py:1238} INFO - 
--------------------------------------------------------------------------------
[2024-05-06 09:30:05,703] {taskinstance.py:1239} INFO - Starting attempt 2 of 4
[2024-05-06 09:30:05,703] {taskinstance.py:1240} INFO - 
--------------------------------------------------------------------------------
[2024-05-06 09:30:05,714] {taskinstance.py:1259} INFO - Executing <Task(BashOperator): download_dataset_task> on 2019-02-02 06:00:00+00:00
[2024-05-06 09:30:05,720] {standard_task_runner.py:52} INFO - Started process 681 to run task
[2024-05-06 09:30:05,724] {standard_task_runner.py:76} INFO - Running: ['***', 'tasks', 'run', 'ingest_data_bigquery_yt', 'download_dataset_task', 'scheduled__2019-02-02T06:00:00+00:00', '--job-id', '4620', '--raw', '--subdir', 'DAGS_FOLDER/data_ingstion_gcs_yt_dag.py', '--cfg-path', '/tmp/tmpvfc89ma7', '--error-file', '/tmp/tmpngfgmg7v']
[2024-05-06 09:30:05,728] {standard_task_runner.py:77} INFO - Job 4620: Subtask download_dataset_task
[2024-05-06 09:30:05,794] {logging_mixin.py:109} INFO - Running <TaskInstance: ingest_data_bigquery_yt.download_dataset_task scheduled__2019-02-02T06:00:00+00:00 [running]> on host 4d4efceb404e
[2024-05-06 09:30:05,834] {warnings.py:99} WARNING - /home/***/.local/lib/python3.6/site-packages/***/utils/context.py:152: AirflowContextDeprecationWarning: Accessing 'execution_date' from the template is deprecated and will be removed in a future version. Please use 'data_interval_start' or 'logical_date' instead.
  warnings.warn(_create_deprecation_warning(key, self._deprecation_replacements[key]))

[2024-05-06 09:30:05,858] {taskinstance.py:1426} INFO - Exporting the following env vars:
AIRFLOW_CTX_DAG_OWNER=***
AIRFLOW_CTX_DAG_ID=ingest_data_bigquery_yt
AIRFLOW_CTX_TASK_ID=download_dataset_task
AIRFLOW_CTX_EXECUTION_DATE=2019-02-02T06:00:00+00:00
AIRFLOW_CTX_DAG_RUN_ID=scheduled__2019-02-02T06:00:00+00:00
[2024-05-06 09:30:05,859] {subprocess.py:62} INFO - Tmp dir root location: 
 /tmp
[2024-05-06 09:30:05,861] {subprocess.py:74} INFO - Running command: ['bash', '-c', 'curl -sSL https://github.com/DataTalksClub/nyc-tlc-data/releases/download/yellow/yellow_tripdata_2019-02.csv.gz > /opt/***/raw_data/yellowtaxi_tripdata_2019-02.csv.gz && gunzip /opt/***/raw_data/yellowtaxi_tripdata_2019-02.csv.gz']
[2024-05-06 09:30:05,874] {subprocess.py:85} INFO - Output:
[2024-05-06 09:30:12,722] {subprocess.py:93} INFO - Command exited with return code 0
[2024-05-06 09:30:12,790] {taskinstance.py:1277} INFO - Marking task as SUCCESS. dag_id=ingest_data_bigquery_yt, task_id=download_dataset_task, execution_date=20190202T060000, start_date=20240506T093005, end_date=20240506T093012
[2024-05-06 09:30:12,852] {local_task_job.py:154} INFO - Task exited with return code 0
[2024-05-06 09:30:12,913] {local_task_job.py:264} INFO - 1 downstream tasks scheduled from follow-on schedule check
