[2024-05-02 04:08:48,207] {taskinstance.py:1032} INFO - Dependencies all met for <TaskInstance: ingest_data_bigquery_yt.download_dataset_task scheduled__2021-02-02T06:00:00+00:00 [queued]>
[2024-05-02 04:08:48,239] {taskinstance.py:1032} INFO - Dependencies all met for <TaskInstance: ingest_data_bigquery_yt.download_dataset_task scheduled__2021-02-02T06:00:00+00:00 [queued]>
[2024-05-02 04:08:48,239] {taskinstance.py:1238} INFO - 
--------------------------------------------------------------------------------
[2024-05-02 04:08:48,239] {taskinstance.py:1239} INFO - Starting attempt 2 of 2
[2024-05-02 04:08:48,240] {taskinstance.py:1240} INFO - 
--------------------------------------------------------------------------------
[2024-05-02 04:08:48,268] {taskinstance.py:1259} INFO - Executing <Task(BashOperator): download_dataset_task> on 2021-02-02 06:00:00+00:00
[2024-05-02 04:08:48,276] {standard_task_runner.py:52} INFO - Started process 5632 to run task
[2024-05-02 04:08:48,299] {standard_task_runner.py:76} INFO - Running: ['***', 'tasks', 'run', 'ingest_data_bigquery_yt', 'download_dataset_task', 'scheduled__2021-02-02T06:00:00+00:00', '--job-id', '3762', '--raw', '--subdir', 'DAGS_FOLDER/data_ingestion_gcs_yt_dag.py', '--cfg-path', '/tmp/tmpni8f6fn6', '--error-file', '/tmp/tmpn3kdg_6c']
[2024-05-02 04:08:48,313] {standard_task_runner.py:77} INFO - Job 3762: Subtask download_dataset_task
[2024-05-02 04:08:48,444] {logging_mixin.py:109} INFO - Running <TaskInstance: ingest_data_bigquery_yt.download_dataset_task scheduled__2021-02-02T06:00:00+00:00 [running]> on host bef445d594dc
[2024-05-02 04:08:48,519] {warnings.py:99} WARNING - /home/***/.local/lib/python3.6/site-packages/***/utils/context.py:152: AirflowContextDeprecationWarning: Accessing 'execution_date' from the template is deprecated and will be removed in a future version. Please use 'data_interval_start' or 'logical_date' instead.
  warnings.warn(_create_deprecation_warning(key, self._deprecation_replacements[key]))

[2024-05-02 04:08:48,566] {taskinstance.py:1426} INFO - Exporting the following env vars:
AIRFLOW_CTX_DAG_OWNER=***
AIRFLOW_CTX_DAG_ID=ingest_data_bigquery_yt
AIRFLOW_CTX_TASK_ID=download_dataset_task
AIRFLOW_CTX_EXECUTION_DATE=2021-02-02T06:00:00+00:00
AIRFLOW_CTX_DAG_RUN_ID=scheduled__2021-02-02T06:00:00+00:00
[2024-05-02 04:08:48,567] {subprocess.py:62} INFO - Tmp dir root location: 
 /tmp
[2024-05-02 04:08:48,568] {subprocess.py:74} INFO - Running command: ['bash', '-c', 'curl -sSL https://github.com/DataTalksClub/nyc-tlc-data/releases/download/yellow/yellow_tripdata_2021-02.csv.gz > /opt/***/raw_data/yellowtaxi_tripdata_2021-02.csv.gz | gzip -d > /opt/***/raw_data/yellowtaxi_tripdata_2021-02.csv && rm /opt/***/raw_data/yellowtaxi_tripdata_2021-02.csv.gz']
[2024-05-02 04:08:48,590] {subprocess.py:85} INFO - Output:
[2024-05-02 04:08:48,613] {subprocess.py:89} INFO - 
[2024-05-02 04:08:48,613] {subprocess.py:89} INFO - gzip: stdin: unexpected end of file
[2024-05-02 04:08:50,026] {subprocess.py:93} INFO - Command exited with return code 1
[2024-05-02 04:08:50,045] {taskinstance.py:1700} ERROR - Task failed with exception
Traceback (most recent call last):
  File "/home/airflow/.local/lib/python3.6/site-packages/airflow/models/taskinstance.py", line 1329, in _run_raw_task
    self._execute_task_with_callbacks(context)
  File "/home/airflow/.local/lib/python3.6/site-packages/airflow/models/taskinstance.py", line 1455, in _execute_task_with_callbacks
    result = self._execute_task(context, self.task)
  File "/home/airflow/.local/lib/python3.6/site-packages/airflow/models/taskinstance.py", line 1511, in _execute_task
    result = execute_callable(context=context)
  File "/home/airflow/.local/lib/python3.6/site-packages/airflow/operators/bash.py", line 188, in execute
    f'Bash command failed. The command returned a non-zero exit code {result.exit_code}.'
airflow.exceptions.AirflowException: Bash command failed. The command returned a non-zero exit code 1.
[2024-05-02 04:08:50,053] {taskinstance.py:1277} INFO - Marking task as FAILED. dag_id=ingest_data_bigquery_yt, task_id=download_dataset_task, execution_date=20210202T060000, start_date=20240502T040848, end_date=20240502T040850
[2024-05-02 04:08:50,067] {standard_task_runner.py:92} ERROR - Failed to execute job 3762 for task download_dataset_task
Traceback (most recent call last):
  File "/home/airflow/.local/lib/python3.6/site-packages/airflow/task/task_runner/standard_task_runner.py", line 85, in _start_by_fork
    args.func(args, dag=self.dag)
  File "/home/airflow/.local/lib/python3.6/site-packages/airflow/cli/cli_parser.py", line 48, in command
    return func(*args, **kwargs)
  File "/home/airflow/.local/lib/python3.6/site-packages/airflow/utils/cli.py", line 92, in wrapper
    return f(*args, **kwargs)
  File "/home/airflow/.local/lib/python3.6/site-packages/airflow/cli/commands/task_command.py", line 298, in task_run
    _run_task_by_selected_method(args, dag, ti)
  File "/home/airflow/.local/lib/python3.6/site-packages/airflow/cli/commands/task_command.py", line 107, in _run_task_by_selected_method
    _run_raw_task(args, ti)
  File "/home/airflow/.local/lib/python3.6/site-packages/airflow/cli/commands/task_command.py", line 184, in _run_raw_task
    error_file=args.error_file,
  File "/home/airflow/.local/lib/python3.6/site-packages/airflow/utils/session.py", line 70, in wrapper
    return func(*args, session=session, **kwargs)
  File "/home/airflow/.local/lib/python3.6/site-packages/airflow/models/taskinstance.py", line 1329, in _run_raw_task
    self._execute_task_with_callbacks(context)
  File "/home/airflow/.local/lib/python3.6/site-packages/airflow/models/taskinstance.py", line 1455, in _execute_task_with_callbacks
    result = self._execute_task(context, self.task)
  File "/home/airflow/.local/lib/python3.6/site-packages/airflow/models/taskinstance.py", line 1511, in _execute_task
    result = execute_callable(context=context)
  File "/home/airflow/.local/lib/python3.6/site-packages/airflow/operators/bash.py", line 188, in execute
    f'Bash command failed. The command returned a non-zero exit code {result.exit_code}.'
airflow.exceptions.AirflowException: Bash command failed. The command returned a non-zero exit code 1.
[2024-05-02 04:08:50,094] {local_task_job.py:154} INFO - Task exited with return code 1
[2024-05-02 04:08:50,134] {local_task_job.py:264} INFO - 0 downstream tasks scheduled from follow-on schedule check
