[2024-05-02 17:56:27,470] {taskinstance.py:1032} INFO - Dependencies all met for <TaskInstance: ingest_data_bigquery_yt.local_to_gcs_task scheduled__2020-10-02T06:00:00+00:00 [queued]>
[2024-05-02 17:56:27,484] {taskinstance.py:1032} INFO - Dependencies all met for <TaskInstance: ingest_data_bigquery_yt.local_to_gcs_task scheduled__2020-10-02T06:00:00+00:00 [queued]>
[2024-05-02 17:56:27,484] {taskinstance.py:1238} INFO - 
--------------------------------------------------------------------------------
[2024-05-02 17:56:27,484] {taskinstance.py:1239} INFO - Starting attempt 1 of 2
[2024-05-02 17:56:27,484] {taskinstance.py:1240} INFO - 
--------------------------------------------------------------------------------
[2024-05-02 17:56:27,497] {taskinstance.py:1259} INFO - Executing <Task(PythonOperator): local_to_gcs_task> on 2020-10-02 06:00:00+00:00
[2024-05-02 17:56:27,507] {standard_task_runner.py:52} INFO - Started process 4474 to run task
[2024-05-02 17:56:27,514] {standard_task_runner.py:76} INFO - Running: ['***', 'tasks', 'run', 'ingest_data_bigquery_yt', 'local_to_gcs_task', 'scheduled__2020-10-02T06:00:00+00:00', '--job-id', '3839', '--raw', '--subdir', 'DAGS_FOLDER/data_ingestion_gcs_yt_dag.py', '--cfg-path', '/tmp/tmpfbq19g14', '--error-file', '/tmp/tmp8f03uccw']
[2024-05-02 17:56:27,521] {standard_task_runner.py:77} INFO - Job 3839: Subtask local_to_gcs_task
[2024-05-02 17:56:27,600] {logging_mixin.py:109} INFO - Running <TaskInstance: ingest_data_bigquery_yt.local_to_gcs_task scheduled__2020-10-02T06:00:00+00:00 [running]> on host 1ed1a38cd1e3
[2024-05-02 17:56:27,648] {warnings.py:99} WARNING - /home/***/.local/lib/python3.6/site-packages/***/utils/context.py:152: AirflowContextDeprecationWarning: Accessing 'execution_date' from the template is deprecated and will be removed in a future version. Please use 'data_interval_start' or 'logical_date' instead.
  warnings.warn(_create_deprecation_warning(key, self._deprecation_replacements[key]))

[2024-05-02 17:56:27,680] {taskinstance.py:1426} INFO - Exporting the following env vars:
AIRFLOW_CTX_DAG_OWNER=***
AIRFLOW_CTX_DAG_ID=ingest_data_bigquery_yt
AIRFLOW_CTX_TASK_ID=local_to_gcs_task
AIRFLOW_CTX_EXECUTION_DATE=2020-10-02T06:00:00+00:00
AIRFLOW_CTX_DAG_RUN_ID=scheduled__2020-10-02T06:00:00+00:00
[2024-05-02 17:56:32,035] {warnings.py:99} WARNING - /home/***/.local/lib/python3.6/site-packages/***/operators/python.py:174: DtypeWarning: Columns (6) have mixed types.Specify dtype option on import or set low_memory=False.
  return_value = self.execute_callable()

[2024-05-02 17:56:35,576] {python.py:175} INFO - Done. Returned value was: None
[2024-05-02 17:56:35,810] {taskinstance.py:1277} INFO - Marking task as SUCCESS. dag_id=ingest_data_bigquery_yt, task_id=local_to_gcs_task, execution_date=20201002T060000, start_date=20240502T175627, end_date=20240502T175635
[2024-05-02 17:56:35,879] {local_task_job.py:154} INFO - Task exited with return code 0
[2024-05-02 17:56:35,921] {local_task_job.py:264} INFO - 1 downstream tasks scheduled from follow-on schedule check
[2024-05-03 08:55:41,769] {taskinstance.py:1032} INFO - Dependencies all met for <TaskInstance: ingest_data_bigquery_yt.local_to_gcs_task scheduled__2020-10-02T06:00:00+00:00 [queued]>
[2024-05-03 08:55:41,781] {taskinstance.py:1032} INFO - Dependencies all met for <TaskInstance: ingest_data_bigquery_yt.local_to_gcs_task scheduled__2020-10-02T06:00:00+00:00 [queued]>
[2024-05-03 08:55:41,781] {taskinstance.py:1238} INFO - 
--------------------------------------------------------------------------------
[2024-05-03 08:55:41,782] {taskinstance.py:1239} INFO - Starting attempt 1 of 2
[2024-05-03 08:55:41,782] {taskinstance.py:1240} INFO - 
--------------------------------------------------------------------------------
[2024-05-03 08:55:41,792] {taskinstance.py:1259} INFO - Executing <Task(PythonOperator): local_to_gcs_task> on 2020-10-02 06:00:00+00:00
[2024-05-03 08:55:41,799] {standard_task_runner.py:52} INFO - Started process 1635 to run task
[2024-05-03 08:55:41,805] {standard_task_runner.py:76} INFO - Running: ['***', 'tasks', 'run', 'ingest_data_bigquery_yt', 'local_to_gcs_task', 'scheduled__2020-10-02T06:00:00+00:00', '--job-id', '3957', '--raw', '--subdir', 'DAGS_FOLDER/data_ingestion_gcs_yt_dag.py', '--cfg-path', '/tmp/tmpl9m7zwev', '--error-file', '/tmp/tmpxskubf49']
[2024-05-03 08:55:41,812] {standard_task_runner.py:77} INFO - Job 3957: Subtask local_to_gcs_task
[2024-05-03 08:55:41,924] {logging_mixin.py:109} INFO - Running <TaskInstance: ingest_data_bigquery_yt.local_to_gcs_task scheduled__2020-10-02T06:00:00+00:00 [running]> on host 5bfe1025092b
[2024-05-03 08:55:41,984] {warnings.py:99} WARNING - /home/***/.local/lib/python3.6/site-packages/***/utils/context.py:152: AirflowContextDeprecationWarning: Accessing 'execution_date' from the template is deprecated and will be removed in a future version. Please use 'data_interval_start' or 'logical_date' instead.
  warnings.warn(_create_deprecation_warning(key, self._deprecation_replacements[key]))

[2024-05-03 08:55:42,024] {taskinstance.py:1426} INFO - Exporting the following env vars:
AIRFLOW_CTX_DAG_OWNER=***
AIRFLOW_CTX_DAG_ID=ingest_data_bigquery_yt
AIRFLOW_CTX_TASK_ID=local_to_gcs_task
AIRFLOW_CTX_EXECUTION_DATE=2020-10-02T06:00:00+00:00
AIRFLOW_CTX_DAG_RUN_ID=scheduled__2020-10-02T06:00:00+00:00
[2024-05-03 08:55:47,738] {warnings.py:99} WARNING - /home/***/.local/lib/python3.6/site-packages/***/operators/python.py:174: DtypeWarning: Columns (6) have mixed types.Specify dtype option on import or set low_memory=False.
  return_value = self.execute_callable()

[2024-05-03 08:55:50,737] {python.py:175} INFO - Done. Returned value was: None
[2024-05-03 08:55:50,772] {taskinstance.py:1277} INFO - Marking task as SUCCESS. dag_id=ingest_data_bigquery_yt, task_id=local_to_gcs_task, execution_date=20201002T060000, start_date=20240503T085541, end_date=20240503T085550
[2024-05-03 08:55:50,845] {local_task_job.py:154} INFO - Task exited with return code 0
[2024-05-03 08:55:50,882] {local_task_job.py:264} INFO - 1 downstream tasks scheduled from follow-on schedule check
[2024-05-03 09:53:05,470] {taskinstance.py:1032} INFO - Dependencies all met for <TaskInstance: ingest_data_bigquery_yt.local_to_gcs_task scheduled__2020-10-02T06:00:00+00:00 [queued]>
[2024-05-03 09:53:05,486] {taskinstance.py:1032} INFO - Dependencies all met for <TaskInstance: ingest_data_bigquery_yt.local_to_gcs_task scheduled__2020-10-02T06:00:00+00:00 [queued]>
[2024-05-03 09:53:05,486] {taskinstance.py:1238} INFO - 
--------------------------------------------------------------------------------
[2024-05-03 09:53:05,486] {taskinstance.py:1239} INFO - Starting attempt 1 of 3
[2024-05-03 09:53:05,486] {taskinstance.py:1240} INFO - 
--------------------------------------------------------------------------------
[2024-05-03 09:53:05,499] {taskinstance.py:1259} INFO - Executing <Task(PythonOperator): local_to_gcs_task> on 2020-10-02 06:00:00+00:00
[2024-05-03 09:53:05,506] {standard_task_runner.py:52} INFO - Started process 907 to run task
[2024-05-03 09:53:05,511] {standard_task_runner.py:76} INFO - Running: ['***', 'tasks', 'run', 'ingest_data_bigquery_yt', 'local_to_gcs_task', 'scheduled__2020-10-02T06:00:00+00:00', '--job-id', '4028', '--raw', '--subdir', 'DAGS_FOLDER/data_ingstion_gcs_yt_dag.py', '--cfg-path', '/tmp/tmpur53ceqr', '--error-file', '/tmp/tmpdlink5j2']
[2024-05-03 09:53:05,516] {standard_task_runner.py:77} INFO - Job 4028: Subtask local_to_gcs_task
[2024-05-03 09:53:05,590] {logging_mixin.py:109} INFO - Running <TaskInstance: ingest_data_bigquery_yt.local_to_gcs_task scheduled__2020-10-02T06:00:00+00:00 [running]> on host b81c18b6cf72
[2024-05-03 09:53:05,641] {warnings.py:99} WARNING - /home/***/.local/lib/python3.6/site-packages/***/utils/context.py:152: AirflowContextDeprecationWarning: Accessing 'execution_date' from the template is deprecated and will be removed in a future version. Please use 'data_interval_start' or 'logical_date' instead.
  warnings.warn(_create_deprecation_warning(key, self._deprecation_replacements[key]))

[2024-05-03 09:53:05,669] {taskinstance.py:1426} INFO - Exporting the following env vars:
AIRFLOW_CTX_DAG_OWNER=***
AIRFLOW_CTX_DAG_ID=ingest_data_bigquery_yt
AIRFLOW_CTX_TASK_ID=local_to_gcs_task
AIRFLOW_CTX_EXECUTION_DATE=2020-10-02T06:00:00+00:00
AIRFLOW_CTX_DAG_RUN_ID=scheduled__2020-10-02T06:00:00+00:00
[2024-05-03 09:53:09,512] {warnings.py:99} WARNING - /home/***/.local/lib/python3.6/site-packages/***/operators/python.py:174: DtypeWarning: Columns (6) have mixed types.Specify dtype option on import or set low_memory=False.
  return_value = self.execute_callable()

[2024-05-03 09:53:12,756] {python.py:175} INFO - Done. Returned value was: None
[2024-05-03 09:53:14,973] {taskinstance.py:1700} ERROR - Task failed with exception
Traceback (most recent call last):
  File "/home/airflow/.local/lib/python3.6/site-packages/sqlalchemy/engine/base.py", line 2336, in _wrap_pool_connect
    return fn()
  File "/home/airflow/.local/lib/python3.6/site-packages/sqlalchemy/pool/base.py", line 364, in connect
    return _ConnectionFairy._checkout(self)
  File "/home/airflow/.local/lib/python3.6/site-packages/sqlalchemy/pool/base.py", line 778, in _checkout
    fairy = _ConnectionRecord.checkout(pool)
  File "/home/airflow/.local/lib/python3.6/site-packages/sqlalchemy/pool/base.py", line 495, in checkout
    rec = pool._do_get()
  File "/home/airflow/.local/lib/python3.6/site-packages/sqlalchemy/pool/impl.py", line 241, in _do_get
    return self._create_connection()
  File "/home/airflow/.local/lib/python3.6/site-packages/sqlalchemy/pool/base.py", line 309, in _create_connection
    return _ConnectionRecord(self)
  File "/home/airflow/.local/lib/python3.6/site-packages/sqlalchemy/pool/base.py", line 440, in __init__
    self.__connect(first_connect_check=True)
  File "/home/airflow/.local/lib/python3.6/site-packages/sqlalchemy/pool/base.py", line 661, in __connect
    pool.logger.debug("Error on connect(): %s", e)
  File "/home/airflow/.local/lib/python3.6/site-packages/sqlalchemy/util/langhelpers.py", line 70, in __exit__
    with_traceback=exc_tb,
  File "/home/airflow/.local/lib/python3.6/site-packages/sqlalchemy/util/compat.py", line 182, in raise_
    raise exception
  File "/home/airflow/.local/lib/python3.6/site-packages/sqlalchemy/pool/base.py", line 656, in __connect
    connection = pool._invoke_creator(self)
  File "/home/airflow/.local/lib/python3.6/site-packages/sqlalchemy/engine/strategies.py", line 114, in connect
    return dialect.connect(*cargs, **cparams)
  File "/home/airflow/.local/lib/python3.6/site-packages/sqlalchemy/engine/default.py", line 508, in connect
    return self.dbapi.connect(*cargs, **cparams)
  File "/home/airflow/.local/lib/python3.6/site-packages/psycopg2/__init__.py", line 122, in connect
    conn = _connect(dsn, connection_factory=connection_factory, **kwasync)
psycopg2.OperationalError: could not translate host name "postgres" to address: Name or service not known


The above exception was the direct cause of the following exception:

Traceback (most recent call last):
  File "/home/airflow/.local/lib/python3.6/site-packages/airflow/models/taskinstance.py", line 1331, in _run_raw_task
    self.refresh_from_db(lock_for_update=True, session=session)
  File "/home/airflow/.local/lib/python3.6/site-packages/airflow/utils/session.py", line 67, in wrapper
    return func(*args, **kwargs)
  File "/home/airflow/.local/lib/python3.6/site-packages/airflow/models/taskinstance.py", line 726, in refresh_from_db
    ti: Optional[TaskInstance] = qry.with_for_update().first()
  File "/home/airflow/.local/lib/python3.6/site-packages/sqlalchemy/orm/query.py", line 3429, in first
    ret = list(self[0:1])
  File "/home/airflow/.local/lib/python3.6/site-packages/sqlalchemy/orm/query.py", line 3203, in __getitem__
    return list(res)
  File "/home/airflow/.local/lib/python3.6/site-packages/sqlalchemy/orm/query.py", line 3535, in __iter__
    return self._execute_and_instances(context)
  File "/home/airflow/.local/lib/python3.6/site-packages/sqlalchemy/orm/query.py", line 3557, in _execute_and_instances
    querycontext, self._connection_from_session, close_w[2024-05-03 17:10:44,143] {taskinstance.py:1032} INFO - Dependencies all met for <TaskInstance: ingest_data_bigquery_yt.local_to_gcs_task scheduled__2020-10-02T06:00:00+00:00 [queued]>
[2024-05-03 17:10:44,163] {taskinstance.py:1032} INFO - Dependencies all met for <TaskInstance: ingest_data_bigquery_yt.local_to_gcs_task scheduled__2020-10-02T06:00:00+00:00 [queued]>
[2024-05-03 17:10:44,163] {taskinstance.py:1238} INFO - 
--------------------------------------------------------------------------------
[2024-05-03 17:10:44,164] {taskinstance.py:1239} INFO - Starting attempt 1 of 3
[2024-05-03 17:10:44,165] {taskinstance.py:1240} INFO - 
--------------------------------------------------------------------------------
[2024-05-03 17:10:44,182] {taskinstance.py:1259} INFO - Executing <Task(PythonOperator): local_to_gcs_task> on 2020-10-02 06:00:00+00:00
[2024-05-03 17:10:44,189] {standard_task_runner.py:52} INFO - Started process 718 to run task
[2024-05-03 17:10:44,196] {standard_task_runner.py:76} INFO - Running: ['***', 'tasks', 'run', 'ingest_data_bigquery_yt', 'local_to_gcs_task', 'scheduled__2020-10-02T06:00:00+00:00', '--job-id', '4273', '--raw', '--subdir', 'DAGS_FOLDER/data_ingstion_gcs_yt_dag.py', '--cfg-path', '/tmp/tmpr1x2qolb', '--error-file', '/tmp/tmpaexguwsn']
[2024-05-03 17:10:44,202] {standard_task_runner.py:77} INFO - Job 4273: Subtask local_to_gcs_task
[2024-05-03 17:10:44,300] {logging_mixin.py:109} INFO - Running <TaskInstance: ingest_data_bigquery_yt.local_to_gcs_task scheduled__2020-10-02T06:00:00+00:00 [running]> on host f0ab9bf9b587
[2024-05-03 17:10:44,366] {warnings.py:99} WARNING - /home/***/.local/lib/python3.6/site-packages/***/utils/context.py:152: AirflowContextDeprecationWarning: Accessing 'execution_date' from the template is deprecated and will be removed in a future version. Please use 'data_interval_start' or 'logical_date' instead.
  warnings.warn(_create_deprecation_warning(key, self._deprecation_replacements[key]))

[2024-05-03 17:10:44,404] {taskinstance.py:1426} INFO - Exporting the following env vars:
AIRFLOW_CTX_DAG_OWNER=***
AIRFLOW_CTX_DAG_ID=ingest_data_bigquery_yt
AIRFLOW_CTX_TASK_ID=local_to_gcs_task
AIRFLOW_CTX_EXECUTION_DATE=2020-10-02T06:00:00+00:00
AIRFLOW_CTX_DAG_RUN_ID=scheduled__2020-10-02T06:00:00+00:00
[2024-05-03 17:10:50,151] {warnings.py:99} WARNING - /home/***/.local/lib/python3.6/site-packages/***/operators/python.py:174: DtypeWarning: Columns (6) have mixed types.Specify dtype option on import or set low_memory=False.
  return_value = self.execute_callable()

[2024-05-03 17:10:55,906] {python.py:175} INFO - Done. Returned value was: None
[2024-05-03 17:10:56,367] {taskinstance.py:1277} INFO - Marking task as SUCCESS. dag_id=ingest_data_bigquery_yt, task_id=local_to_gcs_task, execution_date=20201002T060000, start_date=20240503T171044, end_date=20240503T171056
[2024-05-03 17:10:56,479] {local_task_job.py:154} INFO - Task exited with return code 0
[2024-05-03 17:10:56,578] {local_task_job.py:264} INFO - 1 downstream tasks scheduled from follow-on schedule check
[2024-05-05 13:54:32,454] {taskinstance.py:1032} INFO - Dependencies all met for <TaskInstance: ingest_data_bigquery_yt.local_to_gcs_task scheduled__2020-10-02T06:00:00+00:00 [queued]>
[2024-05-05 13:54:32,541] {taskinstance.py:1032} INFO - Dependencies all met for <TaskInstance: ingest_data_bigquery_yt.local_to_gcs_task scheduled__2020-10-02T06:00:00+00:00 [queued]>
[2024-05-05 13:54:32,541] {taskinstance.py:1238} INFO - 
--------------------------------------------------------------------------------
[2024-05-05 13:54:32,541] {taskinstance.py:1239} INFO - Starting attempt 1 of 3
[2024-05-05 13:54:32,541] {taskinstance.py:1240} INFO - 
--------------------------------------------------------------------------------
[2024-05-05 13:54:32,624] {taskinstance.py:1259} INFO - Executing <Task(PythonOperator): local_to_gcs_task> on 2020-10-02 06:00:00+00:00
[2024-05-05 13:54:32,703] {standard_task_runner.py:76} INFO - Running: ['***', 'tasks', 'run', 'ingest_data_bigquery_yt', 'local_to_gcs_task', 'scheduled__2020-10-02T06:00:00+00:00', '--job-id', '4443', '--raw', '--subdir', 'DAGS_FOLDER/data_ingstion_gcs_yt_dag.py', '--cfg-path', '/tmp/tmp4js05r53', '--error-file', '/tmp/tmponjrhii2']
[2024-05-05 13:54:32,732] {standard_task_runner.py:77} INFO - Job 4443: Subtask local_to_gcs_task
[2024-05-05 13:54:32,659] {standard_task_runner.py:52} INFO - Started process 265 to run task
[2024-05-05 13:54:33,091] {logging_mixin.py:109} INFO - Running <TaskInstance: ingest_data_bigquery_yt.local_to_gcs_task scheduled__2020-10-02T06:00:00+00:00 [running]> on host 43faca6eb596
[2024-05-05 13:54:33,421] {warnings.py:99} WARNING - /home/***/.local/lib/python3.6/site-packages/***/utils/context.py:152: AirflowContextDeprecationWarning: Accessing 'execution_date' from the template is deprecated and will be removed in a future version. Please use 'data_interval_start' or 'logical_date' instead.
  warnings.warn(_create_deprecation_warning(key, self._deprecation_replacements[key]))

[2024-05-05 13:54:33,547] {taskinstance.py:1426} INFO - Exporting the following env vars:
AIRFLOW_CTX_DAG_OWNER=***
AIRFLOW_CTX_DAG_ID=ingest_data_bigquery_yt
AIRFLOW_CTX_TASK_ID=local_to_gcs_task
AIRFLOW_CTX_EXECUTION_DATE=2020-10-02T06:00:00+00:00
AIRFLOW_CTX_DAG_RUN_ID=scheduled__2020-10-02T06:00:00+00:00
[2024-05-05 13:54:56,176] {taskinstance.py:1700} ERROR - Task failed with exception
Traceback (most recent call last):
  File "/home/airflow/.local/lib/python3.6/site-packages/airflow/models/taskinstance.py", line 1329, in _run_raw_task
    self._execute_task_with_callbacks(context)
  File "/home/airflow/.local/lib/python3.6/site-packages/airflow/models/taskinstance.py", line 1455, in _execute_task_with_callbacks
    result = self._execute_task(context, self.task)
  File "/home/airflow/.local/lib/python3.6/site-packages/airflow/models/taskinstance.py", line 1511, in _execute_task
    result = execute_callable(context=context)
  File "/home/airflow/.local/lib/python3.6/site-packages/airflow/operators/python.py", line 174, in execute
    return_value = self.execute_callable()
  File "/home/airflow/.local/lib/python3.6/site-packages/airflow/operators/python.py", line 185, in execute_callable
    return self.python_callable(*self.op_args, **self.op_kwargs)
  File "/opt/airflow/dags/data_ingstion_gcs_yt_dag.py", line 84, in upload_to_gcs
    __clean_file(raw_file_name, clean_file_name)
  File "/opt/airflow/dags/data_ingstion_gcs_yt_dag.py", line 65, in __clean_file
    "payment_type": "int64",
  File "/home/airflow/.local/lib/python3.6/site-packages/pandas/io/parsers.py", line 688, in read_csv
    return _read(filepath_or_buffer, kwds)
  File "/home/airflow/.local/lib/python3.6/site-packages/pandas/io/parsers.py", line 460, in _read
    data = parser.read(nrows)
  File "/home/airflow/.local/lib/python3.6/site-packages/pandas/io/parsers.py", line 1198, in read
    ret = self._engine.read(nrows)
  File "/home/airflow/.local/lib/python3.6/site-packages/pandas/io/parsers.py", line 2157, in read
    data = self._reader.read(nrows)
  File "pandas/_libs/parsers.pyx", line 847, in pandas._libs.parsers.TextReader.read
  File "pandas/_libs/parsers.pyx", line 862, in pandas._libs.parsers.TextReader._read_low_memory
  File "pandas/_libs/parsers.pyx", line 941, in pandas._libs.parsers.TextReader._read_rows
  File "pandas/_libs/parsers.pyx", line 1073, in pandas._libs.parsers.TextReader._convert_column_data
  File "pandas/_libs/parsers.pyx", line 1104, in pandas._libs.parsers.TextReader._convert_tokens
  File "pandas/_libs/parsers.pyx", line 1198, in pandas._libs.parsers.TextReader._convert_with_dtype
ValueError: Integer column has NA values in column 0
[2024-05-05 13:54:56,209] {taskinstance.py:1277} INFO - Marking task as UP_FOR_RETRY. dag_id=ingest_data_bigquery_yt, task_id=local_to_gcs_task, execution_date=20201002T060000, start_date=20240505T135432, end_date=20240505T135456
[2024-05-05 13:54:56,237] {standard_task_runner.py:92} ERROR - Failed to execute job 4443 for task local_to_gcs_task
Traceback (most recent call last):
  File "/home/airflow/.local/lib/python3.6/site-packages/airflow/task/task_runner/standard_task_runner.py", line 85, in _start_by_fork
    args.func(args, dag=self.dag)
  File "/home/airflow/.local/lib/python3.6/site-packages/airflow/cli/cli_parser.py", line 48, in command
    return func(*args, **kwargs)
  File "/home/airflow/.local/lib/python3.6/site-packages/airflow/utils/cli.py", line 92, in wrapper
    return f(*args, **kwargs)
  File "/home/airflow/.local/lib/python3.6/site-packages/airflow/cli/commands/task_command.py", line 298, in task_run
    _run_task_by_selected_method(args, dag, ti)
  File "/home/airflow/.local/lib/python3.6/site-packages/airflow/cli/commands/task_command.py", line 107, in _run_task_by_selected_method
    _run_raw_task(args, ti)
  File "/home/airflow/.local/lib/python3.6/site-packages/airflow/cli/commands/task_command.py", line 184, in _run_raw_task
    error_file=args.error_file,
  File "/home/airflow/.local/lib/python3.6/site-packages/airflow/utils/session.py", line 70, in wrapper
    return func(*args, session=session, **kwargs)
  File "/home/airflow/.local/lib/python3.6/site-packages/airflow/models/taskinstance.py", line 1329, in _run_raw_task
    self._execute_task_with_callbacks(context)
  File "/home/airflow/.local/lib/python3.6/site-packages/airflow/models/taskinstance.py", line 1455, in _execute_task_with_callbacks
    result = self._execute_task(context, self.task)
  File "/home/airflow/.local/lib/python3.6/site-packages/airflow/models/taskinstance.py", line 1511, in _execute_task
    result = execute_callable(context=context)
  File "/home/airflow/.local/lib/python3.6/site-packages/airflow/operators/python.py", line 174, in execute
    return_value = self.execute_callable()
  File "/home/airflow/.local/lib/python3.6/site-packages/airflow/operators/python.py", line 185, in execute_callable
    return self.python_callable(*self.op_args, **self.op_kwargs)
  File "/opt/airflow/dags/data_ingstion_gcs_yt_dag.py", line 84, in upload_to_gcs
    __clean_file(raw_file_name, clean_file_name)
  File "/opt/airflow/dags/data_ingstion_gcs_yt_dag.py", line 65, in __clean_file
    "payment_type": "int64",
  File "/home/airflow/.local/lib/python3.6/site-packages/pandas/io/parsers.py", line 688, in read_csv
    return _read(filepath_or_buffer, kwds)
  File "/home/airflow/.local/lib/python3.6/site-packages/pandas/io/parsers.py", line 460, in _read
    data = parser.read(nrows)
  File "/home/airflow/.local/lib/python3.6/site-packages/pandas/io/parsers.py", line 1198, in read
    ret = self._engine.read(nrows)
  File "/home/airflow/.local/lib/python3.6/site-packages/pandas/io/parsers.py", line 2157, in read
    data = self._reader.read(nrows)
  File "pandas/_libs/parsers.pyx", line 847, in pandas._libs.parsers.TextReader.read
  File "pandas/_libs/parsers.pyx", line 862, in pandas._libs.parsers.TextReader._read_low_memory
  File "pandas/_libs/parsers.pyx", line 941, in pandas._libs.parsers.TextReader._read_rows
  File "pandas/_libs/parsers.pyx", line 1073, in pandas._libs.parsers.TextReader._convert_column_data
  File "pandas/_libs/parsers.pyx", line 1104, in pandas._libs.parsers.TextReader._convert_tokens
  File "pandas/_libs/parsers.pyx", line 1198, in pandas._libs.parsers.TextReader._convert_with_dtype
ValueError: Integer column has NA values in column 0
[2024-05-05 13:54:56,335] {local_task_job.py:154} INFO - Task exited with return code 1
[2024-05-05 13:54:56,746] {local_task_job.py:264} INFO - 0 downstream tasks scheduled from follow-on schedule check
[2024-05-06 09:25:21,153] {taskinstance.py:1032} INFO - Dependencies all met for <TaskInstance: ingest_data_bigquery_yt.local_to_gcs_task scheduled__2020-10-02T06:00:00+00:00 [queued]>
[2024-05-06 09:25:21,188] {taskinstance.py:1032} INFO - Dependencies all met for <TaskInstance: ingest_data_bigquery_yt.local_to_gcs_task scheduled__2020-10-02T06:00:00+00:00 [queued]>
[2024-05-06 09:25:21,189] {taskinstance.py:1238} INFO - 
--------------------------------------------------------------------------------
[2024-05-06 09:25:21,190] {taskinstance.py:1239} INFO - Starting attempt 1 of 3
[2024-05-06 09:25:21,190] {taskinstance.py:1240} INFO - 
--------------------------------------------------------------------------------
[2024-05-06 09:25:21,254] {taskinstance.py:1259} INFO - Executing <Task(PythonOperator): local_to_gcs_task> on 2020-10-02 06:00:00+00:00
[2024-05-06 09:25:21,310] {standard_task_runner.py:52} INFO - Started process 358 to run task
[2024-05-06 09:25:21,339] {standard_task_runner.py:76} INFO - Running: ['***', 'tasks', 'run', 'ingest_data_bigquery_yt', 'local_to_gcs_task', 'scheduled__2020-10-02T06:00:00+00:00', '--job-id', '4597', '--raw', '--subdir', 'DAGS_FOLDER/data_ingstion_gcs_yt_dag.py', '--cfg-path', '/tmp/tmphr76egk5', '--error-file', '/tmp/tmp3ea4uzn8']
[2024-05-06 09:25:21,377] {standard_task_runner.py:77} INFO - Job 4597: Subtask local_to_gcs_task
[2024-05-06 09:25:21,799] {logging_mixin.py:109} INFO - Running <TaskInstance: ingest_data_bigquery_yt.local_to_gcs_task scheduled__2020-10-02T06:00:00+00:00 [running]> on host 4d4efceb404e
[2024-05-06 09:25:21,946] {warnings.py:99} WARNING - /home/***/.local/lib/python3.6/site-packages/***/utils/context.py:152: AirflowContextDeprecationWarning: Accessing 'execution_date' from the template is deprecated and will be removed in a future version. Please use 'data_interval_start' or 'logical_date' instead.
  warnings.warn(_create_deprecation_warning(key, self._deprecation_replacements[key]))

[2024-05-06 09:25:22,040] {taskinstance.py:1426} INFO - Exporting the following env vars:
AIRFLOW_CTX_DAG_OWNER=***
AIRFLOW_CTX_DAG_ID=ingest_data_bigquery_yt
AIRFLOW_CTX_TASK_ID=local_to_gcs_task
AIRFLOW_CTX_EXECUTION_DATE=2020-10-02T06:00:00+00:00
AIRFLOW_CTX_DAG_RUN_ID=scheduled__2020-10-02T06:00:00+00:00
[2024-05-06 09:25:51,134] {warnings.py:99} WARNING - /home/***/.local/lib/python3.6/site-packages/***/operators/python.py:174: DtypeWarning: Columns (6) have mixed types.Specify dtype option on import or set low_memory=False.
  return_value = self.execute_callable()

[2024-05-06 09:26:11,231] {python.py:175} INFO - Done. Returned value was: None
[2024-05-06 09:26:11,252] {taskinstance.py:1277} INFO - Marking task as SUCCESS. dag_id=ingest_data_bigquery_yt, task_id=local_to_gcs_task, execution_date=20201002T060000, start_date=20240506T092521, end_date=20240506T092611
[2024-05-06 09:26:11,475] {local_task_job.py:154} INFO - Task exited with return code 0
[2024-05-06 09:26:11,557] {local_task_job.py:264} INFO - 1 downstream tasks scheduled from follow-on schedule check
