[2024-05-18 12:25:37,415] {taskinstance.py:1032} INFO - Dependencies all met for <TaskInstance: ingest_data_bigquery_fhv.local_to_gcs_task scheduled__2020-11-02T06:00:00+00:00 [queued]>
[2024-05-18 12:25:37,427] {taskinstance.py:1032} INFO - Dependencies all met for <TaskInstance: ingest_data_bigquery_fhv.local_to_gcs_task scheduled__2020-11-02T06:00:00+00:00 [queued]>
[2024-05-18 12:25:37,428] {taskinstance.py:1238} INFO - 
--------------------------------------------------------------------------------
[2024-05-18 12:25:37,428] {taskinstance.py:1239} INFO - Starting attempt 1 of 3
[2024-05-18 12:25:37,428] {taskinstance.py:1240} INFO - 
--------------------------------------------------------------------------------
[2024-05-18 12:25:37,438] {taskinstance.py:1259} INFO - Executing <Task(PythonOperator): local_to_gcs_task> on 2020-11-02 06:00:00+00:00
[2024-05-18 12:25:37,449] {standard_task_runner.py:52} INFO - Started process 5461 to run task
[2024-05-18 12:25:37,453] {standard_task_runner.py:76} INFO - Running: ['***', 'tasks', 'run', 'ingest_data_bigquery_fhv', 'local_to_gcs_task', 'scheduled__2020-11-02T06:00:00+00:00', '--job-id', '5068', '--raw', '--subdir', 'DAGS_FOLDER/data_ingestion_gcs_fhv_dag .py', '--cfg-path', '/tmp/tmpdn3lkqqw', '--error-file', '/tmp/tmp6gfzx4ll']
[2024-05-18 12:25:37,459] {standard_task_runner.py:77} INFO - Job 5068: Subtask local_to_gcs_task
[2024-05-18 12:25:37,546] {logging_mixin.py:109} INFO - Running <TaskInstance: ingest_data_bigquery_fhv.local_to_gcs_task scheduled__2020-11-02T06:00:00+00:00 [running]> on host 45b18388e83d
[2024-05-18 12:25:37,591] {warnings.py:99} WARNING - /home/***/.local/lib/python3.6/site-packages/***/utils/context.py:152: AirflowContextDeprecationWarning: Accessing 'execution_date' from the template is deprecated and will be removed in a future version. Please use 'data_interval_start' or 'logical_date' instead.
  warnings.warn(_create_deprecation_warning(key, self._deprecation_replacements[key]))

[2024-05-18 12:25:37,626] {taskinstance.py:1426} INFO - Exporting the following env vars:
AIRFLOW_CTX_DAG_OWNER=***
AIRFLOW_CTX_DAG_ID=ingest_data_bigquery_fhv
AIRFLOW_CTX_TASK_ID=local_to_gcs_task
AIRFLOW_CTX_EXECUTION_DATE=2020-11-02T06:00:00+00:00
AIRFLOW_CTX_DAG_RUN_ID=scheduled__2020-11-02T06:00:00+00:00
[2024-05-18 12:25:37,641] {taskinstance.py:1700} ERROR - Task failed with exception
Traceback (most recent call last):
  File "/home/airflow/.local/lib/python3.6/site-packages/airflow/models/taskinstance.py", line 1329, in _run_raw_task
    self._execute_task_with_callbacks(context)
  File "/home/airflow/.local/lib/python3.6/site-packages/airflow/models/taskinstance.py", line 1455, in _execute_task_with_callbacks
    result = self._execute_task(context, self.task)
  File "/home/airflow/.local/lib/python3.6/site-packages/airflow/models/taskinstance.py", line 1511, in _execute_task
    result = execute_callable(context=context)
  File "/home/airflow/.local/lib/python3.6/site-packages/airflow/operators/python.py", line 174, in execute
    return_value = self.execute_callable()
  File "/home/airflow/.local/lib/python3.6/site-packages/airflow/operators/python.py", line 185, in execute_callable
    return self.python_callable(*self.op_args, **self.op_kwargs)
  File "/opt/airflow/dags/data_ingestion_gcs_fhv_dag .py", line 82, in upload_to_gcs
    __clean_file(raw_file_name, clean_file_name)
  File "/opt/airflow/dags/data_ingestion_gcs_fhv_dag .py", line 59, in __clean_file
    parse_dates=["pickup_datetime", "dropOff_datetime"],
  File "/home/airflow/.local/lib/python3.6/site-packages/pandas/io/parsers.py", line 688, in read_csv
    return _read(filepath_or_buffer, kwds)
  File "/home/airflow/.local/lib/python3.6/site-packages/pandas/io/parsers.py", line 454, in _read
    parser = TextFileReader(fp_or_buf, **kwds)
  File "/home/airflow/.local/lib/python3.6/site-packages/pandas/io/parsers.py", line 948, in __init__
    self._make_engine(self.engine)
  File "/home/airflow/.local/lib/python3.6/site-packages/pandas/io/parsers.py", line 1180, in _make_engine
    self._engine = CParserWrapper(self.f, **self.options)
  File "/home/airflow/.local/lib/python3.6/site-packages/pandas/io/parsers.py", line 2068, in __init__
    self._validate_parse_dates_presence(self.names)
  File "/home/airflow/.local/lib/python3.6/site-packages/pandas/io/parsers.py", line 1546, in _validate_parse_dates_presence
    f"Missing column provided to 'parse_dates': '{missing_cols}'"
ValueError: Missing column provided to 'parse_dates': 'dropOff_datetime'
[2024-05-18 12:25:37,657] {taskinstance.py:1277} INFO - Marking task as UP_FOR_RETRY. dag_id=ingest_data_bigquery_fhv, task_id=local_to_gcs_task, execution_date=20201102T060000, start_date=20240518T122537, end_date=20240518T122537
[2024-05-18 12:25:37,675] {standard_task_runner.py:92} ERROR - Failed to execute job 5068 for task local_to_gcs_task
Traceback (most recent call last):
  File "/home/airflow/.local/lib/python3.6/site-packages/airflow/task/task_runner/standard_task_runner.py", line 85, in _start_by_fork
    args.func(args, dag=self.dag)
  File "/home/airflow/.local/lib/python3.6/site-packages/airflow/cli/cli_parser.py", line 48, in command
    return func(*args, **kwargs)
  File "/home/airflow/.local/lib/python3.6/site-packages/airflow/utils/cli.py", line 92, in wrapper
    return f(*args, **kwargs)
  File "/home/airflow/.local/lib/python3.6/site-packages/airflow/cli/commands/task_command.py", line 298, in task_run
    _run_task_by_selected_method(args, dag, ti)
  File "/home/airflow/.local/lib/python3.6/site-packages/airflow/cli/commands/task_command.py", line 107, in _run_task_by_selected_method
    _run_raw_task(args, ti)
  File "/home/airflow/.local/lib/python3.6/site-packages/airflow/cli/commands/task_command.py", line 184, in _run_raw_task
    error_file=args.error_file,
  File "/home/airflow/.local/lib/python3.6/site-packages/airflow/utils/session.py", line 70, in wrapper
    return func(*args, session=session, **kwargs)
  File "/home/airflow/.local/lib/python3.6/site-packages/airflow/models/taskinstance.py", line 1329, in _run_raw_task
    self._execute_task_with_callbacks(context)
  File "/home/airflow/.local/lib/python3.6/site-packages/airflow/models/taskinstance.py", line 1455, in _execute_task_with_callbacks
    result = self._execute_task(context, self.task)
  File "/home/airflow/.local/lib/python3.6/site-packages/airflow/models/taskinstance.py", line 1511, in _execute_task
    result = execute_callable(context=context)
  File "/home/airflow/.local/lib/python3.6/site-packages/airflow/operators/python.py", line 174, in execute
    return_value = self.execute_callable()
  File "/home/airflow/.local/lib/python3.6/site-packages/airflow/operators/python.py", line 185, in execute_callable
    return self.python_callable(*self.op_args, **self.op_kwargs)
  File "/opt/airflow/dags/data_ingestion_gcs_fhv_dag .py", line 82, in upload_to_gcs
    __clean_file(raw_file_name, clean_file_name)
  File "/opt/airflow/dags/data_ingestion_gcs_fhv_dag .py", line 59, in __clean_file
    parse_dates=["pickup_datetime", "dropOff_datetime"],
  File "/home/airflow/.local/lib/python3.6/site-packages/pandas/io/parsers.py", line 688, in read_csv
    return _read(filepath_or_buffer, kwds)
  File "/home/airflow/.local/lib/python3.6/site-packages/pandas/io/parsers.py", line 454, in _read
    parser = TextFileReader(fp_or_buf, **kwds)
  File "/home/airflow/.local/lib/python3.6/site-packages/pandas/io/parsers.py", line 948, in __init__
    self._make_engine(self.engine)
  File "/home/airflow/.local/lib/python3.6/site-packages/pandas/io/parsers.py", line 1180, in _make_engine
    self._engine = CParserWrapper(self.f, **self.options)
  File "/home/airflow/.local/lib/python3.6/site-packages/pandas/io/parsers.py", line 2068, in __init__
    self._validate_parse_dates_presence(self.names)
  File "/home/airflow/.local/lib/python3.6/site-packages/pandas/io/parsers.py", line 1546, in _validate_parse_dates_presence
    f"Missing column provided to 'parse_dates': '{missing_cols}'"
ValueError: Missing column provided to 'parse_dates': 'dropOff_datetime'
[2024-05-18 12:25:37,716] {local_task_job.py:154} INFO - Task exited with return code 1
[2024-05-18 12:25:37,764] {local_task_job.py:264} INFO - 0 downstream tasks scheduled from follow-on schedule check
[2024-05-18 12:50:19,459] {taskinstance.py:1032} INFO - Dependencies all met for <TaskInstance: ingest_data_bigquery_fhv.local_to_gcs_task scheduled__2020-11-02T06:00:00+00:00 [queued]>
[2024-05-18 12:50:19,536] {taskinstance.py:1032} INFO - Dependencies all met for <TaskInstance: ingest_data_bigquery_fhv.local_to_gcs_task scheduled__2020-11-02T06:00:00+00:00 [queued]>
[2024-05-18 12:50:19,538] {taskinstance.py:1238} INFO - 
--------------------------------------------------------------------------------
[2024-05-18 12:50:19,539] {taskinstance.py:1239} INFO - Starting attempt 1 of 3
[2024-05-18 12:50:19,540] {taskinstance.py:1240} INFO - 
--------------------------------------------------------------------------------
[2024-05-18 12:50:19,777] {taskinstance.py:1259} INFO - Executing <Task(PythonOperator): local_to_gcs_task> on 2020-11-02 06:00:00+00:00
[2024-05-18 12:50:19,801] {standard_task_runner.py:52} INFO - Started process 7097 to run task
[2024-05-18 12:50:19,840] {standard_task_runner.py:76} INFO - Running: ['***', 'tasks', 'run', 'ingest_data_bigquery_fhv', 'local_to_gcs_task', 'scheduled__2020-11-02T06:00:00+00:00', '--job-id', '5174', '--raw', '--subdir', 'DAGS_FOLDER/data_ingestion_gcs_fhv_dag .py', '--cfg-path', '/tmp/tmpw757y8zh', '--error-file', '/tmp/tmprp05z0ms']
[2024-05-18 12:50:19,865] {standard_task_runner.py:77} INFO - Job 5174: Subtask local_to_gcs_task
[2024-05-18 12:50:20,201] {logging_mixin.py:109} INFO - Running <TaskInstance: ingest_data_bigquery_fhv.local_to_gcs_task scheduled__2020-11-02T06:00:00+00:00 [running]> on host 45b18388e83d
[2024-05-18 12:50:20,391] {warnings.py:99} WARNING - /home/***/.local/lib/python3.6/site-packages/***/utils/context.py:152: AirflowContextDeprecationWarning: Accessing 'execution_date' from the template is deprecated and will be removed in a future version. Please use 'data_interval_start' or 'logical_date' instead.
  warnings.warn(_create_deprecation_warning(key, self._deprecation_replacements[key]))

[2024-05-18 12:50:20,444] {taskinstance.py:1426} INFO - Exporting the following env vars:
AIRFLOW_CTX_DAG_OWNER=***
AIRFLOW_CTX_DAG_ID=ingest_data_bigquery_fhv
AIRFLOW_CTX_TASK_ID=local_to_gcs_task
AIRFLOW_CTX_EXECUTION_DATE=2020-11-02T06:00:00+00:00
AIRFLOW_CTX_DAG_RUN_ID=scheduled__2020-11-02T06:00:00+00:00
[2024-05-18 12:50:20,462] {taskinstance.py:1700} ERROR - Task failed with exception
Traceback (most recent call last):
  File "/home/airflow/.local/lib/python3.6/site-packages/airflow/models/taskinstance.py", line 1329, in _run_raw_task
    self._execute_task_with_callbacks(context)
  File "/home/airflow/.local/lib/python3.6/site-packages/airflow/models/taskinstance.py", line 1455, in _execute_task_with_callbacks
    result = self._execute_task(context, self.task)
  File "/home/airflow/.local/lib/python3.6/site-packages/airflow/models/taskinstance.py", line 1511, in _execute_task
    result = execute_callable(context=context)
  File "/home/airflow/.local/lib/python3.6/site-packages/airflow/operators/python.py", line 174, in execute
    return_value = self.execute_callable()
  File "/home/airflow/.local/lib/python3.6/site-packages/airflow/operators/python.py", line 185, in execute_callable
    return self.python_callable(*self.op_args, **self.op_kwargs)
  File "/opt/airflow/dags/data_ingestion_gcs_fhv_dag .py", line 84, in upload_to_gcs
    __clean_file(raw_file_name, clean_file_name)
  File "/opt/airflow/dags/data_ingestion_gcs_fhv_dag .py", line 59, in __clean_file
    parse_dates=["pickup_datetime", "dropOff_datetime"],
  File "/home/airflow/.local/lib/python3.6/site-packages/pandas/io/parsers.py", line 688, in read_csv
    return _read(filepath_or_buffer, kwds)
  File "/home/airflow/.local/lib/python3.6/site-packages/pandas/io/parsers.py", line 454, in _read
    parser = TextFileReader(fp_or_buf, **kwds)
  File "/home/airflow/.local/lib/python3.6/site-packages/pandas/io/parsers.py", line 948, in __init__
    self._make_engine(self.engine)
  File "/home/airflow/.local/lib/python3.6/site-packages/pandas/io/parsers.py", line 1180, in _make_engine
    self._engine = CParserWrapper(self.f, **self.options)
  File "/home/airflow/.local/lib/python3.6/site-packages/pandas/io/parsers.py", line 2068, in __init__
    self._validate_parse_dates_presence(self.names)
  File "/home/airflow/.local/lib/python3.6/site-packages/pandas/io/parsers.py", line 1546, in _validate_parse_dates_presence
    f"Missing column provided to 'parse_dates': '{missing_cols}'"
ValueError: Missing column provided to 'parse_dates': 'dropOff_datetime'
[2024-05-18 12:50:20,505] {taskinstance.py:1277} INFO - Marking task as UP_FOR_RETRY. dag_id=ingest_data_bigquery_fhv, task_id=local_to_gcs_task, execution_date=20201102T060000, start_date=20240518T125019, end_date=20240518T125020
[2024-05-18 12:50:20,728] {standard_task_runner.py:92} ERROR - Failed to execute job 5174 for task local_to_gcs_task
Traceback (most recent call last):
  File "/home/airflow/.local/lib/python3.6/site-packages/airflow/task/task_runner/standard_task_runner.py", line 85, in _start_by_fork
    args.func(args, dag=self.dag)
  File "/home/airflow/.local/lib/python3.6/site-packages/airflow/cli/cli_parser.py", line 48, in command
    return func(*args, **kwargs)
  File "/home/airflow/.local/lib/python3.6/site-packages/airflow/utils/cli.py", line 92, in wrapper
    return f(*args, **kwargs)
  File "/home/airflow/.local/lib/python3.6/site-packages/airflow/cli/commands/task_command.py", line 298, in task_run
    _run_task_by_selected_method(args, dag, ti)
  File "/home/airflow/.local/lib/python3.6/site-packages/airflow/cli/commands/task_command.py", line 107, in _run_task_by_selected_method
    _run_raw_task(args, ti)
  File "/home/airflow/.local/lib/python3.6/site-packages/airflow/cli/commands/task_command.py", line 184, in _run_raw_task
    error_file=args.error_file,
  File "/home/airflow/.local/lib/python3.6/site-packages/airflow/utils/session.py", line 70, in wrapper
    return func(*args, session=session, **kwargs)
  File "/home/airflow/.local/lib/python3.6/site-packages/airflow/models/taskinstance.py", line 1329, in _run_raw_task
    self._execute_task_with_callbacks(context)
  File "/home/airflow/.local/lib/python3.6/site-packages/airflow/models/taskinstance.py", line 1455, in _execute_task_with_callbacks
    result = self._execute_task(context, self.task)
  File "/home/airflow/.local/lib/python3.6/site-packages/airflow/models/taskinstance.py", line 1511, in _execute_task
    result = execute_callable(context=context)
  File "/home/airflow/.local/lib/python3.6/site-packages/airflow/operators/python.py", line 174, in execute
    return_value = self.execute_callable()
  File "/home/airflow/.local/lib/python3.6/site-packages/airflow/operators/python.py", line 185, in execute_callable
    return self.python_callable(*self.op_args, **self.op_kwargs)
  File "/opt/airflow/dags/data_ingestion_gcs_fhv_dag .py", line 84, in upload_to_gcs
    __clean_file(raw_file_name, clean_file_name)
  File "/opt/airflow/dags/data_ingestion_gcs_fhv_dag .py", line 59, in __clean_file
    parse_dates=["pickup_datetime", "dropOff_datetime"],
  File "/home/airflow/.local/lib/python3.6/site-packages/pandas/io/parsers.py", line 688, in read_csv
    return _read(filepath_or_buffer, kwds)
  File "/home/airflow/.local/lib/python3.6/site-packages/pandas/io/parsers.py", line 454, in _read
    parser = TextFileReader(fp_or_buf, **kwds)
  File "/home/airflow/.local/lib/python3.6/site-packages/pandas/io/parsers.py", line 948, in __init__
    self._make_engine(self.engine)
  File "/home/airflow/.local/lib/python3.6/site-packages/pandas/io/parsers.py", line 1180, in _make_engine
    self._engine = CParserWrapper(self.f, **self.options)
  File "/home/airflow/.local/lib/python3.6/site-packages/pandas/io/parsers.py", line 2068, in __init__
    self._validate_parse_dates_presence(self.names)
  File "/home/airflow/.local/lib/python3.6/site-packages/pandas/io/parsers.py", line 1546, in _validate_parse_dates_presence
    f"Missing column provided to 'parse_dates': '{missing_cols}'"
ValueError: Missing column provided to 'parse_dates': 'dropOff_datetime'
[2024-05-18 12:50:20,850] {local_task_job.py:154} INFO - Task exited with return code 1
[2024-05-18 12:50:21,202] {local_task_job.py:264} INFO - 0 downstream tasks scheduled from follow-on schedule check
[2024-05-18 13:05:06,173] {taskinstance.py:1032} INFO - Dependencies all met for <TaskInstance: ingest_data_bigquery_fhv.local_to_gcs_task scheduled__2020-11-02T06:00:00+00:00 [queued]>
[2024-05-18 13:05:06,259] {taskinstance.py:1032} INFO - Dependencies all met for <TaskInstance: ingest_data_bigquery_fhv.local_to_gcs_task scheduled__2020-11-02T06:00:00+00:00 [queued]>
[2024-05-18 13:05:06,275] {taskinstance.py:1238} INFO - 
--------------------------------------------------------------------------------
[2024-05-18 13:05:06,276] {taskinstance.py:1239} INFO - Starting attempt 1 of 3
[2024-05-18 13:05:06,276] {taskinstance.py:1240} INFO - 
--------------------------------------------------------------------------------
[2024-05-18 13:05:06,391] {taskinstance.py:1259} INFO - Executing <Task(PythonOperator): local_to_gcs_task> on 2020-11-02 06:00:00+00:00
[2024-05-18 13:05:06,445] {standard_task_runner.py:52} INFO - Started process 8305 to run task
[2024-05-18 13:05:06,481] {standard_task_runner.py:76} INFO - Running: ['***', 'tasks', 'run', 'ingest_data_bigquery_fhv', 'local_to_gcs_task', 'scheduled__2020-11-02T06:00:00+00:00', '--job-id', '5293', '--raw', '--subdir', 'DAGS_FOLDER/data_ingestion_gcs_fhv_dag .py', '--cfg-path', '/tmp/tmp_mg15gze', '--error-file', '/tmp/tmpv88qekcx']
[2024-05-18 13:05:06,546] {standard_task_runner.py:77} INFO - Job 5293: Subtask local_to_gcs_task
[2024-05-18 13:05:06,805] {logging_mixin.py:109} INFO - Running <TaskInstance: ingest_data_bigquery_fhv.local_to_gcs_task scheduled__2020-11-02T06:00:00+00:00 [running]> on host 45b18388e83d
[2024-05-18 13:05:06,942] {warnings.py:99} WARNING - /home/***/.local/lib/python3.6/site-packages/***/utils/context.py:152: AirflowContextDeprecationWarning: Accessing 'execution_date' from the template is deprecated and will be removed in a future version. Please use 'data_interval_start' or 'logical_date' instead.
  warnings.warn(_create_deprecation_warning(key, self._deprecation_replacements[key]))

[2024-05-18 13:05:07,096] {taskinstance.py:1426} INFO - Exporting the following env vars:
AIRFLOW_CTX_DAG_OWNER=***
AIRFLOW_CTX_DAG_ID=ingest_data_bigquery_fhv
AIRFLOW_CTX_TASK_ID=local_to_gcs_task
AIRFLOW_CTX_EXECUTION_DATE=2020-11-02T06:00:00+00:00
AIRFLOW_CTX_DAG_RUN_ID=scheduled__2020-11-02T06:00:00+00:00
[2024-05-18 13:05:32,145] {python.py:175} INFO - Done. Returned value was: None
[2024-05-18 13:05:32,413] {taskinstance.py:1277} INFO - Marking task as SUCCESS. dag_id=ingest_data_bigquery_fhv, task_id=local_to_gcs_task, execution_date=20201102T060000, start_date=20240518T130506, end_date=20240518T130532
[2024-05-18 13:05:32,696] {local_task_job.py:212} WARNING - State of this instance has been externally set to success. Terminating instance.
[2024-05-18 13:05:32,714] {process_utils.py:124} INFO - Sending Signals.SIGTERM to group 8305. PIDs of all processes in the group: [8305]
[2024-05-18 13:05:32,720] {process_utils.py:75} INFO - Sending the signal Signals.SIGTERM to group 8305
[2024-05-18 13:05:32,976] {process_utils.py:70} INFO - Process psutil.Process(pid=8305, status='terminated', exitcode=0, started='13:05:05') (8305) terminated with exit code 0
[2024-05-18 13:15:12,868] {taskinstance.py:1032} INFO - Dependencies all met for <TaskInstance: ingest_data_bigquery_fhv.local_to_gcs_task scheduled__2020-11-02T06:00:00+00:00 [queued]>
[2024-05-18 13:15:12,947] {taskinstance.py:1032} INFO - Dependencies all met for <TaskInstance: ingest_data_bigquery_fhv.local_to_gcs_task scheduled__2020-11-02T06:00:00+00:00 [queued]>
[2024-05-18 13:15:12,951] {taskinstance.py:1238} INFO - 
--------------------------------------------------------------------------------
[2024-05-18 13:15:12,951] {taskinstance.py:1239} INFO - Starting attempt 1 of 3
[2024-05-18 13:15:12,952] {taskinstance.py:1240} INFO - 
--------------------------------------------------------------------------------
[2024-05-18 13:15:13,041] {taskinstance.py:1259} INFO - Executing <Task(PythonOperator): local_to_gcs_task> on 2020-11-02 06:00:00+00:00
[2024-05-18 13:15:13,110] {standard_task_runner.py:76} INFO - Running: ['***', 'tasks', 'run', 'ingest_data_bigquery_fhv', 'local_to_gcs_task', 'scheduled__2020-11-02T06:00:00+00:00', '--job-id', '5384', '--raw', '--subdir', 'DAGS_FOLDER/data_ingestion_gcs_fhv_dag .py', '--cfg-path', '/tmp/tmpzbr6jcgb', '--error-file', '/tmp/tmplk1f7xe6']
[2024-05-18 13:15:13,118] {standard_task_runner.py:77} INFO - Job 5384: Subtask local_to_gcs_task
[2024-05-18 13:15:13,089] {standard_task_runner.py:52} INFO - Started process 9271 to run task
[2024-05-18 13:15:13,366] {logging_mixin.py:109} INFO - Running <TaskInstance: ingest_data_bigquery_fhv.local_to_gcs_task scheduled__2020-11-02T06:00:00+00:00 [running]> on host 45b18388e83d
[2024-05-18 13:15:13,526] {warnings.py:99} WARNING - /home/***/.local/lib/python3.6/site-packages/***/utils/context.py:152: AirflowContextDeprecationWarning: Accessing 'execution_date' from the template is deprecated and will be removed in a future version. Please use 'data_interval_start' or 'logical_date' instead.
  warnings.warn(_create_deprecation_warning(key, self._deprecation_replacements[key]))

[2024-05-18 13:15:13,608] {taskinstance.py:1426} INFO - Exporting the following env vars:
AIRFLOW_CTX_DAG_OWNER=***
AIRFLOW_CTX_DAG_ID=ingest_data_bigquery_fhv
AIRFLOW_CTX_TASK_ID=local_to_gcs_task
AIRFLOW_CTX_EXECUTION_DATE=2020-11-02T06:00:00+00:00
AIRFLOW_CTX_DAG_RUN_ID=scheduled__2020-11-02T06:00:00+00:00
[2024-05-18 13:15:33,623] {python.py:175} INFO - Done. Returned value was: None
[2024-05-18 13:15:33,641] {taskinstance.py:1277} INFO - Marking task as SUCCESS. dag_id=ingest_data_bigquery_fhv, task_id=local_to_gcs_task, execution_date=20201102T060000, start_date=20240518T131512, end_date=20240518T131533
[2024-05-18 13:15:33,727] {local_task_job.py:212} WARNING - State of this instance has been externally set to success. Terminating instance.
[2024-05-18 13:15:33,759] {process_utils.py:124} INFO - Sending Signals.SIGTERM to group 9271. PIDs of all processes in the group: [9271]
[2024-05-18 13:15:33,759] {process_utils.py:75} INFO - Sending the signal Signals.SIGTERM to group 9271
[2024-05-18 13:15:33,878] {process_utils.py:70} INFO - Process psutil.Process(pid=9271, status='terminated', exitcode=0, started='13:15:12') (9271) terminated with exit code 0
