[2024-03-29 07:29:52,294] {taskinstance.py:1032} INFO - Dependencies all met for <TaskInstance: ingest_data_bigquery.bigquery_external_table_task scheduled__2021-01-02T06:00:00+00:00 [queued]>
[2024-03-29 07:29:52,305] {taskinstance.py:1032} INFO - Dependencies all met for <TaskInstance: ingest_data_bigquery.bigquery_external_table_task scheduled__2021-01-02T06:00:00+00:00 [queued]>
[2024-03-29 07:29:52,305] {taskinstance.py:1238} INFO - 
--------------------------------------------------------------------------------
[2024-03-29 07:29:52,306] {taskinstance.py:1239} INFO - Starting attempt 2 of 4
[2024-03-29 07:29:52,306] {taskinstance.py:1240} INFO - 
--------------------------------------------------------------------------------
[2024-03-29 07:29:52,317] {taskinstance.py:1259} INFO - Executing <Task(BigQueryCreateExternalTableOperator): bigquery_external_table_task> on 2021-01-02 06:00:00+00:00
[2024-03-29 07:29:52,324] {standard_task_runner.py:52} INFO - Started process 867 to run task
[2024-03-29 07:29:52,329] {standard_task_runner.py:76} INFO - Running: ['***', 'tasks', 'run', 'ingest_data_bigquery', 'bigquery_external_table_task', 'scheduled__2021-01-02T06:00:00+00:00', '--job-id', '1485', '--raw', '--subdir', 'DAGS_FOLDER/data_ingestion_gcs_dag.py', '--cfg-path', '/tmp/tmp07oontr9', '--error-file', '/tmp/tmp2xo7rkz1']
[2024-03-29 07:29:52,333] {standard_task_runner.py:77} INFO - Job 1485: Subtask bigquery_external_table_task
[2024-03-29 07:29:52,392] {logging_mixin.py:109} INFO - Running <TaskInstance: ingest_data_bigquery.bigquery_external_table_task scheduled__2021-01-02T06:00:00+00:00 [running]> on host b8c510ab3cfc
[2024-03-29 07:29:52,461] {taskinstance.py:1426} INFO - Exporting the following env vars:
AIRFLOW_CTX_DAG_OWNER=***
AIRFLOW_CTX_DAG_ID=ingest_data_bigquery
AIRFLOW_CTX_TASK_ID=bigquery_external_table_task
AIRFLOW_CTX_EXECUTION_DATE=2021-01-02T06:00:00+00:00
AIRFLOW_CTX_DAG_RUN_ID=scheduled__2021-01-02T06:00:00+00:00
[2024-03-29 07:29:52,465] {crypto.py:82} WARNING - empty cryptography key - values will not be stored encrypted.
[2024-03-29 07:29:52,473] {taskinstance.py:1700} ERROR - Task failed with exception
Traceback (most recent call last):
  File "/home/airflow/.local/lib/python3.6/site-packages/airflow/models/taskinstance.py", line 1329, in _run_raw_task
    self._execute_task_with_callbacks(context)
  File "/home/airflow/.local/lib/python3.6/site-packages/airflow/models/taskinstance.py", line 1455, in _execute_task_with_callbacks
    result = self._execute_task(context, self.task)
  File "/home/airflow/.local/lib/python3.6/site-packages/airflow/models/taskinstance.py", line 1511, in _execute_task
    result = execute_callable(context=context)
  File "/home/airflow/.local/lib/python3.6/site-packages/airflow/providers/google/cloud/operators/bigquery.py", line 1196, in execute
    table_resource=self.table_resource,
  File "/home/airflow/.local/lib/python3.6/site-packages/airflow/providers/google/common/hooks/base_google.py", line 430, in inner_wrapper
    return func(self, *args, **kwargs)
  File "/home/airflow/.local/lib/python3.6/site-packages/airflow/providers/google/cloud/hooks/bigquery.py", line 404, in create_empty_table
    table_id=table_id,
  File "/home/airflow/.local/lib/python3.6/site-packages/airflow/providers/google/cloud/hooks/bigquery.py", line 172, in _resolve_table_reference
    TableReference.from_api_repr(table_resource["tableReference"])
  File "/home/airflow/.local/lib/python3.6/site-packages/google/cloud/bigquery/table.py", line 277, in from_api_repr
    return cls(DatasetReference(project, dataset_id), table_id)
  File "/home/airflow/.local/lib/python3.6/site-packages/google/cloud/bigquery/dataset.py", line 265, in __init__
    raise ValueError("Pass a string for dataset_id")
ValueError: Pass a string for dataset_id
[2024-03-29 07:29:52,490] {taskinstance.py:1277} INFO - Marking task as UP_FOR_RETRY. dag_id=ingest_data_bigquery, task_id=bigquery_external_table_task, execution_date=20210102T060000, start_date=20240329T072952, end_date=20240329T072952
[2024-03-29 07:29:52,502] {standard_task_runner.py:92} ERROR - Failed to execute job 1485 for task bigquery_external_table_task
Traceback (most recent call last):
  File "/home/airflow/.local/lib/python3.6/site-packages/airflow/task/task_runner/standard_task_runner.py", line 85, in _start_by_fork
    args.func(args, dag=self.dag)
  File "/home/airflow/.local/lib/python3.6/site-packages/airflow/cli/cli_parser.py", line 48, in command
    return func(*args, **kwargs)
  File "/home/airflow/.local/lib/python3.6/site-packages/airflow/utils/cli.py", line 92, in wrapper
    return f(*args, **kwargs)
  File "/home/airflow/.local/lib/python3.6/site-packages/airflow/cli/commands/task_command.py", line 298, in task_run
    _run_task_by_selected_method(args, dag, ti)
  File "/home/airflow/.local/lib/python3.6/site-packages/airflow/cli/commands/task_command.py", line 107, in _run_task_by_selected_method
    _run_raw_task(args, ti)
  File "/home/airflow/.local/lib/python3.6/site-packages/airflow/cli/commands/task_command.py", line 184, in _run_raw_task
    error_file=args.error_file,
  File "/home/airflow/.local/lib/python3.6/site-packages/airflow/utils/session.py", line 70, in wrapper
    return func(*args, session=session, **kwargs)
  File "/home/airflow/.local/lib/python3.6/site-packages/airflow/models/taskinstance.py", line 1329, in _run_raw_task
    self._execute_task_with_callbacks(context)
  File "/home/airflow/.local/lib/python3.6/site-packages/airflow/models/taskinstance.py", line 1455, in _execute_task_with_callbacks
    result = self._execute_task(context, self.task)
  File "/home/airflow/.local/lib/python3.6/site-packages/airflow/models/taskinstance.py", line 1511, in _execute_task
    result = execute_callable(context=context)
  File "/home/airflow/.local/lib/python3.6/site-packages/airflow/providers/google/cloud/operators/bigquery.py", line 1196, in execute
    table_resource=self.table_resource,
  File "/home/airflow/.local/lib/python3.6/site-packages/airflow/providers/google/common/hooks/base_google.py", line 430, in inner_wrapper
    return func(self, *args, **kwargs)
  File "/home/airflow/.local/lib/python3.6/site-packages/airflow/providers/google/cloud/hooks/bigquery.py", line 404, in create_empty_table
    table_id=table_id,
  File "/home/airflow/.local/lib/python3.6/site-packages/airflow/providers/google/cloud/hooks/bigquery.py", line 172, in _resolve_table_reference
    TableReference.from_api_repr(table_resource["tableReference"])
  File "/home/airflow/.local/lib/python3.6/site-packages/google/cloud/bigquery/table.py", line 277, in from_api_repr
    return cls(DatasetReference(project, dataset_id), table_id)
  File "/home/airflow/.local/lib/python3.6/site-packages/google/cloud/bigquery/dataset.py", line 265, in __init__
    raise ValueError("Pass a string for dataset_id")
ValueError: Pass a string for dataset_id
[2024-03-29 07:29:52,548] {local_task_job.py:154} INFO - Task exited with return code 1
[2024-03-29 07:29:52,667] {local_task_job.py:264} INFO - 0 downstream tasks scheduled from follow-on schedule check
[2024-03-29 07:36:03,043] {taskinstance.py:1032} INFO - Dependencies all met for <TaskInstance: ingest_data_bigquery.bigquery_external_table_task scheduled__2021-01-02T06:00:00+00:00 [queued]>
[2024-03-29 07:36:03,060] {taskinstance.py:1032} INFO - Dependencies all met for <TaskInstance: ingest_data_bigquery.bigquery_external_table_task scheduled__2021-01-02T06:00:00+00:00 [queued]>
[2024-03-29 07:36:03,060] {taskinstance.py:1238} INFO - 
--------------------------------------------------------------------------------
[2024-03-29 07:36:03,060] {taskinstance.py:1239} INFO - Starting attempt 2 of 4
[2024-03-29 07:36:03,060] {taskinstance.py:1240} INFO - 
--------------------------------------------------------------------------------
[2024-03-29 07:36:03,076] {taskinstance.py:1259} INFO - Executing <Task(BigQueryCreateExternalTableOperator): bigquery_external_table_task> on 2021-01-02 06:00:00+00:00
[2024-03-29 07:36:03,082] {standard_task_runner.py:52} INFO - Started process 1368 to run task
[2024-03-29 07:36:03,089] {standard_task_runner.py:76} INFO - Running: ['***', 'tasks', 'run', 'ingest_data_bigquery', 'bigquery_external_table_task', 'scheduled__2021-01-02T06:00:00+00:00', '--job-id', '1546', '--raw', '--subdir', 'DAGS_FOLDER/data_ingestion_gcs_dag.py', '--cfg-path', '/tmp/tmp5zbrw34r', '--error-file', '/tmp/tmp2ec7ucip']
[2024-03-29 07:36:03,095] {standard_task_runner.py:77} INFO - Job 1546: Subtask bigquery_external_table_task
[2024-03-29 07:36:03,182] {logging_mixin.py:109} INFO - Running <TaskInstance: ingest_data_bigquery.bigquery_external_table_task scheduled__2021-01-02T06:00:00+00:00 [running]> on host b8c510ab3cfc
[2024-03-29 07:36:03,253] {taskinstance.py:1426} INFO - Exporting the following env vars:
AIRFLOW_CTX_DAG_OWNER=***
AIRFLOW_CTX_DAG_ID=ingest_data_bigquery
AIRFLOW_CTX_TASK_ID=bigquery_external_table_task
AIRFLOW_CTX_EXECUTION_DATE=2021-01-02T06:00:00+00:00
AIRFLOW_CTX_DAG_RUN_ID=scheduled__2021-01-02T06:00:00+00:00
[2024-03-29 07:36:03,258] {crypto.py:82} WARNING - empty cryptography key - values will not be stored encrypted.
[2024-03-29 07:36:03,270] {taskinstance.py:1700} ERROR - Task failed with exception
Traceback (most recent call last):
  File "/home/airflow/.local/lib/python3.6/site-packages/airflow/models/taskinstance.py", line 1329, in _run_raw_task
    self._execute_task_with_callbacks(context)
  File "/home/airflow/.local/lib/python3.6/site-packages/airflow/models/taskinstance.py", line 1455, in _execute_task_with_callbacks
    result = self._execute_task(context, self.task)
  File "/home/airflow/.local/lib/python3.6/site-packages/airflow/models/taskinstance.py", line 1511, in _execute_task
    result = execute_callable(context=context)
  File "/home/airflow/.local/lib/python3.6/site-packages/airflow/providers/google/cloud/operators/bigquery.py", line 1196, in execute
    table_resource=self.table_resource,
  File "/home/airflow/.local/lib/python3.6/site-packages/airflow/providers/google/common/hooks/base_google.py", line 430, in inner_wrapper
    return func(self, *args, **kwargs)
  File "/home/airflow/.local/lib/python3.6/site-packages/airflow/providers/google/cloud/hooks/bigquery.py", line 404, in create_empty_table
    table_id=table_id,
  File "/home/airflow/.local/lib/python3.6/site-packages/airflow/providers/google/cloud/hooks/bigquery.py", line 172, in _resolve_table_reference
    TableReference.from_api_repr(table_resource["tableReference"])
  File "/home/airflow/.local/lib/python3.6/site-packages/google/cloud/bigquery/table.py", line 277, in from_api_repr
    return cls(DatasetReference(project, dataset_id), table_id)
  File "/home/airflow/.local/lib/python3.6/site-packages/google/cloud/bigquery/dataset.py", line 265, in __init__
    raise ValueError("Pass a string for dataset_id")
ValueError: Pass a string for dataset_id
[2024-03-29 07:36:03,294] {taskinstance.py:1277} INFO - Marking task as UP_FOR_RETRY. dag_id=ingest_data_bigquery, task_id=bigquery_external_table_task, execution_date=20210102T060000, start_date=20240329T073603, end_date=20240329T073603
[2024-03-29 07:36:03,308] {standard_task_runner.py:92} ERROR - Failed to execute job 1546 for task bigquery_external_table_task
Traceback (most recent call last):
  File "/home/airflow/.local/lib/python3.6/site-packages/airflow/task/task_runner/standard_task_runner.py", line 85, in _start_by_fork
    args.func(args, dag=self.dag)
  File "/home/airflow/.local/lib/python3.6/site-packages/airflow/cli/cli_parser.py", line 48, in command
    return func(*args, **kwargs)
  File "/home/airflow/.local/lib/python3.6/site-packages/airflow/utils/cli.py", line 92, in wrapper
    return f(*args, **kwargs)
  File "/home/airflow/.local/lib/python3.6/site-packages/airflow/cli/commands/task_command.py", line 298, in task_run
    _run_task_by_selected_method(args, dag, ti)
  File "/home/airflow/.local/lib/python3.6/site-packages/airflow/cli/commands/task_command.py", line 107, in _run_task_by_selected_method
    _run_raw_task(args, ti)
  File "/home/airflow/.local/lib/python3.6/site-packages/airflow/cli/commands/task_command.py", line 184, in _run_raw_task
    error_file=args.error_file,
  File "/home/airflow/.local/lib/python3.6/site-packages/airflow/utils/session.py", line 70, in wrapper
    return func(*args, session=session, **kwargs)
  File "/home/airflow/.local/lib/python3.6/site-packages/airflow/models/taskinstance.py", line 1329, in _run_raw_task
    self._execute_task_with_callbacks(context)
  File "/home/airflow/.local/lib/python3.6/site-packages/airflow/models/taskinstance.py", line 1455, in _execute_task_with_callbacks
    result = self._execute_task(context, self.task)
  File "/home/airflow/.local/lib/python3.6/site-packages/airflow/models/taskinstance.py", line 1511, in _execute_task
    result = execute_callable(context=context)
  File "/home/airflow/.local/lib/python3.6/site-packages/airflow/providers/google/cloud/operators/bigquery.py", line 1196, in execute
    table_resource=self.table_resource,
  File "/home/airflow/.local/lib/python3.6/site-packages/airflow/providers/google/common/hooks/base_google.py", line 430, in inner_wrapper
    return func(self, *args, **kwargs)
  File "/home/airflow/.local/lib/python3.6/site-packages/airflow/providers/google/cloud/hooks/bigquery.py", line 404, in create_empty_table
    table_id=table_id,
  File "/home/airflow/.local/lib/python3.6/site-packages/airflow/providers/google/cloud/hooks/bigquery.py", line 172, in _resolve_table_reference
    TableReference.from_api_repr(table_resource["tableReference"])
  File "/home/airflow/.local/lib/python3.6/site-packages/google/cloud/bigquery/table.py", line 277, in from_api_repr
    return cls(DatasetReference(project, dataset_id), table_id)
  File "/home/airflow/.local/lib/python3.6/site-packages/google/cloud/bigquery/dataset.py", line 265, in __init__
    raise ValueError("Pass a string for dataset_id")
ValueError: Pass a string for dataset_id
[2024-03-29 07:36:03,351] {local_task_job.py:154} INFO - Task exited with return code 1
[2024-03-29 07:36:03,387] {local_task_job.py:264} INFO - 0 downstream tasks scheduled from follow-on schedule check
[2024-03-29 07:42:49,335] {taskinstance.py:1032} INFO - Dependencies all met for <TaskInstance: ingest_data_bigquery.bigquery_external_table_task scheduled__2021-01-02T06:00:00+00:00 [queued]>
[2024-03-29 07:42:49,354] {taskinstance.py:1032} INFO - Dependencies all met for <TaskInstance: ingest_data_bigquery.bigquery_external_table_task scheduled__2021-01-02T06:00:00+00:00 [queued]>
[2024-03-29 07:42:49,355] {taskinstance.py:1238} INFO - 
--------------------------------------------------------------------------------
[2024-03-29 07:42:49,355] {taskinstance.py:1239} INFO - Starting attempt 2 of 4
[2024-03-29 07:42:49,355] {taskinstance.py:1240} INFO - 
--------------------------------------------------------------------------------
[2024-03-29 07:42:49,371] {taskinstance.py:1259} INFO - Executing <Task(BigQueryCreateExternalTableOperator): bigquery_external_table_task> on 2021-01-02 06:00:00+00:00
[2024-03-29 07:42:49,381] {standard_task_runner.py:52} INFO - Started process 1893 to run task
[2024-03-29 07:42:49,388] {standard_task_runner.py:76} INFO - Running: ['***', 'tasks', 'run', 'ingest_data_bigquery', 'bigquery_external_table_task', 'scheduled__2021-01-02T06:00:00+00:00', '--job-id', '1607', '--raw', '--subdir', 'DAGS_FOLDER/data_ingestion_gcs_dag.py', '--cfg-path', '/tmp/tmpyrtogkwj', '--error-file', '/tmp/tmpbras41zn']
[2024-03-29 07:42:49,394] {standard_task_runner.py:77} INFO - Job 1607: Subtask bigquery_external_table_task
[2024-03-29 07:42:49,474] {logging_mixin.py:109} INFO - Running <TaskInstance: ingest_data_bigquery.bigquery_external_table_task scheduled__2021-01-02T06:00:00+00:00 [running]> on host b8c510ab3cfc
[2024-03-29 07:42:49,547] {taskinstance.py:1426} INFO - Exporting the following env vars:
AIRFLOW_CTX_DAG_OWNER=***
AIRFLOW_CTX_DAG_ID=ingest_data_bigquery
AIRFLOW_CTX_TASK_ID=bigquery_external_table_task
AIRFLOW_CTX_EXECUTION_DATE=2021-01-02T06:00:00+00:00
AIRFLOW_CTX_DAG_RUN_ID=scheduled__2021-01-02T06:00:00+00:00
[2024-03-29 07:42:49,552] {crypto.py:82} WARNING - empty cryptography key - values will not be stored encrypted.
[2024-03-29 07:42:49,954] {taskinstance.py:1700} ERROR - Task failed with exception
Traceback (most recent call last):
  File "/home/airflow/.local/lib/python3.6/site-packages/airflow/models/taskinstance.py", line 1329, in _run_raw_task
    self._execute_task_with_callbacks(context)
  File "/home/airflow/.local/lib/python3.6/site-packages/airflow/models/taskinstance.py", line 1455, in _execute_task_with_callbacks
    result = self._execute_task(context, self.task)
  File "/home/airflow/.local/lib/python3.6/site-packages/airflow/models/taskinstance.py", line 1511, in _execute_task
    result = execute_callable(context=context)
  File "/home/airflow/.local/lib/python3.6/site-packages/airflow/providers/google/cloud/operators/bigquery.py", line 1196, in execute
    table_resource=self.table_resource,
  File "/home/airflow/.local/lib/python3.6/site-packages/airflow/providers/google/common/hooks/base_google.py", line 430, in inner_wrapper
    return func(self, *args, **kwargs)
  File "/home/airflow/.local/lib/python3.6/site-packages/airflow/providers/google/cloud/hooks/bigquery.py", line 408, in create_empty_table
    table=table, exists_ok=exists_ok, retry=retry
  File "/home/airflow/.local/lib/python3.6/site-packages/google/cloud/bigquery/client.py", line 755, in create_table
    timeout=timeout,
  File "/home/airflow/.local/lib/python3.6/site-packages/google/cloud/bigquery/client.py", line 782, in _call_api
    return call()
  File "/home/airflow/.local/lib/python3.6/site-packages/google/api_core/retry.py", line 291, in retry_wrapped_func
    on_error=on_error,
  File "/home/airflow/.local/lib/python3.6/site-packages/google/api_core/retry.py", line 189, in retry_target
    return target()
  File "/home/airflow/.local/lib/python3.6/site-packages/google/cloud/_http.py", line 484, in api_request
    raise exceptions.from_http_response(response)
google.api_core.exceptions.BadRequest: 400 POST https://bigquery.googleapis.com/bigquery/v2/projects/ny-rides-peter-415106/datasets/test_dataset/tables?prettyPrint=false: Error while reading table: external_table, error message: Failed to expand table external_table with file pattern gs://test_bucket_415106/yellowtaxi_tripdata/{ execution_date.strftime('%Y-%m') }.parquet: matched no files. File: gs://test_bucket_415106/yellowtaxi_tripdata/{ execution_date.strftime('%Y-%m') }.parquet
[2024-03-29 07:42:49,974] {taskinstance.py:1277} INFO - Marking task as UP_FOR_RETRY. dag_id=ingest_data_bigquery, task_id=bigquery_external_table_task, execution_date=20210102T060000, start_date=20240329T074249, end_date=20240329T074249
[2024-03-29 07:42:49,993] {standard_task_runner.py:92} ERROR - Failed to execute job 1607 for task bigquery_external_table_task
Traceback (most recent call last):
  File "/home/airflow/.local/lib/python3.6/site-packages/airflow/task/task_runner/standard_task_runner.py", line 85, in _start_by_fork
    args.func(args, dag=self.dag)
  File "/home/airflow/.local/lib/python3.6/site-packages/airflow/cli/cli_parser.py", line 48, in command
    return func(*args, **kwargs)
  File "/home/airflow/.local/lib/python3.6/site-packages/airflow/utils/cli.py", line 92, in wrapper
    return f(*args, **kwargs)
  File "/home/airflow/.local/lib/python3.6/site-packages/airflow/cli/commands/task_command.py", line 298, in task_run
    _run_task_by_selected_method(args, dag, ti)
  File "/home/airflow/.local/lib/python3.6/site-packages/airflow/cli/commands/task_command.py", line 107, in _run_task_by_selected_method
    _run_raw_task(args, ti)
  File "/home/airflow/.local/lib/python3.6/site-packages/airflow/cli/commands/task_command.py", line 184, in _run_raw_task
    error_file=args.error_file,
  File "/home/airflow/.local/lib/python3.6/site-packages/airflow/utils/session.py", line 70, in wrapper
    return func(*args, session=session, **kwargs)
  File "/home/airflow/.local/lib/python3.6/site-packages/airflow/models/taskinstance.py", line 1329, in _run_raw_task
    self._execute_task_with_callbacks(context)
  File "/home/airflow/.local/lib/python3.6/site-packages/airflow/models/taskinstance.py", line 1455, in _execute_task_with_callbacks
    result = self._execute_task(context, self.task)
  File "/home/airflow/.local/lib/python3.6/site-packages/airflow/models/taskinstance.py", line 1511, in _execute_task
    result = execute_callable(context=context)
  File "/home/airflow/.local/lib/python3.6/site-packages/airflow/providers/google/cloud/operators/bigquery.py", line 1196, in execute
    table_resource=self.table_resource,
  File "/home/airflow/.local/lib/python3.6/site-packages/airflow/providers/google/common/hooks/base_google.py", line 430, in inner_wrapper
    return func(self, *args, **kwargs)
  File "/home/airflow/.local/lib/python3.6/site-packages/airflow/providers/google/cloud/hooks/bigquery.py", line 408, in create_empty_table
    table=table, exists_ok=exists_ok, retry=retry
  File "/home/airflow/.local/lib/python3.6/site-packages/google/cloud/bigquery/client.py", line 755, in create_table
    timeout=timeout,
  File "/home/airflow/.local/lib/python3.6/site-packages/google/cloud/bigquery/client.py", line 782, in _call_api
    return call()
  File "/home/airflow/.local/lib/python3.6/site-packages/google/api_core/retry.py", line 291, in retry_wrapped_func
    on_error=on_error,
  File "/home/airflow/.local/lib/python3.6/site-packages/google/api_core/retry.py", line 189, in retry_target
    return target()
  File "/home/airflow/.local/lib/python3.6/site-packages/google/cloud/_http.py", line 484, in api_request
    raise exceptions.from_http_response(response)
google.api_core.exceptions.BadRequest: 400 POST https://bigquery.googleapis.com/bigquery/v2/projects/ny-rides-peter-415106/datasets/test_dataset/tables?prettyPrint=false: Error while reading table: external_table, error message: Failed to expand table external_table with file pattern gs://test_bucket_415106/yellowtaxi_tripdata/{ execution_date.strftime('%Y-%m') }.parquet: matched no files. File: gs://test_bucket_415106/yellowtaxi_tripdata/{ execution_date.strftime('%Y-%m') }.parquet
[2024-03-29 07:42:50,012] {local_task_job.py:154} INFO - Task exited with return code 1
[2024-03-29 07:42:50,059] {local_task_job.py:264} INFO - 0 downstream tasks scheduled from follow-on schedule check
[2024-03-29 08:16:19,563] {taskinstance.py:1032} INFO - Dependencies all met for <TaskInstance: ingest_data_bigquery.bigquery_external_table_task scheduled__2021-01-02T06:00:00+00:00 [queued]>
[2024-03-29 08:16:19,580] {taskinstance.py:1032} INFO - Dependencies all met for <TaskInstance: ingest_data_bigquery.bigquery_external_table_task scheduled__2021-01-02T06:00:00+00:00 [queued]>
[2024-03-29 08:16:19,580] {taskinstance.py:1238} INFO - 
--------------------------------------------------------------------------------
[2024-03-29 08:16:19,580] {taskinstance.py:1239} INFO - Starting attempt 2 of 4
[2024-03-29 08:16:19,580] {taskinstance.py:1240} INFO - 
--------------------------------------------------------------------------------
[2024-03-29 08:16:19,597] {taskinstance.py:1259} INFO - Executing <Task(BigQueryCreateExternalTableOperator): bigquery_external_table_task> on 2021-01-02 06:00:00+00:00
[2024-03-29 08:16:19,611] {standard_task_runner.py:76} INFO - Running: ['***', 'tasks', 'run', 'ingest_data_bigquery', 'bigquery_external_table_task', 'scheduled__2021-01-02T06:00:00+00:00', '--job-id', '1716', '--raw', '--subdir', 'DAGS_FOLDER/data_ingestion_gcs_dag.py', '--cfg-path', '/tmp/tmp051nnvlr', '--error-file', '/tmp/tmpeoo6f7p_']
[2024-03-29 08:16:19,622] {standard_task_runner.py:77} INFO - Job 1716: Subtask bigquery_external_table_task
[2024-03-29 08:16:19,605] {standard_task_runner.py:52} INFO - Started process 869 to run task
[2024-03-29 08:16:19,698] {logging_mixin.py:109} INFO - Running <TaskInstance: ingest_data_bigquery.bigquery_external_table_task scheduled__2021-01-02T06:00:00+00:00 [running]> on host b5e5a5778b83
[2024-03-29 08:16:19,737] {warnings.py:99} WARNING - /home/***/.local/lib/python3.6/site-packages/***/utils/context.py:152: AirflowContextDeprecationWarning: Accessing 'execution_date' from the template is deprecated and will be removed in a future version. Please use 'data_interval_start' or 'logical_date' instead.
  warnings.warn(_create_deprecation_warning(key, self._deprecation_replacements[key]))

[2024-03-29 08:16:19,763] {taskinstance.py:1426} INFO - Exporting the following env vars:
AIRFLOW_CTX_DAG_OWNER=***
AIRFLOW_CTX_DAG_ID=ingest_data_bigquery
AIRFLOW_CTX_TASK_ID=bigquery_external_table_task
AIRFLOW_CTX_EXECUTION_DATE=2021-01-02T06:00:00+00:00
AIRFLOW_CTX_DAG_RUN_ID=scheduled__2021-01-02T06:00:00+00:00
[2024-03-29 08:16:19,765] {crypto.py:82} WARNING - empty cryptography key - values will not be stored encrypted.
[2024-03-29 08:16:19,773] {warnings.py:99} WARNING - /home/***/.local/lib/python3.6/site-packages/***/providers/google/cloud/hooks/bigquery.py:637: DeprecationWarning: This method is deprecated. Please use `BigQueryHook.create_empty_table` method with passing the `table_resource` object. This gives more flexibility than this method.
  DeprecationWarning,

[2024-03-29 08:16:19,774] {bigquery.py:700} INFO - Creating external table: test_dataset.external_table
[2024-03-29 08:16:19,936] {taskinstance.py:1700} ERROR - Task failed with exception
Traceback (most recent call last):
  File "/home/airflow/.local/lib/python3.6/site-packages/airflow/models/taskinstance.py", line 1329, in _run_raw_task
    self._execute_task_with_callbacks(context)
  File "/home/airflow/.local/lib/python3.6/site-packages/airflow/models/taskinstance.py", line 1455, in _execute_task_with_callbacks
    result = self._execute_task(context, self.task)
  File "/home/airflow/.local/lib/python3.6/site-packages/airflow/models/taskinstance.py", line 1511, in _execute_task
    result = execute_callable(context=context)
  File "/home/airflow/.local/lib/python3.6/site-packages/airflow/providers/google/cloud/operators/bigquery.py", line 1226, in execute
    encryption_configuration=self.encryption_configuration,
  File "/home/airflow/.local/lib/python3.6/site-packages/airflow/providers/google/common/hooks/base_google.py", line 430, in inner_wrapper
    return func(self, *args, **kwargs)
  File "/home/airflow/.local/lib/python3.6/site-packages/airflow/providers/google/cloud/hooks/bigquery.py", line 702, in create_external_table
    table_resource=table.to_api_repr(), project_id=project_id, location=location, exists_ok=True
  File "/home/airflow/.local/lib/python3.6/site-packages/airflow/providers/google/common/hooks/base_google.py", line 430, in inner_wrapper
    return func(self, *args, **kwargs)
  File "/home/airflow/.local/lib/python3.6/site-packages/airflow/providers/google/cloud/hooks/bigquery.py", line 408, in create_empty_table
    table=table, exists_ok=exists_ok, retry=retry
  File "/home/airflow/.local/lib/python3.6/site-packages/google/cloud/bigquery/client.py", line 755, in create_table
    timeout=timeout,
  File "/home/airflow/.local/lib/python3.6/site-packages/google/cloud/bigquery/client.py", line 782, in _call_api
    return call()
  File "/home/airflow/.local/lib/python3.6/site-packages/google/api_core/retry.py", line 291, in retry_wrapped_func
    on_error=on_error,
  File "/home/airflow/.local/lib/python3.6/site-packages/google/api_core/retry.py", line 189, in retry_target
    return target()
  File "/home/airflow/.local/lib/python3.6/site-packages/google/cloud/_http.py", line 484, in api_request
    raise exceptions.from_http_response(response)
google.api_core.exceptions.BadRequest: 400 POST https://bigquery.googleapis.com/bigquery/v2/projects/ny-rides-peter-415106/datasets/test_dataset/tables?prettyPrint=false: When defining a table with an ExternalDataConfiguration, a schema must be present on either the Table or the ExternalDataConfiguration. If the schema is present on both, the schemas must be the same.
[2024-03-29 08:16:19,955] {taskinstance.py:1277} INFO - Marking task as UP_FOR_RETRY. dag_id=ingest_data_bigquery, task_id=bigquery_external_table_task, execution_date=20210102T060000, start_date=20240329T081619, end_date=20240329T081619
[2024-03-29 08:16:19,968] {standard_task_runner.py:92} ERROR - Failed to execute job 1716 for task bigquery_external_table_task
Traceback (most recent call last):
  File "/home/airflow/.local/lib/python3.6/site-packages/airflow/task/task_runner/standard_task_runner.py", line 85, in _start_by_fork
    args.func(args, dag=self.dag)
  File "/home/airflow/.local/lib/python3.6/site-packages/airflow/cli/cli_parser.py", line 48, in command
    return func(*args, **kwargs)
  File "/home/airflow/.local/lib/python3.6/site-packages/airflow/utils/cli.py", line 92, in wrapper
    return f(*args, **kwargs)
  File "/home/airflow/.local/lib/python3.6/site-packages/airflow/cli/commands/task_command.py", line 298, in task_run
    _run_task_by_selected_method(args, dag, ti)
  File "/home/airflow/.local/lib/python3.6/site-packages/airflow/cli/commands/task_command.py", line 107, in _run_task_by_selected_method
    _run_raw_task(args, ti)
  File "/home/airflow/.local/lib/python3.6/site-packages/airflow/cli/commands/task_command.py", line 184, in _run_raw_task
    error_file=args.error_file,
  File "/home/airflow/.local/lib/python3.6/site-packages/airflow/utils/session.py", line 70, in wrapper
    return func(*args, session=session, **kwargs)
  File "/home/airflow/.local/lib/python3.6/site-packages/airflow/models/taskinstance.py", line 1329, in _run_raw_task
    self._execute_task_with_callbacks(context)
  File "/home/airflow/.local/lib/python3.6/site-packages/airflow/models/taskinstance.py", line 1455, in _execute_task_with_callbacks
    result = self._execute_task(context, self.task)
  File "/home/airflow/.local/lib/python3.6/site-packages/airflow/models/taskinstance.py", line 1511, in _execute_task
    result = execute_callable(context=context)
  File "/home/airflow/.local/lib/python3.6/site-packages/airflow/providers/google/cloud/operators/bigquery.py", line 1226, in execute
    encryption_configuration=self.encryption_configuration,
  File "/home/airflow/.local/lib/python3.6/site-packages/airflow/providers/google/common/hooks/base_google.py", line 430, in inner_wrapper
    return func(self, *args, **kwargs)
  File "/home/airflow/.local/lib/python3.6/site-packages/airflow/providers/google/cloud/hooks/bigquery.py", line 702, in create_external_table
    table_resource=table.to_api_repr(), project_id=project_id, location=location, exists_ok=True
  File "/home/airflow/.local/lib/python3.6/site-packages/airflow/providers/google/common/hooks/base_google.py", line 430, in inner_wrapper
    return func(self, *args, **kwargs)
  File "/home/airflow/.local/lib/python3.6/site-packages/airflow/providers/google/cloud/hooks/bigquery.py", line 408, in create_empty_table
    table=table, exists_ok=exists_ok, retry=retry
  File "/home/airflow/.local/lib/python3.6/site-packages/google/cloud/bigquery/client.py", line 755, in create_table
    timeout=timeout,
  File "/home/airflow/.local/lib/python3.6/site-packages/google/cloud/bigquery/client.py", line 782, in _call_api
    return call()
  File "/home/airflow/.local/lib/python3.6/site-packages/google/api_core/retry.py", line 291, in retry_wrapped_func
    on_error=on_error,
  File "/home/airflow/.local/lib/python3.6/site-packages/google/api_core/retry.py", line 189, in retry_target
    return target()
  File "/home/airflow/.local/lib/python3.6/site-packages/google/cloud/_http.py", line 484, in api_request
    raise exceptions.from_http_response(response)
google.api_core.exceptions.BadRequest: 400 POST https://bigquery.googleapis.com/bigquery/v2/projects/ny-rides-peter-415106/datasets/test_dataset/tables?prettyPrint=false: When defining a table with an ExternalDataConfiguration, a schema must be present on either the Table or the ExternalDataConfiguration. If the schema is present on both, the schemas must be the same.
[2024-03-29 08:16:19,998] {local_task_job.py:154} INFO - Task exited with return code 1
[2024-03-29 08:16:20,040] {local_task_job.py:264} INFO - 0 downstream tasks scheduled from follow-on schedule check
[2024-03-30 03:35:24,606] {taskinstance.py:1032} INFO - Dependencies all met for <TaskInstance: ingest_data_bigquery.bigquery_external_table_task scheduled__2021-01-02T06:00:00+00:00 [queued]>
[2024-03-30 03:35:24,624] {taskinstance.py:1032} INFO - Dependencies all met for <TaskInstance: ingest_data_bigquery.bigquery_external_table_task scheduled__2021-01-02T06:00:00+00:00 [queued]>
[2024-03-30 03:35:24,624] {taskinstance.py:1238} INFO - 
--------------------------------------------------------------------------------
[2024-03-30 03:35:24,625] {taskinstance.py:1239} INFO - Starting attempt 2 of 4
[2024-03-30 03:35:24,625] {taskinstance.py:1240} INFO - 
--------------------------------------------------------------------------------
[2024-03-30 03:35:24,639] {taskinstance.py:1259} INFO - Executing <Task(BigQueryCreateExternalTableOperator): bigquery_external_table_task> on 2021-01-02 06:00:00+00:00
[2024-03-30 03:35:24,645] {standard_task_runner.py:52} INFO - Started process 828 to run task
[2024-03-30 03:35:24,651] {standard_task_runner.py:76} INFO - Running: ['***', 'tasks', 'run', 'ingest_data_bigquery', 'bigquery_external_table_task', 'scheduled__2021-01-02T06:00:00+00:00', '--job-id', '1860', '--raw', '--subdir', 'DAGS_FOLDER/data_ingestion_gcs_dag.py', '--cfg-path', '/tmp/tmpla2n4raw', '--error-file', '/tmp/tmpzqpcd07i']
[2024-03-30 03:35:24,656] {standard_task_runner.py:77} INFO - Job 1860: Subtask bigquery_external_table_task
[2024-03-30 03:35:24,716] {logging_mixin.py:109} INFO - Running <TaskInstance: ingest_data_bigquery.bigquery_external_table_task scheduled__2021-01-02T06:00:00+00:00 [running]> on host 98c5b3fde4c4
[2024-03-30 03:35:24,754] {warnings.py:99} WARNING - /home/***/.local/lib/python3.6/site-packages/***/utils/context.py:152: AirflowContextDeprecationWarning: Accessing 'execution_date' from the template is deprecated and will be removed in a future version. Please use 'data_interval_start' or 'logical_date' instead.
  warnings.warn(_create_deprecation_warning(key, self._deprecation_replacements[key]))

[2024-03-30 03:35:24,780] {taskinstance.py:1426} INFO - Exporting the following env vars:
AIRFLOW_CTX_DAG_OWNER=***
AIRFLOW_CTX_DAG_ID=ingest_data_bigquery
AIRFLOW_CTX_TASK_ID=bigquery_external_table_task
AIRFLOW_CTX_EXECUTION_DATE=2021-01-02T06:00:00+00:00
AIRFLOW_CTX_DAG_RUN_ID=scheduled__2021-01-02T06:00:00+00:00
[2024-03-30 03:35:24,782] {crypto.py:82} WARNING - empty cryptography key - values will not be stored encrypted.
[2024-03-30 03:35:24,791] {warnings.py:99} WARNING - /home/***/.local/lib/python3.6/site-packages/***/providers/google/cloud/hooks/bigquery.py:637: DeprecationWarning: This method is deprecated. Please use `BigQueryHook.create_empty_table` method with passing the `table_resource` object. This gives more flexibility than this method.
  DeprecationWarning,

[2024-03-30 03:35:24,792] {bigquery.py:700} INFO - Creating external table: test_dataset.external_table
[2024-03-30 03:35:24,970] {taskinstance.py:1700} ERROR - Task failed with exception
Traceback (most recent call last):
  File "/home/airflow/.local/lib/python3.6/site-packages/airflow/models/taskinstance.py", line 1329, in _run_raw_task
    self._execute_task_with_callbacks(context)
  File "/home/airflow/.local/lib/python3.6/site-packages/airflow/models/taskinstance.py", line 1455, in _execute_task_with_callbacks
    result = self._execute_task(context, self.task)
  File "/home/airflow/.local/lib/python3.6/site-packages/airflow/models/taskinstance.py", line 1511, in _execute_task
    result = execute_callable(context=context)
  File "/home/airflow/.local/lib/python3.6/site-packages/airflow/providers/google/cloud/operators/bigquery.py", line 1226, in execute
    encryption_configuration=self.encryption_configuration,
  File "/home/airflow/.local/lib/python3.6/site-packages/airflow/providers/google/common/hooks/base_google.py", line 430, in inner_wrapper
    return func(self, *args, **kwargs)
  File "/home/airflow/.local/lib/python3.6/site-packages/airflow/providers/google/cloud/hooks/bigquery.py", line 702, in create_external_table
    table_resource=table.to_api_repr(), project_id=project_id, location=location, exists_ok=True
  File "/home/airflow/.local/lib/python3.6/site-packages/airflow/providers/google/common/hooks/base_google.py", line 430, in inner_wrapper
    return func(self, *args, **kwargs)
  File "/home/airflow/.local/lib/python3.6/site-packages/airflow/providers/google/cloud/hooks/bigquery.py", line 408, in create_empty_table
    table=table, exists_ok=exists_ok, retry=retry
  File "/home/airflow/.local/lib/python3.6/site-packages/google/cloud/bigquery/client.py", line 755, in create_table
    timeout=timeout,
  File "/home/airflow/.local/lib/python3.6/site-packages/google/cloud/bigquery/client.py", line 782, in _call_api
    return call()
  File "/home/airflow/.local/lib/python3.6/site-packages/google/api_core/retry.py", line 291, in retry_wrapped_func
    on_error=on_error,
  File "/home/airflow/.local/lib/python3.6/site-packages/google/api_core/retry.py", line 189, in retry_target
    return target()
  File "/home/airflow/.local/lib/python3.6/site-packages/google/cloud/_http.py", line 484, in api_request
    raise exceptions.from_http_response(response)
google.api_core.exceptions.BadRequest: 400 POST https://bigquery.googleapis.com/bigquery/v2/projects/ny-rides-peter-415106/datasets/test_dataset/tables?prettyPrint=false: When defining a table with an ExternalDataConfiguration, a schema must be present on either the Table or the ExternalDataConfiguration. If the schema is present on both, the schemas must be the same.
[2024-03-30 03:35:24,988] {taskinstance.py:1277} INFO - Marking task as UP_FOR_RETRY. dag_id=ingest_data_bigquery, task_id=bigquery_external_table_task, execution_date=20210102T060000, start_date=20240330T033524, end_date=20240330T033524
[2024-03-30 03:35:25,007] {standard_task_runner.py:92} ERROR - Failed to execute job 1860 for task bigquery_external_table_task
Traceback (most recent call last):
  File "/home/airflow/.local/lib/python3.6/site-packages/airflow/task/task_runner/standard_task_runner.py", line 85, in _start_by_fork
    args.func(args, dag=self.dag)
  File "/home/airflow/.local/lib/python3.6/site-packages/airflow/cli/cli_parser.py", line 48, in command
    return func(*args, **kwargs)
  File "/home/airflow/.local/lib/python3.6/site-packages/airflow/utils/cli.py", line 92, in wrapper
    return f(*args, **kwargs)
  File "/home/airflow/.local/lib/python3.6/site-packages/airflow/cli/commands/task_command.py", line 298, in task_run
    _run_task_by_selected_method(args, dag, ti)
  File "/home/airflow/.local/lib/python3.6/site-packages/airflow/cli/commands/task_command.py", line 107, in _run_task_by_selected_method
    _run_raw_task(args, ti)
  File "/home/airflow/.local/lib/python3.6/site-packages/airflow/cli/commands/task_command.py", line 184, in _run_raw_task
    error_file=args.error_file,
  File "/home/airflow/.local/lib/python3.6/site-packages/airflow/utils/session.py", line 70, in wrapper
    return func(*args, session=session, **kwargs)
  File "/home/airflow/.local/lib/python3.6/site-packages/airflow/models/taskinstance.py", line 1329, in _run_raw_task
    self._execute_task_with_callbacks(context)
  File "/home/airflow/.local/lib/python3.6/site-packages/airflow/models/taskinstance.py", line 1455, in _execute_task_with_callbacks
    result = self._execute_task(context, self.task)
  File "/home/airflow/.local/lib/python3.6/site-packages/airflow/models/taskinstance.py", line 1511, in _execute_task
    result = execute_callable(context=context)
  File "/home/airflow/.local/lib/python3.6/site-packages/airflow/providers/google/cloud/operators/bigquery.py", line 1226, in execute
    encryption_configuration=self.encryption_configuration,
  File "/home/airflow/.local/lib/python3.6/site-packages/airflow/providers/google/common/hooks/base_google.py", line 430, in inner_wrapper
    return func(self, *args, **kwargs)
  File "/home/airflow/.local/lib/python3.6/site-packages/airflow/providers/google/cloud/hooks/bigquery.py", line 702, in create_external_table
    table_resource=table.to_api_repr(), project_id=project_id, location=location, exists_ok=True
  File "/home/airflow/.local/lib/python3.6/site-packages/airflow/providers/google/common/hooks/base_google.py", line 430, in inner_wrapper
    return func(self, *args, **kwargs)
  File "/home/airflow/.local/lib/python3.6/site-packages/airflow/providers/google/cloud/hooks/bigquery.py", line 408, in create_empty_table
    table=table, exists_ok=exists_ok, retry=retry
  File "/home/airflow/.local/lib/python3.6/site-packages/google/cloud/bigquery/client.py", line 755, in create_table
    timeout=timeout,
  File "/home/airflow/.local/lib/python3.6/site-packages/google/cloud/bigquery/client.py", line 782, in _call_api
    return call()
  File "/home/airflow/.local/lib/python3.6/site-packages/google/api_core/retry.py", line 291, in retry_wrapped_func
    on_error=on_error,
  File "/home/airflow/.local/lib/python3.6/site-packages/google/api_core/retry.py", line 189, in retry_target
    return target()
  File "/home/airflow/.local/lib/python3.6/site-packages/google/cloud/_http.py", line 484, in api_request
    raise exceptions.from_http_response(response)
google.api_core.exceptions.BadRequest: 400 POST https://bigquery.googleapis.com/bigquery/v2/projects/ny-rides-peter-415106/datasets/test_dataset/tables?prettyPrint=false: When defining a table with an ExternalDataConfiguration, a schema must be present on either the Table or the ExternalDataConfiguration. If the schema is present on both, the schemas must be the same.
[2024-03-30 03:35:25,035] {local_task_job.py:154} INFO - Task exited with return code 1
[2024-03-30 03:35:25,307] {local_task_job.py:264} INFO - 0 downstream tasks scheduled from follow-on schedule check
[2024-03-30 03:47:13,892] {taskinstance.py:1032} INFO - Dependencies all met for <TaskInstance: ingest_data_bigquery.bigquery_external_table_task scheduled__2021-01-02T06:00:00+00:00 [queued]>
[2024-03-30 03:47:13,908] {taskinstance.py:1032} INFO - Dependencies all met for <TaskInstance: ingest_data_bigquery.bigquery_external_table_task scheduled__2021-01-02T06:00:00+00:00 [queued]>
[2024-03-30 03:47:13,908] {taskinstance.py:1238} INFO - 
--------------------------------------------------------------------------------
[2024-03-30 03:47:13,908] {taskinstance.py:1239} INFO - Starting attempt 2 of 4
[2024-03-30 03:47:13,908] {taskinstance.py:1240} INFO - 
--------------------------------------------------------------------------------
[2024-03-30 03:47:13,922] {taskinstance.py:1259} INFO - Executing <Task(BigQueryCreateExternalTableOperator): bigquery_external_table_task> on 2021-01-02 06:00:00+00:00
[2024-03-30 03:47:13,932] {standard_task_runner.py:52} INFO - Started process 1642 to run task
[2024-03-30 03:47:13,936] {standard_task_runner.py:76} INFO - Running: ['***', 'tasks', 'run', 'ingest_data_bigquery', 'bigquery_external_table_task', 'scheduled__2021-01-02T06:00:00+00:00', '--job-id', '1938', '--raw', '--subdir', 'DAGS_FOLDER/data_ingestion_gcs_dag.py', '--cfg-path', '/tmp/tmp7m12ttny', '--error-file', '/tmp/tmpsaf7i679']
[2024-03-30 03:47:13,942] {standard_task_runner.py:77} INFO - Job 1938: Subtask bigquery_external_table_task
[2024-03-30 03:47:14,004] {logging_mixin.py:109} INFO - Running <TaskInstance: ingest_data_bigquery.bigquery_external_table_task scheduled__2021-01-02T06:00:00+00:00 [running]> on host 98c5b3fde4c4
[2024-03-30 03:47:14,038] {warnings.py:99} WARNING - /home/***/.local/lib/python3.6/site-packages/***/utils/context.py:152: AirflowContextDeprecationWarning: Accessing 'execution_date' from the template is deprecated and will be removed in a future version. Please use 'data_interval_start' or 'logical_date' instead.
  warnings.warn(_create_deprecation_warning(key, self._deprecation_replacements[key]))

[2024-03-30 03:47:14,066] {taskinstance.py:1426} INFO - Exporting the following env vars:
AIRFLOW_CTX_DAG_OWNER=***
AIRFLOW_CTX_DAG_ID=ingest_data_bigquery
AIRFLOW_CTX_TASK_ID=bigquery_external_table_task
AIRFLOW_CTX_EXECUTION_DATE=2021-01-02T06:00:00+00:00
AIRFLOW_CTX_DAG_RUN_ID=scheduled__2021-01-02T06:00:00+00:00
[2024-03-30 03:47:14,068] {crypto.py:82} WARNING - empty cryptography key - values will not be stored encrypted.
[2024-03-30 03:47:14,076] {warnings.py:99} WARNING - /home/***/.local/lib/python3.6/site-packages/***/providers/google/cloud/hooks/bigquery.py:637: DeprecationWarning: This method is deprecated. Please use `BigQueryHook.create_empty_table` method with passing the `table_resource` object. This gives more flexibility than this method.
  DeprecationWarning,

[2024-03-30 03:47:14,077] {bigquery.py:700} INFO - Creating external table: test_dataset.external_table
[2024-03-30 03:47:14,202] {taskinstance.py:1700} ERROR - Task failed with exception
Traceback (most recent call last):
  File "/home/airflow/.local/lib/python3.6/site-packages/airflow/models/taskinstance.py", line 1329, in _run_raw_task
    self._execute_task_with_callbacks(context)
  File "/home/airflow/.local/lib/python3.6/site-packages/airflow/models/taskinstance.py", line 1455, in _execute_task_with_callbacks
    result = self._execute_task(context, self.task)
  File "/home/airflow/.local/lib/python3.6/site-packages/airflow/models/taskinstance.py", line 1511, in _execute_task
    result = execute_callable(context=context)
  File "/home/airflow/.local/lib/python3.6/site-packages/airflow/providers/google/cloud/operators/bigquery.py", line 1226, in execute
    encryption_configuration=self.encryption_configuration,
  File "/home/airflow/.local/lib/python3.6/site-packages/airflow/providers/google/common/hooks/base_google.py", line 430, in inner_wrapper
    return func(self, *args, **kwargs)
  File "/home/airflow/.local/lib/python3.6/site-packages/airflow/providers/google/cloud/hooks/bigquery.py", line 702, in create_external_table
    table_resource=table.to_api_repr(), project_id=project_id, location=location, exists_ok=True
  File "/home/airflow/.local/lib/python3.6/site-packages/airflow/providers/google/common/hooks/base_google.py", line 430, in inner_wrapper
    return func(self, *args, **kwargs)
  File "/home/airflow/.local/lib/python3.6/site-packages/airflow/providers/google/cloud/hooks/bigquery.py", line 408, in create_empty_table
    table=table, exists_ok=exists_ok, retry=retry
  File "/home/airflow/.local/lib/python3.6/site-packages/google/cloud/bigquery/client.py", line 755, in create_table
    timeout=timeout,
  File "/home/airflow/.local/lib/python3.6/site-packages/google/cloud/bigquery/client.py", line 782, in _call_api
    return call()
  File "/home/airflow/.local/lib/python3.6/site-packages/google/api_core/retry.py", line 291, in retry_wrapped_func
    on_error=on_error,
  File "/home/airflow/.local/lib/python3.6/site-packages/google/api_core/retry.py", line 189, in retry_target
    return target()
  File "/home/airflow/.local/lib/python3.6/site-packages/google/cloud/_http.py", line 484, in api_request
    raise exceptions.from_http_response(response)
google.api_core.exceptions.BadRequest: 400 POST https://bigquery.googleapis.com/bigquery/v2/projects/ny-rides-peter-415106/datasets/test_dataset/tables?prettyPrint=false: Invalid value for type: NUMBER is not a valid value
[2024-03-30 03:47:14,218] {taskinstance.py:1277} INFO - Marking task as UP_FOR_RETRY. dag_id=ingest_data_bigquery, task_id=bigquery_external_table_task, execution_date=20210102T060000, start_date=20240330T034713, end_date=20240330T034714
[2024-03-30 03:47:14,230] {standard_task_runner.py:92} ERROR - Failed to execute job 1938 for task bigquery_external_table_task
Traceback (most recent call last):
  File "/home/airflow/.local/lib/python3.6/site-packages/airflow/task/task_runner/standard_task_runner.py", line 85, in _start_by_fork
    args.func(args, dag=self.dag)
  File "/home/airflow/.local/lib/python3.6/site-packages/airflow/cli/cli_parser.py", line 48, in command
    return func(*args, **kwargs)
  File "/home/airflow/.local/lib/python3.6/site-packages/airflow/utils/cli.py", line 92, in wrapper
    return f(*args, **kwargs)
  File "/home/airflow/.local/lib/python3.6/site-packages/airflow/cli/commands/task_command.py", line 298, in task_run
    _run_task_by_selected_method(args, dag, ti)
  File "/home/airflow/.local/lib/python3.6/site-packages/airflow/cli/commands/task_command.py", line 107, in _run_task_by_selected_method
    _run_raw_task(args, ti)
  File "/home/airflow/.local/lib/python3.6/site-packages/airflow/cli/commands/task_command.py", line 184, in _run_raw_task
    error_file=args.error_file,
  File "/home/airflow/.local/lib/python3.6/site-packages/airflow/utils/session.py", line 70, in wrapper
    return func(*args, session=session, **kwargs)
  File "/home/airflow/.local/lib/python3.6/site-packages/airflow/models/taskinstance.py", line 1329, in _run_raw_task
    self._execute_task_with_callbacks(context)
  File "/home/airflow/.local/lib/python3.6/site-packages/airflow/models/taskinstance.py", line 1455, in _execute_task_with_callbacks
    result = self._execute_task(context, self.task)
  File "/home/airflow/.local/lib/python3.6/site-packages/airflow/models/taskinstance.py", line 1511, in _execute_task
    result = execute_callable(context=context)
  File "/home/airflow/.local/lib/python3.6/site-packages/airflow/providers/google/cloud/operators/bigquery.py", line 1226, in execute
    encryption_configuration=self.encryption_configuration,
  File "/home/airflow/.local/lib/python3.6/site-packages/airflow/providers/google/common/hooks/base_google.py", line 430, in inner_wrapper
    return func(self, *args, **kwargs)
  File "/home/airflow/.local/lib/python3.6/site-packages/airflow/providers/google/cloud/hooks/bigquery.py", line 702, in create_external_table
    table_resource=table.to_api_repr(), project_id=project_id, location=location, exists_ok=True
  File "/home/airflow/.local/lib/python3.6/site-packages/airflow/providers/google/common/hooks/base_google.py", line 430, in inner_wrapper
    return func(self, *args, **kwargs)
  File "/home/airflow/.local/lib/python3.6/site-packages/airflow/providers/google/cloud/hooks/bigquery.py", line 408, in create_empty_table
    table=table, exists_ok=exists_ok, retry=retry
  File "/home/airflow/.local/lib/python3.6/site-packages/google/cloud/bigquery/client.py", line 755, in create_table
    timeout=timeout,
  File "/home/airflow/.local/lib/python3.6/site-packages/google/cloud/bigquery/client.py", line 782, in _call_api
    return call()
  File "/home/airflow/.local/lib/python3.6/site-packages/google/api_core/retry.py", line 291, in retry_wrapped_func
    on_error=on_error,
  File "/home/airflow/.local/lib/python3.6/site-packages/google/api_core/retry.py", line 189, in retry_target
    return target()
  File "/home/airflow/.local/lib/python3.6/site-packages/google/cloud/_http.py", line 484, in api_request
    raise exceptions.from_http_response(response)
google.api_core.exceptions.BadRequest: 400 POST https://bigquery.googleapis.com/bigquery/v2/projects/ny-rides-peter-415106/datasets/test_dataset/tables?prettyPrint=false: Invalid value for type: NUMBER is not a valid value
[2024-03-30 03:47:14,277] {local_task_job.py:154} INFO - Task exited with return code 1
[2024-03-30 03:47:14,319] {local_task_job.py:264} INFO - 0 downstream tasks scheduled from follow-on schedule check
[2024-03-30 04:41:44,254] {taskinstance.py:1032} INFO - Dependencies all met for <TaskInstance: ingest_data_bigquery.bigquery_external_table_task scheduled__2021-01-02T06:00:00+00:00 [queued]>
[2024-03-30 04:41:44,266] {taskinstance.py:1032} INFO - Dependencies all met for <TaskInstance: ingest_data_bigquery.bigquery_external_table_task scheduled__2021-01-02T06:00:00+00:00 [queued]>
[2024-03-30 04:41:44,266] {taskinstance.py:1238} INFO - 
--------------------------------------------------------------------------------
[2024-03-30 04:41:44,266] {taskinstance.py:1239} INFO - Starting attempt 2 of 5
[2024-03-30 04:41:44,266] {taskinstance.py:1240} INFO - 
--------------------------------------------------------------------------------
[2024-03-30 04:41:44,276] {taskinstance.py:1259} INFO - Executing <Task(BigQueryCreateExternalTableOperator): bigquery_external_table_task> on 2021-01-02 06:00:00+00:00
[2024-03-30 04:41:44,283] {standard_task_runner.py:52} INFO - Started process 5460 to run task
[2024-03-30 04:41:44,289] {standard_task_runner.py:76} INFO - Running: ['***', 'tasks', 'run', 'ingest_data_bigquery', 'bigquery_external_table_task', 'scheduled__2021-01-02T06:00:00+00:00', '--job-id', '2316', '--raw', '--subdir', 'DAGS_FOLDER/data_ingestion_gcs_dag.py', '--cfg-path', '/tmp/tmpqv3ej_qy', '--error-file', '/tmp/tmp74wo0f7v']
[2024-03-30 04:41:44,294] {standard_task_runner.py:77} INFO - Job 2316: Subtask bigquery_external_table_task
[2024-03-30 04:41:44,354] {logging_mixin.py:109} INFO - Running <TaskInstance: ingest_data_bigquery.bigquery_external_table_task scheduled__2021-01-02T06:00:00+00:00 [running]> on host 98c5b3fde4c4
[2024-03-30 04:41:44,393] {warnings.py:99} WARNING - /home/***/.local/lib/python3.6/site-packages/***/utils/context.py:152: AirflowContextDeprecationWarning: Accessing 'execution_date' from the template is deprecated and will be removed in a future version. Please use 'data_interval_start' or 'logical_date' instead.
  warnings.warn(_create_deprecation_warning(key, self._deprecation_replacements[key]))

[2024-03-30 04:41:44,421] {taskinstance.py:1426} INFO - Exporting the following env vars:
AIRFLOW_CTX_DAG_OWNER=***
AIRFLOW_CTX_DAG_ID=ingest_data_bigquery
AIRFLOW_CTX_TASK_ID=bigquery_external_table_task
AIRFLOW_CTX_EXECUTION_DATE=2021-01-02T06:00:00+00:00
AIRFLOW_CTX_DAG_RUN_ID=scheduled__2021-01-02T06:00:00+00:00
[2024-03-30 04:41:44,423] {crypto.py:82} WARNING - empty cryptography key - values will not be stored encrypted.
[2024-03-30 04:41:44,435] {warnings.py:99} WARNING - /home/***/.local/lib/python3.6/site-packages/***/providers/google/cloud/hooks/bigquery.py:637: DeprecationWarning: This method is deprecated. Please use `BigQueryHook.create_empty_table` method with passing the `table_resource` object. This gives more flexibility than this method.
  DeprecationWarning,

[2024-03-30 04:41:44,436] {bigquery.py:700} INFO - Creating external table: test_dataset.yellowtaxi_trips
[2024-03-30 04:41:44,667] {bigquery.py:704} INFO - External table created successfully: test_dataset.yellowtaxi_trips
[2024-03-30 04:41:44,684] {taskinstance.py:1277} INFO - Marking task as SUCCESS. dag_id=ingest_data_bigquery, task_id=bigquery_external_table_task, execution_date=20210102T060000, start_date=20240330T044144, end_date=20240330T044144
[2024-03-30 04:41:44,711] {local_task_job.py:154} INFO - Task exited with return code 0
[2024-03-30 04:41:44,931] {local_task_job.py:264} INFO - 0 downstream tasks scheduled from follow-on schedule check
[2024-04-30 06:43:59,545] {taskinstance.py:1032} INFO - Dependencies all met for <TaskInstance: ingest_data_bigquery.bigquery_external_table_task scheduled__2021-01-02T06:00:00+00:00 [queued]>
[2024-04-30 06:43:59,624] {taskinstance.py:1032} INFO - Dependencies all met for <TaskInstance: ingest_data_bigquery.bigquery_external_table_task scheduled__2021-01-02T06:00:00+00:00 [queued]>
[2024-04-30 06:43:59,625] {taskinstance.py:1238} INFO - 
--------------------------------------------------------------------------------
[2024-04-30 06:43:59,625] {taskinstance.py:1239} INFO - Starting attempt 2 of 2
[2024-04-30 06:43:59,625] {taskinstance.py:1240} INFO - 
--------------------------------------------------------------------------------
[2024-04-30 06:43:59,733] {taskinstance.py:1259} INFO - Executing <Task(BigQueryCreateExternalTableOperator): bigquery_external_table_task> on 2021-01-02 06:00:00+00:00
[2024-04-30 06:43:59,751] {standard_task_runner.py:52} INFO - Started process 95 to run task
[2024-04-30 06:43:59,829] {standard_task_runner.py:76} INFO - Running: ['***', 'tasks', 'run', 'ingest_data_bigquery', 'bigquery_external_table_task', 'scheduled__2021-01-02T06:00:00+00:00', '--job-id', '3648', '--raw', '--subdir', 'DAGS_FOLDER/data_ingestion_gcs_dag.py', '--cfg-path', '/tmp/tmp78a0so41', '--error-file', '/tmp/tmp9yp5dbyd']
[2024-04-30 06:43:59,849] {standard_task_runner.py:77} INFO - Job 3648: Subtask bigquery_external_table_task
[2024-04-30 06:44:00,271] {logging_mixin.py:109} INFO - Running <TaskInstance: ingest_data_bigquery.bigquery_external_table_task scheduled__2021-01-02T06:00:00+00:00 [running]> on host 4d5ad4aa2a9b
[2024-04-30 06:44:00,618] {taskinstance.py:1426} INFO - Exporting the following env vars:
AIRFLOW_CTX_DAG_OWNER=***
AIRFLOW_CTX_DAG_ID=ingest_data_bigquery
AIRFLOW_CTX_TASK_ID=bigquery_external_table_task
AIRFLOW_CTX_EXECUTION_DATE=2021-01-02T06:00:00+00:00
AIRFLOW_CTX_DAG_RUN_ID=scheduled__2021-01-02T06:00:00+00:00
[2024-04-30 06:44:00,625] {crypto.py:82} WARNING - empty cryptography key - values will not be stored encrypted.
[2024-04-30 06:44:00,666] {warnings.py:99} WARNING - /home/***/.local/lib/python3.6/site-packages/***/providers/google/cloud/hooks/bigquery.py:637: DeprecationWarning: This method is deprecated. Please use `BigQueryHook.create_empty_table` method with passing the `table_resource` object. This gives more flexibility than this method.
  DeprecationWarning,

[2024-04-30 06:44:00,674] {bigquery.py:700} INFO - Creating external table: test_dataset.yellowtaxi_trips
[2024-04-30 06:44:01,246] {bigquery.py:704} INFO - External table created successfully: test_dataset.yellowtaxi_trips
[2024-04-30 06:44:01,306] {taskinstance.py:1277} INFO - Marking task as SUCCESS. dag_id=ingest_data_bigquery, task_id=bigquery_external_table_task, execution_date=20210102T060000, start_date=20240430T064359, end_date=20240430T064401
[2024-04-30 06:44:01,435] {local_task_job.py:154} INFO - Task exited with return code 0
[2024-04-30 06:44:01,574] {local_task_job.py:264} INFO - 0 downstream tasks scheduled from follow-on schedule check
