[2024-05-03 17:35:55,015] {taskinstance.py:1032} INFO - Dependencies all met for <TaskInstance: ingest_data_bigquery_yt.local_to_gcs_task scheduled__2019-06-02T06:00:00+00:00 [queued]>
[2024-05-03 17:35:55,156] {taskinstance.py:1032} INFO - Dependencies all met for <TaskInstance: ingest_data_bigquery_yt.local_to_gcs_task scheduled__2019-06-02T06:00:00+00:00 [queued]>
[2024-05-03 17:35:55,158] {taskinstance.py:1238} INFO - 
--------------------------------------------------------------------------------
[2024-05-03 17:35:55,158] {taskinstance.py:1239} INFO - Starting attempt 3 of 3
[2024-05-03 17:35:55,160] {taskinstance.py:1240} INFO - 
--------------------------------------------------------------------------------
[2024-05-03 17:35:55,334] {taskinstance.py:1259} INFO - Executing <Task(PythonOperator): local_to_gcs_task> on 2019-06-02 06:00:00+00:00
[2024-05-03 17:35:55,403] {standard_task_runner.py:52} INFO - Started process 1099 to run task
[2024-05-03 17:35:55,467] {standard_task_runner.py:76} INFO - Running: ['***', 'tasks', 'run', 'ingest_data_bigquery_yt', 'local_to_gcs_task', 'scheduled__2019-06-02T06:00:00+00:00', '--job-id', '4310', '--raw', '--subdir', 'DAGS_FOLDER/data_ingstion_gcs_yt_dag.py', '--cfg-path', '/tmp/tmpmtmg25c1', '--error-file', '/tmp/tmp0epgmbjt']
[2024-05-03 17:35:55,609] {standard_task_runner.py:77} INFO - Job 4310: Subtask local_to_gcs_task
[2024-05-03 17:35:56,205] {logging_mixin.py:109} INFO - Running <TaskInstance: ingest_data_bigquery_yt.local_to_gcs_task scheduled__2019-06-02T06:00:00+00:00 [running]> on host f0ab9bf9b587
[2024-05-03 17:35:56,621] {warnings.py:99} WARNING - /home/***/.local/lib/python3.6/site-packages/***/utils/context.py:152: AirflowContextDeprecationWarning: Accessing 'execution_date' from the template is deprecated and will be removed in a future version. Please use 'data_interval_start' or 'logical_date' instead.
  warnings.warn(_create_deprecation_warning(key, self._deprecation_replacements[key]))

[2024-05-03 17:35:56,888] {taskinstance.py:1426} INFO - Exporting the following env vars:
AIRFLOW_CTX_DAG_OWNER=***
AIRFLOW_CTX_DAG_ID=ingest_data_bigquery_yt
AIRFLOW_CTX_TASK_ID=local_to_gcs_task
AIRFLOW_CTX_EXECUTION_DATE=2019-06-02T06:00:00+00:00
AIRFLOW_CTX_DAG_RUN_ID=scheduled__2019-06-02T06:00:00+00:00
[2024-05-03 17:41:26,689] {python.py:175} INFO - Done. Returned value was: None
[2024-05-03 17:41:26,970] {taskinstance.py:1277} INFO - Marking task as SUCCESS. dag_id=ingest_data_bigquery_yt, task_id=local_to_gcs_task, execution_date=20190602T060000, start_date=20240503T173555, end_date=20240503T174126
[2024-05-03 17:41:27,115] {local_task_job.py:154} INFO - Task exited with return code 0
[2024-05-03 17:41:27,191] {local_task_job.py:264} INFO - 1 downstream tasks scheduled from follow-on schedule check
[2024-05-05 13:53:59,850] {taskinstance.py:1032} INFO - Dependencies all met for <TaskInstance: ingest_data_bigquery_yt.local_to_gcs_task scheduled__2019-06-02T06:00:00+00:00 [queued]>
[2024-05-05 13:53:59,905] {taskinstance.py:1032} INFO - Dependencies all met for <TaskInstance: ingest_data_bigquery_yt.local_to_gcs_task scheduled__2019-06-02T06:00:00+00:00 [queued]>
[2024-05-05 13:53:59,905] {taskinstance.py:1238} INFO - 
--------------------------------------------------------------------------------
[2024-05-05 13:53:59,905] {taskinstance.py:1239} INFO - Starting attempt 3 of 3
[2024-05-05 13:53:59,905] {taskinstance.py:1240} INFO - 
--------------------------------------------------------------------------------
[2024-05-05 13:53:59,933] {taskinstance.py:1259} INFO - Executing <Task(PythonOperator): local_to_gcs_task> on 2019-06-02 06:00:00+00:00
[2024-05-05 13:53:59,964] {standard_task_runner.py:52} INFO - Started process 119 to run task
[2024-05-05 13:53:59,991] {standard_task_runner.py:76} INFO - Running: ['***', 'tasks', 'run', 'ingest_data_bigquery_yt', 'local_to_gcs_task', 'scheduled__2019-06-02T06:00:00+00:00', '--job-id', '4414', '--raw', '--subdir', 'DAGS_FOLDER/data_ingstion_gcs_yt_dag.py', '--cfg-path', '/tmp/tmpn1rcrn0h', '--error-file', '/tmp/tmpdvoak0o7']
[2024-05-05 13:54:00,072] {standard_task_runner.py:77} INFO - Job 4414: Subtask local_to_gcs_task
[2024-05-05 13:54:00,379] {logging_mixin.py:109} INFO - Running <TaskInstance: ingest_data_bigquery_yt.local_to_gcs_task scheduled__2019-06-02T06:00:00+00:00 [running]> on host 43faca6eb596
[2024-05-05 13:54:00,580] {warnings.py:99} WARNING - /home/***/.local/lib/python3.6/site-packages/***/utils/context.py:152: AirflowContextDeprecationWarning: Accessing 'execution_date' from the template is deprecated and will be removed in a future version. Please use 'data_interval_start' or 'logical_date' instead.
  warnings.warn(_create_deprecation_warning(key, self._deprecation_replacements[key]))

[2024-05-05 13:54:00,796] {taskinstance.py:1426} INFO - Exporting the following env vars:
AIRFLOW_CTX_DAG_OWNER=***
AIRFLOW_CTX_DAG_ID=ingest_data_bigquery_yt
AIRFLOW_CTX_TASK_ID=local_to_gcs_task
AIRFLOW_CTX_EXECUTION_DATE=2019-06-02T06:00:00+00:00
AIRFLOW_CTX_DAG_RUN_ID=scheduled__2019-06-02T06:00:00+00:00
[2024-05-05 13:54:00,944] {taskinstance.py:1700} ERROR - Task failed with exception
Traceback (most recent call last):
  File "/home/airflow/.local/lib/python3.6/site-packages/airflow/models/taskinstance.py", line 1329, in _run_raw_task
    self._execute_task_with_callbacks(context)
  File "/home/airflow/.local/lib/python3.6/site-packages/airflow/models/taskinstance.py", line 1455, in _execute_task_with_callbacks
    result = self._execute_task(context, self.task)
  File "/home/airflow/.local/lib/python3.6/site-packages/airflow/models/taskinstance.py", line 1511, in _execute_task
    result = execute_callable(context=context)
  File "/home/airflow/.local/lib/python3.6/site-packages/airflow/operators/python.py", line 174, in execute
    return_value = self.execute_callable()
  File "/home/airflow/.local/lib/python3.6/site-packages/airflow/operators/python.py", line 185, in execute_callable
    return self.python_callable(*self.op_args, **self.op_kwargs)
  File "/opt/airflow/dags/data_ingstion_gcs_yt_dag.py", line 84, in upload_to_gcs
    __clean_file(raw_file_name, clean_file_name)
  File "/opt/airflow/dags/data_ingstion_gcs_yt_dag.py", line 65, in __clean_file
    "payment_type": "int64",
  File "/home/airflow/.local/lib/python3.6/site-packages/pandas/io/parsers.py", line 688, in read_csv
    return _read(filepath_or_buffer, kwds)
  File "/home/airflow/.local/lib/python3.6/site-packages/pandas/io/parsers.py", line 454, in _read
    parser = TextFileReader(fp_or_buf, **kwds)
  File "/home/airflow/.local/lib/python3.6/site-packages/pandas/io/parsers.py", line 948, in __init__
    self._make_engine(self.engine)
  File "/home/airflow/.local/lib/python3.6/site-packages/pandas/io/parsers.py", line 1180, in _make_engine
    self._engine = CParserWrapper(self.f, **self.options)
  File "/home/airflow/.local/lib/python3.6/site-packages/pandas/io/parsers.py", line 2010, in __init__
    self._reader = parsers.TextReader(src, **kwds)
  File "pandas/_libs/parsers.pyx", line 382, in pandas._libs.parsers.TextReader.__cinit__
  File "pandas/_libs/parsers.pyx", line 674, in pandas._libs.parsers.TextReader._setup_parser_source
FileNotFoundError: [Errno 2] No such file or directory: '/opt/airflow/raw_data/yellowtaxi_tripdata_2019-06.csv'
[2024-05-05 13:54:01,024] {taskinstance.py:1277} INFO - Marking task as FAILED. dag_id=ingest_data_bigquery_yt, task_id=local_to_gcs_task, execution_date=20190602T060000, start_date=20240505T135359, end_date=20240505T135401
[2024-05-05 13:54:01,159] {standard_task_runner.py:92} ERROR - Failed to execute job 4414 for task local_to_gcs_task
Traceback (most recent call last):
  File "/home/airflow/.local/lib/python3.6/site-packages/airflow/task/task_runner/standard_task_runner.py", line 85, in _start_by_fork
    args.func(args, dag=self.dag)
  File "/home/airflow/.local/lib/python3.6/site-packages/airflow/cli/cli_parser.py", line 48, in command
    return func(*args, **kwargs)
  File "/home/airflow/.local/lib/python3.6/site-packages/airflow/utils/cli.py", line 92, in wrapper
    return f(*args, **kwargs)
  File "/home/airflow/.local/lib/python3.6/site-packages/airflow/cli/commands/task_command.py", line 298, in task_run
    _run_task_by_selected_method(args, dag, ti)
  File "/home/airflow/.local/lib/python3.6/site-packages/airflow/cli/commands/task_command.py", line 107, in _run_task_by_selected_method
    _run_raw_task(args, ti)
  File "/home/airflow/.local/lib/python3.6/site-packages/airflow/cli/commands/task_command.py", line 184, in _run_raw_task
    error_file=args.error_file,
  File "/home/airflow/.local/lib/python3.6/site-packages/airflow/utils/session.py", line 70, in wrapper
    return func(*args, session=session, **kwargs)
  File "/home/airflow/.local/lib/python3.6/site-packages/airflow/models/taskinstance.py", line 1329, in _run_raw_task
    self._execute_task_with_callbacks(context)
  File "/home/airflow/.local/lib/python3.6/site-packages/airflow/models/taskinstance.py", line 1455, in _execute_task_with_callbacks
    result = self._execute_task(context, self.task)
  File "/home/airflow/.local/lib/python3.6/site-packages/airflow/models/taskinstance.py", line 1511, in _execute_task
    result = execute_callable(context=context)
  File "/home/airflow/.local/lib/python3.6/site-packages/airflow/operators/python.py", line 174, in execute
    return_value = self.execute_callable()
  File "/home/airflow/.local/lib/python3.6/site-packages/airflow/operators/python.py", line 185, in execute_callable
    return self.python_callable(*self.op_args, **self.op_kwargs)
  File "/opt/airflow/dags/data_ingstion_gcs_yt_dag.py", line 84, in upload_to_gcs
    __clean_file(raw_file_name, clean_file_name)
  File "/opt/airflow/dags/data_ingstion_gcs_yt_dag.py", line 65, in __clean_file
    "payment_type": "int64",
  File "/home/airflow/.local/lib/python3.6/site-packages/pandas/io/parsers.py", line 688, in read_csv
    return _read(filepath_or_buffer, kwds)
  File "/home/airflow/.local/lib/python3.6/site-packages/pandas/io/parsers.py", line 454, in _read
    parser = TextFileReader(fp_or_buf, **kwds)
  File "/home/airflow/.local/lib/python3.6/site-packages/pandas/io/parsers.py", line 948, in __init__
    self._make_engine(self.engine)
  File "/home/airflow/.local/lib/python3.6/site-packages/pandas/io/parsers.py", line 1180, in _make_engine
    self._engine = CParserWrapper(self.f, **self.options)
  File "/home/airflow/.local/lib/python3.6/site-packages/pandas/io/parsers.py", line 2010, in __init__
    self._reader = parsers.TextReader(src, **kwds)
  File "pandas/_libs/parsers.pyx", line 382, in pandas._libs.parsers.TextReader.__cinit__
  File "pandas/_libs/parsers.pyx", line 674, in pandas._libs.parsers.TextReader._setup_parser_source
FileNotFoundError: [Errno 2] No such file or directory: '/opt/airflow/raw_data/yellowtaxi_tripdata_2019-06.csv'
[2024-05-05 13:54:01,239] {local_task_job.py:154} INFO - Task exited with return code 1
[2024-05-05 13:54:01,390] {local_task_job.py:264} INFO - 0 downstream tasks scheduled from follow-on schedule check
[2024-05-06 09:24:43,615] {taskinstance.py:1032} INFO - Dependencies all met for <TaskInstance: ingest_data_bigquery_yt.local_to_gcs_task scheduled__2019-06-02T06:00:00+00:00 [queued]>
[2024-05-06 09:24:43,757] {taskinstance.py:1032} INFO - Dependencies all met for <TaskInstance: ingest_data_bigquery_yt.local_to_gcs_task scheduled__2019-06-02T06:00:00+00:00 [queued]>
[2024-05-06 09:24:43,757] {taskinstance.py:1238} INFO - 
--------------------------------------------------------------------------------
[2024-05-06 09:24:43,757] {taskinstance.py:1239} INFO - Starting attempt 3 of 3
[2024-05-06 09:24:43,758] {taskinstance.py:1240} INFO - 
--------------------------------------------------------------------------------
[2024-05-06 09:24:43,931] {taskinstance.py:1259} INFO - Executing <Task(PythonOperator): local_to_gcs_task> on 2019-06-02 06:00:00+00:00
[2024-05-06 09:24:43,957] {standard_task_runner.py:52} INFO - Started process 207 to run task
[2024-05-06 09:24:44,014] {standard_task_runner.py:76} INFO - Running: ['***', 'tasks', 'run', 'ingest_data_bigquery_yt', 'local_to_gcs_task', 'scheduled__2019-06-02T06:00:00+00:00', '--job-id', '4566', '--raw', '--subdir', 'DAGS_FOLDER/data_ingstion_gcs_yt_dag.py', '--cfg-path', '/tmp/tmpjl6b7b3u', '--error-file', '/tmp/tmp6vzh52em']
[2024-05-06 09:24:44,054] {standard_task_runner.py:77} INFO - Job 4566: Subtask local_to_gcs_task
[2024-05-06 09:24:44,613] {logging_mixin.py:109} INFO - Running <TaskInstance: ingest_data_bigquery_yt.local_to_gcs_task scheduled__2019-06-02T06:00:00+00:00 [running]> on host 4d4efceb404e
[2024-05-06 09:24:44,808] {warnings.py:99} WARNING - /home/***/.local/lib/python3.6/site-packages/***/utils/context.py:152: AirflowContextDeprecationWarning: Accessing 'execution_date' from the template is deprecated and will be removed in a future version. Please use 'data_interval_start' or 'logical_date' instead.
  warnings.warn(_create_deprecation_warning(key, self._deprecation_replacements[key]))

[2024-05-06 09:24:44,932] {taskinstance.py:1426} INFO - Exporting the following env vars:
AIRFLOW_CTX_DAG_OWNER=***
AIRFLOW_CTX_DAG_ID=ingest_data_bigquery_yt
AIRFLOW_CTX_TASK_ID=local_to_gcs_task
AIRFLOW_CTX_EXECUTION_DATE=2019-06-02T06:00:00+00:00
AIRFLOW_CTX_DAG_RUN_ID=scheduled__2019-06-02T06:00:00+00:00
[2024-05-06 09:24:45,083] {taskinstance.py:1700} ERROR - Task failed with exception
Traceback (most recent call last):
  File "/home/airflow/.local/lib/python3.6/site-packages/airflow/models/taskinstance.py", line 1329, in _run_raw_task
    self._execute_task_with_callbacks(context)
  File "/home/airflow/.local/lib/python3.6/site-packages/airflow/models/taskinstance.py", line 1455, in _execute_task_with_callbacks
    result = self._execute_task(context, self.task)
  File "/home/airflow/.local/lib/python3.6/site-packages/airflow/models/taskinstance.py", line 1511, in _execute_task
    result = execute_callable(context=context)
  File "/home/airflow/.local/lib/python3.6/site-packages/airflow/operators/python.py", line 174, in execute
    return_value = self.execute_callable()
  File "/home/airflow/.local/lib/python3.6/site-packages/airflow/operators/python.py", line 185, in execute_callable
    return self.python_callable(*self.op_args, **self.op_kwargs)
  File "/opt/airflow/dags/data_ingstion_gcs_yt_dag.py", line 84, in upload_to_gcs
    __clean_file(raw_file_name, clean_file_name)
  File "/opt/airflow/dags/data_ingstion_gcs_yt_dag.py", line 59, in __clean_file
    parse_dates=["tpep_pickup_datetime", "tpep_dropoff_datetime"],
  File "/home/airflow/.local/lib/python3.6/site-packages/pandas/io/parsers.py", line 688, in read_csv
    return _read(filepath_or_buffer, kwds)
  File "/home/airflow/.local/lib/python3.6/site-packages/pandas/io/parsers.py", line 454, in _read
    parser = TextFileReader(fp_or_buf, **kwds)
  File "/home/airflow/.local/lib/python3.6/site-packages/pandas/io/parsers.py", line 948, in __init__
    self._make_engine(self.engine)
  File "/home/airflow/.local/lib/python3.6/site-packages/pandas/io/parsers.py", line 1180, in _make_engine
    self._engine = CParserWrapper(self.f, **self.options)
  File "/home/airflow/.local/lib/python3.6/site-packages/pandas/io/parsers.py", line 2010, in __init__
    self._reader = parsers.TextReader(src, **kwds)
  File "pandas/_libs/parsers.pyx", line 382, in pandas._libs.parsers.TextReader.__cinit__
  File "pandas/_libs/parsers.pyx", line 674, in pandas._libs.parsers.TextReader._setup_parser_source
FileNotFoundError: [Errno 2] No such file or directory: '/opt/airflow/raw_data/yellowtaxi_tripdata_2019-06.csv'
[2024-05-06 09:24:45,252] {taskinstance.py:1277} INFO - Marking task as FAILED. dag_id=ingest_data_bigquery_yt, task_id=local_to_gcs_task, execution_date=20190602T060000, start_date=20240506T092443, end_date=20240506T092445
[2024-05-06 09:24:45,465] {standard_task_runner.py:92} ERROR - Failed to execute job 4566 for task local_to_gcs_task
Traceback (most recent call last):
  File "/home/airflow/.local/lib/python3.6/site-packages/airflow/task/task_runner/standard_task_runner.py", line 85, in _start_by_fork
    args.func(args, dag=self.dag)
  File "/home/airflow/.local/lib/python3.6/site-packages/airflow/cli/cli_parser.py", line 48, in command
    return func(*args, **kwargs)
  File "/home/airflow/.local/lib/python3.6/site-packages/airflow/utils/cli.py", line 92, in wrapper
    return f(*args, **kwargs)
  File "/home/airflow/.local/lib/python3.6/site-packages/airflow/cli/commands/task_command.py", line 298, in task_run
    _run_task_by_selected_method(args, dag, ti)
  File "/home/airflow/.local/lib/python3.6/site-packages/airflow/cli/commands/task_command.py", line 107, in _run_task_by_selected_method
    _run_raw_task(args, ti)
  File "/home/airflow/.local/lib/python3.6/site-packages/airflow/cli/commands/task_command.py", line 184, in _run_raw_task
    error_file=args.error_file,
  File "/home/airflow/.local/lib/python3.6/site-packages/airflow/utils/session.py", line 70, in wrapper
    return func(*args, session=session, **kwargs)
  File "/home/airflow/.local/lib/python3.6/site-packages/airflow/models/taskinstance.py", line 1329, in _run_raw_task
    self._execute_task_with_callbacks(context)
  File "/home/airflow/.local/lib/python3.6/site-packages/airflow/models/taskinstance.py", line 1455, in _execute_task_with_callbacks
    result = self._execute_task(context, self.task)
  File "/home/airflow/.local/lib/python3.6/site-packages/airflow/models/taskinstance.py", line 1511, in _execute_task
    result = execute_callable(context=context)
  File "/home/airflow/.local/lib/python3.6/site-packages/airflow/operators/python.py", line 174, in execute
    return_value = self.execute_callable()
  File "/home/airflow/.local/lib/python3.6/site-packages/airflow/operators/python.py", line 185, in execute_callable
    return self.python_callable(*self.op_args, **self.op_kwargs)
  File "/opt/airflow/dags/data_ingstion_gcs_yt_dag.py", line 84, in upload_to_gcs
    __clean_file(raw_file_name, clean_file_name)
  File "/opt/airflow/dags/data_ingstion_gcs_yt_dag.py", line 59, in __clean_file
    parse_dates=["tpep_pickup_datetime", "tpep_dropoff_datetime"],
  File "/home/airflow/.local/lib/python3.6/site-packages/pandas/io/parsers.py", line 688, in read_csv
    return _read(filepath_or_buffer, kwds)
  File "/home/airflow/.local/lib/python3.6/site-packages/pandas/io/parsers.py", line 454, in _read
    parser = TextFileReader(fp_or_buf, **kwds)
  File "/home/airflow/.local/lib/python3.6/site-packages/pandas/io/parsers.py", line 948, in __init__
    self._make_engine(self.engine)
  File "/home/airflow/.local/lib/python3.6/site-packages/pandas/io/parsers.py", line 1180, in _make_engine
    self._engine = CParserWrapper(self.f, **self.options)
  File "/home/airflow/.local/lib/python3.6/site-packages/pandas/io/parsers.py", line 2010, in __init__
    self._reader = parsers.TextReader(src, **kwds)
  File "pandas/_libs/parsers.pyx", line 382, in pandas._libs.parsers.TextReader.__cinit__
  File "pandas/_libs/parsers.pyx", line 674, in pandas._libs.parsers.TextReader._setup_parser_source
FileNotFoundError: [Errno 2] No such file or directory: '/opt/airflow/raw_data/yellowtaxi_tripdata_2019-06.csv'
[2024-05-06 09:24:45,597] {local_task_job.py:154} INFO - Task exited with return code 1
[2024-05-06 09:24:45,960] {local_task_job.py:264} INFO - 0 downstream tasks scheduled from follow-on schedule check
