[2024-03-30 11:10:25,488] {taskinstance.py:1032} INFO - Dependencies all met for <TaskInstance: ingest_data_bigquery.local_to_gcs_task scheduled__2021-12-02T06:00:00+00:00 [queued]>
[2024-03-30 11:10:25,591] {taskinstance.py:1032} INFO - Dependencies all met for <TaskInstance: ingest_data_bigquery.local_to_gcs_task scheduled__2021-12-02T06:00:00+00:00 [queued]>
[2024-03-30 11:10:25,591] {taskinstance.py:1238} INFO - 
--------------------------------------------------------------------------------
[2024-03-30 11:10:25,591] {taskinstance.py:1239} INFO - Starting attempt 2 of 4
[2024-03-30 11:10:25,594] {taskinstance.py:1240} INFO - 
--------------------------------------------------------------------------------
[2024-03-30 11:10:25,663] {taskinstance.py:1259} INFO - Executing <Task(PythonOperator): local_to_gcs_task> on 2021-12-02 06:00:00+00:00
[2024-03-30 11:10:25,691] {standard_task_runner.py:52} INFO - Started process 24976 to run task
[2024-03-30 11:10:25,742] {standard_task_runner.py:76} INFO - Running: ['***', 'tasks', 'run', 'ingest_data_bigquery', 'local_to_gcs_task', 'scheduled__2021-12-02T06:00:00+00:00', '--job-id', '2717', '--raw', '--subdir', 'DAGS_FOLDER/data_ingestion_gcs_dag.py', '--cfg-path', '/tmp/tmpuzblvg09', '--error-file', '/tmp/tmp3iunkp0f']
[2024-03-30 11:10:25,783] {standard_task_runner.py:77} INFO - Job 2717: Subtask local_to_gcs_task
[2024-03-30 11:10:26,158] {logging_mixin.py:109} INFO - Running <TaskInstance: ingest_data_bigquery.local_to_gcs_task scheduled__2021-12-02T06:00:00+00:00 [running]> on host 98c5b3fde4c4
[2024-03-30 11:10:26,277] {warnings.py:99} WARNING - /home/***/.local/lib/python3.6/site-packages/***/utils/context.py:152: AirflowContextDeprecationWarning: Accessing 'execution_date' from the template is deprecated and will be removed in a future version. Please use 'data_interval_start' or 'logical_date' instead.
  warnings.warn(_create_deprecation_warning(key, self._deprecation_replacements[key]))

[2024-03-30 11:10:26,348] {taskinstance.py:1426} INFO - Exporting the following env vars:
AIRFLOW_CTX_DAG_OWNER=***
AIRFLOW_CTX_DAG_ID=ingest_data_bigquery
AIRFLOW_CTX_TASK_ID=local_to_gcs_task
AIRFLOW_CTX_EXECUTION_DATE=2021-12-02T06:00:00+00:00
AIRFLOW_CTX_DAG_RUN_ID=scheduled__2021-12-02T06:00:00+00:00
[2024-03-30 11:10:36,852] {taskinstance.py:1700} ERROR - Task failed with exception
Traceback (most recent call last):
  File "/home/airflow/.local/lib/python3.6/site-packages/airflow/models/taskinstance.py", line 1329, in _run_raw_task
    self._execute_task_with_callbacks(context)
  File "/home/airflow/.local/lib/python3.6/site-packages/airflow/models/taskinstance.py", line 1455, in _execute_task_with_callbacks
    result = self._execute_task(context, self.task)
  File "/home/airflow/.local/lib/python3.6/site-packages/airflow/models/taskinstance.py", line 1511, in _execute_task
    result = execute_callable(context=context)
  File "/home/airflow/.local/lib/python3.6/site-packages/airflow/operators/python.py", line 174, in execute
    return_value = self.execute_callable()
  File "/home/airflow/.local/lib/python3.6/site-packages/airflow/operators/python.py", line 185, in execute_callable
    return self.python_callable(*self.op_args, **self.op_kwargs)
  File "/opt/airflow/dags/data_ingestion_gcs_dag.py", line 61, in upload_to_gcs
    index=False,
  File "/home/airflow/.local/lib/python3.6/site-packages/pandas/util/_decorators.py", line 199, in wrapper
    return func(*args, **kwargs)
  File "/home/airflow/.local/lib/python3.6/site-packages/pandas/core/frame.py", line 2372, in to_parquet
    **kwargs,
  File "/home/airflow/.local/lib/python3.6/site-packages/pandas/io/parquet.py", line 276, in to_parquet
    **kwargs,
  File "/home/airflow/.local/lib/python3.6/site-packages/pandas/io/parquet.py", line 101, in write
    table = self.api.Table.from_pandas(df, **from_pandas_kwargs)
  File "pyarrow/table.pxi", line 1561, in pyarrow.lib.Table.from_pandas
  File "/home/airflow/.local/lib/python3.6/site-packages/pyarrow/pandas_compat.py", line 607, in dataframe_to_arrays
    arrays[i] = maybe_fut.result()
  File "/usr/local/lib/python3.6/concurrent/futures/_base.py", line 425, in result
    return self.__get_result()
  File "/usr/local/lib/python3.6/concurrent/futures/_base.py", line 384, in __get_result
    raise self._exception
  File "/usr/local/lib/python3.6/concurrent/futures/thread.py", line 56, in run
    result = self.fn(*self.args, **self.kwargs)
  File "/home/airflow/.local/lib/python3.6/site-packages/pyarrow/pandas_compat.py", line 581, in convert_column
    raise e
  File "/home/airflow/.local/lib/python3.6/site-packages/pyarrow/pandas_compat.py", line 575, in convert_column
    result = pa.array(col, type=type_, from_pandas=True, safe=safe)
  File "pyarrow/array.pxi", line 302, in pyarrow.lib.array
  File "pyarrow/array.pxi", line 83, in pyarrow.lib._ndarray_to_array
  File "pyarrow/error.pxi", line 122, in pyarrow.lib.check_status
pyarrow.lib.ArrowTypeError: ("Expected bytes, got a 'int' object", 'Conversion failed for column store_and_fwd_flag with type object')
[2024-03-30 11:10:36,872] {taskinstance.py:1277} INFO - Marking task as UP_FOR_RETRY. dag_id=ingest_data_bigquery, task_id=local_to_gcs_task, execution_date=20211202T060000, start_date=20240330T111025, end_date=20240330T111036
[2024-03-30 11:10:36,884] {standard_task_runner.py:92} ERROR - Failed to execute job 2717 for task local_to_gcs_task
Traceback (most recent call last):
  File "/home/airflow/.local/lib/python3.6/site-packages/airflow/task/task_runner/standard_task_runner.py", line 85, in _start_by_fork
    args.func(args, dag=self.dag)
  File "/home/airflow/.local/lib/python3.6/site-packages/airflow/cli/cli_parser.py", line 48, in command
    return func(*args, **kwargs)
  File "/home/airflow/.local/lib/python3.6/site-packages/airflow/utils/cli.py", line 92, in wrapper
    return f(*args, **kwargs)
  File "/home/airflow/.local/lib/python3.6/site-packages/airflow/cli/commands/task_command.py", line 298, in task_run
    _run_task_by_selected_method(args, dag, ti)
  File "/home/airflow/.local/lib/python3.6/site-packages/airflow/cli/commands/task_command.py", line 107, in _run_task_by_selected_method
    _run_raw_task(args, ti)
  File "/home/airflow/.local/lib/python3.6/site-packages/airflow/cli/commands/task_command.py", line 184, in _run_raw_task
    error_file=args.error_file,
  File "/home/airflow/.local/lib/python3.6/site-packages/airflow/utils/session.py", line 70, in wrapper
    return func(*args, session=session, **kwargs)
  File "/home/airflow/.local/lib/python3.6/site-packages/airflow/models/taskinstance.py", line 1329, in _run_raw_task
    self._execute_task_with_callbacks(context)
  File "/home/airflow/.local/lib/python3.6/site-packages/airflow/models/taskinstance.py", line 1455, in _execute_task_with_callbacks
    result = self._execute_task(context, self.task)
  File "/home/airflow/.local/lib/python3.6/site-packages/airflow/models/taskinstance.py", line 1511, in _execute_task
    result = execute_callable(context=context)
  File "/home/airflow/.local/lib/python3.6/site-packages/airflow/operators/python.py", line 174, in execute
    return_value = self.execute_callable()
  File "/home/airflow/.local/lib/python3.6/site-packages/airflow/operators/python.py", line 185, in execute_callable
    return self.python_callable(*self.op_args, **self.op_kwargs)
  File "/opt/airflow/dags/data_ingestion_gcs_dag.py", line 61, in upload_to_gcs
    index=False,
  File "/home/airflow/.local/lib/python3.6/site-packages/pandas/util/_decorators.py", line 199, in wrapper
    return func(*args, **kwargs)
  File "/home/airflow/.local/lib/python3.6/site-packages/pandas/core/frame.py", line 2372, in to_parquet
    **kwargs,
  File "/home/airflow/.local/lib/python3.6/site-packages/pandas/io/parquet.py", line 276, in to_parquet
    **kwargs,
  File "/home/airflow/.local/lib/python3.6/site-packages/pandas/io/parquet.py", line 101, in write
    table = self.api.Table.from_pandas(df, **from_pandas_kwargs)
  File "pyarrow/table.pxi", line 1561, in pyarrow.lib.Table.from_pandas
  File "/home/airflow/.local/lib/python3.6/site-packages/pyarrow/pandas_compat.py", line 607, in dataframe_to_arrays
    arrays[i] = maybe_fut.result()
  File "/usr/local/lib/python3.6/concurrent/futures/_base.py", line 425, in result
    return self.__get_result()
  File "/usr/local/lib/python3.6/concurrent/futures/_base.py", line 384, in __get_result
    raise self._exception
  File "/usr/local/lib/python3.6/concurrent/futures/thread.py", line 56, in run
    result = self.fn(*self.args, **self.kwargs)
  File "/home/airflow/.local/lib/python3.6/site-packages/pyarrow/pandas_compat.py", line 581, in convert_column
    raise e
  File "/home/airflow/.local/lib/python3.6/site-packages/pyarrow/pandas_compat.py", line 575, in convert_column
    result = pa.array(col, type=type_, from_pandas=True, safe=safe)
  File "pyarrow/array.pxi", line 302, in pyarrow.lib.array
  File "pyarrow/array.pxi", line 83, in pyarrow.lib._ndarray_to_array
  File "pyarrow/error.pxi", line 122, in pyarrow.lib.check_status
pyarrow.lib.ArrowTypeError: ("Expected bytes, got a 'int' object", 'Conversion failed for column store_and_fwd_flag with type object')
[2024-03-30 11:10:36,942] {local_task_job.py:154} INFO - Task exited with return code 1
[2024-03-30 11:10:37,255] {local_task_job.py:264} INFO - 0 downstream tasks scheduled from follow-on schedule check
[2024-03-30 11:21:11,639] {taskinstance.py:1032} INFO - Dependencies all met for <TaskInstance: ingest_data_bigquery.local_to_gcs_task scheduled__2021-12-02T06:00:00+00:00 [queued]>
[2024-03-30 11:21:11,660] {taskinstance.py:1032} INFO - Dependencies all met for <TaskInstance: ingest_data_bigquery.local_to_gcs_task scheduled__2021-12-02T06:00:00+00:00 [queued]>
[2024-03-30 11:21:11,660] {taskinstance.py:1238} INFO - 
--------------------------------------------------------------------------------
[2024-03-30 11:21:11,660] {taskinstance.py:1239} INFO - Starting attempt 2 of 4
[2024-03-30 11:21:11,660] {taskinstance.py:1240} INFO - 
--------------------------------------------------------------------------------
[2024-03-30 11:21:11,686] {taskinstance.py:1259} INFO - Executing <Task(PythonOperator): local_to_gcs_task> on 2021-12-02 06:00:00+00:00
[2024-03-30 11:21:11,697] {standard_task_runner.py:52} INFO - Started process 25863 to run task
[2024-03-30 11:21:11,717] {standard_task_runner.py:76} INFO - Running: ['***', 'tasks', 'run', 'ingest_data_bigquery', 'local_to_gcs_task', 'scheduled__2021-12-02T06:00:00+00:00', '--job-id', '2761', '--raw', '--subdir', 'DAGS_FOLDER/data_ingestion_gcs_dag.py', '--cfg-path', '/tmp/tmpmc9hpk_o', '--error-file', '/tmp/tmpxwq9z2hw']
[2024-03-30 11:21:11,723] {standard_task_runner.py:77} INFO - Job 2761: Subtask local_to_gcs_task
[2024-03-30 11:21:11,836] {logging_mixin.py:109} INFO - Running <TaskInstance: ingest_data_bigquery.local_to_gcs_task scheduled__2021-12-02T06:00:00+00:00 [running]> on host 98c5b3fde4c4
[2024-03-30 11:21:11,908] {warnings.py:99} WARNING - /home/***/.local/lib/python3.6/site-packages/***/utils/context.py:152: AirflowContextDeprecationWarning: Accessing 'execution_date' from the template is deprecated and will be removed in a future version. Please use 'data_interval_start' or 'logical_date' instead.
  warnings.warn(_create_deprecation_warning(key, self._deprecation_replacements[key]))

[2024-03-30 11:21:11,955] {taskinstance.py:1426} INFO - Exporting the following env vars:
AIRFLOW_CTX_DAG_OWNER=***
AIRFLOW_CTX_DAG_ID=ingest_data_bigquery
AIRFLOW_CTX_TASK_ID=local_to_gcs_task
AIRFLOW_CTX_EXECUTION_DATE=2021-12-02T06:00:00+00:00
AIRFLOW_CTX_DAG_RUN_ID=scheduled__2021-12-02T06:00:00+00:00
[2024-03-30 11:21:18,259] {taskinstance.py:1700} ERROR - Task failed with exception
Traceback (most recent call last):
  File "/home/airflow/.local/lib/python3.6/site-packages/airflow/models/taskinstance.py", line 1329, in _run_raw_task
    self._execute_task_with_callbacks(context)
  File "/home/airflow/.local/lib/python3.6/site-packages/airflow/models/taskinstance.py", line 1455, in _execute_task_with_callbacks
    result = self._execute_task(context, self.task)
  File "/home/airflow/.local/lib/python3.6/site-packages/airflow/models/taskinstance.py", line 1511, in _execute_task
    result = execute_callable(context=context)
  File "/home/airflow/.local/lib/python3.6/site-packages/airflow/operators/python.py", line 174, in execute
    return_value = self.execute_callable()
  File "/home/airflow/.local/lib/python3.6/site-packages/airflow/operators/python.py", line 185, in execute_callable
    return self.python_callable(*self.op_args, **self.op_kwargs)
  File "/opt/airflow/dags/data_ingestion_gcs_dag.py", line 65, in upload_to_gcs
    index=False,
  File "/home/airflow/.local/lib/python3.6/site-packages/pandas/util/_decorators.py", line 199, in wrapper
    return func(*args, **kwargs)
  File "/home/airflow/.local/lib/python3.6/site-packages/pandas/core/frame.py", line 2372, in to_parquet
    **kwargs,
  File "/home/airflow/.local/lib/python3.6/site-packages/pandas/io/parquet.py", line 276, in to_parquet
    **kwargs,
  File "/home/airflow/.local/lib/python3.6/site-packages/pandas/io/parquet.py", line 101, in write
    table = self.api.Table.from_pandas(df, **from_pandas_kwargs)
  File "pyarrow/table.pxi", line 1561, in pyarrow.lib.Table.from_pandas
  File "/home/airflow/.local/lib/python3.6/site-packages/pyarrow/pandas_compat.py", line 607, in dataframe_to_arrays
    arrays[i] = maybe_fut.result()
  File "/usr/local/lib/python3.6/concurrent/futures/_base.py", line 425, in result
    return self.__get_result()
  File "/usr/local/lib/python3.6/concurrent/futures/_base.py", line 384, in __get_result
    raise self._exception
  File "/usr/local/lib/python3.6/concurrent/futures/thread.py", line 56, in run
    result = self.fn(*self.args, **self.kwargs)
  File "/home/airflow/.local/lib/python3.6/site-packages/pyarrow/pandas_compat.py", line 581, in convert_column
    raise e
  File "/home/airflow/.local/lib/python3.6/site-packages/pyarrow/pandas_compat.py", line 575, in convert_column
    result = pa.array(col, type=type_, from_pandas=True, safe=safe)
  File "pyarrow/array.pxi", line 302, in pyarrow.lib.array
  File "pyarrow/array.pxi", line 83, in pyarrow.lib._ndarray_to_array
  File "pyarrow/error.pxi", line 122, in pyarrow.lib.check_status
pyarrow.lib.ArrowTypeError: ("Expected bytes, got a 'int' object", 'Conversion failed for column store_and_fwd_flag with type object')
[2024-03-30 11:21:18,296] {taskinstance.py:1277} INFO - Marking task as UP_FOR_RETRY. dag_id=ingest_data_bigquery, task_id=local_to_gcs_task, execution_date=20211202T060000, start_date=20240330T112111, end_date=20240330T112118
[2024-03-30 11:21:18,339] {standard_task_runner.py:92} ERROR - Failed to execute job 2761 for task local_to_gcs_task
Traceback (most recent call last):
  File "/home/airflow/.local/lib/python3.6/site-packages/airflow/task/task_runner/standard_task_runner.py", line 85, in _start_by_fork
    args.func(args, dag=self.dag)
  File "/home/airflow/.local/lib/python3.6/site-packages/airflow/cli/cli_parser.py", line 48, in command
    return func(*args, **kwargs)
  File "/home/airflow/.local/lib/python3.6/site-packages/airflow/utils/cli.py", line 92, in wrapper
    return f(*args, **kwargs)
  File "/home/airflow/.local/lib/python3.6/site-packages/airflow/cli/commands/task_command.py", line 298, in task_run
    _run_task_by_selected_method(args, dag, ti)
  File "/home/airflow/.local/lib/python3.6/site-packages/airflow/cli/commands/task_command.py", line 107, in _run_task_by_selected_method
    _run_raw_task(args, ti)
  File "/home/airflow/.local/lib/python3.6/site-packages/airflow/cli/commands/task_command.py", line 184, in _run_raw_task
    error_file=args.error_file,
  File "/home/airflow/.local/lib/python3.6/site-packages/airflow/utils/session.py", line 70, in wrapper
    return func(*args, session=session, **kwargs)
  File "/home/airflow/.local/lib/python3.6/site-packages/airflow/models/taskinstance.py", line 1329, in _run_raw_task
    self._execute_task_with_callbacks(context)
  File "/home/airflow/.local/lib/python3.6/site-packages/airflow/models/taskinstance.py", line 1455, in _execute_task_with_callbacks
    result = self._execute_task(context, self.task)
  File "/home/airflow/.local/lib/python3.6/site-packages/airflow/models/taskinstance.py", line 1511, in _execute_task
    result = execute_callable(context=context)
  File "/home/airflow/.local/lib/python3.6/site-packages/airflow/operators/python.py", line 174, in execute
    return_value = self.execute_callable()
  File "/home/airflow/.local/lib/python3.6/site-packages/airflow/operators/python.py", line 185, in execute_callable
    return self.python_callable(*self.op_args, **self.op_kwargs)
  File "/opt/airflow/dags/data_ingestion_gcs_dag.py", line 65, in upload_to_gcs
    index=False,
  File "/home/airflow/.local/lib/python3.6/site-packages/pandas/util/_decorators.py", line 199, in wrapper
    return func(*args, **kwargs)
  File "/home/airflow/.local/lib/python3.6/site-packages/pandas/core/frame.py", line 2372, in to_parquet
    **kwargs,
  File "/home/airflow/.local/lib/python3.6/site-packages/pandas/io/parquet.py", line 276, in to_parquet
    **kwargs,
  File "/home/airflow/.local/lib/python3.6/site-packages/pandas/io/parquet.py", line 101, in write
    table = self.api.Table.from_pandas(df, **from_pandas_kwargs)
  File "pyarrow/table.pxi", line 1561, in pyarrow.lib.Table.from_pandas
  File "/home/airflow/.local/lib/python3.6/site-packages/pyarrow/pandas_compat.py", line 607, in dataframe_to_arrays
    arrays[i] = maybe_fut.result()
  File "/usr/local/lib/python3.6/concurrent/futures/_base.py", line 425, in result
    return self.__get_result()
  File "/usr/local/lib/python3.6/concurrent/futures/_base.py", line 384, in __get_result
    raise self._exception
  File "/usr/local/lib/python3.6/concurrent/futures/thread.py", line 56, in run
    result = self.fn(*self.args, **self.kwargs)
  File "/home/airflow/.local/lib/python3.6/site-packages/pyarrow/pandas_compat.py", line 581, in convert_column
    raise e
  File "/home/airflow/.local/lib/python3.6/site-packages/pyarrow/pandas_compat.py", line 575, in convert_column
    result = pa.array(col, type=type_, from_pandas=True, safe=safe)
  File "pyarrow/array.pxi", line 302, in pyarrow.lib.array
  File "pyarrow/array.pxi", line 83, in pyarrow.lib._ndarray_to_array
  File "pyarrow/error.pxi", line 122, in pyarrow.lib.check_status
pyarrow.lib.ArrowTypeError: ("Expected bytes, got a 'int' object", 'Conversion failed for column store_and_fwd_flag with type object')
[2024-03-30 11:21:18,512] {local_task_job.py:154} INFO - Task exited with return code 1
[2024-03-30 11:21:18,590] {local_task_job.py:264} INFO - 0 downstream tasks scheduled from follow-on schedule check
[2024-03-30 11:45:55,808] {taskinstance.py:1032} INFO - Dependencies all met for <TaskInstance: ingest_data_bigquery.local_to_gcs_task scheduled__2021-12-02T06:00:00+00:00 [queued]>
[2024-03-30 11:45:55,912] {taskinstance.py:1032} INFO - Dependencies all met for <TaskInstance: ingest_data_bigquery.local_to_gcs_task scheduled__2021-12-02T06:00:00+00:00 [queued]>
[2024-03-30 11:45:55,913] {taskinstance.py:1238} INFO - 
--------------------------------------------------------------------------------
[2024-03-30 11:45:55,913] {taskinstance.py:1239} INFO - Starting attempt 2 of 4
[2024-03-30 11:45:55,913] {taskinstance.py:1240} INFO - 
--------------------------------------------------------------------------------
[2024-03-30 11:45:56,019] {taskinstance.py:1259} INFO - Executing <Task(PythonOperator): local_to_gcs_task> on 2021-12-02 06:00:00+00:00
[2024-03-30 11:45:56,067] {standard_task_runner.py:52} INFO - Started process 27393 to run task
[2024-03-30 11:45:56,106] {standard_task_runner.py:76} INFO - Running: ['***', 'tasks', 'run', 'ingest_data_bigquery', 'local_to_gcs_task', 'scheduled__2021-12-02T06:00:00+00:00', '--job-id', '2836', '--raw', '--subdir', 'DAGS_FOLDER/data_ingestion_gcs_dag.py', '--cfg-path', '/tmp/tmpiio5zx_d', '--error-file', '/tmp/tmp3jg38n4v']
[2024-03-30 11:45:56,143] {standard_task_runner.py:77} INFO - Job 2836: Subtask local_to_gcs_task
[2024-03-30 11:45:56,601] {logging_mixin.py:109} INFO - Running <TaskInstance: ingest_data_bigquery.local_to_gcs_task scheduled__2021-12-02T06:00:00+00:00 [running]> on host 98c5b3fde4c4
[2024-03-30 11:45:56,825] {warnings.py:99} WARNING - /home/***/.local/lib/python3.6/site-packages/***/utils/context.py:152: AirflowContextDeprecationWarning: Accessing 'execution_date' from the template is deprecated and will be removed in a future version. Please use 'data_interval_start' or 'logical_date' instead.
  warnings.warn(_create_deprecation_warning(key, self._deprecation_replacements[key]))

[2024-03-30 11:45:56,999] {taskinstance.py:1426} INFO - Exporting the following env vars:
AIRFLOW_CTX_DAG_OWNER=***
AIRFLOW_CTX_DAG_ID=ingest_data_bigquery
AIRFLOW_CTX_TASK_ID=local_to_gcs_task
AIRFLOW_CTX_EXECUTION_DATE=2021-12-02T06:00:00+00:00
AIRFLOW_CTX_DAG_RUN_ID=scheduled__2021-12-02T06:00:00+00:00
[2024-03-30 11:46:31,322] {local_task_job.py:154} INFO - Task exited with return code Negsignal.SIGKILL
[2024-03-30 11:46:31,568] {taskinstance.py:1277} INFO - Marking task as UP_FOR_RETRY. dag_id=ingest_data_bigquery, task_id=local_to_gcs_task, execution_date=20211202T060000, start_date=20240330T114555, end_date=20240330T114631
[2024-03-30 11:46:36,346] {local_task_job.py:264} INFO - 0 downstream tasks scheduled from follow-on schedule check
[2024-04-30 02:19:58,070] {taskinstance.py:1032} INFO - Dependencies all met for <TaskInstance: ingest_data_bigquery.local_to_gcs_task scheduled__2021-12-02T06:00:00+00:00 [queued]>
[2024-04-30 02:19:58,200] {taskinstance.py:1032} INFO - Dependencies all met for <TaskInstance: ingest_data_bigquery.local_to_gcs_task scheduled__2021-12-02T06:00:00+00:00 [queued]>
[2024-04-30 02:19:58,200] {taskinstance.py:1238} INFO - 
--------------------------------------------------------------------------------
[2024-04-30 02:19:58,200] {taskinstance.py:1239} INFO - Starting attempt 2 of 4
[2024-04-30 02:19:58,200] {taskinstance.py:1240} INFO - 
--------------------------------------------------------------------------------
[2024-04-30 02:19:58,304] {taskinstance.py:1259} INFO - Executing <Task(PythonOperator): local_to_gcs_task> on 2021-12-02 06:00:00+00:00
[2024-04-30 02:19:58,412] {standard_task_runner.py:76} INFO - Running: ['***', 'tasks', 'run', 'ingest_data_bigquery', 'local_to_gcs_task', 'scheduled__2021-12-02T06:00:00+00:00', '--job-id', '3057', '--raw', '--subdir', 'DAGS_FOLDER/data_ingestion_gcs_dag.py', '--cfg-path', '/tmp/tmpibejro8a', '--error-file', '/tmp/tmpz5act1bt']
[2024-04-30 02:19:58,428] {standard_task_runner.py:77} INFO - Job 3057: Subtask local_to_gcs_task
[2024-04-30 02:19:58,363] {standard_task_runner.py:52} INFO - Started process 814 to run task
[2024-04-30 02:19:58,826] {logging_mixin.py:109} INFO - Running <TaskInstance: ingest_data_bigquery.local_to_gcs_task scheduled__2021-12-02T06:00:00+00:00 [running]> on host a1ae6a0259c5
[2024-04-30 02:19:59,134] {warnings.py:99} WARNING - /home/***/.local/lib/python3.6/site-packages/***/utils/context.py:152: AirflowContextDeprecationWarning: Accessing 'execution_date' from the template is deprecated and will be removed in a future version. Please use 'data_interval_start' or 'logical_date' instead.
  warnings.warn(_create_deprecation_warning(key, self._deprecation_replacements[key]))

[2024-04-30 02:19:59,316] {taskinstance.py:1426} INFO - Exporting the following env vars:
AIRFLOW_CTX_DAG_OWNER=***
AIRFLOW_CTX_DAG_ID=ingest_data_bigquery
AIRFLOW_CTX_TASK_ID=local_to_gcs_task
AIRFLOW_CTX_EXECUTION_DATE=2021-12-02T06:00:00+00:00
AIRFLOW_CTX_DAG_RUN_ID=scheduled__2021-12-02T06:00:00+00:00
[2024-04-30 02:20:12,079] {local_task_job.py:154} INFO - Task exited with return code Negsignal.SIGKILL
[2024-04-30 02:20:30,123] {taskinstance.py:1277} INFO - Marking task as UP_FOR_RETRY. dag_id=ingest_data_bigquery, task_id=local_to_gcs_task, execution_date=20211202T060000, start_date=20240430T021958, end_date=20240430T022030
[2024-04-30 02:20:31,054] {local_task_job.py:264} INFO - 0 downstream tasks scheduled from follow-on schedule check
[2024-04-30 06:43:59,511] {taskinstance.py:1032} INFO - Dependencies all met for <TaskInstance: ingest_data_bigquery.local_to_gcs_task scheduled__2021-12-02T06:00:00+00:00 [queued]>
[2024-04-30 06:43:59,560] {taskinstance.py:1032} INFO - Dependencies all met for <TaskInstance: ingest_data_bigquery.local_to_gcs_task scheduled__2021-12-02T06:00:00+00:00 [queued]>
[2024-04-30 06:43:59,560] {taskinstance.py:1238} INFO - 
--------------------------------------------------------------------------------
[2024-04-30 06:43:59,560] {taskinstance.py:1239} INFO - Starting attempt 2 of 2
[2024-04-30 06:43:59,561] {taskinstance.py:1240} INFO - 
--------------------------------------------------------------------------------
[2024-04-30 06:43:59,644] {taskinstance.py:1259} INFO - Executing <Task(PythonOperator): local_to_gcs_task> on 2021-12-02 06:00:00+00:00
[2024-04-30 06:43:59,682] {standard_task_runner.py:76} INFO - Running: ['***', 'tasks', 'run', 'ingest_data_bigquery', 'local_to_gcs_task', 'scheduled__2021-12-02T06:00:00+00:00', '--job-id', '3645', '--raw', '--subdir', 'DAGS_FOLDER/data_ingestion_gcs_dag.py', '--cfg-path', '/tmp/tmpubd5m2oy', '--error-file', '/tmp/tmpy3lezsil']
[2024-04-30 06:43:59,726] {standard_task_runner.py:77} INFO - Job 3645: Subtask local_to_gcs_task
[2024-04-30 06:43:59,668] {standard_task_runner.py:52} INFO - Started process 94 to run task
[2024-04-30 06:44:00,116] {logging_mixin.py:109} INFO - Running <TaskInstance: ingest_data_bigquery.local_to_gcs_task scheduled__2021-12-02T06:00:00+00:00 [running]> on host 4d5ad4aa2a9b
[2024-04-30 06:44:00,402] {warnings.py:99} WARNING - /home/***/.local/lib/python3.6/site-packages/***/utils/context.py:152: AirflowContextDeprecationWarning: Accessing 'execution_date' from the template is deprecated and will be removed in a future version. Please use 'data_interval_start' or 'logical_date' instead.
  warnings.warn(_create_deprecation_warning(key, self._deprecation_replacements[key]))

[2024-04-30 06:44:00,525] {taskinstance.py:1426} INFO - Exporting the following env vars:
AIRFLOW_CTX_DAG_OWNER=***
AIRFLOW_CTX_DAG_ID=ingest_data_bigquery
AIRFLOW_CTX_TASK_ID=local_to_gcs_task
AIRFLOW_CTX_EXECUTION_DATE=2021-12-02T06:00:00+00:00
AIRFLOW_CTX_DAG_RUN_ID=scheduled__2021-12-02T06:00:00+00:00
[2024-04-30 06:44:01,114] {taskinstance.py:1700} ERROR - Task failed with exception
Traceback (most recent call last):
  File "/home/airflow/.local/lib/python3.6/site-packages/airflow/models/taskinstance.py", line 1329, in _run_raw_task
    self._execute_task_with_callbacks(context)
  File "/home/airflow/.local/lib/python3.6/site-packages/airflow/models/taskinstance.py", line 1455, in _execute_task_with_callbacks
    result = self._execute_task(context, self.task)
  File "/home/airflow/.local/lib/python3.6/site-packages/airflow/models/taskinstance.py", line 1511, in _execute_task
    result = execute_callable(context=context)
  File "/home/airflow/.local/lib/python3.6/site-packages/airflow/operators/python.py", line 174, in execute
    return_value = self.execute_callable()
  File "/home/airflow/.local/lib/python3.6/site-packages/airflow/operators/python.py", line 185, in execute_callable
    return self.python_callable(*self.op_args, **self.op_kwargs)
  File "/opt/airflow/dags/data_ingestion_gcs_dag.py", line 81, in upload_to_gcs
    __clean_file(raw_file_name, clean_file_name)
  File "/opt/airflow/dags/data_ingestion_gcs_dag.py", line 57, in __clean_file
    df = pd.read_parquet(raw_file_name)
  File "/home/airflow/.local/lib/python3.6/site-packages/pandas/io/parquet.py", line 317, in read_parquet
    return impl.read(path, columns=columns, **kwargs)
  File "/home/airflow/.local/lib/python3.6/site-packages/pandas/io/parquet.py", line 142, in read
    path, columns=columns, filesystem=fs, **kwargs
  File "/home/airflow/.local/lib/python3.6/site-packages/pyarrow/parquet.py", line 1869, in read_table
    coerce_int96_timestamp_unit=coerce_int96_timestamp_unit
  File "/home/airflow/.local/lib/python3.6/site-packages/pyarrow/parquet.py", line 1697, in __init__
    ignore_prefixes=ignore_prefixes)
  File "/home/airflow/.local/lib/python3.6/site-packages/pyarrow/dataset.py", line 655, in dataset
    return _filesystem_dataset(source, **kwargs)
  File "/home/airflow/.local/lib/python3.6/site-packages/pyarrow/dataset.py", line 400, in _filesystem_dataset
    fs, paths_or_selector = _ensure_single_source(source, filesystem)
  File "/home/airflow/.local/lib/python3.6/site-packages/pyarrow/dataset.py", line 376, in _ensure_single_source
    raise FileNotFoundError(path)
FileNotFoundError: /opt/***/raw_data/yellowtaxi_tripdata_2021-12.parquet
[2024-04-30 06:44:01,140] {taskinstance.py:1277} INFO - Marking task as FAILED. dag_id=ingest_data_bigquery, task_id=local_to_gcs_task, execution_date=20211202T060000, start_date=20240430T064359, end_date=20240430T064401
[2024-04-30 06:44:01,162] {standard_task_runner.py:92} ERROR - Failed to execute job 3645 for task local_to_gcs_task
Traceback (most recent call last):
  File "/home/airflow/.local/lib/python3.6/site-packages/airflow/task/task_runner/standard_task_runner.py", line 85, in _start_by_fork
    args.func(args, dag=self.dag)
  File "/home/airflow/.local/lib/python3.6/site-packages/airflow/cli/cli_parser.py", line 48, in command
    return func(*args, **kwargs)
  File "/home/airflow/.local/lib/python3.6/site-packages/airflow/utils/cli.py", line 92, in wrapper
    return f(*args, **kwargs)
  File "/home/airflow/.local/lib/python3.6/site-packages/airflow/cli/commands/task_command.py", line 298, in task_run
    _run_task_by_selected_method(args, dag, ti)
  File "/home/airflow/.local/lib/python3.6/site-packages/airflow/cli/commands/task_command.py", line 107, in _run_task_by_selected_method
    _run_raw_task(args, ti)
  File "/home/airflow/.local/lib/python3.6/site-packages/airflow/cli/commands/task_command.py", line 184, in _run_raw_task
    error_file=args.error_file,
  File "/home/airflow/.local/lib/python3.6/site-packages/airflow/utils/session.py", line 70, in wrapper
    return func(*args, session=session, **kwargs)
  File "/home/airflow/.local/lib/python3.6/site-packages/airflow/models/taskinstance.py", line 1329, in _run_raw_task
    self._execute_task_with_callbacks(context)
  File "/home/airflow/.local/lib/python3.6/site-packages/airflow/models/taskinstance.py", line 1455, in _execute_task_with_callbacks
    result = self._execute_task(context, self.task)
  File "/home/airflow/.local/lib/python3.6/site-packages/airflow/models/taskinstance.py", line 1511, in _execute_task
    result = execute_callable(context=context)
  File "/home/airflow/.local/lib/python3.6/site-packages/airflow/operators/python.py", line 174, in execute
    return_value = self.execute_callable()
  File "/home/airflow/.local/lib/python3.6/site-packages/airflow/operators/python.py", line 185, in execute_callable
    return self.python_callable(*self.op_args, **self.op_kwargs)
  File "/opt/airflow/dags/data_ingestion_gcs_dag.py", line 81, in upload_to_gcs
    __clean_file(raw_file_name, clean_file_name)
  File "/opt/airflow/dags/data_ingestion_gcs_dag.py", line 57, in __clean_file
    df = pd.read_parquet(raw_file_name)
  File "/home/airflow/.local/lib/python3.6/site-packages/pandas/io/parquet.py", line 317, in read_parquet
    return impl.read(path, columns=columns, **kwargs)
  File "/home/airflow/.local/lib/python3.6/site-packages/pandas/io/parquet.py", line 142, in read
    path, columns=columns, filesystem=fs, **kwargs
  File "/home/airflow/.local/lib/python3.6/site-packages/pyarrow/parquet.py", line 1869, in read_table
    coerce_int96_timestamp_unit=coerce_int96_timestamp_unit
  File "/home/airflow/.local/lib/python3.6/site-packages/pyarrow/parquet.py", line 1697, in __init__
    ignore_prefixes=ignore_prefixes)
  File "/home/airflow/.local/lib/python3.6/site-packages/pyarrow/dataset.py", line 655, in dataset
    return _filesystem_dataset(source, **kwargs)
  File "/home/airflow/.local/lib/python3.6/site-packages/pyarrow/dataset.py", line 400, in _filesystem_dataset
    fs, paths_or_selector = _ensure_single_source(source, filesystem)
  File "/home/airflow/.local/lib/python3.6/site-packages/pyarrow/dataset.py", line 376, in _ensure_single_source
    raise FileNotFoundError(path)
FileNotFoundError: /opt/***/raw_data/yellowtaxi_tripdata_2021-12.parquet
[2024-04-30 06:44:01,195] {local_task_job.py:154} INFO - Task exited with return code 1
[2024-04-30 06:44:01,368] {local_task_job.py:264} INFO - 0 downstream tasks scheduled from follow-on schedule check
