[2024-05-19 04:26:13,233] {taskinstance.py:1032} INFO - Dependencies all met for <TaskInstance: ingest_data_bigquery_fhvhv.local_to_gcs_task scheduled__2020-11-02T06:00:00+00:00 [queued]>
[2024-05-19 04:26:13,247] {taskinstance.py:1032} INFO - Dependencies all met for <TaskInstance: ingest_data_bigquery_fhvhv.local_to_gcs_task scheduled__2020-11-02T06:00:00+00:00 [queued]>
[2024-05-19 04:26:13,248] {taskinstance.py:1238} INFO - 
--------------------------------------------------------------------------------
[2024-05-19 04:26:13,248] {taskinstance.py:1239} INFO - Starting attempt 2 of 3
[2024-05-19 04:26:13,248] {taskinstance.py:1240} INFO - 
--------------------------------------------------------------------------------
[2024-05-19 04:26:13,260] {taskinstance.py:1259} INFO - Executing <Task(PythonOperator): local_to_gcs_task> on 2020-11-02 06:00:00+00:00
[2024-05-19 04:26:13,266] {standard_task_runner.py:52} INFO - Started process 774 to run task
[2024-05-19 04:26:13,271] {standard_task_runner.py:76} INFO - Running: ['***', 'tasks', 'run', 'ingest_data_bigquery_fhvhv', 'local_to_gcs_task', 'scheduled__2020-11-02T06:00:00+00:00', '--job-id', '5521', '--raw', '--subdir', 'DAGS_FOLDER/data_ingestion_gcs_fhvhv_dag.py', '--cfg-path', '/tmp/tmp2gz2bflr', '--error-file', '/tmp/tmpeltje0pt']
[2024-05-19 04:26:13,276] {standard_task_runner.py:77} INFO - Job 5521: Subtask local_to_gcs_task
[2024-05-19 04:26:13,346] {logging_mixin.py:109} INFO - Running <TaskInstance: ingest_data_bigquery_fhvhv.local_to_gcs_task scheduled__2020-11-02T06:00:00+00:00 [running]> on host b57d73dcebce
[2024-05-19 04:26:13,387] {warnings.py:99} WARNING - /home/***/.local/lib/python3.6/site-packages/***/utils/context.py:152: AirflowContextDeprecationWarning: Accessing 'execution_date' from the template is deprecated and will be removed in a future version. Please use 'data_interval_start' or 'logical_date' instead.
  warnings.warn(_create_deprecation_warning(key, self._deprecation_replacements[key]))

[2024-05-19 04:26:13,414] {taskinstance.py:1426} INFO - Exporting the following env vars:
AIRFLOW_CTX_DAG_OWNER=***
AIRFLOW_CTX_DAG_ID=ingest_data_bigquery_fhvhv
AIRFLOW_CTX_TASK_ID=local_to_gcs_task
AIRFLOW_CTX_EXECUTION_DATE=2020-11-02T06:00:00+00:00
AIRFLOW_CTX_DAG_RUN_ID=scheduled__2020-11-02T06:00:00+00:00
[2024-05-19 04:26:41,610] {python.py:175} INFO - Done. Returned value was: None
[2024-05-19 04:26:41,630] {taskinstance.py:1277} INFO - Marking task as SUCCESS. dag_id=ingest_data_bigquery_fhvhv, task_id=local_to_gcs_task, execution_date=20201102T060000, start_date=20240519T042613, end_date=20240519T042641
[2024-05-19 04:26:41,719] {local_task_job.py:154} INFO - Task exited with return code 0
[2024-05-19 04:26:41,755] {local_task_job.py:264} INFO - 1 downstream tasks scheduled from follow-on schedule check
[2024-12-22 09:26:40,326] {taskinstance.py:1032} INFO - Dependencies all met for <TaskInstance: ingest_data_bigquery_fhvhv.local_to_gcs_task scheduled__2020-11-02T06:00:00+00:00 [queued]>
[2024-12-22 09:26:40,379] {taskinstance.py:1032} INFO - Dependencies all met for <TaskInstance: ingest_data_bigquery_fhvhv.local_to_gcs_task scheduled__2020-11-02T06:00:00+00:00 [queued]>
[2024-12-22 09:26:40,379] {taskinstance.py:1238} INFO - 
--------------------------------------------------------------------------------
[2024-12-22 09:26:40,379] {taskinstance.py:1239} INFO - Starting attempt 2 of 3
[2024-12-22 09:26:40,379] {taskinstance.py:1240} INFO - 
--------------------------------------------------------------------------------
[2024-12-22 09:26:40,460] {taskinstance.py:1259} INFO - Executing <Task(PythonOperator): local_to_gcs_task> on 2020-11-02 06:00:00+00:00
[2024-12-22 09:26:40,484] {standard_task_runner.py:52} INFO - Started process 104 to run task
[2024-12-22 09:26:40,526] {standard_task_runner.py:76} INFO - Running: ['***', 'tasks', 'run', 'ingest_data_bigquery_fhvhv', 'local_to_gcs_task', 'scheduled__2020-11-02T06:00:00+00:00', '--job-id', '5775', '--raw', '--subdir', 'DAGS_FOLDER/data_ingestion_gcs_fhvhv_dag.py', '--cfg-path', '/tmp/tmp__3b40dk', '--error-file', '/tmp/tmp3fo_sr0f']
[2024-12-22 09:26:40,563] {standard_task_runner.py:77} INFO - Job 5775: Subtask local_to_gcs_task
[2024-12-22 09:26:40,886] {logging_mixin.py:109} INFO - Running <TaskInstance: ingest_data_bigquery_fhvhv.local_to_gcs_task scheduled__2020-11-02T06:00:00+00:00 [running]> on host dbc21e3af8a1
[2024-12-22 09:26:41,077] {warnings.py:99} WARNING - /home/***/.local/lib/python3.6/site-packages/***/utils/context.py:152: AirflowContextDeprecationWarning: Accessing 'execution_date' from the template is deprecated and will be removed in a future version. Please use 'data_interval_start' or 'logical_date' instead.
  warnings.warn(_create_deprecation_warning(key, self._deprecation_replacements[key]))

[2024-12-22 09:26:41,155] {taskinstance.py:1426} INFO - Exporting the following env vars:
AIRFLOW_CTX_DAG_OWNER=***
AIRFLOW_CTX_DAG_ID=ingest_data_bigquery_fhvhv
AIRFLOW_CTX_TASK_ID=local_to_gcs_task
AIRFLOW_CTX_EXECUTION_DATE=2020-11-02T06:00:00+00:00
AIRFLOW_CTX_DAG_RUN_ID=scheduled__2020-11-02T06:00:00+00:00
[2024-12-22 09:26:41,316] {taskinstance.py:1700} ERROR - Task failed with exception
Traceback (most recent call last):
  File "/home/airflow/.local/lib/python3.6/site-packages/airflow/models/taskinstance.py", line 1329, in _run_raw_task
    self._execute_task_with_callbacks(context)
  File "/home/airflow/.local/lib/python3.6/site-packages/airflow/models/taskinstance.py", line 1455, in _execute_task_with_callbacks
    result = self._execute_task(context, self.task)
  File "/home/airflow/.local/lib/python3.6/site-packages/airflow/models/taskinstance.py", line 1511, in _execute_task
    result = execute_callable(context=context)
  File "/home/airflow/.local/lib/python3.6/site-packages/airflow/operators/python.py", line 174, in execute
    return_value = self.execute_callable()
  File "/home/airflow/.local/lib/python3.6/site-packages/airflow/operators/python.py", line 185, in execute_callable
    return self.python_callable(*self.op_args, **self.op_kwargs)
  File "/opt/airflow/dags/data_ingestion_gcs_fhvhv_dag.py", line 74, in upload_to_gcs
    __clean_file(raw_file_name, clean_file_name)
  File "/opt/airflow/dags/data_ingestion_gcs_fhvhv_dag.py", line 57, in __clean_file
    df = pd.read_parquet(raw_file_name)
  File "/home/airflow/.local/lib/python3.6/site-packages/pandas/io/parquet.py", line 317, in read_parquet
    return impl.read(path, columns=columns, **kwargs)
  File "/home/airflow/.local/lib/python3.6/site-packages/pandas/io/parquet.py", line 142, in read
    path, columns=columns, filesystem=fs, **kwargs
  File "/home/airflow/.local/lib/python3.6/site-packages/pyarrow/parquet.py", line 1869, in read_table
    coerce_int96_timestamp_unit=coerce_int96_timestamp_unit
  File "/home/airflow/.local/lib/python3.6/site-packages/pyarrow/parquet.py", line 1697, in __init__
    ignore_prefixes=ignore_prefixes)
  File "/home/airflow/.local/lib/python3.6/site-packages/pyarrow/dataset.py", line 655, in dataset
    return _filesystem_dataset(source, **kwargs)
  File "/home/airflow/.local/lib/python3.6/site-packages/pyarrow/dataset.py", line 400, in _filesystem_dataset
    fs, paths_or_selector = _ensure_single_source(source, filesystem)
  File "/home/airflow/.local/lib/python3.6/site-packages/pyarrow/dataset.py", line 376, in _ensure_single_source
    raise FileNotFoundError(path)
FileNotFoundError: /opt/***/raw_data/fhvhvtaxi_tripdata_2020-11.parquet
[2024-12-22 09:26:41,358] {taskinstance.py:1277} INFO - Marking task as UP_FOR_RETRY. dag_id=ingest_data_bigquery_fhvhv, task_id=local_to_gcs_task, execution_date=20201102T060000, start_date=20241222T092640, end_date=20241222T092641
[2024-12-22 09:26:41,380] {standard_task_runner.py:92} ERROR - Failed to execute job 5775 for task local_to_gcs_task
Traceback (most recent call last):
  File "/home/airflow/.local/lib/python3.6/site-packages/airflow/task/task_runner/standard_task_runner.py", line 85, in _start_by_fork
    args.func(args, dag=self.dag)
  File "/home/airflow/.local/lib/python3.6/site-packages/airflow/cli/cli_parser.py", line 48, in command
    return func(*args, **kwargs)
  File "/home/airflow/.local/lib/python3.6/site-packages/airflow/utils/cli.py", line 92, in wrapper
    return f(*args, **kwargs)
  File "/home/airflow/.local/lib/python3.6/site-packages/airflow/cli/commands/task_command.py", line 298, in task_run
    _run_task_by_selected_method(args, dag, ti)
  File "/home/airflow/.local/lib/python3.6/site-packages/airflow/cli/commands/task_command.py", line 107, in _run_task_by_selected_method
    _run_raw_task(args, ti)
  File "/home/airflow/.local/lib/python3.6/site-packages/airflow/cli/commands/task_command.py", line 184, in _run_raw_task
    error_file=args.error_file,
  File "/home/airflow/.local/lib/python3.6/site-packages/airflow/utils/session.py", line 70, in wrapper
    return func(*args, session=session, **kwargs)
  File "/home/airflow/.local/lib/python3.6/site-packages/airflow/models/taskinstance.py", line 1329, in _run_raw_task
    self._execute_task_with_callbacks(context)
  File "/home/airflow/.local/lib/python3.6/site-packages/airflow/models/taskinstance.py", line 1455, in _execute_task_with_callbacks
    result = self._execute_task(context, self.task)
  File "/home/airflow/.local/lib/python3.6/site-packages/airflow/models/taskinstance.py", line 1511, in _execute_task
    result = execute_callable(context=context)
  File "/home/airflow/.local/lib/python3.6/site-packages/airflow/operators/python.py", line 174, in execute
    return_value = self.execute_callable()
  File "/home/airflow/.local/lib/python3.6/site-packages/airflow/operators/python.py", line 185, in execute_callable
    return self.python_callable(*self.op_args, **self.op_kwargs)
  File "/opt/airflow/dags/data_ingestion_gcs_fhvhv_dag.py", line 74, in upload_to_gcs
    __clean_file(raw_file_name, clean_file_name)
  File "/opt/airflow/dags/data_ingestion_gcs_fhvhv_dag.py", line 57, in __clean_file
    df = pd.read_parquet(raw_file_name)
  File "/home/airflow/.local/lib/python3.6/site-packages/pandas/io/parquet.py", line 317, in read_parquet
    return impl.read(path, columns=columns, **kwargs)
  File "/home/airflow/.local/lib/python3.6/site-packages/pandas/io/parquet.py", line 142, in read
    path, columns=columns, filesystem=fs, **kwargs
  File "/home/airflow/.local/lib/python3.6/site-packages/pyarrow/parquet.py", line 1869, in read_table
    coerce_int96_timestamp_unit=coerce_int96_timestamp_unit
  File "/home/airflow/.local/lib/python3.6/site-packages/pyarrow/parquet.py", line 1697, in __init__
    ignore_prefixes=ignore_prefixes)
  File "/home/airflow/.local/lib/python3.6/site-packages/pyarrow/dataset.py", line 655, in dataset
    return _filesystem_dataset(source, **kwargs)
  File "/home/airflow/.local/lib/python3.6/site-packages/pyarrow/dataset.py", line 400, in _filesystem_dataset
    fs, paths_or_selector = _ensure_single_source(source, filesystem)
  File "/home/airflow/.local/lib/python3.6/site-packages/pyarrow/dataset.py", line 376, in _ensure_single_source
    raise FileNotFoundError(path)
FileNotFoundError: /opt/***/raw_data/fhvhvtaxi_tripdata_2020-11.parquet
[2024-12-22 09:26:41,436] {local_task_job.py:154} INFO - Task exited with return code 1
[2024-12-22 09:26:41,543] {local_task_job.py:264} INFO - 0 downstream tasks scheduled from follow-on schedule check
[2024-12-29 15:15:05,003] {taskinstance.py:1032} INFO - Dependencies all met for <TaskInstance: ingest_data_bigquery_fhvhv.local_to_gcs_task scheduled__2020-11-02T06:00:00+00:00 [queued]>
[2024-12-29 15:15:05,042] {taskinstance.py:1032} INFO - Dependencies all met for <TaskInstance: ingest_data_bigquery_fhvhv.local_to_gcs_task scheduled__2020-11-02T06:00:00+00:00 [queued]>
[2024-12-29 15:15:05,043] {taskinstance.py:1238} INFO - 
--------------------------------------------------------------------------------
[2024-12-29 15:15:05,043] {taskinstance.py:1239} INFO - Starting attempt 2 of 3
[2024-12-29 15:15:05,043] {taskinstance.py:1240} INFO - 
--------------------------------------------------------------------------------
[2024-12-29 15:15:05,065] {taskinstance.py:1259} INFO - Executing <Task(PythonOperator): local_to_gcs_task> on 2020-11-02 06:00:00+00:00
[2024-12-29 15:15:05,074] {standard_task_runner.py:52} INFO - Started process 357 to run task
[2024-12-29 15:15:05,108] {standard_task_runner.py:76} INFO - Running: ['***', 'tasks', 'run', 'ingest_data_bigquery_fhvhv', 'local_to_gcs_task', 'scheduled__2020-11-02T06:00:00+00:00', '--job-id', '5964', '--raw', '--subdir', 'DAGS_FOLDER/data_ingestion_gcs_fhvhv_dag.py', '--cfg-path', '/tmp/tmpru4j1jjz', '--error-file', '/tmp/tmp_i0rmvm5']
[2024-12-29 15:15:05,120] {standard_task_runner.py:77} INFO - Job 5964: Subtask local_to_gcs_task
[2024-12-29 15:15:05,395] {logging_mixin.py:109} INFO - Running <TaskInstance: ingest_data_bigquery_fhvhv.local_to_gcs_task scheduled__2020-11-02T06:00:00+00:00 [running]> on host a180708a7c2c
[2024-12-29 15:15:05,535] {warnings.py:99} WARNING - /home/***/.local/lib/python3.6/site-packages/***/utils/context.py:152: AirflowContextDeprecationWarning: Accessing 'execution_date' from the template is deprecated and will be removed in a future version. Please use 'data_interval_start' or 'logical_date' instead.
  warnings.warn(_create_deprecation_warning(key, self._deprecation_replacements[key]))

[2024-12-29 15:15:05,635] {taskinstance.py:1426} INFO - Exporting the following env vars:
AIRFLOW_CTX_DAG_OWNER=***
AIRFLOW_CTX_DAG_ID=ingest_data_bigquery_fhvhv
AIRFLOW_CTX_TASK_ID=local_to_gcs_task
AIRFLOW_CTX_EXECUTION_DATE=2020-11-02T06:00:00+00:00
AIRFLOW_CTX_DAG_RUN_ID=scheduled__2020-11-02T06:00:00+00:00
[2024-12-29 15:15:05,957] {taskinstance.py:1700} ERROR - Task failed with exception
Traceback (most recent call last):
  File "/home/airflow/.local/lib/python3.6/site-packages/airflow/models/taskinstance.py", line 1329, in _run_raw_task
    self._execute_task_with_callbacks(context)
  File "/home/airflow/.local/lib/python3.6/site-packages/airflow/models/taskinstance.py", line 1455, in _execute_task_with_callbacks
    result = self._execute_task(context, self.task)
  File "/home/airflow/.local/lib/python3.6/site-packages/airflow/models/taskinstance.py", line 1511, in _execute_task
    result = execute_callable(context=context)
  File "/home/airflow/.local/lib/python3.6/site-packages/airflow/operators/python.py", line 174, in execute
    return_value = self.execute_callable()
  File "/home/airflow/.local/lib/python3.6/site-packages/airflow/operators/python.py", line 185, in execute_callable
    return self.python_callable(*self.op_args, **self.op_kwargs)
  File "/opt/airflow/dags/data_ingestion_gcs_fhvhv_dag.py", line 74, in upload_to_gcs
    __clean_file(raw_file_name, clean_file_name)
  File "/opt/airflow/dags/data_ingestion_gcs_fhvhv_dag.py", line 57, in __clean_file
    df = pd.read_parquet(raw_file_name)
  File "/home/airflow/.local/lib/python3.6/site-packages/pandas/io/parquet.py", line 317, in read_parquet
    return impl.read(path, columns=columns, **kwargs)
  File "/home/airflow/.local/lib/python3.6/site-packages/pandas/io/parquet.py", line 142, in read
    path, columns=columns, filesystem=fs, **kwargs
  File "/home/airflow/.local/lib/python3.6/site-packages/pyarrow/parquet.py", line 1869, in read_table
    coerce_int96_timestamp_unit=coerce_int96_timestamp_unit
  File "/home/airflow/.local/lib/python3.6/site-packages/pyarrow/parquet.py", line 1697, in __init__
    ignore_prefixes=ignore_prefixes)
  File "/home/airflow/.local/lib/python3.6/site-packages/pyarrow/dataset.py", line 655, in dataset
    return _filesystem_dataset(source, **kwargs)
  File "/home/airflow/.local/lib/python3.6/site-packages/pyarrow/dataset.py", line 400, in _filesystem_dataset
    fs, paths_or_selector = _ensure_single_source(source, filesystem)
  File "/home/airflow/.local/lib/python3.6/site-packages/pyarrow/dataset.py", line 376, in _ensure_single_source
    raise FileNotFoundError(path)
FileNotFoundError: /opt/***/raw_data/fhvhvtaxi_tripdata_2020-11.parquet
[2024-12-29 15:15:06,027] {taskinstance.py:1277} INFO - Marking task as UP_FOR_RETRY. dag_id=ingest_data_bigquery_fhvhv, task_id=local_to_gcs_task, execution_date=20201102T060000, start_date=20241229T151505, end_date=20241229T151506
[2024-12-29 15:15:06,093] {standard_task_runner.py:92} ERROR - Failed to execute job 5964 for task local_to_gcs_task
Traceback (most recent call last):
  File "/home/airflow/.local/lib/python3.6/site-packages/airflow/task/task_runner/standard_task_runner.py", line 85, in _start_by_fork
    args.func(args, dag=self.dag)
  File "/home/airflow/.local/lib/python3.6/site-packages/airflow/cli/cli_parser.py", line 48, in command
    return func(*args, **kwargs)
  File "/home/airflow/.local/lib/python3.6/site-packages/airflow/utils/cli.py", line 92, in wrapper
    return f(*args, **kwargs)
  File "/home/airflow/.local/lib/python3.6/site-packages/airflow/cli/commands/task_command.py", line 298, in task_run
    _run_task_by_selected_method(args, dag, ti)
  File "/home/airflow/.local/lib/python3.6/site-packages/airflow/cli/commands/task_command.py", line 107, in _run_task_by_selected_method
    _run_raw_task(args, ti)
  File "/home/airflow/.local/lib/python3.6/site-packages/airflow/cli/commands/task_command.py", line 184, in _run_raw_task
    error_file=args.error_file,
  File "/home/airflow/.local/lib/python3.6/site-packages/airflow/utils/session.py", line 70, in wrapper
    return func(*args, session=session, **kwargs)
  File "/home/airflow/.local/lib/python3.6/site-packages/airflow/models/taskinstance.py", line 1329, in _run_raw_task
    self._execute_task_with_callbacks(context)
  File "/home/airflow/.local/lib/python3.6/site-packages/airflow/models/taskinstance.py", line 1455, in _execute_task_with_callbacks
    result = self._execute_task(context, self.task)
  File "/home/airflow/.local/lib/python3.6/site-packages/airflow/models/taskinstance.py", line 1511, in _execute_task
    result = execute_callable(context=context)
  File "/home/airflow/.local/lib/python3.6/site-packages/airflow/operators/python.py", line 174, in execute
    return_value = self.execute_callable()
  File "/home/airflow/.local/lib/python3.6/site-packages/airflow/operators/python.py", line 185, in execute_callable
    return self.python_callable(*self.op_args, **self.op_kwargs)
  File "/opt/airflow/dags/data_ingestion_gcs_fhvhv_dag.py", line 74, in upload_to_gcs
    __clean_file(raw_file_name, clean_file_name)
  File "/opt/airflow/dags/data_ingestion_gcs_fhvhv_dag.py", line 57, in __clean_file
    df = pd.read_parquet(raw_file_name)
  File "/home/airflow/.local/lib/python3.6/site-packages/pandas/io/parquet.py", line 317, in read_parquet
    return impl.read(path, columns=columns, **kwargs)
  File "/home/airflow/.local/lib/python3.6/site-packages/pandas/io/parquet.py", line 142, in read
    path, columns=columns, filesystem=fs, **kwargs
  File "/home/airflow/.local/lib/python3.6/site-packages/pyarrow/parquet.py", line 1869, in read_table
    coerce_int96_timestamp_unit=coerce_int96_timestamp_unit
  File "/home/airflow/.local/lib/python3.6/site-packages/pyarrow/parquet.py", line 1697, in __init__
    ignore_prefixes=ignore_prefixes)
  File "/home/airflow/.local/lib/python3.6/site-packages/pyarrow/dataset.py", line 655, in dataset
    return _filesystem_dataset(source, **kwargs)
  File "/home/airflow/.local/lib/python3.6/site-packages/pyarrow/dataset.py", line 400, in _filesystem_dataset
    fs, paths_or_selector = _ensure_single_source(source, filesystem)
  File "/home/airflow/.local/lib/python3.6/site-packages/pyarrow/dataset.py", line 376, in _ensure_single_source
    raise FileNotFoundError(path)
FileNotFoundError: /opt/***/raw_data/fhvhvtaxi_tripdata_2020-11.parquet
[2024-12-29 15:15:06,186] {local_task_job.py:154} INFO - Task exited with return code 1
[2024-12-29 15:15:06,332] {local_task_job.py:264} INFO - 0 downstream tasks scheduled from follow-on schedule check
