[2024-03-26 14:34:25,976] {taskinstance.py:1032} INFO - Dependencies all met for <TaskInstance: LocalIngestionDag.ingest scheduled__2021-11-02T06:00:00+00:00 [queued]>
[2024-03-26 14:34:26,028] {taskinstance.py:1032} INFO - Dependencies all met for <TaskInstance: LocalIngestionDag.ingest scheduled__2021-11-02T06:00:00+00:00 [queued]>
[2024-03-26 14:34:26,029] {taskinstance.py:1238} INFO - 
--------------------------------------------------------------------------------
[2024-03-26 14:34:26,029] {taskinstance.py:1239} INFO - Starting attempt 1 of 1
[2024-03-26 14:34:26,032] {taskinstance.py:1240} INFO - 
--------------------------------------------------------------------------------
[2024-03-26 14:34:26,073] {taskinstance.py:1259} INFO - Executing <Task(PythonOperator): ingest> on 2021-11-02 06:00:00+00:00
[2024-03-26 14:34:26,099] {standard_task_runner.py:52} INFO - Started process 222 to run task
[2024-03-26 14:34:26,235] {standard_task_runner.py:76} INFO - Running: ['***', 'tasks', 'run', 'LocalIngestionDag', 'ingest', 'scheduled__2021-11-02T06:00:00+00:00', '--job-id', '168', '--raw', '--subdir', 'DAGS_FOLDER/data_ingestion_local.py', '--cfg-path', '/tmp/tmpe4ac53lz', '--error-file', '/tmp/tmpgi4qgbsu']
[2024-03-26 14:34:26,240] {standard_task_runner.py:77} INFO - Job 168: Subtask ingest
[2024-03-26 14:34:26,515] {logging_mixin.py:109} INFO - Running <TaskInstance: LocalIngestionDag.ingest scheduled__2021-11-02T06:00:00+00:00 [running]> on host 55b5831905d1
[2024-03-26 14:34:26,702] {warnings.py:99} WARNING - /home/***/.local/lib/python3.6/site-packages/***/utils/context.py:152: AirflowContextDeprecationWarning: Accessing 'execution_date' from the template is deprecated and will be removed in a future version. Please use 'data_interval_start' or 'logical_date' instead.
  warnings.warn(_create_deprecation_warning(key, self._deprecation_replacements[key]))

[2024-03-26 14:34:26,829] {taskinstance.py:1426} INFO - Exporting the following env vars:
AIRFLOW_CTX_DAG_OWNER=***
AIRFLOW_CTX_DAG_ID=LocalIngestionDag
AIRFLOW_CTX_TASK_ID=ingest
AIRFLOW_CTX_EXECUTION_DATE=2021-11-02T06:00:00+00:00
AIRFLOW_CTX_DAG_RUN_ID=scheduled__2021-11-02T06:00:00+00:00
[2024-03-26 14:34:26,837] {logging_mixin.py:109} INFO - yellow_taxi_2021_11 /opt/***/output_2021-11.csv 2021-11-02T06:00:00+00:00
[2024-03-26 14:34:26,838] {logging_mixin.py:109} INFO - Starting data ingestion process...
[2024-03-26 14:34:26,950] {logging_mixin.py:109} INFO - Writing data to table yellow_taxi_2021_11 in the database...
[2024-03-26 14:34:26,951] {taskinstance.py:1700} ERROR - Task failed with exception
Traceback (most recent call last):
  File "/home/airflow/.local/lib/python3.6/site-packages/airflow/models/taskinstance.py", line 1329, in _run_raw_task
    self._execute_task_with_callbacks(context)
  File "/home/airflow/.local/lib/python3.6/site-packages/airflow/models/taskinstance.py", line 1455, in _execute_task_with_callbacks
    result = self._execute_task(context, self.task)
  File "/home/airflow/.local/lib/python3.6/site-packages/airflow/models/taskinstance.py", line 1511, in _execute_task
    result = execute_callable(context=context)
  File "/home/airflow/.local/lib/python3.6/site-packages/airflow/operators/python.py", line 174, in execute
    return_value = self.execute_callable()
  File "/home/airflow/.local/lib/python3.6/site-packages/airflow/operators/python.py", line 185, in execute_callable
    return self.python_callable(*self.op_args, **self.op_kwargs)
  File "/opt/airflow/dags/ingest_scipt.py", line 38, in ingest_callable
    chunk.tpep_pickup_datetime = pd.to_datetime(chunk.tpep_pickup_datetime)
  File "/home/airflow/.local/lib/python3.6/site-packages/pandas/core/generic.py", line 5141, in __getattr__
    return object.__getattribute__(self, name)
AttributeError: 'DataFrame' object has no attribute 'tpep_pickup_datetime'
[2024-03-26 14:34:27,004] {taskinstance.py:1277} INFO - Marking task as FAILED. dag_id=LocalIngestionDag, task_id=ingest, execution_date=20211102T060000, start_date=20240326T143425, end_date=20240326T143427
[2024-03-26 14:34:27,053] {standard_task_runner.py:92} ERROR - Failed to execute job 168 for task ingest
Traceback (most recent call last):
  File "/home/airflow/.local/lib/python3.6/site-packages/airflow/task/task_runner/standard_task_runner.py", line 85, in _start_by_fork
    args.func(args, dag=self.dag)
  File "/home/airflow/.local/lib/python3.6/site-packages/airflow/cli/cli_parser.py", line 48, in command
    return func(*args, **kwargs)
  File "/home/airflow/.local/lib/python3.6/site-packages/airflow/utils/cli.py", line 92, in wrapper
    return f(*args, **kwargs)
  File "/home/airflow/.local/lib/python3.6/site-packages/airflow/cli/commands/task_command.py", line 298, in task_run
    _run_task_by_selected_method(args, dag, ti)
  File "/home/airflow/.local/lib/python3.6/site-packages/airflow/cli/commands/task_command.py", line 107, in _run_task_by_selected_method
    _run_raw_task(args, ti)
  File "/home/airflow/.local/lib/python3.6/site-packages/airflow/cli/commands/task_command.py", line 184, in _run_raw_task
    error_file=args.error_file,
  File "/home/airflow/.local/lib/python3.6/site-packages/airflow/utils/session.py", line 70, in wrapper
    return func(*args, session=session, **kwargs)
  File "/home/airflow/.local/lib/python3.6/site-packages/airflow/models/taskinstance.py", line 1329, in _run_raw_task
    self._execute_task_with_callbacks(context)
  File "/home/airflow/.local/lib/python3.6/site-packages/airflow/models/taskinstance.py", line 1455, in _execute_task_with_callbacks
    result = self._execute_task(context, self.task)
  File "/home/airflow/.local/lib/python3.6/site-packages/airflow/models/taskinstance.py", line 1511, in _execute_task
    result = execute_callable(context=context)
  File "/home/airflow/.local/lib/python3.6/site-packages/airflow/operators/python.py", line 174, in execute
    return_value = self.execute_callable()
  File "/home/airflow/.local/lib/python3.6/site-packages/airflow/operators/python.py", line 185, in execute_callable
    return self.python_callable(*self.op_args, **self.op_kwargs)
  File "/opt/airflow/dags/ingest_scipt.py", line 38, in ingest_callable
    chunk.tpep_pickup_datetime = pd.to_datetime(chunk.tpep_pickup_datetime)
  File "/home/airflow/.local/lib/python3.6/site-packages/pandas/core/generic.py", line 5141, in __getattr__
    return object.__getattribute__(self, name)
AttributeError: 'DataFrame' object has no attribute 'tpep_pickup_datetime'
[2024-03-26 14:34:27,147] {local_task_job.py:154} INFO - Task exited with return code 1
[2024-03-26 14:34:27,222] {local_task_job.py:264} INFO - 0 downstream tasks scheduled from follow-on schedule check
[2024-03-26 15:30:04,324] {taskinstance.py:1032} INFO - Dependencies all met for <TaskInstance: LocalIngestionDag.ingest scheduled__2021-11-02T06:00:00+00:00 [queued]>
[2024-03-26 15:30:04,350] {taskinstance.py:1032} INFO - Dependencies all met for <TaskInstance: LocalIngestionDag.ingest scheduled__2021-11-02T06:00:00+00:00 [queued]>
[2024-03-26 15:30:04,350] {taskinstance.py:1238} INFO - 
--------------------------------------------------------------------------------
[2024-03-26 15:30:04,350] {taskinstance.py:1239} INFO - Starting attempt 1 of 1
[2024-03-26 15:30:04,350] {taskinstance.py:1240} INFO - 
--------------------------------------------------------------------------------
[2024-03-26 15:30:04,370] {taskinstance.py:1259} INFO - Executing <Task(PythonOperator): ingest> on 2021-11-02 06:00:00+00:00
[2024-03-26 15:30:04,377] {standard_task_runner.py:52} INFO - Started process 963 to run task
[2024-03-26 15:30:04,385] {standard_task_runner.py:76} INFO - Running: ['***', 'tasks', 'run', 'LocalIngestionDag', 'ingest', 'scheduled__2021-11-02T06:00:00+00:00', '--job-id', '286', '--raw', '--subdir', 'DAGS_FOLDER/data_ingestion_local.py', '--cfg-path', '/tmp/tmpujwetp8i', '--error-file', '/tmp/tmph57dw0gj']
[2024-03-26 15:30:04,386] {standard_task_runner.py:77} INFO - Job 286: Subtask ingest
[2024-03-26 15:30:04,491] {logging_mixin.py:109} INFO - Running <TaskInstance: LocalIngestionDag.ingest scheduled__2021-11-02T06:00:00+00:00 [running]> on host 153a478eba08
[2024-03-26 15:30:04,550] {warnings.py:99} WARNING - /home/***/.local/lib/python3.6/site-packages/***/utils/context.py:152: AirflowContextDeprecationWarning: Accessing 'execution_date' from the template is deprecated and will be removed in a future version. Please use 'data_interval_start' or 'logical_date' instead.
  warnings.warn(_create_deprecation_warning(key, self._deprecation_replacements[key]))

[2024-03-26 15:30:04,576] {taskinstance.py:1426} INFO - Exporting the following env vars:
AIRFLOW_CTX_DAG_OWNER=***
AIRFLOW_CTX_DAG_ID=LocalIngestionDag
AIRFLOW_CTX_TASK_ID=ingest
AIRFLOW_CTX_EXECUTION_DATE=2021-11-02T06:00:00+00:00
AIRFLOW_CTX_DAG_RUN_ID=scheduled__2021-11-02T06:00:00+00:00
[2024-03-26 15:30:04,578] {logging_mixin.py:109} INFO - yellow_taxi_2021_11 /opt/***/output_2021-11.csv 2021-11-02T06:00:00+00:00
[2024-03-26 15:30:04,578] {logging_mixin.py:109} INFO - Starting data ingestion process...
[2024-03-26 15:30:04,622] {logging_mixin.py:109} INFO - Writing data to table yellow_taxi_2021_11 in the database...
[2024-03-26 15:30:04,645] {logging_mixin.py:109} INFO - Data ingestion complete
[2024-03-26 15:30:04,645] {logging_mixin.py:109} INFO - Data ingestion process completed in 0.07 seconds.
[2024-03-26 15:30:04,645] {python.py:175} INFO - Done. Returned value was: None
[2024-03-26 15:30:04,658] {taskinstance.py:1277} INFO - Marking task as SUCCESS. dag_id=LocalIngestionDag, task_id=ingest, execution_date=20211102T060000, start_date=20240326T153004, end_date=20240326T153004
[2024-03-26 15:30:04,683] {local_task_job.py:154} INFO - Task exited with return code 0
[2024-03-26 15:30:04,730] {local_task_job.py:264} INFO - 0 downstream tasks scheduled from follow-on schedule check
