[2025-01-14 15:07:11,995] {taskinstance.py:1032} INFO - Dependencies all met for <TaskInstance: ingest_data_bigquery_gt.download_dataset_task scheduled__2022-08-02T06:00:00+00:00 [queued]>
[2025-01-14 15:07:12,033] {taskinstance.py:1032} INFO - Dependencies all met for <TaskInstance: ingest_data_bigquery_gt.download_dataset_task scheduled__2022-08-02T06:00:00+00:00 [queued]>
[2025-01-14 15:07:12,033] {taskinstance.py:1238} INFO - 
--------------------------------------------------------------------------------
[2025-01-14 15:07:12,034] {taskinstance.py:1239} INFO - Starting attempt 1 of 3
[2025-01-14 15:07:12,034] {taskinstance.py:1240} INFO - 
--------------------------------------------------------------------------------
[2025-01-14 15:07:12,073] {taskinstance.py:1259} INFO - Executing <Task(BashOperator): download_dataset_task> on 2022-08-02 06:00:00+00:00
[2025-01-14 15:07:12,089] {standard_task_runner.py:52} INFO - Started process 280 to run task
[2025-01-14 15:07:12,135] {standard_task_runner.py:76} INFO - Running: ['***', 'tasks', 'run', 'ingest_data_bigquery_gt', 'download_dataset_task', 'scheduled__2022-08-02T06:00:00+00:00', '--job-id', '6389', '--raw', '--subdir', 'DAGS_FOLDER/data_ingestion_gcs_gt_dag .py', '--cfg-path', '/tmp/tmp85m_1mh3', '--error-file', '/tmp/tmpak00t_b5']
[2025-01-14 15:07:12,152] {standard_task_runner.py:77} INFO - Job 6389: Subtask download_dataset_task
[2025-01-14 15:07:12,339] {logging_mixin.py:109} INFO - Running <TaskInstance: ingest_data_bigquery_gt.download_dataset_task scheduled__2022-08-02T06:00:00+00:00 [running]> on host d4593c1e0983
[2025-01-14 15:07:12,478] {warnings.py:99} WARNING - /home/***/.local/lib/python3.6/site-packages/***/utils/context.py:152: AirflowContextDeprecationWarning: Accessing 'execution_date' from the template is deprecated and will be removed in a future version. Please use 'data_interval_start' or 'logical_date' instead.
  warnings.warn(_create_deprecation_warning(key, self._deprecation_replacements[key]))

[2025-01-14 15:07:12,588] {taskinstance.py:1426} INFO - Exporting the following env vars:
AIRFLOW_CTX_DAG_OWNER=***
AIRFLOW_CTX_DAG_ID=ingest_data_bigquery_gt
AIRFLOW_CTX_TASK_ID=download_dataset_task
AIRFLOW_CTX_EXECUTION_DATE=2022-08-02T06:00:00+00:00
AIRFLOW_CTX_DAG_RUN_ID=scheduled__2022-08-02T06:00:00+00:00
[2025-01-14 15:07:12,590] {subprocess.py:62} INFO - Tmp dir root location: 
 /tmp
[2025-01-14 15:07:12,591] {subprocess.py:74} INFO - Running command: ['bash', '-c', 'curl -sSL https://github.com/DataTalksClub/nyc-tlc-data/releases/download/green/green_tripdata_2022-08.csv.gz > /opt/***/raw_data/greentaxi_tripdata_2022-08.csv.gz && gunzip /opt/***/raw_data/greentaxi_tripdata_2022-08.csv.gz']
[2025-01-14 15:07:12,628] {subprocess.py:85} INFO - Output:
[2025-01-14 15:07:13,077] {subprocess.py:89} INFO - 
[2025-01-14 15:07:13,078] {subprocess.py:89} INFO - gzip: /opt/***/raw_data/greentaxi_tripdata_2022-08.csv.gz: not in gzip format
[2025-01-14 15:07:13,078] {subprocess.py:93} INFO - Command exited with return code 1
[2025-01-14 15:07:13,124] {taskinstance.py:1700} ERROR - Task failed with exception
Traceback (most recent call last):
  File "/home/airflow/.local/lib/python3.6/site-packages/airflow/models/taskinstance.py", line 1329, in _run_raw_task
    self._execute_task_with_callbacks(context)
  File "/home/airflow/.local/lib/python3.6/site-packages/airflow/models/taskinstance.py", line 1455, in _execute_task_with_callbacks
    result = self._execute_task(context, self.task)
  File "/home/airflow/.local/lib/python3.6/site-packages/airflow/models/taskinstance.py", line 1511, in _execute_task
    result = execute_callable(context=context)
  File "/home/airflow/.local/lib/python3.6/site-packages/airflow/operators/bash.py", line 188, in execute
    f'Bash command failed. The command returned a non-zero exit code {result.exit_code}.'
airflow.exceptions.AirflowException: Bash command failed. The command returned a non-zero exit code 1.
[2025-01-14 15:07:13,139] {taskinstance.py:1277} INFO - Marking task as UP_FOR_RETRY. dag_id=ingest_data_bigquery_gt, task_id=download_dataset_task, execution_date=20220802T060000, start_date=20250114T150711, end_date=20250114T150713
[2025-01-14 15:07:13,185] {standard_task_runner.py:92} ERROR - Failed to execute job 6389 for task download_dataset_task
Traceback (most recent call last):
  File "/home/airflow/.local/lib/python3.6/site-packages/airflow/task/task_runner/standard_task_runner.py", line 85, in _start_by_fork
    args.func(args, dag=self.dag)
  File "/home/airflow/.local/lib/python3.6/site-packages/airflow/cli/cli_parser.py", line 48, in command
    return func(*args, **kwargs)
  File "/home/airflow/.local/lib/python3.6/site-packages/airflow/utils/cli.py", line 92, in wrapper
    return f(*args, **kwargs)
  File "/home/airflow/.local/lib/python3.6/site-packages/airflow/cli/commands/task_command.py", line 298, in task_run
    _run_task_by_selected_method(args, dag, ti)
  File "/home/airflow/.local/lib/python3.6/site-packages/airflow/cli/commands/task_command.py", line 107, in _run_task_by_selected_method
    _run_raw_task(args, ti)
  File "/home/airflow/.local/lib/python3.6/site-packages/airflow/cli/commands/task_command.py", line 184, in _run_raw_task
    error_file=args.error_file,
  File "/home/airflow/.local/lib/python3.6/site-packages/airflow/utils/session.py", line 70, in wrapper
    return func(*args, session=session, **kwargs)
  File "/home/airflow/.local/lib/python3.6/site-packages/airflow/models/taskinstance.py", line 1329, in _run_raw_task
    self._execute_task_with_callbacks(context)
  File "/home/airflow/.local/lib/python3.6/site-packages/airflow/models/taskinstance.py", line 1455, in _execute_task_with_callbacks
    result = self._execute_task(context, self.task)
  File "/home/airflow/.local/lib/python3.6/site-packages/airflow/models/taskinstance.py", line 1511, in _execute_task
    result = execute_callable(context=context)
  File "/home/airflow/.local/lib/python3.6/site-packages/airflow/operators/bash.py", line 188, in execute
    f'Bash command failed. The command returned a non-zero exit code {result.exit_code}.'
airflow.exceptions.AirflowException: Bash command failed. The command returned a non-zero exit code 1.
[2025-01-14 15:07:13,230] {local_task_job.py:154} INFO - Task exited with return code 1
[2025-01-14 15:07:13,311] {local_task_job.py:264} INFO - 0 downstream tasks scheduled from follow-on schedule check
