[2025-01-01 04:24:48,706] {taskinstance.py:1032} INFO - Dependencies all met for <TaskInstance: ingest_data_bigquery_fhvhv.local_to_gcs_task scheduled__2019-01-02T06:00:00+00:00 [queued]>
[2025-01-01 04:24:48,720] {taskinstance.py:1032} INFO - Dependencies all met for <TaskInstance: ingest_data_bigquery_fhvhv.local_to_gcs_task scheduled__2019-01-02T06:00:00+00:00 [queued]>
[2025-01-01 04:24:48,720] {taskinstance.py:1238} INFO - 
--------------------------------------------------------------------------------
[2025-01-01 04:24:48,720] {taskinstance.py:1239} INFO - Starting attempt 2 of 3
[2025-01-01 04:24:48,720] {taskinstance.py:1240} INFO - 
--------------------------------------------------------------------------------
[2025-01-01 04:24:48,732] {taskinstance.py:1259} INFO - Executing <Task(PythonOperator): local_to_gcs_task> on 2019-01-02 06:00:00+00:00
[2025-01-01 04:24:48,738] {standard_task_runner.py:52} INFO - Started process 1885 to run task
[2025-01-01 04:24:48,743] {standard_task_runner.py:76} INFO - Running: ['***', 'tasks', 'run', 'ingest_data_bigquery_fhvhv', 'local_to_gcs_task', 'scheduled__2019-01-02T06:00:00+00:00', '--job-id', '6161', '--raw', '--subdir', 'DAGS_FOLDER/data_ingestion_gcs_fhvhv_dag.py', '--cfg-path', '/tmp/tmp7o_b3gxr', '--error-file', '/tmp/tmpwjijzya9']
[2025-01-01 04:24:48,747] {standard_task_runner.py:77} INFO - Job 6161: Subtask local_to_gcs_task
[2025-01-01 04:24:48,817] {logging_mixin.py:109} INFO - Running <TaskInstance: ingest_data_bigquery_fhvhv.local_to_gcs_task scheduled__2019-01-02T06:00:00+00:00 [running]> on host 4228b0d90dbc
[2025-01-01 04:24:48,861] {warnings.py:99} WARNING - /home/***/.local/lib/python3.6/site-packages/***/utils/context.py:152: AirflowContextDeprecationWarning: Accessing 'execution_date' from the template is deprecated and will be removed in a future version. Please use 'data_interval_start' or 'logical_date' instead.
  warnings.warn(_create_deprecation_warning(key, self._deprecation_replacements[key]))

[2025-01-01 04:24:48,893] {taskinstance.py:1426} INFO - Exporting the following env vars:
AIRFLOW_CTX_DAG_OWNER=***
AIRFLOW_CTX_DAG_ID=ingest_data_bigquery_fhvhv
AIRFLOW_CTX_TASK_ID=local_to_gcs_task
AIRFLOW_CTX_EXECUTION_DATE=2019-01-02T06:00:00+00:00
AIRFLOW_CTX_DAG_RUN_ID=scheduled__2019-01-02T06:00:00+00:00
[2025-01-01 04:24:48,954] {taskinstance.py:1700} ERROR - Task failed with exception
Traceback (most recent call last):
  File "/home/airflow/.local/lib/python3.6/site-packages/airflow/models/taskinstance.py", line 1329, in _run_raw_task
    self._execute_task_with_callbacks(context)
  File "/home/airflow/.local/lib/python3.6/site-packages/airflow/models/taskinstance.py", line 1455, in _execute_task_with_callbacks
    result = self._execute_task(context, self.task)
  File "/home/airflow/.local/lib/python3.6/site-packages/airflow/models/taskinstance.py", line 1511, in _execute_task
    result = execute_callable(context=context)
  File "/home/airflow/.local/lib/python3.6/site-packages/airflow/operators/python.py", line 174, in execute
    return_value = self.execute_callable()
  File "/home/airflow/.local/lib/python3.6/site-packages/airflow/operators/python.py", line 185, in execute_callable
    return self.python_callable(*self.op_args, **self.op_kwargs)
  File "/opt/airflow/dags/data_ingestion_gcs_fhvhv_dag.py", line 74, in upload_to_gcs
    __clean_file(raw_file_name, clean_file_name)
  File "/opt/airflow/dags/data_ingestion_gcs_fhvhv_dag.py", line 57, in __clean_file
    df = pd.read_parquet(raw_file_name)
  File "/home/airflow/.local/lib/python3.6/site-packages/pandas/io/parquet.py", line 317, in read_parquet
    return impl.read(path, columns=columns, **kwargs)
  File "/home/airflow/.local/lib/python3.6/site-packages/pandas/io/parquet.py", line 142, in read
    path, columns=columns, filesystem=fs, **kwargs
  File "/home/airflow/.local/lib/python3.6/site-packages/pyarrow/parquet.py", line 1869, in read_table
    coerce_int96_timestamp_unit=coerce_int96_timestamp_unit
  File "/home/airflow/.local/lib/python3.6/site-packages/pyarrow/parquet.py", line 1679, in __init__
    [fragment], schema=fragment.physical_schema,
  File "pyarrow/_dataset.pyx", line 952, in pyarrow._dataset.Fragment.physical_schema.__get__
  File "pyarrow/error.pxi", line 143, in pyarrow.lib.pyarrow_internal_check_status
  File "pyarrow/error.pxi", line 99, in pyarrow.lib.check_status
pyarrow.lib.ArrowInvalid: Could not open Parquet input source '/opt/***/raw_data/fhvhvtaxi_tripdata_2019-01.parquet': Parquet magic bytes not found in footer. Either the file is corrupted or this is not a parquet file.
[2025-01-01 04:24:48,969] {taskinstance.py:1277} INFO - Marking task as UP_FOR_RETRY. dag_id=ingest_data_bigquery_fhvhv, task_id=local_to_gcs_task, execution_date=20190102T060000, start_date=20250101T042448, end_date=20250101T042448
[2025-01-01 04:24:48,983] {standard_task_runner.py:92} ERROR - Failed to execute job 6161 for task local_to_gcs_task
Traceback (most recent call last):
  File "/home/airflow/.local/lib/python3.6/site-packages/airflow/task/task_runner/standard_task_runner.py", line 85, in _start_by_fork
    args.func(args, dag=self.dag)
  File "/home/airflow/.local/lib/python3.6/site-packages/airflow/cli/cli_parser.py", line 48, in command
    return func(*args, **kwargs)
  File "/home/airflow/.local/lib/python3.6/site-packages/airflow/utils/cli.py", line 92, in wrapper
    return f(*args, **kwargs)
  File "/home/airflow/.local/lib/python3.6/site-packages/airflow/cli/commands/task_command.py", line 298, in task_run
    _run_task_by_selected_method(args, dag, ti)
  File "/home/airflow/.local/lib/python3.6/site-packages/airflow/cli/commands/task_command.py", line 107, in _run_task_by_selected_method
    _run_raw_task(args, ti)
  File "/home/airflow/.local/lib/python3.6/site-packages/airflow/cli/commands/task_command.py", line 184, in _run_raw_task
    error_file=args.error_file,
  File "/home/airflow/.local/lib/python3.6/site-packages/airflow/utils/session.py", line 70, in wrapper
    return func(*args, session=session, **kwargs)
  File "/home/airflow/.local/lib/python3.6/site-packages/airflow/models/taskinstance.py", line 1329, in _run_raw_task
    self._execute_task_with_callbacks(context)
  File "/home/airflow/.local/lib/python3.6/site-packages/airflow/models/taskinstance.py", line 1455, in _execute_task_with_callbacks
    result = self._execute_task(context, self.task)
  File "/home/airflow/.local/lib/python3.6/site-packages/airflow/models/taskinstance.py", line 1511, in _execute_task
    result = execute_callable(context=context)
  File "/home/airflow/.local/lib/python3.6/site-packages/airflow/operators/python.py", line 174, in execute
    return_value = self.execute_callable()
  File "/home/airflow/.local/lib/python3.6/site-packages/airflow/operators/python.py", line 185, in execute_callable
    return self.python_callable(*self.op_args, **self.op_kwargs)
  File "/opt/airflow/dags/data_ingestion_gcs_fhvhv_dag.py", line 74, in upload_to_gcs
    __clean_file(raw_file_name, clean_file_name)
  File "/opt/airflow/dags/data_ingestion_gcs_fhvhv_dag.py", line 57, in __clean_file
    df = pd.read_parquet(raw_file_name)
  File "/home/airflow/.local/lib/python3.6/site-packages/pandas/io/parquet.py", line 317, in read_parquet
    return impl.read(path, columns=columns, **kwargs)
  File "/home/airflow/.local/lib/python3.6/site-packages/pandas/io/parquet.py", line 142, in read
    path, columns=columns, filesystem=fs, **kwargs
  File "/home/airflow/.local/lib/python3.6/site-packages/pyarrow/parquet.py", line 1869, in read_table
    coerce_int96_timestamp_unit=coerce_int96_timestamp_unit
  File "/home/airflow/.local/lib/python3.6/site-packages/pyarrow/parquet.py", line 1679, in __init__
    [fragment], schema=fragment.physical_schema,
  File "pyarrow/_dataset.pyx", line 952, in pyarrow._dataset.Fragment.physical_schema.__get__
  File "pyarrow/error.pxi", line 143, in pyarrow.lib.pyarrow_internal_check_status
  File "pyarrow/error.pxi", line 99, in pyarrow.lib.check_status
pyarrow.lib.ArrowInvalid: Could not open Parquet input source '/opt/***/raw_data/fhvhvtaxi_tripdata_2019-01.parquet': Parquet magic bytes not found in footer. Either the file is corrupted or this is not a parquet file.
[2025-01-01 04:24:49,002] {local_task_job.py:154} INFO - Task exited with return code 1
[2025-01-01 04:24:49,044] {local_task_job.py:264} INFO - 0 downstream tasks scheduled from follow-on schedule check
[2025-01-01 09:36:07,612] {taskinstance.py:1032} INFO - Dependencies all met for <TaskInstance: ingest_data_bigquery_fhvhv.local_to_gcs_task scheduled__2019-01-02T06:00:00+00:00 [queued]>
[2025-01-01 09:36:07,628] {taskinstance.py:1032} INFO - Dependencies all met for <TaskInstance: ingest_data_bigquery_fhvhv.local_to_gcs_task scheduled__2019-01-02T06:00:00+00:00 [queued]>
[2025-01-01 09:36:07,628] {taskinstance.py:1238} INFO - 
--------------------------------------------------------------------------------
[2025-01-01 09:36:07,628] {taskinstance.py:1239} INFO - Starting attempt 2 of 3
[2025-01-01 09:36:07,628] {taskinstance.py:1240} INFO - 
--------------------------------------------------------------------------------
[2025-01-01 09:36:07,641] {taskinstance.py:1259} INFO - Executing <Task(PythonOperator): local_to_gcs_task> on 2019-01-02 06:00:00+00:00
[2025-01-01 09:36:07,649] {standard_task_runner.py:52} INFO - Started process 1035 to run task
[2025-01-01 09:36:07,657] {standard_task_runner.py:76} INFO - Running: ['***', 'tasks', 'run', 'ingest_data_bigquery_fhvhv', 'local_to_gcs_task', 'scheduled__2019-01-02T06:00:00+00:00', '--job-id', '6262', '--raw', '--subdir', 'DAGS_FOLDER/data_ingestion_gcs_fhvhv_dag.py', '--cfg-path', '/tmp/tmp6aul03aw', '--error-file', '/tmp/tmpql3jthxb']
[2025-01-01 09:36:07,664] {standard_task_runner.py:77} INFO - Job 6262: Subtask local_to_gcs_task
[2025-01-01 09:36:07,740] {logging_mixin.py:109} INFO - Running <TaskInstance: ingest_data_bigquery_fhvhv.local_to_gcs_task scheduled__2019-01-02T06:00:00+00:00 [running]> on host b9549a156c09
[2025-01-01 09:36:07,793] {warnings.py:99} WARNING - /home/***/.local/lib/python3.6/site-packages/***/utils/context.py:152: AirflowContextDeprecationWarning: Accessing 'execution_date' from the template is deprecated and will be removed in a future version. Please use 'data_interval_start' or 'logical_date' instead.
  warnings.warn(_create_deprecation_warning(key, self._deprecation_replacements[key]))

[2025-01-01 09:36:07,832] {taskinstance.py:1426} INFO - Exporting the following env vars:
AIRFLOW_CTX_DAG_OWNER=***
AIRFLOW_CTX_DAG_ID=ingest_data_bigquery_fhvhv
AIRFLOW_CTX_TASK_ID=local_to_gcs_task
AIRFLOW_CTX_EXECUTION_DATE=2019-01-02T06:00:00+00:00
AIRFLOW_CTX_DAG_RUN_ID=scheduled__2019-01-02T06:00:00+00:00
[2025-01-01 09:36:07,912] {taskinstance.py:1700} ERROR - Task failed with exception
Traceback (most recent call last):
  File "/home/airflow/.local/lib/python3.6/site-packages/airflow/models/taskinstance.py", line 1329, in _run_raw_task
    self._execute_task_with_callbacks(context)
  File "/home/airflow/.local/lib/python3.6/site-packages/airflow/models/taskinstance.py", line 1455, in _execute_task_with_callbacks
    result = self._execute_task(context, self.task)
  File "/home/airflow/.local/lib/python3.6/site-packages/airflow/models/taskinstance.py", line 1511, in _execute_task
    result = execute_callable(context=context)
  File "/home/airflow/.local/lib/python3.6/site-packages/airflow/operators/python.py", line 174, in execute
    return_value = self.execute_callable()
  File "/home/airflow/.local/lib/python3.6/site-packages/airflow/operators/python.py", line 185, in execute_callable
    return self.python_callable(*self.op_args, **self.op_kwargs)
  File "/opt/airflow/dags/data_ingestion_gcs_fhvhv_dag.py", line 77, in upload_to_gcs
    __clean_file(raw_file_name, clean_file_name)
  File "/opt/airflow/dags/data_ingestion_gcs_fhvhv_dag.py", line 57, in __clean_file
    df = pd.read_parquet(raw_file_name)
  File "/home/airflow/.local/lib/python3.6/site-packages/pandas/io/parquet.py", line 317, in read_parquet
    return impl.read(path, columns=columns, **kwargs)
  File "/home/airflow/.local/lib/python3.6/site-packages/pandas/io/parquet.py", line 142, in read
    path, columns=columns, filesystem=fs, **kwargs
  File "/home/airflow/.local/lib/python3.6/site-packages/pyarrow/parquet.py", line 1869, in read_table
    coerce_int96_timestamp_unit=coerce_int96_timestamp_unit
  File "/home/airflow/.local/lib/python3.6/site-packages/pyarrow/parquet.py", line 1679, in __init__
    [fragment], schema=fragment.physical_schema,
  File "pyarrow/_dataset.pyx", line 952, in pyarrow._dataset.Fragment.physical_schema.__get__
  File "pyarrow/error.pxi", line 143, in pyarrow.lib.pyarrow_internal_check_status
  File "pyarrow/error.pxi", line 99, in pyarrow.lib.check_status
pyarrow.lib.ArrowInvalid: Could not open Parquet input source '/opt/***/raw_data/fhvhvtaxi_tripdata_2019-01.parquet': Parquet magic bytes not found in footer. Either the file is corrupted or this is not a parquet file.
[2025-01-01 09:36:07,933] {taskinstance.py:1277} INFO - Marking task as UP_FOR_RETRY. dag_id=ingest_data_bigquery_fhvhv, task_id=local_to_gcs_task, execution_date=20190102T060000, start_date=20250101T093607, end_date=20250101T093607
[2025-01-01 09:36:07,949] {standard_task_runner.py:92} ERROR - Failed to execute job 6262 for task local_to_gcs_task
Traceback (most recent call last):
  File "/home/airflow/.local/lib/python3.6/site-packages/airflow/task/task_runner/standard_task_runner.py", line 85, in _start_by_fork
    args.func(args, dag=self.dag)
  File "/home/airflow/.local/lib/python3.6/site-packages/airflow/cli/cli_parser.py", line 48, in command
    return func(*args, **kwargs)
  File "/home/airflow/.local/lib/python3.6/site-packages/airflow/utils/cli.py", line 92, in wrapper
    return f(*args, **kwargs)
  File "/home/airflow/.local/lib/python3.6/site-packages/airflow/cli/commands/task_command.py", line 298, in task_run
    _run_task_by_selected_method(args, dag, ti)
  File "/home/airflow/.local/lib/python3.6/site-packages/airflow/cli/commands/task_command.py", line 107, in _run_task_by_selected_method
    _run_raw_task(args, ti)
  File "/home/airflow/.local/lib/python3.6/site-packages/airflow/cli/commands/task_command.py", line 184, in _run_raw_task
    error_file=args.error_file,
  File "/home/airflow/.local/lib/python3.6/site-packages/airflow/utils/session.py", line 70, in wrapper
    return func(*args, session=session, **kwargs)
  File "/home/airflow/.local/lib/python3.6/site-packages/airflow/models/taskinstance.py", line 1329, in _run_raw_task
    self._execute_task_with_callbacks(context)
  File "/home/airflow/.local/lib/python3.6/site-packages/airflow/models/taskinstance.py", line 1455, in _execute_task_with_callbacks
    result = self._execute_task(context, self.task)
  File "/home/airflow/.local/lib/python3.6/site-packages/airflow/models/taskinstance.py", line 1511, in _execute_task
    result = execute_callable(context=context)
  File "/home/airflow/.local/lib/python3.6/site-packages/airflow/operators/python.py", line 174, in execute
    return_value = self.execute_callable()
  File "/home/airflow/.local/lib/python3.6/site-packages/airflow/operators/python.py", line 185, in execute_callable
    return self.python_callable(*self.op_args, **self.op_kwargs)
  File "/opt/airflow/dags/data_ingestion_gcs_fhvhv_dag.py", line 77, in upload_to_gcs
    __clean_file(raw_file_name, clean_file_name)
  File "/opt/airflow/dags/data_ingestion_gcs_fhvhv_dag.py", line 57, in __clean_file
    df = pd.read_parquet(raw_file_name)
  File "/home/airflow/.local/lib/python3.6/site-packages/pandas/io/parquet.py", line 317, in read_parquet
    return impl.read(path, columns=columns, **kwargs)
  File "/home/airflow/.local/lib/python3.6/site-packages/pandas/io/parquet.py", line 142, in read
    path, columns=columns, filesystem=fs, **kwargs
  File "/home/airflow/.local/lib/python3.6/site-packages/pyarrow/parquet.py", line 1869, in read_table
    coerce_int96_timestamp_unit=coerce_int96_timestamp_unit
  File "/home/airflow/.local/lib/python3.6/site-packages/pyarrow/parquet.py", line 1679, in __init__
    [fragment], schema=fragment.physical_schema,
  File "pyarrow/_dataset.pyx", line 952, in pyarrow._dataset.Fragment.physical_schema.__get__
  File "pyarrow/error.pxi", line 143, in pyarrow.lib.pyarrow_internal_check_status
  File "pyarrow/error.pxi", line 99, in pyarrow.lib.check_status
pyarrow.lib.ArrowInvalid: Could not open Parquet input source '/opt/***/raw_data/fhvhvtaxi_tripdata_2019-01.parquet': Parquet magic bytes not found in footer. Either the file is corrupted or this is not a parquet file.
[2025-01-01 09:36:08,000] {local_task_job.py:154} INFO - Task exited with return code 1
[2025-01-01 09:36:08,055] {local_task_job.py:264} INFO - 0 downstream tasks scheduled from follow-on schedule check
