[2024-05-02 03:34:08,478] {taskinstance.py:1032} INFO - Dependencies all met for <TaskInstance: ingest_data_bigquery_yt.local_to_gcs_task scheduled__2019-06-02T06:00:00+00:00 [queued]>
[2024-05-02 03:34:08,637] {taskinstance.py:1032} INFO - Dependencies all met for <TaskInstance: ingest_data_bigquery_yt.local_to_gcs_task scheduled__2019-06-02T06:00:00+00:00 [queued]>
[2024-05-02 03:34:08,663] {taskinstance.py:1238} INFO - 
--------------------------------------------------------------------------------
[2024-05-02 03:34:08,688] {taskinstance.py:1239} INFO - Starting attempt 1 of 2
[2024-05-02 03:34:08,689] {taskinstance.py:1240} INFO - 
--------------------------------------------------------------------------------
[2024-05-02 03:34:08,810] {taskinstance.py:1259} INFO - Executing <Task(PythonOperator): local_to_gcs_task> on 2019-06-02 06:00:00+00:00
[2024-05-02 03:34:08,874] {standard_task_runner.py:52} INFO - Started process 3448 to run task
[2024-05-02 03:34:08,948] {standard_task_runner.py:76} INFO - Running: ['***', 'tasks', 'run', 'ingest_data_bigquery_yt', 'local_to_gcs_task', 'scheduled__2019-06-02T06:00:00+00:00', '--job-id', '3675', '--raw', '--subdir', 'DAGS_FOLDER/data_ingestion_gcs_yt_dag.py', '--cfg-path', '/tmp/tmprbun_ghs', '--error-file', '/tmp/tmpbipt5qii']
[2024-05-02 03:34:08,999] {standard_task_runner.py:77} INFO - Job 3675: Subtask local_to_gcs_task
[2024-05-02 03:34:09,424] {logging_mixin.py:109} INFO - Running <TaskInstance: ingest_data_bigquery_yt.local_to_gcs_task scheduled__2019-06-02T06:00:00+00:00 [running]> on host bef445d594dc
[2024-05-02 03:34:09,776] {warnings.py:99} WARNING - /home/***/.local/lib/python3.6/site-packages/***/utils/context.py:152: AirflowContextDeprecationWarning: Accessing 'execution_date' from the template is deprecated and will be removed in a future version. Please use 'data_interval_start' or 'logical_date' instead.
  warnings.warn(_create_deprecation_warning(key, self._deprecation_replacements[key]))

[2024-05-02 03:34:09,921] {taskinstance.py:1426} INFO - Exporting the following env vars:
AIRFLOW_CTX_DAG_OWNER=***
AIRFLOW_CTX_DAG_ID=ingest_data_bigquery_yt
AIRFLOW_CTX_TASK_ID=local_to_gcs_task
AIRFLOW_CTX_EXECUTION_DATE=2019-06-02T06:00:00+00:00
AIRFLOW_CTX_DAG_RUN_ID=scheduled__2019-06-02T06:00:00+00:00
[2024-05-02 03:34:10,020] {taskinstance.py:1700} ERROR - Task failed with exception
Traceback (most recent call last):
  File "/home/airflow/.local/lib/python3.6/site-packages/airflow/models/taskinstance.py", line 1329, in _run_raw_task
    self._execute_task_with_callbacks(context)
  File "/home/airflow/.local/lib/python3.6/site-packages/airflow/models/taskinstance.py", line 1455, in _execute_task_with_callbacks
    result = self._execute_task(context, self.task)
  File "/home/airflow/.local/lib/python3.6/site-packages/airflow/models/taskinstance.py", line 1511, in _execute_task
    result = execute_callable(context=context)
  File "/home/airflow/.local/lib/python3.6/site-packages/airflow/operators/python.py", line 174, in execute
    return_value = self.execute_callable()
  File "/home/airflow/.local/lib/python3.6/site-packages/airflow/operators/python.py", line 185, in execute_callable
    return self.python_callable(*self.op_args, **self.op_kwargs)
  File "/opt/airflow/dags/data_ingestion_gcs_yt_dag.py", line 81, in upload_to_gcs
    __clean_file(raw_file_name, clean_file_name)
  File "/opt/airflow/dags/data_ingestion_gcs_yt_dag.py", line 57, in __clean_file
    df = pd.read_csv(raw_file_name)
  File "/home/airflow/.local/lib/python3.6/site-packages/pandas/io/parsers.py", line 688, in read_csv
    return _read(filepath_or_buffer, kwds)
  File "/home/airflow/.local/lib/python3.6/site-packages/pandas/io/parsers.py", line 454, in _read
    parser = TextFileReader(fp_or_buf, **kwds)
  File "/home/airflow/.local/lib/python3.6/site-packages/pandas/io/parsers.py", line 948, in __init__
    self._make_engine(self.engine)
  File "/home/airflow/.local/lib/python3.6/site-packages/pandas/io/parsers.py", line 1180, in _make_engine
    self._engine = CParserWrapper(self.f, **self.options)
  File "/home/airflow/.local/lib/python3.6/site-packages/pandas/io/parsers.py", line 2010, in __init__
    self._reader = parsers.TextReader(src, **kwds)
  File "pandas/_libs/parsers.pyx", line 540, in pandas._libs.parsers.TextReader.__cinit__
pandas.errors.EmptyDataError: No columns to parse from file
[2024-05-02 03:34:10,071] {taskinstance.py:1277} INFO - Marking task as UP_FOR_RETRY. dag_id=ingest_data_bigquery_yt, task_id=local_to_gcs_task, execution_date=20190602T060000, start_date=20240502T033408, end_date=20240502T033410
[2024-05-02 03:34:10,139] {standard_task_runner.py:92} ERROR - Failed to execute job 3675 for task local_to_gcs_task
Traceback (most recent call last):
  File "/home/airflow/.local/lib/python3.6/site-packages/airflow/task/task_runner/standard_task_runner.py", line 85, in _start_by_fork
    args.func(args, dag=self.dag)
  File "/home/airflow/.local/lib/python3.6/site-packages/airflow/cli/cli_parser.py", line 48, in command
    return func(*args, **kwargs)
  File "/home/airflow/.local/lib/python3.6/site-packages/airflow/utils/cli.py", line 92, in wrapper
    return f(*args, **kwargs)
  File "/home/airflow/.local/lib/python3.6/site-packages/airflow/cli/commands/task_command.py", line 298, in task_run
    _run_task_by_selected_method(args, dag, ti)
  File "/home/airflow/.local/lib/python3.6/site-packages/airflow/cli/commands/task_command.py", line 107, in _run_task_by_selected_method
    _run_raw_task(args, ti)
  File "/home/airflow/.local/lib/python3.6/site-packages/airflow/cli/commands/task_command.py", line 184, in _run_raw_task
    error_file=args.error_file,
  File "/home/airflow/.local/lib/python3.6/site-packages/airflow/utils/session.py", line 70, in wrapper
    return func(*args, session=session, **kwargs)
  File "/home/airflow/.local/lib/python3.6/site-packages/airflow/models/taskinstance.py", line 1329, in _run_raw_task
    self._execute_task_with_callbacks(context)
  File "/home/airflow/.local/lib/python3.6/site-packages/airflow/models/taskinstance.py", line 1455, in _execute_task_with_callbacks
    result = self._execute_task(context, self.task)
  File "/home/airflow/.local/lib/python3.6/site-packages/airflow/models/taskinstance.py", line 1511, in _execute_task
    result = execute_callable(context=context)
  File "/home/airflow/.local/lib/python3.6/site-packages/airflow/operators/python.py", line 174, in execute
    return_value = self.execute_callable()
  File "/home/airflow/.local/lib/python3.6/site-packages/airflow/operators/python.py", line 185, in execute_callable
    return self.python_callable(*self.op_args, **self.op_kwargs)
  File "/opt/airflow/dags/data_ingestion_gcs_yt_dag.py", line 81, in upload_to_gcs
    __clean_file(raw_file_name, clean_file_name)
  File "/opt/airflow/dags/data_ingestion_gcs_yt_dag.py", line 57, in __clean_file
    df = pd.read_csv(raw_file_name)
  File "/home/airflow/.local/lib/python3.6/site-packages/pandas/io/parsers.py", line 688, in read_csv
    return _read(filepath_or_buffer, kwds)
  File "/home/airflow/.local/lib/python3.6/site-packages/pandas/io/parsers.py", line 454, in _read
    parser = TextFileReader(fp_or_buf, **kwds)
  File "/home/airflow/.local/lib/python3.6/site-packages/pandas/io/parsers.py", line 948, in __init__
    self._make_engine(self.engine)
  File "/home/airflow/.local/lib/python3.6/site-packages/pandas/io/parsers.py", line 1180, in _make_engine
    self._engine = CParserWrapper(self.f, **self.options)
  File "/home/airflow/.local/lib/python3.6/site-packages/pandas/io/parsers.py", line 2010, in __init__
    self._reader = parsers.TextReader(src, **kwds)
  File "pandas/_libs/parsers.pyx", line 540, in pandas._libs.parsers.TextReader.__cinit__
pandas.errors.EmptyDataError: No columns to parse from file
[2024-05-02 03:34:10,180] {local_task_job.py:154} INFO - Task exited with return code 1
[2024-05-02 03:34:10,356] {local_task_job.py:264} INFO - 0 downstream tasks scheduled from follow-on schedule check
[2024-05-03 15:57:43,879] {taskinstance.py:1032} INFO - Dependencies all met for <TaskInstance: ingest_data_bigquery_yt.local_to_gcs_task scheduled__2019-06-02T06:00:00+00:00 [queued]>
[2024-05-03 15:57:43,990] {taskinstance.py:1032} INFO - Dependencies all met for <TaskInstance: ingest_data_bigquery_yt.local_to_gcs_task scheduled__2019-06-02T06:00:00+00:00 [queued]>
[2024-05-03 15:57:43,990] {taskinstance.py:1238} INFO - 
--------------------------------------------------------------------------------
[2024-05-03 15:57:43,990] {taskinstance.py:1239} INFO - Starting attempt 1 of 3
[2024-05-03 15:57:43,990] {taskinstance.py:1240} INFO - 
--------------------------------------------------------------------------------
[2024-05-03 15:57:44,080] {taskinstance.py:1259} INFO - Executing <Task(PythonOperator): local_to_gcs_task> on 2019-06-02 06:00:00+00:00
[2024-05-03 15:57:44,142] {standard_task_runner.py:76} INFO - Running: ['***', 'tasks', 'run', 'ingest_data_bigquery_yt', 'local_to_gcs_task', 'scheduled__2019-06-02T06:00:00+00:00', '--job-id', '4164', '--raw', '--subdir', 'DAGS_FOLDER/data_ingstion_gcs_yt_dag.py', '--cfg-path', '/tmp/tmpsgvtkiez', '--error-file', '/tmp/tmpvtexxg9q']
[2024-05-03 15:57:44,148] {standard_task_runner.py:77} INFO - Job 4164: Subtask local_to_gcs_task
[2024-05-03 15:57:44,121] {standard_task_runner.py:52} INFO - Started process 257 to run task
[2024-05-03 15:57:44,293] {logging_mixin.py:109} INFO - Running <TaskInstance: ingest_data_bigquery_yt.local_to_gcs_task scheduled__2019-06-02T06:00:00+00:00 [running]> on host f603d4872b21
[2024-05-03 15:57:44,498] {warnings.py:99} WARNING - /home/***/.local/lib/python3.6/site-packages/***/utils/context.py:152: AirflowContextDeprecationWarning: Accessing 'execution_date' from the template is deprecated and will be removed in a future version. Please use 'data_interval_start' or 'logical_date' instead.
  warnings.warn(_create_deprecation_warning(key, self._deprecation_replacements[key]))

[2024-05-03 15:57:44,568] {taskinstance.py:1426} INFO - Exporting the following env vars:
AIRFLOW_CTX_DAG_OWNER=***
AIRFLOW_CTX_DAG_ID=ingest_data_bigquery_yt
AIRFLOW_CTX_TASK_ID=local_to_gcs_task
AIRFLOW_CTX_EXECUTION_DATE=2019-06-02T06:00:00+00:00
AIRFLOW_CTX_DAG_RUN_ID=scheduled__2019-06-02T06:00:00+00:00
[2024-05-03 16:40:49,585] {taskinstance.py:1032} INFO - Dependencies all met for <TaskInstance: ingest_data_bigquery_yt.local_to_gcs_task scheduled__2019-06-02T06:00:00+00:00 [queued]>
[2024-05-03 16:40:49,736] {taskinstance.py:1032} INFO - Dependencies all met for <TaskInstance: ingest_data_bigquery_yt.local_to_gcs_task scheduled__2019-06-02T06:00:00+00:00 [queued]>
[2024-05-03 16:40:49,736] {taskinstance.py:1238} INFO - 
--------------------------------------------------------------------------------
[2024-05-03 16:40:49,736] {taskinstance.py:1239} INFO - Starting attempt 1 of 3
[2024-05-03 16:40:49,736] {taskinstance.py:1240} INFO - 
--------------------------------------------------------------------------------
[2024-05-03 16:40:49,844] {taskinstance.py:1259} INFO - Executing <Task(PythonOperator): local_to_gcs_task> on 2019-06-02 06:00:00+00:00
[2024-05-03 16:40:49,882] {standard_task_runner.py:76} INFO - Running: ['***', 'tasks', 'run', 'ingest_data_bigquery_yt', 'local_to_gcs_task', 'scheduled__2019-06-02T06:00:00+00:00', '--job-id', '4237', '--raw', '--subdir', 'DAGS_FOLDER/data_ingstion_gcs_yt_dag.py', '--cfg-path', '/tmp/tmpkvrkrwz0', '--error-file', '/tmp/tmp_2ntpeoz']
[2024-05-03 16:40:49,920] {standard_task_runner.py:77} INFO - Job 4237: Subtask local_to_gcs_task
[2024-05-03 16:40:49,858] {standard_task_runner.py:52} INFO - Started process 438 to run task
[2024-05-03 16:40:50,095] {logging_mixin.py:109} INFO - Running <TaskInstance: ingest_data_bigquery_yt.local_to_gcs_task scheduled__2019-06-02T06:00:00+00:00 [running]> on host f0ab9bf9b587
[2024-05-03 16:40:50,182] {warnings.py:99} WARNING - /home/***/.local/lib/python3.6/site-packages/***/utils/context.py:152: AirflowContextDeprecationWarning: Accessing 'execution_date' from the template is deprecated and will be removed in a future version. Please use 'data_interval_start' or 'logical_date' instead.
  warnings.warn(_create_deprecation_warning(key, self._deprecation_replacements[key]))

[2024-05-03 16:40:50,224] {taskinstance.py:1426} INFO - Exporting the following env vars:
AIRFLOW_CTX_DAG_OWNER=***
AIRFLOW_CTX_DAG_ID=ingest_data_bigquery_yt
AIRFLOW_CTX_TASK_ID=local_to_gcs_task
AIRFLOW_CTX_EXECUTION_DATE=2019-06-02T06:00:00+00:00
AIRFLOW_CTX_DAG_RUN_ID=scheduled__2019-06-02T06:00:00+00:00
[2024-05-03 17:08:48,021] {local_task_job.py:154} INFO - Task exited with return code Negsignal.SIGKILL
[2024-05-03 17:08:48,399] {taskinstance.py:1277} INFO - Marking task as UP_FOR_RETRY. dag_id=ingest_data_bigquery_yt, task_id=local_to_gcs_task, execution_date=20190602T060000, start_date=20240503T164049, end_date=20240503T170848
[2024-05-03 17:08:49,288] {local_task_job.py:264} INFO - 0 downstream tasks scheduled from follow-on schedule check
[2024-05-05 12:02:19,773] {taskinstance.py:1032} INFO - Dependencies all met for <TaskInstance: ingest_data_bigquery_yt.local_to_gcs_task scheduled__2019-06-02T06:00:00+00:00 [queued]>
[2024-05-05 12:02:19,827] {taskinstance.py:1032} INFO - Dependencies all met for <TaskInstance: ingest_data_bigquery_yt.local_to_gcs_task scheduled__2019-06-02T06:00:00+00:00 [queued]>
[2024-05-05 12:02:19,827] {taskinstance.py:1238} INFO - 
--------------------------------------------------------------------------------
[2024-05-05 12:02:19,827] {taskinstance.py:1239} INFO - Starting attempt 1 of 3
[2024-05-05 12:02:19,827] {taskinstance.py:1240} INFO - 
--------------------------------------------------------------------------------
[2024-05-05 12:02:19,887] {taskinstance.py:1259} INFO - Executing <Task(PythonOperator): local_to_gcs_task> on 2019-06-02 06:00:00+00:00
[2024-05-05 12:02:19,895] {standard_task_runner.py:52} INFO - Started process 1121 to run task
[2024-05-05 12:02:19,982] {standard_task_runner.py:76} INFO - Running: ['***', 'tasks', 'run', 'ingest_data_bigquery_yt', 'local_to_gcs_task', 'scheduled__2019-06-02T06:00:00+00:00', '--job-id', '4360', '--raw', '--subdir', 'DAGS_FOLDER/data_ingstion_gcs_yt_dag.py', '--cfg-path', '/tmp/tmp49nfq9xf', '--error-file', '/tmp/tmp0bntponx']
[2024-05-05 12:02:20,014] {standard_task_runner.py:77} INFO - Job 4360: Subtask local_to_gcs_task
[2024-05-05 12:02:20,286] {logging_mixin.py:109} INFO - Running <TaskInstance: ingest_data_bigquery_yt.local_to_gcs_task scheduled__2019-06-02T06:00:00+00:00 [running]> on host 19865117eb6d
[2024-05-05 12:02:20,359] {warnings.py:99} WARNING - /home/***/.local/lib/python3.6/site-packages/***/utils/context.py:152: AirflowContextDeprecationWarning: Accessing 'execution_date' from the template is deprecated and will be removed in a future version. Please use 'data_interval_start' or 'logical_date' instead.
  warnings.warn(_create_deprecation_warning(key, self._deprecation_replacements[key]))

[2024-05-05 12:02:20,474] {taskinstance.py:1426} INFO - Exporting the following env vars:
AIRFLOW_CTX_DAG_OWNER=***
AIRFLOW_CTX_DAG_ID=ingest_data_bigquery_yt
AIRFLOW_CTX_TASK_ID=local_to_gcs_task
AIRFLOW_CTX_EXECUTION_DATE=2019-06-02T06:00:00+00:00
AIRFLOW_CTX_DAG_RUN_ID=scheduled__2019-06-02T06:00:00+00:00
[2024-05-05 13:29:00,054] {base_job.py:230} ERROR - LocalTaskJob heartbeat got an exception
Traceback (most recent call last):
  File "/home/airflow/.local/lib/python3.6/site-packages/sqlalchemy/engine/base.py", line 2336, in _wrap_pool_connect
    return fn()
  File "/home/airflow/.local/lib/python3.6/site-packages/sqlalchemy/pool/base.py", line 364, in connect
    return _ConnectionFairy._checkout(self)
  File "/home/airflow/.local/lib/python3.6/site-packages/sqlalchemy/pool/base.py", line 778, in _checkout
    fairy = _ConnectionRecord.checkout(pool)
  File "/home/airflow/.local/lib/python3.6/site-packages/sqlalchemy/pool/base.py", line 495, in checkout
    rec = pool._do_get()
  File "/home/airflow/.local/lib/python3.6/site-packages/sqlalchemy/pool/impl.py", line 241, in _do_get
    return self._create_connection()
  File "/home/airflow/.local/lib/python3.6/site-packages/sqlalchemy/pool/base.py", line 309, in _create_connection
    return _ConnectionRecord(self)
  File "/home/airflow/.local/lib/python3.6/site-packages/sqlalchemy/pool/base.py", line 440, in __init__
    self.__connect(first_connect_check=True)
  File "/home/airflow/.local/lib/python3.6/site-packages/sqlalchemy/pool/base.py", line 661, in __connect
    pool.logger.debug("Error on connect(): %s", e)
  File "/home/airflow/.local/lib/python3.6/site-packages/sqlalchemy/util/langhelpers.py", line 70, in __exit__
    with_traceback=exc_tb,
  File "/home/airflow/.local/lib/python3.6/site-packages/sqlalchemy/util/compat.py", line 182, in raise_
    raise exception
  File "/home/airflow/.local/lib/python3.6/site-packages/sqlalchemy/pool/base.py", line 656, in __connect
    connection = pool._invoke_creator(self)
  File "/home/airflow/.local/lib/python3.6/site-packages/sqlalchemy/engine/strategies.py", line 114, in connect
    return dialect.connect(*cargs, **cparams)
  File "/home/airflow/.local/lib/python3.6/site-packages/sqlalchemy/engine/default.py", line 508, in connect
    return self.dbapi.connect(*cargs, **cparams)
  File "/home/airflow/.local/lib/python3.6/site-packages/psycopg2/__init__.py", line 122, in connect
    conn = _connect(dsn, connection_factory=connection_factory, **kwasync)
psycopg2.OperationalError: could not translate host name "postgres" to address: Temporary failure in name resolution


The above exception was the direct cause of the following exception:

Traceback (most recent call last):
  File "/home/airflow/.local/lib/python3.6/site-packages/airflow/jobs/base_job.py", line 202, in heartbeat
    session.merge(self)
  File "/home/airflow/.local/lib/python3.6/site-packages/sqlalchemy/orm/session.py", line 2171, in merge
    _resolve_conflict_map=_resolve_conflict_map,
  File "/home/airflow/.local/lib/python3.6/site-packages/sqlalchemy/orm/session.py", line 2244, in _merge
    merged = self.query(mapper.class_).get(key[1])
  File "/home/airflow/.local/lib/python3.6/site-packages/sqlalchemy/orm/query.py", line 1018, in get
    return self._get_impl(ident, loading.load_on_pk_identity)
  File "/home/airflow/.local/lib/python3.6/site-packages/sqlalchemy/orm/query.py", line 1135, in _get_impl
    return db_load_fn(self, primary_key_identity)
  File "/home/airflow/.local/lib/python3.6/site-packages/sqlalchemy/orm/loading.py", line 286, in load_on_pk_identity
    return q.one()
  File "/home/airflow/.local/lib/python3.6/site-packages/sqlalchemy/orm/query.py", line 3490, in one
    ret = self.one_or_none()
  File "/home/airflow/.local/lib/python3.6/site-packages/sqlalchemy/orm/query.py", line 3459, in one_or_none
    ret = list(self)
  File "/home/airflow/.local/lib/python3.6/site-packages/sqlalchemy/orm/query.py", line 3535, in __iter__
    return self._execute_and_instances(context)
  File "/home/airflow/.local/lib/python3.6/site-packages/sqlalchemy/orm/query.py", line 3557, in _execute_and_instances
    querycontext, self._connection_from_session, close_with_result=True
  File "/home/airflow/.local/lib/python3.6/site-packages/sqlalchemy/orm/query.py", line 3572, in _get_bind_args
    mapper=self._bind_mapper(), clause=querycontext.statement, **kw
  File "/home/airflow/.local/lib/python3.6/site-packages/sqlalchemy/orm/query.py", line 3550, in _connection_from_session
    conn = self.session.connection(**kw)
  File "/home/airflow/.local/lib/python3.6/site-packages/sqlalchemy/orm/session.py", line 1145, in connection
    execution_options=execution_options,
  File "/home/airflow/.local/lib/python3.6/site-packages/sqlalchemy/orm/session.py", line 1151, in _connection_for_bind
    engine, execution_options
  File "/home/airflow/.local/lib/python3.6/site-packages/sqlalchemy/orm/session.py", line 433, in _connection_for_bind
    conn = bind._contextual_connect()
  File "/home/airflow/.local/lib/python3.6/site-packages/sqlalchemy/engine/base.py", line 2302, in _contextual_connect
    self._wrap_pool_connect(self.pool.connect, None),
  File "/home/airflow/.local/lib/python3.6/site-packages/sqlalchemy/engine/base.py", line 2340, in _wrap_pool_connect
    e, dialect, self
  File "/home/airflow/.local/lib/python3.6/site-packages/sqlalchemy/engine/base.py", line 1584, in _handle_dbapi_exception_noconnection
    sqlalchemy_exception, with_traceback=exc_info[2], from_=e
  File "/home/airflow/.local/lib/python3.6/site-packages/sqlalchemy/util/compat.py", line 182, in raise_
    raise exception
  File "/home/airflow/.local/lib/python3.6/site-packages/sqlalchemy/engine/base.py", line 2336, in _wrap_pool_connect
    return fn()
  File "/home/airflow/.local/lib/python3.6/site-packages/sqlalchemy/pool/base.py", line 364, in connect
    return _ConnectionFairy._checkout(self)
  File "/home/airflow/.local/lib/python3.6/site-packages/sqlalchemy/pool/base.py", line 778, in _checkout
    fairy = _ConnectionRecord.checkout(pool)
  File "/home/airflow/.local/lib/python3.6/site-packages/sqlalchemy/pool/base.py", line 495, in checkout
    rec = pool._do_get()
  File "/home/airflow/.local/lib/python3.6/site-packages/sqlalchemy/pool/impl.py", line 241, in _do_get
    return self._create_connection()
  File "/home/airflow/.local/lib/python3.6/site-packages/sqlalchemy/pool/base.py", line 309, in _create_connection
    return _ConnectionRecord(self)
  File "/home/airflow/.local/lib/python3.6/site-packages/sqlalchemy/pool/base.py", line 440, in __init__
    self.__connect(first_connect_check=True)
  File "/home/airflow/.local/lib/python3.6/site-packages/sqlalchemy/pool/base.py", line 661, in __connect
    pool.logger.debug("Error on connect(): %s", e)
  File "/home/airflow/.local/lib/python3.6/site-packages/sqlalchemy/util/langhelpers.py", line 70, in __exit__
    with_traceback=exc_tb,
  File "/home/airflow/.local/lib/python3.6/site-packages/sqlalchemy/util/compat.py", line 182, in raise_
    raise exception
  File "/home/airflow/.local/lib/python3.6/site-packages/sqlalchemy/pool/base.py", line 656, in __connect
    connection = pool._invoke_creator(self)
  File "/home/airflow/.local/lib/python3.6/site-packages/sqlalchemy/engine/strategies.py", line 114, in connect
    return dialect.connect(*cargs, **cparams)
  File "/home/airflow/.local/lib/python3.6/site-packages/sqlalchemy/engine/default.py", line 508, in connect
    return self.dbapi.connect(*cargs, **cparams)
  File "/home/airflow/.local/lib/python3.6/site-packages/psycopg2/__init__.py", line 122, in connect
    conn = _connect(dsn, connection_factory=connection_factory, **kwasync)
sqlalchemy.exc.OperationalError: (psycopg2.OperationalError) could not translate host name "postgres" to address: Temporary failure in name resolution

(Background on this error at: http://sqlalche.me/e/13/e3q8)
[2024-05-05 13:37:59,637] {local_task_job.py:142} ERROR - Heartbeat time limit exceeded!
[2024-05-05 13:37:59,849] {process_utils.py:124} INFO - Sending Signals.SIGTERM to group 1121. PIDs of all processes in the group: [1121]
[2024-05-05 13:37:59,886] {process_utils.py:75} INFO - Sending the signal Signals.SIGTERM to group 1121
[2024-05-05 13:37:59,996] {taskinstance.py:1408} ERROR - Received SIGTERM. Terminating subprocesses.
[2024-05-05 13:38:05,473] {taskinstance.py:1700} ERROR - Task failed with exception
Traceback (most recent call last):
  File "/home/airflow/.local/lib/python3.6/site-packages/airflow/models/taskinstance.py", line 1329, in _run_raw_task
    self._execute_task_with_callbacks(context)
  File "/home/airflow/.local/lib/python3.6/site-packages/airflow/models/taskinstance.py", line 1455, in _execute_task_with_callbacks
    result = self._execute_task(context, self.task)
  File "/home/airflow/.local/lib/python3.6/site-packages/airflow/models/taskinstance.py", line 1511, in _execute_task
    result = execute_callable(context=context)
  File "/home/airflow/.local/lib/python3.6/site-packages/airflow/operators/python.py", line 174, in execute
    return_value = self.execute_callable()
  File "/home/airflow/.local/lib/python3.6/site-packages/airflow/operators/python.py", line 185, in execute_callable
    return self.python_callable(*self.op_args, **self.op_kwargs)
  File "/opt/airflow/dags/data_ingstion_gcs_yt_dag.py", line 84, in upload_to_gcs
    __clean_file(raw_file_name, clean_file_name)
  File "/opt/airflow/dags/data_ingstion_gcs_yt_dag.py", line 65, in __clean_file
    "payment_type": "int64",
  File "/home/airflow/.local/lib/python3.6/site-packages/pandas/io/parsers.py", line 688, in read_csv
    return _read(filepath_or_buffer, kwds)
  File "/home/airflow/.local/lib/python3.6/site-packages/pandas/io/parsers.py", line 460, in _read
    data = parser.read(nrows)
  File "/home/airflow/.local/lib/python3.6/site-packages/pandas/io/parsers.py", line 1198, in read
    ret = self._engine.read(nrows)
  File "/home/airflow/.local/lib/python3.6/site-packages/pandas/io/parsers.py", line 2157, in read
    data = self._reader.read(nrows)
  File "pandas/_libs/parsers.pyx", line 847, in pandas._libs.parsers.TextReader.read
  File "pandas/_libs/parsers.pyx", line 862, in pandas._libs.parsers.TextReader._read_low_memory
  File "pandas/_libs/parsers.pyx", line 941, in pandas._libs.parsers.TextReader._read_rows
  File "pandas/_libs/parsers.pyx", line 1073, in pandas._libs.parsers.TextReader._convert_column_data
  File "pandas/_libs/parsers.pyx", line 1104, in pandas._libs.parsers.TextReader._convert_tokens
  File "pandas/_libs/parsers.pyx", line 1162, in pandas._libs.parsers.TextReader._convert_with_dtype
  File "/home/airflow/.local/lib/python3.6/site-packages/pandas/core/dtypes/common.py", line 530, in is_categorical_dtype
    def is_categorical_dtype(arr_or_dtype) -> bool:
  File "/home/airflow/.local/lib/python3.6/site-packages/airflow/models/taskinstance.py", line 1410, in signal_handler
    raise AirflowException("Task received SIGTERM signal")
airflow.exceptions.AirflowException: Task received SIGTERM signal
[2024-05-05 13:38:05,568] {taskinstance.py:1277} INFO - Marking task as UP_FOR_RETRY. dag_id=ingest_data_bigquery_yt, task_id=local_to_gcs_task, execution_date=20190602T060000, start_date=20240505T120219, end_date=20240505T133805
[2024-05-05 13:38:05,634] {standard_task_runner.py:92} ERROR - Failed to execute job 4360 for task local_to_gcs_task
Traceback (most recent call last):
  File "/home/airflow/.local/lib/python3.6/site-packages/airflow/task/task_runner/standard_task_runner.py", line 85, in _start_by_fork
    args.func(args, dag=self.dag)
  File "/home/airflow/.local/lib/python3.6/site-packages/airflow/cli/cli_parser.py", line 48, in command
    return func(*args, **kwargs)
  File "/home/airflow/.local/lib/python3.6/site-packages/airflow/utils/cli.py", line 92, in wrapper
    return f(*args, **kwargs)
  File "/home/airflow/.local/lib/python3.6/site-packages/airflow/cli/commands/task_command.py", line 298, in task_run
    _run_task_by_selected_method(args, dag, ti)
  File "/home/airflow/.local/lib/python3.6/site-packages/airflow/cli/commands/task_command.py", line 107, in _run_task_by_selected_method
    _run_raw_task(args, ti)
  File "/home/airflow/.local/lib/python3.6/site-packages/airflow/cli/commands/task_command.py", line 184, in _run_raw_task
    error_file=args.error_file,
  File "/home/airflow/.local/lib/python3.6/site-packages/airflow/utils/session.py", line 70, in wrapper
    return func(*args, session=session, **kwargs)
  File "/home/airflow/.local/lib/python3.6/site-packages/airflow/models/taskinstance.py", line 1329, in _run_raw_task
    self._execute_task_with_callbacks(context)
  File "/home/airflow/.local/lib/python3.6/site-packages/airflow/models/taskinstance.py", line 1455, in _execute_task_with_callbacks
    result = self._execute_task(context, self.task)
  File "/home/airflow/.local/lib/python3.6/site-packages/airflow/models/taskinstance.py", line 1511, in _execute_task
    result = execute_callable(context=context)
  File "/home/airflow/.local/lib/python3.6/site-packages/airflow/operators/python.py", line 174, in execute
    return_value = self.execute_callable()
  File "/home/airflow/.local/lib/python3.6/site-packages/airflow/operators/python.py", line 185, in execute_callable
    return self.python_callable(*self.op_args, **self.op_kwargs)
  File "/opt/airflow/dags/data_ingstion_gcs_yt_dag.py", line 84, in upload_to_gcs
    __clean_file(raw_file_name, clean_file_name)
  File "/opt/airflow/dags/data_ingstion_gcs_yt_dag.py", line 65, in __clean_file
    "payment_type": "int64",
  File "/home/airflow/.local/lib/python3.6/site-packages/pandas/io/parsers.py", line 688, in read_csv
    return _read(filepath_or_buffer, kwds)
  File "/home/airflow/.local/lib/python3.6/site-packages/pandas/io/parsers.py", line 460, in _read
    data = parser.read(nrows)
  File "/home/airflow/.local/lib/python3.6/site-packages/pandas/io/parsers.py", line 1198, in read
    ret = self._engine.read(nrows)
  File "/home/airflow/.local/lib/python3.6/site-packages/pandas/io/parsers.py", line 2157, in read
    data = self._reader.read(nrows)
  File "pandas/_libs/parsers.pyx", line 847, in pandas._libs.parsers.TextReader.read
  File "pandas/_libs/parsers.pyx", line 862, in pandas._libs.parsers.TextReader._read_low_memory
  File "pandas/_libs/parsers.pyx", line 941, in pandas._libs.parsers.TextReader._read_rows
  File "pandas/_libs/parsers.pyx", line 1073, in pandas._libs.parsers.TextReader._convert_column_data
  File "pandas/_libs/parsers.pyx", line 1104, in pandas._libs.parsers.TextReader._convert_tokens
  File "pandas/_libs/parsers.pyx", line 1162, in pandas._libs.parsers.TextReader._convert_with_dtype
  File "/home/airflow/.local/lib/python3.6/site-packages/pandas/core/dtypes/common.py", line 530, in is_categorical_dtype
    def is_categorical_dtype(arr_or_dtype) -> bool:
  File "/home/airflow/.local/lib/python3.6/site-packages/airflow/models/taskinstance.py", line 1410, in signal_handler
    raise AirflowException("Task received SIGTERM signal")
airflow.exceptions.AirflowException: Task received SIGTERM signal
[2024-05-05 13:38:05,847] {process_utils.py:70} INFO - Process psutil.Process(pid=1121, status='terminated', exitcode=1, started='12:02:19') (1121) terminated with exit code 1
[2024-05-06 07:40:44,027] {taskinstance.py:1032} INFO - Dependencies all met for <TaskInstance: ingest_data_bigquery_yt.local_to_gcs_task scheduled__2019-06-02T06:00:00+00:00 [queued]>
[2024-05-06 07:40:44,136] {taskinstance.py:1032} INFO - Dependencies all met for <TaskInstance: ingest_data_bigquery_yt.local_to_gcs_task scheduled__2019-06-02T06:00:00+00:00 [queued]>
[2024-05-06 07:40:44,137] {taskinstance.py:1238} INFO - 
--------------------------------------------------------------------------------
[2024-05-06 07:40:44,137] {taskinstance.py:1239} INFO - Starting attempt 1 of 3
[2024-05-06 07:40:44,137] {taskinstance.py:1240} INFO - 
--------------------------------------------------------------------------------
[2024-05-06 07:40:44,400] {taskinstance.py:1259} INFO - Executing <Task(PythonOperator): local_to_gcs_task> on 2019-06-02 06:00:00+00:00
[2024-05-06 07:40:44,417] {standard_task_runner.py:52} INFO - Started process 3366 to run task
[2024-05-06 07:40:44,472] {standard_task_runner.py:76} INFO - Running: ['***', 'tasks', 'run', 'ingest_data_bigquery_yt', 'local_to_gcs_task', 'scheduled__2019-06-02T06:00:00+00:00', '--job-id', '4513', '--raw', '--subdir', 'DAGS_FOLDER/data_ingstion_gcs_yt_dag.py', '--cfg-path', '/tmp/tmp2n0q9ymw', '--error-file', '/tmp/tmp73zcru95']
[2024-05-06 07:40:44,502] {standard_task_runner.py:77} INFO - Job 4513: Subtask local_to_gcs_task
[2024-05-06 07:40:45,002] {logging_mixin.py:109} INFO - Running <TaskInstance: ingest_data_bigquery_yt.local_to_gcs_task scheduled__2019-06-02T06:00:00+00:00 [running]> on host 1aa5194a14e3
[2024-05-06 07:40:45,278] {warnings.py:99} WARNING - /home/***/.local/lib/python3.6/site-packages/***/utils/context.py:152: AirflowContextDeprecationWarning: Accessing 'execution_date' from the template is deprecated and will be removed in a future version. Please use 'data_interval_start' or 'logical_date' instead.
  warnings.warn(_create_deprecation_warning(key, self._deprecation_replacements[key]))

[2024-05-06 07:40:45,505] {taskinstance.py:1426} INFO - Exporting the following env vars:
AIRFLOW_CTX_DAG_OWNER=***
AIRFLOW_CTX_DAG_ID=ingest_data_bigquery_yt
AIRFLOW_CTX_TASK_ID=local_to_gcs_task
AIRFLOW_CTX_EXECUTION_DATE=2019-06-02T06:00:00+00:00
AIRFLOW_CTX_DAG_RUN_ID=scheduled__2019-06-02T06:00:00+00:00
