[2024-05-02 03:33:57,004] {taskinstance.py:1032} INFO - Dependencies all met for <TaskInstance: ingest_data_bigquery_yt.download_dataset_task scheduled__2019-01-02T06:00:00+00:00 [queued]>
[2024-05-02 03:33:57,123] {taskinstance.py:1032} INFO - Dependencies all met for <TaskInstance: ingest_data_bigquery_yt.download_dataset_task scheduled__2019-01-02T06:00:00+00:00 [queued]>
[2024-05-02 03:33:57,138] {taskinstance.py:1238} INFO - 
--------------------------------------------------------------------------------
[2024-05-02 03:33:57,139] {taskinstance.py:1239} INFO - Starting attempt 1 of 2
[2024-05-02 03:33:57,139] {taskinstance.py:1240} INFO - 
--------------------------------------------------------------------------------
[2024-05-02 03:33:57,255] {taskinstance.py:1259} INFO - Executing <Task(BashOperator): download_dataset_task> on 2019-01-02 06:00:00+00:00
[2024-05-02 03:33:57,333] {standard_task_runner.py:52} INFO - Started process 3323 to run task
[2024-05-02 03:33:57,370] {standard_task_runner.py:76} INFO - Running: ['***', 'tasks', 'run', 'ingest_data_bigquery_yt', 'download_dataset_task', 'scheduled__2019-01-02T06:00:00+00:00', '--job-id', '3663', '--raw', '--subdir', 'DAGS_FOLDER/data_ingestion_gcs_yt_dag.py', '--cfg-path', '/tmp/tmpht98mj2h', '--error-file', '/tmp/tmpz_o0etfk']
[2024-05-02 03:33:57,457] {standard_task_runner.py:77} INFO - Job 3663: Subtask download_dataset_task
[2024-05-02 03:33:58,121] {logging_mixin.py:109} INFO - Running <TaskInstance: ingest_data_bigquery_yt.download_dataset_task scheduled__2019-01-02T06:00:00+00:00 [running]> on host bef445d594dc
[2024-05-02 03:33:58,364] {warnings.py:99} WARNING - /home/***/.local/lib/python3.6/site-packages/***/utils/context.py:152: AirflowContextDeprecationWarning: Accessing 'execution_date' from the template is deprecated and will be removed in a future version. Please use 'data_interval_start' or 'logical_date' instead.
  warnings.warn(_create_deprecation_warning(key, self._deprecation_replacements[key]))

[2024-05-02 03:33:58,512] {taskinstance.py:1426} INFO - Exporting the following env vars:
AIRFLOW_CTX_DAG_OWNER=***
AIRFLOW_CTX_DAG_ID=ingest_data_bigquery_yt
AIRFLOW_CTX_TASK_ID=download_dataset_task
AIRFLOW_CTX_EXECUTION_DATE=2019-01-02T06:00:00+00:00
AIRFLOW_CTX_DAG_RUN_ID=scheduled__2019-01-02T06:00:00+00:00
[2024-05-02 03:33:58,534] {subprocess.py:62} INFO - Tmp dir root location: 
 /tmp
[2024-05-02 03:33:58,541] {subprocess.py:74} INFO - Running command: ['bash', '-c', 'curl -sSL https://github.com/DataTalksClub/nyc-tlc-data/releases/download/yellow/yellow_tripdata_2019-01.csv.gz > /opt/***/raw_data/yellowtaxi_tripdata_2019-01.csv.gz | gzip -d > /opt/***/raw_data/yellowtaxi_tripdata_2019-01.csv | rm /opt/***/raw_data/yellowtaxi_tripdata_2019-01.csv.gz']
[2024-05-02 03:33:58,691] {subprocess.py:85} INFO - Output:
[2024-05-02 03:33:58,836] {subprocess.py:89} INFO - 
[2024-05-02 03:33:58,837] {subprocess.py:89} INFO - gzip: stdin: unexpected end of file
[2024-05-02 03:34:02,196] {subprocess.py:93} INFO - Command exited with return code 0
[2024-05-02 03:34:02,363] {taskinstance.py:1277} INFO - Marking task as SUCCESS. dag_id=ingest_data_bigquery_yt, task_id=download_dataset_task, execution_date=20190102T060000, start_date=20240502T033357, end_date=20240502T033402
[2024-05-02 03:34:02,643] {local_task_job.py:154} INFO - Task exited with return code 0
[2024-05-02 03:34:02,878] {local_task_job.py:264} INFO - 1 downstream tasks scheduled from follow-on schedule check
[2024-05-02 03:39:42,199] {taskinstance.py:1032} INFO - Dependencies all met for <TaskInstance: ingest_data_bigquery_yt.download_dataset_task scheduled__2019-01-02T06:00:00+00:00 [queued]>
[2024-05-02 03:39:42,294] {taskinstance.py:1032} INFO - Dependencies all met for <TaskInstance: ingest_data_bigquery_yt.download_dataset_task scheduled__2019-01-02T06:00:00+00:00 [queued]>
[2024-05-02 03:39:42,295] {taskinstance.py:1238} INFO - 
--------------------------------------------------------------------------------
[2024-05-02 03:39:42,295] {taskinstance.py:1239} INFO - Starting attempt 1 of 2
[2024-05-02 03:39:42,295] {taskinstance.py:1240} INFO - 
--------------------------------------------------------------------------------
[2024-05-02 03:39:42,378] {taskinstance.py:1259} INFO - Executing <Task(BashOperator): download_dataset_task> on 2019-01-02 06:00:00+00:00
[2024-05-02 03:39:42,409] {standard_task_runner.py:52} INFO - Started process 3749 to run task
[2024-05-02 03:39:42,432] {standard_task_runner.py:76} INFO - Running: ['***', 'tasks', 'run', 'ingest_data_bigquery_yt', 'download_dataset_task', 'scheduled__2019-01-02T06:00:00+00:00', '--job-id', '3690', '--raw', '--subdir', 'DAGS_FOLDER/data_ingestion_gcs_yt_dag.py', '--cfg-path', '/tmp/tmpozi4iuls', '--error-file', '/tmp/tmp82d9oydo']
[2024-05-02 03:39:42,446] {standard_task_runner.py:77} INFO - Job 3690: Subtask download_dataset_task
[2024-05-02 03:39:42,578] {logging_mixin.py:109} INFO - Running <TaskInstance: ingest_data_bigquery_yt.download_dataset_task scheduled__2019-01-02T06:00:00+00:00 [running]> on host bef445d594dc
[2024-05-02 03:39:42,671] {warnings.py:99} WARNING - /home/***/.local/lib/python3.6/site-packages/***/utils/context.py:152: AirflowContextDeprecationWarning: Accessing 'execution_date' from the template is deprecated and will be removed in a future version. Please use 'data_interval_start' or 'logical_date' instead.
  warnings.warn(_create_deprecation_warning(key, self._deprecation_replacements[key]))

[2024-05-02 03:39:42,754] {taskinstance.py:1426} INFO - Exporting the following env vars:
AIRFLOW_CTX_DAG_OWNER=***
AIRFLOW_CTX_DAG_ID=ingest_data_bigquery_yt
AIRFLOW_CTX_TASK_ID=download_dataset_task
AIRFLOW_CTX_EXECUTION_DATE=2019-01-02T06:00:00+00:00
AIRFLOW_CTX_DAG_RUN_ID=scheduled__2019-01-02T06:00:00+00:00
[2024-05-02 03:39:42,755] {subprocess.py:62} INFO - Tmp dir root location: 
 /tmp
[2024-05-02 03:39:42,756] {subprocess.py:74} INFO - Running command: ['bash', '-c', 'curl -sSL https://github.com/DataTalksClub/nyc-tlc-data/releases/download/yellow/yellow_tripdata_2019-01.csv.gz > /opt/***/raw_data/yellowtaxi_tripdata_2019-01.csv.gz | gzip -d > /opt/***/raw_data/yellowtaxi_tripdata_2019-01.csv && rm /opt/***/raw_data/yellowtaxi_tripdata_2019-01.csv.gz']
[2024-05-02 03:39:42,912] {subprocess.py:85} INFO - Output:
[2024-05-02 03:39:43,031] {subprocess.py:89} INFO - 
[2024-05-02 03:39:43,031] {subprocess.py:89} INFO - gzip: stdin: unexpected end of file
[2024-05-02 03:39:46,991] {subprocess.py:93} INFO - Command exited with return code 1
[2024-05-02 03:39:47,039] {taskinstance.py:1700} ERROR - Task failed with exception
Traceback (most recent call last):
  File "/home/airflow/.local/lib/python3.6/site-packages/airflow/models/taskinstance.py", line 1329, in _run_raw_task
    self._execute_task_with_callbacks(context)
  File "/home/airflow/.local/lib/python3.6/site-packages/airflow/models/taskinstance.py", line 1455, in _execute_task_with_callbacks
    result = self._execute_task(context, self.task)
  File "/home/airflow/.local/lib/python3.6/site-packages/airflow/models/taskinstance.py", line 1511, in _execute_task
    result = execute_callable(context=context)
  File "/home/airflow/.local/lib/python3.6/site-packages/airflow/operators/bash.py", line 188, in execute
    f'Bash command failed. The command returned a non-zero exit code {result.exit_code}.'
airflow.exceptions.AirflowException: Bash command failed. The command returned a non-zero exit code 1.
[2024-05-02 03:39:47,073] {taskinstance.py:1277} INFO - Marking task as UP_FOR_RETRY. dag_id=ingest_data_bigquery_yt, task_id=download_dataset_task, execution_date=20190102T060000, start_date=20240502T033942, end_date=20240502T033947
[2024-05-02 03:39:47,134] {standard_task_runner.py:92} ERROR - Failed to execute job 3690 for task download_dataset_task
Traceback (most recent call last):
  File "/home/airflow/.local/lib/python3.6/site-packages/airflow/task/task_runner/standard_task_runner.py", line 85, in _start_by_fork
    args.func(args, dag=self.dag)
  File "/home/airflow/.local/lib/python3.6/site-packages/airflow/cli/cli_parser.py", line 48, in command
    return func(*args, **kwargs)
  File "/home/airflow/.local/lib/python3.6/site-packages/airflow/utils/cli.py", line 92, in wrapper
    return f(*args, **kwargs)
  File "/home/airflow/.local/lib/python3.6/site-packages/airflow/cli/commands/task_command.py", line 298, in task_run
    _run_task_by_selected_method(args, dag, ti)
  File "/home/airflow/.local/lib/python3.6/site-packages/airflow/cli/commands/task_command.py", line 107, in _run_task_by_selected_method
    _run_raw_task(args, ti)
  File "/home/airflow/.local/lib/python3.6/site-packages/airflow/cli/commands/task_command.py", line 184, in _run_raw_task
    error_file=args.error_file,
  File "/home/airflow/.local/lib/python3.6/site-packages/airflow/utils/session.py", line 70, in wrapper
    return func(*args, session=session, **kwargs)
  File "/home/airflow/.local/lib/python3.6/site-packages/airflow/models/taskinstance.py", line 1329, in _run_raw_task
    self._execute_task_with_callbacks(context)
  File "/home/airflow/.local/lib/python3.6/site-packages/airflow/models/taskinstance.py", line 1455, in _execute_task_with_callbacks
    result = self._execute_task(context, self.task)
  File "/home/airflow/.local/lib/python3.6/site-packages/airflow/models/taskinstance.py", line 1511, in _execute_task
    result = execute_callable(context=context)
  File "/home/airflow/.local/lib/python3.6/site-packages/airflow/operators/bash.py", line 188, in execute
    f'Bash command failed. The command returned a non-zero exit code {result.exit_code}.'
airflow.exceptions.AirflowException: Bash command failed. The command returned a non-zero exit code 1.
[2024-05-02 03:39:47,203] {local_task_job.py:154} INFO - Task exited with return code 1
[2024-05-02 03:39:47,726] {local_task_job.py:264} INFO - 0 downstream tasks scheduled from follow-on schedule check
[2024-05-02 03:57:52,076] {taskinstance.py:1032} INFO - Dependencies all met for <TaskInstance: ingest_data_bigquery_yt.download_dataset_task scheduled__2019-01-02T06:00:00+00:00 [queued]>
[2024-05-02 03:57:52,119] {taskinstance.py:1032} INFO - Dependencies all met for <TaskInstance: ingest_data_bigquery_yt.download_dataset_task scheduled__2019-01-02T06:00:00+00:00 [queued]>
[2024-05-02 03:57:52,120] {taskinstance.py:1238} INFO - 
--------------------------------------------------------------------------------
[2024-05-02 03:57:52,120] {taskinstance.py:1239} INFO - Starting attempt 1 of 2
[2024-05-02 03:57:52,121] {taskinstance.py:1240} INFO - 
--------------------------------------------------------------------------------
[2024-05-02 03:57:52,175] {taskinstance.py:1259} INFO - Executing <Task(BashOperator): download_dataset_task> on 2019-01-02 06:00:00+00:00
[2024-05-02 03:57:52,200] {standard_task_runner.py:52} INFO - Started process 4689 to run task
[2024-05-02 03:57:52,220] {standard_task_runner.py:76} INFO - Running: ['***', 'tasks', 'run', 'ingest_data_bigquery_yt', 'download_dataset_task', 'scheduled__2019-01-02T06:00:00+00:00', '--job-id', '3705', '--raw', '--subdir', 'DAGS_FOLDER/data_ingestion_gcs_yt_dag.py', '--cfg-path', '/tmp/tmpamnbcqz8', '--error-file', '/tmp/tmp_yiklwh_']
[2024-05-02 03:57:52,258] {standard_task_runner.py:77} INFO - Job 3705: Subtask download_dataset_task
[2024-05-02 03:57:52,398] {logging_mixin.py:109} INFO - Running <TaskInstance: ingest_data_bigquery_yt.download_dataset_task scheduled__2019-01-02T06:00:00+00:00 [running]> on host bef445d594dc
[2024-05-02 03:57:52,528] {warnings.py:99} WARNING - /home/***/.local/lib/python3.6/site-packages/***/utils/context.py:152: AirflowContextDeprecationWarning: Accessing 'execution_date' from the template is deprecated and will be removed in a future version. Please use 'data_interval_start' or 'logical_date' instead.
  warnings.warn(_create_deprecation_warning(key, self._deprecation_replacements[key]))

[2024-05-02 03:57:52,599] {taskinstance.py:1426} INFO - Exporting the following env vars:
AIRFLOW_CTX_DAG_OWNER=***
AIRFLOW_CTX_DAG_ID=ingest_data_bigquery_yt
AIRFLOW_CTX_TASK_ID=download_dataset_task
AIRFLOW_CTX_EXECUTION_DATE=2019-01-02T06:00:00+00:00
AIRFLOW_CTX_DAG_RUN_ID=scheduled__2019-01-02T06:00:00+00:00
[2024-05-02 03:57:52,601] {subprocess.py:62} INFO - Tmp dir root location: 
 /tmp
[2024-05-02 03:57:52,603] {subprocess.py:74} INFO - Running command: ['bash', '-c', 'curl -sSL https://github.com/DataTalksClub/nyc-tlc-data/releases/download/yellow/yellow_tripdata_2019-01.csv.gz > /opt/***/raw_data/yellowtaxi_tripdata_2019-01.csv.gz | gzip -d > /opt/***/raw_data/yellowtaxi_tripdata_2019-01.csv && rm /opt/***/raw_data/yellowtaxi_tripdata_2019-01.csv.gz']
[2024-05-02 03:57:52,686] {subprocess.py:85} INFO - Output:
[2024-05-02 03:57:52,793] {subprocess.py:89} INFO - 
[2024-05-02 03:57:52,794] {subprocess.py:89} INFO - gzip: stdin: unexpected end of file
[2024-05-02 03:57:56,656] {subprocess.py:93} INFO - Command exited with return code 1
[2024-05-02 03:57:56,720] {taskinstance.py:1700} ERROR - Task failed with exception
Traceback (most recent call last):
  File "/home/airflow/.local/lib/python3.6/site-packages/airflow/models/taskinstance.py", line 1329, in _run_raw_task
    self._execute_task_with_callbacks(context)
  File "/home/airflow/.local/lib/python3.6/site-packages/airflow/models/taskinstance.py", line 1455, in _execute_task_with_callbacks
    result = self._execute_task(context, self.task)
  File "/home/airflow/.local/lib/python3.6/site-packages/airflow/models/taskinstance.py", line 1511, in _execute_task
    result = execute_callable(context=context)
  File "/home/airflow/.local/lib/python3.6/site-packages/airflow/operators/bash.py", line 188, in execute
    f'Bash command failed. The command returned a non-zero exit code {result.exit_code}.'
airflow.exceptions.AirflowException: Bash command failed. The command returned a non-zero exit code 1.
[2024-05-02 03:57:56,730] {taskinstance.py:1277} INFO - Marking task as UP_FOR_RETRY. dag_id=ingest_data_bigquery_yt, task_id=download_dataset_task, execution_date=20190102T060000, start_date=20240502T035752, end_date=20240502T035756
[2024-05-02 03:57:56,800] {standard_task_runner.py:92} ERROR - Failed to execute job 3705 for task download_dataset_task
Traceback (most recent call last):
  File "/home/airflow/.local/lib/python3.6/site-packages/airflow/task/task_runner/standard_task_runner.py", line 85, in _start_by_fork
    args.func(args, dag=self.dag)
  File "/home/airflow/.local/lib/python3.6/site-packages/airflow/cli/cli_parser.py", line 48, in command
    return func(*args, **kwargs)
  File "/home/airflow/.local/lib/python3.6/site-packages/airflow/utils/cli.py", line 92, in wrapper
    return f(*args, **kwargs)
  File "/home/airflow/.local/lib/python3.6/site-packages/airflow/cli/commands/task_command.py", line 298, in task_run
    _run_task_by_selected_method(args, dag, ti)
  File "/home/airflow/.local/lib/python3.6/site-packages/airflow/cli/commands/task_command.py", line 107, in _run_task_by_selected_method
    _run_raw_task(args, ti)
  File "/home/airflow/.local/lib/python3.6/site-packages/airflow/cli/commands/task_command.py", line 184, in _run_raw_task
    error_file=args.error_file,
  File "/home/airflow/.local/lib/python3.6/site-packages/airflow/utils/session.py", line 70, in wrapper
    return func(*args, session=session, **kwargs)
  File "/home/airflow/.local/lib/python3.6/site-packages/airflow/models/taskinstance.py", line 1329, in _run_raw_task
    self._execute_task_with_callbacks(context)
  File "/home/airflow/.local/lib/python3.6/site-packages/airflow/models/taskinstance.py", line 1455, in _execute_task_with_callbacks
    result = self._execute_task(context, self.task)
  File "/home/airflow/.local/lib/python3.6/site-packages/airflow/models/taskinstance.py", line 1511, in _execute_task
    result = execute_callable(context=context)
  File "/home/airflow/.local/lib/python3.6/site-packages/airflow/operators/bash.py", line 188, in execute
    f'Bash command failed. The command returned a non-zero exit code {result.exit_code}.'
airflow.exceptions.AirflowException: Bash command failed. The command returned a non-zero exit code 1.
[2024-05-02 03:57:56,891] {local_task_job.py:154} INFO - Task exited with return code 1
[2024-05-02 03:57:57,402] {local_task_job.py:264} INFO - 0 downstream tasks scheduled from follow-on schedule check
[2024-05-02 17:52:35,844] {taskinstance.py:1032} INFO - Dependencies all met for <TaskInstance: ingest_data_bigquery_yt.download_dataset_task scheduled__2019-01-02T06:00:00+00:00 [queued]>
[2024-05-02 17:52:35,936] {taskinstance.py:1032} INFO - Dependencies all met for <TaskInstance: ingest_data_bigquery_yt.download_dataset_task scheduled__2019-01-02T06:00:00+00:00 [queued]>
[2024-05-02 17:52:35,936] {taskinstance.py:1238} INFO - 
--------------------------------------------------------------------------------
[2024-05-02 17:52:35,947] {taskinstance.py:1239} INFO - Starting attempt 1 of 2
[2024-05-02 17:52:35,947] {taskinstance.py:1240} INFO - 
--------------------------------------------------------------------------------
[2024-05-02 17:52:36,026] {taskinstance.py:1259} INFO - Executing <Task(BashOperator): download_dataset_task> on 2019-01-02 06:00:00+00:00
[2024-05-02 17:52:36,071] {standard_task_runner.py:52} INFO - Started process 4109 to run task
[2024-05-02 17:52:36,128] {standard_task_runner.py:76} INFO - Running: ['***', 'tasks', 'run', 'ingest_data_bigquery_yt', 'download_dataset_task', 'scheduled__2019-01-02T06:00:00+00:00', '--job-id', '3804', '--raw', '--subdir', 'DAGS_FOLDER/data_ingestion_gcs_yt_dag.py', '--cfg-path', '/tmp/tmp3xdr0yqg', '--error-file', '/tmp/tmpu8u6hqp1']
[2024-05-02 17:52:36,164] {standard_task_runner.py:77} INFO - Job 3804: Subtask download_dataset_task
[2024-05-02 17:52:36,495] {logging_mixin.py:109} INFO - Running <TaskInstance: ingest_data_bigquery_yt.download_dataset_task scheduled__2019-01-02T06:00:00+00:00 [running]> on host 1ed1a38cd1e3
[2024-05-02 17:52:36,624] {warnings.py:99} WARNING - /home/***/.local/lib/python3.6/site-packages/***/utils/context.py:152: AirflowContextDeprecationWarning: Accessing 'execution_date' from the template is deprecated and will be removed in a future version. Please use 'data_interval_start' or 'logical_date' instead.
  warnings.warn(_create_deprecation_warning(key, self._deprecation_replacements[key]))

[2024-05-02 17:52:36,691] {taskinstance.py:1426} INFO - Exporting the following env vars:
AIRFLOW_CTX_DAG_OWNER=***
AIRFLOW_CTX_DAG_ID=ingest_data_bigquery_yt
AIRFLOW_CTX_TASK_ID=download_dataset_task
AIRFLOW_CTX_EXECUTION_DATE=2019-01-02T06:00:00+00:00
AIRFLOW_CTX_DAG_RUN_ID=scheduled__2019-01-02T06:00:00+00:00
[2024-05-02 17:52:36,693] {subprocess.py:62} INFO - Tmp dir root location: 
 /tmp
[2024-05-02 17:52:36,694] {subprocess.py:74} INFO - Running command: ['bash', '-c', 'curl -sSL https://github.com/DataTalksClub/nyc-tlc-data/releases/download/yellow/yellow_tripdata_2019-01.csv.gz > /opt/***/raw_data/yellowtaxi_tripdata_2019-01.csv.gz && gunzip /opt/***/raw_data/yellowtaxi_tripdata_2019-01.csv.gz']
[2024-05-02 17:52:36,800] {subprocess.py:85} INFO - Output:
[2024-05-02 17:53:11,234] {subprocess.py:89} INFO - 
[2024-05-02 17:53:11,235] {subprocess.py:89} INFO - gzip: /opt/***/raw_data/yellowtaxi_tripdata_2019-01.csv: No space left on device
[2024-05-02 17:53:11,436] {subprocess.py:93} INFO - Command exited with return code 1
[2024-05-02 17:53:11,831] {taskinstance.py:1700} ERROR - Task failed with exception
Traceback (most recent call last):
  File "/home/airflow/.local/lib/python3.6/site-packages/airflow/models/taskinstance.py", line 1329, in _run_raw_task
    self._execute_task_with_callbacks(context)
  File "/home/airflow/.local/lib/python3.6/site-packages/airflow/models/taskinstance.py", line 1455, in _execute_task_with_callbacks
    result = self._execute_task(context, self.task)
  File "/home/airflow/.local/lib/python3.6/site-packages/airflow/models/taskinstance.py", line 1511, in _execute_task
    result = execute_callable(context=context)
  File "/home/airflow/.local/lib/python3.6/site-packages/airflow/operators/bash.py", line 188, in execute
    f'Bash command failed. The command returned a non-zero exit code {result.exit_code}.'
airflow.exceptions.AirflowException: Bash command failed. The command returned a non-zero exit code 1.
[2024-05-02 17:53:11,898] {taskinstance.py:1277} INFO - Marking task as UP_FOR_RETRY. dag_id=ingest_data_bigquery_yt, task_id=download_dataset_task, execution_date=20190102T060000, start_date=20240502T175235, end_date=20240502T175311
[2024-05-02 17:53:11,954] {standard_task_runner.py:92} ERROR - Failed to execute job 3804 for task download_dataset_task
Traceback (most recent call last):
  File "/home/airflow/.local/lib/python3.6/site-packages/airflow/task/task_runner/standard_task_runner.py", line 85, in _start_by_fork
    args.func(args, dag=self.dag)
  File "/home/airflow/.local/lib/python3.6/site-packages/airflow/cli/cli_parser.py", line 48, in command
    return func(*args, **kwargs)
  File "/home/airflow/.local/lib/python3.6/site-packages/airflow/utils/cli.py", line 92, in wrapper
    return f(*args, **kwargs)
  File "/home/airflow/.local/lib/python3.6/site-packages/airflow/cli/commands/task_command.py", line 298, in task_run
    _run_task_by_selected_method(args, dag, ti)
  File "/home/airflow/.local/lib/python3.6/site-packages/airflow/cli/commands/task_command.py", line 107, in _run_task_by_selected_method
    _run_raw_task(args, ti)
  File "/home/airflow/.local/lib/python3.6/site-packages/airflow/cli/commands/task_command.py", line 184, in _run_raw_task
    error_file=args.error_file,
  File "/home/airflow/.local/lib/python3.6/site-packages/airflow/utils/session.py", line 70, in wrapper
    return func(*args, session=session, **kwargs)
  File "/home/airflow/.local/lib/python3.6/site-packages/airflow/models/taskinstance.py", line 1329, in _run_raw_task
    self._execute_task_with_callbacks(context)
  File "/home/airflow/.local/lib/python3.6/site-packages/airflow/models/taskinstance.py", line 1455, in _execute_task_with_callbacks
    result = self._execute_task(context, self.task)
  File "/home/airflow/.local/lib/python3.6/site-packages/airflow/models/taskinstance.py", line 1511, in _execute_task
    result = execute_callable(context=context)
  File "/home/airflow/.local/lib/python3.6/site-packages/airflow/operators/bash.py", line 188, in execute
    f'Bash command failed. The command returned a non-zero exit code {result.exit_code}.'
airflow.exceptions.AirflowException: Bash command failed. The command returned a non-zero exit code 1.
[2024-05-02 17:53:12,029] {local_task_job.py:154} INFO - Task exited with return code 1
[2024-05-02 17:53:12,236] {local_task_job.py:264} INFO - 0 downstream tasks scheduled from follow-on schedule check
[2024-05-03 08:54:16,849] {taskinstance.py:1032} INFO - Dependencies all met for <TaskInstance: ingest_data_bigquery_yt.download_dataset_task scheduled__2019-01-02T06:00:00+00:00 [queued]>
[2024-05-03 08:54:16,922] {taskinstance.py:1032} INFO - Dependencies all met for <TaskInstance: ingest_data_bigquery_yt.download_dataset_task scheduled__2019-01-02T06:00:00+00:00 [queued]>
[2024-05-03 08:54:16,928] {taskinstance.py:1238} INFO - 
--------------------------------------------------------------------------------
[2024-05-03 08:54:16,928] {taskinstance.py:1239} INFO - Starting attempt 1 of 2
[2024-05-03 08:54:16,929] {taskinstance.py:1240} INFO - 
--------------------------------------------------------------------------------
[2024-05-03 08:54:16,997] {taskinstance.py:1259} INFO - Executing <Task(BashOperator): download_dataset_task> on 2019-01-02 06:00:00+00:00
[2024-05-03 08:54:17,012] {standard_task_runner.py:52} INFO - Started process 1385 to run task
[2024-05-03 08:54:17,038] {standard_task_runner.py:76} INFO - Running: ['***', 'tasks', 'run', 'ingest_data_bigquery_yt', 'download_dataset_task', 'scheduled__2019-01-02T06:00:00+00:00', '--job-id', '3925', '--raw', '--subdir', 'DAGS_FOLDER/data_ingestion_gcs_yt_dag.py', '--cfg-path', '/tmp/tmphqse4nmz', '--error-file', '/tmp/tmplhvp5lsh']
[2024-05-03 08:54:17,077] {standard_task_runner.py:77} INFO - Job 3925: Subtask download_dataset_task
[2024-05-03 08:54:17,304] {logging_mixin.py:109} INFO - Running <TaskInstance: ingest_data_bigquery_yt.download_dataset_task scheduled__2019-01-02T06:00:00+00:00 [running]> on host 5bfe1025092b
[2024-05-03 08:54:17,407] {warnings.py:99} WARNING - /home/***/.local/lib/python3.6/site-packages/***/utils/context.py:152: AirflowContextDeprecationWarning: Accessing 'execution_date' from the template is deprecated and will be removed in a future version. Please use 'data_interval_start' or 'logical_date' instead.
  warnings.warn(_create_deprecation_warning(key, self._deprecation_replacements[key]))

[2024-05-03 08:54:17,490] {taskinstance.py:1426} INFO - Exporting the following env vars:
AIRFLOW_CTX_DAG_OWNER=***
AIRFLOW_CTX_DAG_ID=ingest_data_bigquery_yt
AIRFLOW_CTX_TASK_ID=download_dataset_task
AIRFLOW_CTX_EXECUTION_DATE=2019-01-02T06:00:00+00:00
AIRFLOW_CTX_DAG_RUN_ID=scheduled__2019-01-02T06:00:00+00:00
[2024-05-03 08:54:17,493] {subprocess.py:62} INFO - Tmp dir root location: 
 /tmp
[2024-05-03 08:54:17,494] {subprocess.py:74} INFO - Running command: ['bash', '-c', 'curl -sSL https://github.com/DataTalksClub/nyc-tlc-data/releases/download/yellow/yellow_tripdata_2019-01.csv.gz > /opt/***/raw_data/yellowtaxi_tripdata_2019-01.csv.gz && gunzip /opt/***/raw_data/yellowtaxi_tripdata_2019-01.csv.gz']
[2024-05-03 08:54:17,553] {subprocess.py:85} INFO - Output:
[2024-05-03 08:54:49,121] {subprocess.py:89} INFO - 
[2024-05-03 08:54:49,121] {subprocess.py:89} INFO - gzip: /opt/***/raw_data/yellowtaxi_tripdata_2019-01.csv: No space left on device
[2024-05-03 08:54:49,380] {subprocess.py:93} INFO - Command exited with return code 1
[2024-05-03 08:54:49,442] {taskinstance.py:1700} ERROR - Task failed with exception
Traceback (most recent call last):
  File "/home/airflow/.local/lib/python3.6/site-packages/airflow/models/taskinstance.py", line 1329, in _run_raw_task
    self._execute_task_with_callbacks(context)
  File "/home/airflow/.local/lib/python3.6/site-packages/airflow/models/taskinstance.py", line 1455, in _execute_task_with_callbacks
    result = self._execute_task(context, self.task)
  File "/home/airflow/.local/lib/python3.6/site-packages/airflow/models/taskinstance.py", line 1511, in _execute_task
    result = execute_callable(context=context)
  File "/home/airflow/.local/lib/python3.6/site-packages/airflow/operators/bash.py", line 188, in execute
    f'Bash command failed. The command returned a non-zero exit code {result.exit_code}.'
airflow.exceptions.AirflowException: Bash command failed. The command returned a non-zero exit code 1.
[2024-05-03 08:54:49,479] {taskinstance.py:1277} INFO - Marking task as UP_FOR_RETRY. dag_id=ingest_data_bigquery_yt, task_id=download_dataset_task, execution_date=20190102T060000, start_date=20240503T085416, end_date=20240503T085449
[2024-05-03 08:54:49,639] {standard_task_runner.py:92} ERROR - Failed to execute job 3925 for task download_dataset_task
Traceback (most recent call last):
  File "/home/airflow/.local/lib/python3.6/site-packages/airflow/task/task_runner/standard_task_runner.py", line 85, in _start_by_fork
    args.func(args, dag=self.dag)
  File "/home/airflow/.local/lib/python3.6/site-packages/airflow/cli/cli_parser.py", line 48, in command
    return func(*args, **kwargs)
  File "/home/airflow/.local/lib/python3.6/site-packages/airflow/utils/cli.py", line 92, in wrapper
    return f(*args, **kwargs)
  File "/home/airflow/.local/lib/python3.6/site-packages/airflow/cli/commands/task_command.py", line 298, in task_run
    _run_task_by_selected_method(args, dag, ti)
  File "/home/airflow/.local/lib/python3.6/site-packages/airflow/cli/commands/task_command.py", line 107, in _run_task_by_selected_method
    _run_raw_task(args, ti)
  File "/home/airflow/.local/lib/python3.6/site-packages/airflow/cli/commands/task_command.py", line 184, in _run_raw_task
    error_file=args.error_file,
  File "/home/airflow/.local/lib/python3.6/site-packages/airflow/utils/session.py", line 70, in wrapper
    return func(*args, session=session, **kwargs)
  File "/home/airflow/.local/lib/python3.6/site-packages/airflow/models/taskinstance.py", line 1329, in _run_raw_task
    self._execute_task_with_callbacks(context)
  File "/home/airflow/.local/lib/python3.6/site-packages/airflow/models/taskinstance.py", line 1455, in _execute_task_with_callbacks
    result = self._execute_task(context, self.task)
  File "/home/airflow/.local/lib/python3.6/site-packages/airflow/models/taskinstance.py", line 1511, in _execute_task
    result = execute_callable(context=context)
  File "/home/airflow/.local/lib/python3.6/site-packages/airflow/operators/bash.py", line 188, in execute
    f'Bash command failed. The command returned a non-zero exit code {result.exit_code}.'
airflow.exceptions.AirflowException: Bash command failed. The command returned a non-zero exit code 1.
[2024-05-03 08:54:49,741] {local_task_job.py:154} INFO - Task exited with return code 1
[2024-05-03 08:54:50,008] {local_task_job.py:264} INFO - 0 downstream tasks scheduled from follow-on schedule check
[2024-05-03 09:50:38,643] {taskinstance.py:1032} INFO - Dependencies all met for <TaskInstance: ingest_data_bigquery_yt.download_dataset_task scheduled__2019-01-02T06:00:00+00:00 [queued]>
[2024-05-03 09:50:38,705] {taskinstance.py:1032} INFO - Dependencies all met for <TaskInstance: ingest_data_bigquery_yt.download_dataset_task scheduled__2019-01-02T06:00:00+00:00 [queued]>
[2024-05-03 09:50:38,706] {taskinstance.py:1238} INFO - 
--------------------------------------------------------------------------------
[2024-05-03 09:50:38,709] {taskinstance.py:1239} INFO - Starting attempt 1 of 3
[2024-05-03 09:50:38,709] {taskinstance.py:1240} INFO - 
--------------------------------------------------------------------------------
[2024-05-03 09:50:38,775] {taskinstance.py:1259} INFO - Executing <Task(BashOperator): download_dataset_task> on 2019-01-02 06:00:00+00:00
[2024-05-03 09:50:38,820] {standard_task_runner.py:52} INFO - Started process 612 to run task
[2024-05-03 09:50:38,839] {standard_task_runner.py:76} INFO - Running: ['***', 'tasks', 'run', 'ingest_data_bigquery_yt', 'download_dataset_task', 'scheduled__2019-01-02T06:00:00+00:00', '--job-id', '3997', '--raw', '--subdir', 'DAGS_FOLDER/data_ingstion_gcs_yt_dag.py', '--cfg-path', '/tmp/tmpcsc2nn1k', '--error-file', '/tmp/tmpmeth09_1']
[2024-05-03 09:50:38,902] {standard_task_runner.py:77} INFO - Job 3997: Subtask download_dataset_task
[2024-05-03 09:50:39,263] {logging_mixin.py:109} INFO - Running <TaskInstance: ingest_data_bigquery_yt.download_dataset_task scheduled__2019-01-02T06:00:00+00:00 [running]> on host b81c18b6cf72
[2024-05-03 09:50:39,544] {warnings.py:99} WARNING - /home/***/.local/lib/python3.6/site-packages/***/utils/context.py:152: AirflowContextDeprecationWarning: Accessing 'execution_date' from the template is deprecated and will be removed in a future version. Please use 'data_interval_start' or 'logical_date' instead.
  warnings.warn(_create_deprecation_warning(key, self._deprecation_replacements[key]))

[2024-05-03 09:50:39,677] {taskinstance.py:1426} INFO - Exporting the following env vars:
AIRFLOW_CTX_DAG_OWNER=***
AIRFLOW_CTX_DAG_ID=ingest_data_bigquery_yt
AIRFLOW_CTX_TASK_ID=download_dataset_task
AIRFLOW_CTX_EXECUTION_DATE=2019-01-02T06:00:00+00:00
AIRFLOW_CTX_DAG_RUN_ID=scheduled__2019-01-02T06:00:00+00:00
[2024-05-03 09:50:39,703] {subprocess.py:62} INFO - Tmp dir root location: 
 /tmp
[2024-05-03 09:50:39,703] {subprocess.py:74} INFO - Running command: ['bash', '-c', 'curl -sSL https://github.com/DataTalksClub/nyc-tlc-data/releases/download/yellow/yellow_tripdata_2019-01.csv.gz > /opt/***/raw_data/yellowtaxi_tripdata_2019-01.csv.gz && gunzip /opt/***/raw_data/yellowtaxi_tripdata_2019-01.csv.gz']
[2024-05-03 09:50:39,824] {subprocess.py:85} INFO - Output:
[2024-05-03 09:51:01,821] {subprocess.py:89} INFO - 
[2024-05-03 09:51:01,821] {subprocess.py:89} INFO - gzip: /opt/***/raw_data/yellowtaxi_tripdata_2019-01.csv: No space left on device
[2024-05-03 09:51:02,060] {subprocess.py:93} INFO - Command exited with return code 1
[2024-05-03 09:51:02,132] {taskinstance.py:1700} ERROR - Task failed with exception
Traceback (most recent call last):
  File "/home/airflow/.local/lib/python3.6/site-packages/airflow/models/taskinstance.py", line 1329, in _run_raw_task
    self._execute_task_with_callbacks(context)
  File "/home/airflow/.local/lib/python3.6/site-packages/airflow/models/taskinstance.py", line 1455, in _execute_task_with_callbacks
    result = self._execute_task(context, self.task)
  File "/home/airflow/.local/lib/python3.6/site-packages/airflow/models/taskinstance.py", line 1511, in _execute_task
    result = execute_callable(context=context)
  File "/home/airflow/.local/lib/python3.6/site-packages/airflow/operators/bash.py", line 188, in execute
    f'Bash command failed. The command returned a non-zero exit code {result.exit_code}.'
airflow.exceptions.AirflowException: Bash command failed. The command returned a non-zero exit code 1.
[2024-05-03 09:51:02,175] {taskinstance.py:1277} INFO - Marking task as UP_FOR_RETRY. dag_id=ingest_data_bigquery_yt, task_id=download_dataset_task, execution_date=20190102T060000, start_date=20240503T095038, end_date=20240503T095102
[2024-05-03 09:51:02,716] {standard_task_runner.py:92} ERROR - Failed to execute job 3997 for task download_dataset_task
Traceback (most recent call last):
  File "/home/airflow/.local/lib/python3.6/site-packages/airflow/task/task_runner/standard_task_runner.py", line 85, in _start_by_fork
    args.func(args, dag=self.dag)
  File "/home/airflow/.local/lib/python3.6/site-packages/airflow/cli/cli_parser.py", line 48, in command
    return func(*args, **kwargs)
  File "/home/airflow/.local/lib/python3.6/site-packages/airflow/utils/cli.py", line 92, in wrapper
    return f(*args, **kwargs)
  File "/home/airflow/.local/lib/python3.6/site-packages/airflow/cli/commands/task_command.py", line 298, in task_run
    _run_task_by_selected_method(args, dag, ti)
  File "/home/airflow/.local/lib/python3.6/site-packages/airflow/cli/commands/task_command.py", line 107, in _run_task_by_selected_method
    _run_raw_task(args, ti)
  File "/home/airflow/.local/lib/python3.6/site-packages/airflow/cli/commands/task_command.py", line 184, in _run_raw_task
    error_file=args.error_file,
  File "/home/airflow/.local/lib/python3.6/site-packages/airflow/utils/session.py", line 70, in wrapper
    return func(*args, session=session, **kwargs)
  File "/home/airflow/.local/lib/python3.6/site-packages/airflow/models/taskinstance.py", line 1329, in _run_raw_task
    self._execute_task_with_callbacks(context)
  File "/home/airflow/.local/lib/python3.6/site-packages/airflow/models/taskinstance.py", line 1455, in _execute_task_with_callbacks
    result = self._execute_task(context, self.task)
  File "/home/airflow/.local/lib/python3.6/site-packages/airflow/models/taskinstance.py", line 1511, in _execute_task
    result = execute_callable(context=context)
  File "/home/airflow/.local/lib/python3.6/site-packages/airflow/operators/bash.py", line 188, in execute
    f'Bash command failed. The command returned a non-zero exit code {result.exit_code}.'
airflow.exceptions.AirflowException: Bash command failed. The command returned a non-zero exit code 1.
[2024-05-03 09:51:02,838] {local_task_job.py:154} INFO - Task exited with return code 1
[2024-05-03 09:51:03,271] {local_task_job.py:264} INFO - 0 downstream tasks scheduled from follow-on schedule check
[2024-05-03 16:39:46,752] {taskinstance.py:1032} INFO - Dependencies all met for <TaskInstance: ingest_data_bigquery_yt.download_dataset_task scheduled__2019-01-02T06:00:00+00:00 [queued]>
[2024-05-03 16:39:46,816] {taskinstance.py:1032} INFO - Dependencies all met for <TaskInstance: ingest_data_bigquery_yt.download_dataset_task scheduled__2019-01-02T06:00:00+00:00 [queued]>
[2024-05-03 16:39:46,816] {taskinstance.py:1238} INFO - 
--------------------------------------------------------------------------------
[2024-05-03 16:39:46,817] {taskinstance.py:1239} INFO - Starting attempt 1 of 3
[2024-05-03 16:39:46,817] {taskinstance.py:1240} INFO - 
--------------------------------------------------------------------------------
[2024-05-03 16:39:46,876] {taskinstance.py:1259} INFO - Executing <Task(BashOperator): download_dataset_task> on 2019-01-02 06:00:00+00:00
[2024-05-03 16:39:46,888] {standard_task_runner.py:52} INFO - Started process 271 to run task
[2024-05-03 16:39:46,934] {standard_task_runner.py:76} INFO - Running: ['***', 'tasks', 'run', 'ingest_data_bigquery_yt', 'download_dataset_task', 'scheduled__2019-01-02T06:00:00+00:00', '--job-id', '4214', '--raw', '--subdir', 'DAGS_FOLDER/data_ingstion_gcs_yt_dag.py', '--cfg-path', '/tmp/tmp2x43lmp7', '--error-file', '/tmp/tmpxj1ey5ef']
[2024-05-03 16:39:46,987] {standard_task_runner.py:77} INFO - Job 4214: Subtask download_dataset_task
[2024-05-03 16:39:47,271] {logging_mixin.py:109} INFO - Running <TaskInstance: ingest_data_bigquery_yt.download_dataset_task scheduled__2019-01-02T06:00:00+00:00 [running]> on host f0ab9bf9b587
[2024-05-03 16:39:47,540] {warnings.py:99} WARNING - /home/***/.local/lib/python3.6/site-packages/***/utils/context.py:152: AirflowContextDeprecationWarning: Accessing 'execution_date' from the template is deprecated and will be removed in a future version. Please use 'data_interval_start' or 'logical_date' instead.
  warnings.warn(_create_deprecation_warning(key, self._deprecation_replacements[key]))

[2024-05-03 16:39:47,759] {taskinstance.py:1426} INFO - Exporting the following env vars:
AIRFLOW_CTX_DAG_OWNER=***
AIRFLOW_CTX_DAG_ID=ingest_data_bigquery_yt
AIRFLOW_CTX_TASK_ID=download_dataset_task
AIRFLOW_CTX_EXECUTION_DATE=2019-01-02T06:00:00+00:00
AIRFLOW_CTX_DAG_RUN_ID=scheduled__2019-01-02T06:00:00+00:00
[2024-05-03 16:39:47,764] {subprocess.py:62} INFO - Tmp dir root location: 
 /tmp
[2024-05-03 16:39:47,772] {subprocess.py:74} INFO - Running command: ['bash', '-c', 'curl -sSL https://github.com/DataTalksClub/nyc-tlc-data/releases/download/yellow/yellow_tripdata_2019-01.csv.gz > /opt/***/raw_data/yellowtaxi_tripdata_2019-01.csv.gz && gunzip /opt/***/raw_data/yellowtaxi_tripdata_2019-01.csv.gz']
[2024-05-03 16:39:47,896] {subprocess.py:85} INFO - Output:
[2024-05-03 16:40:42,533] {subprocess.py:93} INFO - Command exited with return code 0
[2024-05-03 16:40:42,700] {taskinstance.py:1277} INFO - Marking task as SUCCESS. dag_id=ingest_data_bigquery_yt, task_id=download_dataset_task, execution_date=20190102T060000, start_date=20240503T163946, end_date=20240503T164042
[2024-05-03 16:40:42,752] {local_task_job.py:154} INFO - Task exited with return code 0
[2024-05-03 16:40:43,265] {local_task_job.py:264} INFO - 1 downstream tasks scheduled from follow-on schedule check
[2024-05-05 12:01:18,874] {taskinstance.py:1032} INFO - Dependencies all met for <TaskInstance: ingest_data_bigquery_yt.download_dataset_task scheduled__2019-01-02T06:00:00+00:00 [queued]>
[2024-05-05 12:01:18,968] {taskinstance.py:1032} INFO - Dependencies all met for <TaskInstance: ingest_data_bigquery_yt.download_dataset_task scheduled__2019-01-02T06:00:00+00:00 [queued]>
[2024-05-05 12:01:18,968] {taskinstance.py:1238} INFO - 
--------------------------------------------------------------------------------
[2024-05-05 12:01:18,968] {taskinstance.py:1239} INFO - Starting attempt 1 of 3
[2024-05-05 12:01:18,968] {taskinstance.py:1240} INFO - 
--------------------------------------------------------------------------------
[2024-05-05 12:01:19,052] {taskinstance.py:1259} INFO - Executing <Task(BashOperator): download_dataset_task> on 2019-01-02 06:00:00+00:00
[2024-05-05 12:01:19,108] {standard_task_runner.py:52} INFO - Started process 981 to run task
[2024-05-05 12:01:19,146] {standard_task_runner.py:76} INFO - Running: ['***', 'tasks', 'run', 'ingest_data_bigquery_yt', 'download_dataset_task', 'scheduled__2019-01-02T06:00:00+00:00', '--job-id', '4341', '--raw', '--subdir', 'DAGS_FOLDER/data_ingstion_gcs_yt_dag.py', '--cfg-path', '/tmp/tmp2qvpfa4x', '--error-file', '/tmp/tmp3yq0mkdc']
[2024-05-05 12:01:19,175] {standard_task_runner.py:77} INFO - Job 4341: Subtask download_dataset_task
[2024-05-05 12:01:19,434] {logging_mixin.py:109} INFO - Running <TaskInstance: ingest_data_bigquery_yt.download_dataset_task scheduled__2019-01-02T06:00:00+00:00 [running]> on host 19865117eb6d
[2024-05-05 12:01:19,625] {warnings.py:99} WARNING - /home/***/.local/lib/python3.6/site-packages/***/utils/context.py:152: AirflowContextDeprecationWarning: Accessing 'execution_date' from the template is deprecated and will be removed in a future version. Please use 'data_interval_start' or 'logical_date' instead.
  warnings.warn(_create_deprecation_warning(key, self._deprecation_replacements[key]))

[2024-05-05 12:01:19,685] {taskinstance.py:1426} INFO - Exporting the following env vars:
AIRFLOW_CTX_DAG_OWNER=***
AIRFLOW_CTX_DAG_ID=ingest_data_bigquery_yt
AIRFLOW_CTX_TASK_ID=download_dataset_task
AIRFLOW_CTX_EXECUTION_DATE=2019-01-02T06:00:00+00:00
AIRFLOW_CTX_DAG_RUN_ID=scheduled__2019-01-02T06:00:00+00:00
[2024-05-05 12:01:19,686] {subprocess.py:62} INFO - Tmp dir root location: 
 /tmp
[2024-05-05 12:01:19,687] {subprocess.py:74} INFO - Running command: ['bash', '-c', 'curl -sSL https://github.com/DataTalksClub/nyc-tlc-data/releases/download/yellow/yellow_tripdata_2019-01.csv.gz > /opt/***/raw_data/yellowtaxi_tripdata_2019-01.csv.gz && gunzip /opt/***/raw_data/yellowtaxi_tripdata_2019-01.csv.gz']
[2024-05-05 12:01:19,784] {subprocess.py:85} INFO - Output:
[2024-05-05 12:02:12,743] {subprocess.py:93} INFO - Command exited with return code 0
[2024-05-05 12:02:12,969] {taskinstance.py:1277} INFO - Marking task as SUCCESS. dag_id=ingest_data_bigquery_yt, task_id=download_dataset_task, execution_date=20190102T060000, start_date=20240505T120118, end_date=20240505T120212
[2024-05-05 12:02:13,152] {local_task_job.py:154} INFO - Task exited with return code 0
[2024-05-05 12:02:13,528] {local_task_job.py:264} INFO - 1 downstream tasks scheduled from follow-on schedule check
[2024-05-06 07:39:50,022] {taskinstance.py:1032} INFO - Dependencies all met for <TaskInstance: ingest_data_bigquery_yt.download_dataset_task scheduled__2019-01-02T06:00:00+00:00 [queued]>
[2024-05-06 07:39:50,101] {taskinstance.py:1032} INFO - Dependencies all met for <TaskInstance: ingest_data_bigquery_yt.download_dataset_task scheduled__2019-01-02T06:00:00+00:00 [queued]>
[2024-05-06 07:39:50,102] {taskinstance.py:1238} INFO - 
--------------------------------------------------------------------------------
[2024-05-06 07:39:50,102] {taskinstance.py:1239} INFO - Starting attempt 1 of 3
[2024-05-06 07:39:50,102] {taskinstance.py:1240} INFO - 
--------------------------------------------------------------------------------
[2024-05-06 07:39:50,170] {taskinstance.py:1259} INFO - Executing <Task(BashOperator): download_dataset_task> on 2019-01-02 06:00:00+00:00
[2024-05-06 07:39:50,209] {standard_task_runner.py:76} INFO - Running: ['***', 'tasks', 'run', 'ingest_data_bigquery_yt', 'download_dataset_task', 'scheduled__2019-01-02T06:00:00+00:00', '--job-id', '4492', '--raw', '--subdir', 'DAGS_FOLDER/data_ingstion_gcs_yt_dag.py', '--cfg-path', '/tmp/tmpn84sg1ot', '--error-file', '/tmp/tmpak8rod3_']
[2024-05-06 07:39:50,187] {standard_task_runner.py:52} INFO - Started process 3205 to run task
[2024-05-06 07:39:50,261] {standard_task_runner.py:77} INFO - Job 4492: Subtask download_dataset_task
[2024-05-06 07:39:50,484] {logging_mixin.py:109} INFO - Running <TaskInstance: ingest_data_bigquery_yt.download_dataset_task scheduled__2019-01-02T06:00:00+00:00 [running]> on host 1aa5194a14e3
[2024-05-06 07:39:50,653] {warnings.py:99} WARNING - /home/***/.local/lib/python3.6/site-packages/***/utils/context.py:152: AirflowContextDeprecationWarning: Accessing 'execution_date' from the template is deprecated and will be removed in a future version. Please use 'data_interval_start' or 'logical_date' instead.
  warnings.warn(_create_deprecation_warning(key, self._deprecation_replacements[key]))

[2024-05-06 07:39:50,735] {taskinstance.py:1426} INFO - Exporting the following env vars:
AIRFLOW_CTX_DAG_OWNER=***
AIRFLOW_CTX_DAG_ID=ingest_data_bigquery_yt
AIRFLOW_CTX_TASK_ID=download_dataset_task
AIRFLOW_CTX_EXECUTION_DATE=2019-01-02T06:00:00+00:00
AIRFLOW_CTX_DAG_RUN_ID=scheduled__2019-01-02T06:00:00+00:00
[2024-05-06 07:39:50,738] {subprocess.py:62} INFO - Tmp dir root location: 
 /tmp
[2024-05-06 07:39:50,741] {subprocess.py:74} INFO - Running command: ['bash', '-c', 'curl -sSL https://github.com/DataTalksClub/nyc-tlc-data/releases/download/yellow/yellow_tripdata_2019-01.csv.gz > /opt/***/raw_data/yellowtaxi_tripdata_2019-01.csv.gz && gunzip /opt/***/raw_data/yellowtaxi_tripdata_2019-01.csv.gz']
[2024-05-06 07:39:50,780] {subprocess.py:85} INFO - Output:
[2024-05-06 07:40:33,742] {subprocess.py:93} INFO - Command exited with return code 0
[2024-05-06 07:40:34,009] {taskinstance.py:1277} INFO - Marking task as SUCCESS. dag_id=ingest_data_bigquery_yt, task_id=download_dataset_task, execution_date=20190102T060000, start_date=20240506T073950, end_date=20240506T074034
[2024-05-06 07:40:34,308] {local_task_job.py:154} INFO - Task exited with return code 0
[2024-05-06 07:40:34,694] {local_task_job.py:264} INFO - 1 downstream tasks scheduled from follow-on schedule check
